Workbook
Name ___a1: {"PR1","pr1",TRUE,"Sch PR-1"}
Name ___a11: {"PR1","pr1",TRUE,"Sch PR-1"}
Name ___a16: {"PR1","pr1",TRUE,"Sch PR-1"}
Name ___a17: {"PR1","pr1",TRUE,"Sch PR-1"}
Name ___a18: {"PR1","pr1",TRUE,"Sch PR-1"}
Name ___a19: {"PR1","pr1",TRUE,"Sch PR-1"}
Name ___a2: {"PR1","pr1",TRUE,"Sch PR-1"}
Name ___a21: {"PR1","pr1",TRUE,"Sch PR-1"}
Name ___a4: {"PR1","pr1",TRUE,"Sch PR-1"}
Name ___a5: {"PR1","pr1",TRUE,"Sch PR-1"}
Name ___a6: {"PR1","pr1",TRUE,"Sch PR-1"}
Name ___a7: {"PR1","pr1",TRUE,"Sch PR-1"}
Name ___a8: {"PR1","pr1",TRUE,"Sch PR-1"}
Name __123Graph_A: [1]XOM!#REF!
Name __123Graph_AChart1: [2]P!#REF!
Name __123Graph_ACurrent: [2]P!#REF!
Name __123Graph_AGRAPH1: [3]A!#REF!
Name __123Graph_AGRAPH1: [4]A!#REF!
Name __123Graph_B: [1]XOM!#REF!
Name __123Graph_BGRAPH1: [3]A!#REF!
Name __123Graph_BGRAPH1: [4]A!#REF!
Name __123Graph_CGRAPH1: [3]A!#REF!
Name __123Graph_CGRAPH1: [4]A!#REF!
Name __123Graph_DGRAPH1: [3]A!#REF!
Name __123Graph_DGRAPH1: [4]A!#REF!
Name __123Graph_X: [1]XOM!#REF!
Name __123Graph_XGRAPH1: [3]A!#REF!
Name __123Graph_XGRAPH1: [4]A!#REF!
Name __a1: {"PR1","pr1",TRUE,"Sch PR-1"}
Name __a11: {"PR1","pr1",TRUE,"Sch PR-1"}
Name __a16: {"PR1","pr1",TRUE,"Sch PR-1"}
Name __a17: {"PR1","pr1",TRUE,"Sch PR-1"}
Name __a18: {"PR1","pr1",TRUE,"Sch PR-1"}
Name __a19: {"PR1","pr1",TRUE,"Sch PR-1"}
Name __a2: {"PR1","pr1",TRUE,"Sch PR-1"}
Name __a21: {"PR1","pr1",TRUE,"Sch PR-1"}
Name __a4: {"PR1","pr1",TRUE,"Sch PR-1"}
Name __a5: {"PR1","pr1",TRUE,"Sch PR-1"}
Name __a6: {"PR1","pr1",TRUE,"Sch PR-1"}
Name __a7: {"PR1","pr1",TRUE,"Sch PR-1"}
Name __a8: {"PR1","pr1",TRUE,"Sch PR-1"}
Name __FDS_HYPERLINK_TOGGLE_STATE__: "ON"
Name __FDS_UNIQUE_RANGE_ID_GENERATOR_COUNTER: 28
Name __FDS_UNIQUE_RANGE_ID_GENERATOR_COUNTER: 28
Name __FDS_USED_FOR_REUSING_RANGE_IDS_RECYCLE: {16,16,16,16,16,16,16,16,16,16,16}
Name __FDS_USED_FOR_REUSING_RANGE_IDS_RECYCLE: {16,16,16,16,16,16,16,16,16,16,16}
Name __IntlFixup: TRUE
Name _1__123Graph_AR_M_MARG: [2]P!#REF!
Name _1_0HS: [5]EPS!#REF!
Name _1_0HS: [6]EPS!#REF!
Name _1999E: '[7]P&L'!$Q$9:$Q$68
Name _1999E: '[8]P&L'!$Q$9:$Q$68
Name _1H_96: "assumpt"
Name _1Q97A: '[7]P&L'!$C$9:$C$68
Name _1Q97A: '[8]P&L'!$C$9:$C$68
Name _1Q98A: '[7]P&L'!$H$9:$H$68
Name _1Q98A: '[8]P&L'!$H$9:$H$68
Name _1Q99A: '[7]P&L'!$M$9:$M$68
Name _1Q99A: '[8]P&L'!$M$9:$M$68
Name _2__123Graph_AR_M_MARG: [2]P!#REF!

Sheet XN
A1: Code | B1: ETN US | C1: Please enter the ticker in B1, e.g. 700 HK
A2: Last annual report | B2: 46022 | C2: Please enter the date in B2, e.g. 2020/3/31
A3: Start year | B3: 2024
A4: Currency | B4: US$
A5: Unit | B5: mn
A6: =B4&" "&B5 -> US$ mn | B6: =TEXT(DATE($B$3+1,MONTH($B$2),DAY($B$2)),"mmm-yy")&IF($B$3+1>YEAR($B$2),"E","A") -> Dec-25A | C6: =TEXT(DATE($B$3+2,MONTH($B$2),DAY($B$2)),"mmm-yy")&IF($B$3+2>YEAR($B$2),"E","A") -> Dec-26E | D6: =TEXT(DATE($B$3+3,MONTH($B$2),DAY($B$2)),"mmm-yy")&IF($B$3+3>YEAR($B$2),"E","A") -> Dec-27E | E6: =TEXT(DATE($B$3+3,MONTH($B$2),DAY($B$2)),"mmm-yy")&IF($B$3+3>YEAR($B$2),"E","A") -> Dec-27E
A7: P&L
A8: Revenue | B8: =SumFS!M6 -> 27450 | C8: =SumFS!N6 -> 29504.545 | D8: =SumFS!O6 -> 31735.358 | E8: =SumFS!P6 -> 34158.609
A9: (+/-) | B9: =DCF!M6 -> 0.10338452 | C9: =DCF!N6 -> 0.074846812 | D9: =DCF!O6 -> 0.075609147 | E9: =DCF!P6 -> 0.076358051 | N9: ='[149]PL-CF-BS'!B115 -> #REF!
A10: Net profit | B10: ='PL-CF-BS'!M42 -> 4089 | C10: ='PL-CF-BS'!N42 -> 4723.5403 | D10: ='PL-CF-BS'!O42 -> 5115.763 | E10: ='PL-CF-BS'!P42 -> 5543.5682
A11: (+/-) | B11: ='PL-CF-BS'!M43 -> 0.077754349 | C11: ='PL-CF-BS'!N43 -> 0.15518227 | D11: ='PL-CF-BS'!O43 -> 0.083035756 | E11: ='PL-CF-BS'!P43 -> 0.083624894
A12: ="Diluted EPS ("&B4&")" -> Diluted EPS (US$) | B12: =SumFS!M64 -> 10.325758 | C12: =SumFS!N64 -> 11.928132 | D12: =SumFS!O64 -> 12.918594 | E12: =SumFS!P64 -> 13.99891
A13: GPM | B13: =SumFS!M55 -> 0.37591985 | C13: =SumFS!N55 -> 0.37691985 | D13: =SumFS!O55 -> 0.37791985 | E13: =SumFS!P55 -> 0.37891985 | F13: e.g. 50.5%
A14: ROE | B14: =B10/B27 -> 0.2100262 | C14: =C10/C27 -> 0.22525222 | D14: =D10/D27 -> 0.23032362 | E14: =E10/E27 -> 0.23565047 | F14: e.g. 50.5%
A15: EBITDA | B15: ='PL-CF-BS'!M28 -> 5976 | C15: ='PL-CF-BS'!N28 -> 6608.0704 | D15: ='PL-CF-BS'!O28 -> 7117.7672 | E15: ='PL-CF-BS'!P28 -> 7670.7908
A16: EBIT | B16: =DCF!M7 -> 4970 | C16: =DCF!N7 -> 5838.5141 | D16: =DCF!O7 -> 6311.6946 | E16: =DCF!P7 -> 6827.8019
A17: Interest Revenue | B17: 0 | C17: 0 | D17: -140 | E17: -140
A18: Interest Expense | B18: 0 | C18: 0 | D18: 0 | E18: 0
A19: Operating Profit | B19: =XN!B16 -> 4970 | C19: =C16 -> 5838.5141 | D19: =D16 -> 6311.6946 | E19: =E16 -> 6827.8019
A20: Gross Profit | B20: ='PL-CF-BS'!M8 -> 10319 | C20: ='PL-CF-BS'!N8 -> 11120.849 | D20: ='PL-CF-BS'!O8 -> 11993.422 | E20: ='PL-CF-BS'!P8 -> 12943.375
A21: Depreciation | B21: ='PL-CF-BS'!M66 -> 1006 | C21: ='PL-CF-BS'!N66 -> 769.5563 | D21: ='PL-CF-BS'!O66 -> 806.07261 | E21: ='PL-CF-BS'!P66 -> 842.98891
A22: Pre-Tax Profit | B22: =SumFS!M12 -> 4933 | C22: =SumFS!N12 -> 5698.5141 | D22: =SumFS!O12 -> 6171.6946 | E22: =SumFS!P12 -> 6687.8019
A23: Balance Sheet
A24: Total Assets | B24: =SumFS!M39 -> 41250 | C24: =SumFS!N39 -> 41133.923 | D24: =SumFS!O39 -> 42528.743 | E24: =SumFS!P39 -> 44442.963
A25: Total Liabilities | B25: =SumFS!M52 -> 21782 | C25: =SumFS!N52 -> 20916.235 | D25: =SumFS!O52 -> 21069.865 | E25: =SumFS!P52 -> 21670.745
A26: Shareholder Equity | B26: ='PL-CF-BS'!M134 -> 19425 | C26: ='PL-CF-BS'!N134 -> 20922.54 | D26: ='PL-CF-BS'!O134 -> 22159.977 | E26: ='PL-CF-BS'!P134 -> 23469.251
A27: Total Equity | B27: ='PL-CF-BS'!M138 -> 19469 | C27: ='PL-CF-BS'!N138 -> 20970.006 | D27: ='PL-CF-BS'!O138 -> 22211.196 | E27: ='PL-CF-BS'!P138 -> 23524.537
A28: Cash Flow
A29: Profit before tax | B29: =B22 -> 4933 | C29: =C22 -> 5698.5141 | D29: =D22 -> 6171.6946 | E29: =E22 -> 6687.8019
A30: Net Cash from operations | B30: =SumFS!M16 -> 4472 | C30: =SumFS!N16 -> 5711.9954 | D30: =SumFS!O16 -> 5022.3018 | E30: =SumFS!P16 -> 6529.5456
A31: Net Cash from investment activity | B31: =SumFS!M17 -> -1101 | C31: =SumFS!N17 -> -1529 | D31: =SumFS!O17 -> -1539 | E31: =SumFS!P17 -> -1549
A32: Net Cash from financing activity | B32: =SumFS!M18 -> -3173 | C32: =SumFS!N18 -> -3396 | D32: =SumFS!O18 -> -4048.3264 | E32: =SumFS!P18 -> -4404.2946
A33: Net change in Cash | B33: =SumFS!M19 -> 198 | C33: =SumFS!N19 -> 786.99541 | D33: =SumFS!O19 -> -565.02455 | E33: =SumFS!P19 -> 576.251
A34: Implied cash at end of period | B34: =SumFS!M21 -> 623 | C34: =SumFS!N21 -> 1278.9954 | D34: =SumFS!O21 -> 582.97086 | E34: =SumFS!P21 -> 1028.2219
A35: Free Cash Flow | B35: =DCF!M14 -> 3637.0099 | C35: =DCF!N14 -> 4699.1276 | D35: =DCF!O14 -> 3999.434 | E35: =DCF!P14 -> 5496.6778
A40: EPS | B40: =B12 -> 10.325758 | C40: =C12 -> 11.928132 | D40: =D12 -> 12.918594 | E40: =E12 -> 13.99891
A41: EPS1 | B41: =IF(A43-YEAR($B$2)>=0,VLOOKUP((A43-B3+1),A45:B48,2,FALSE),"na") -> 12.918594
A42: EPS2 | B42: =IF(A43-YEAR($B$2)>=0,VLOOKUP((A43-B3+2),A45:B48,2,FALSE),"na") -> 13.99891
A43: =YEAR(TODAY()) -> 2026
A44: =YEAR(TODAY()) -> 2026
...

Sheet PL-CF-BS
B1: Eaton
B2: Financial Statements | F2: =F110-F129-F138 -> 0 | G2: =G110-G129-G138 -> 0 | H2: =H110-H129-H138 -> 0 | I2: =I110-I129-I138 -> 0 | J2: =J110-J129-J138 -> 0 | K2: =K110-K129-K138 -> #REF! | L2: =L110-L129-L138 -> -1 | M2: =M110-M129-M138 -> -1 | ... T2: =T110-T129-T138 -> -752.31786
B3: ='S&C'!B3 -> (all in Rmb mn unless otherwise noted)
F4: ='S&C'!F4 -> 2018A | G4: ='S&C'!G4 -> 2019A | H4: ='S&C'!H4 -> 2020A | I4: ='S&C'!I4 -> 2021A | J4: ='S&C'!J4 -> 2022A | K4: ='S&C'!K4 -> 2023A | L4: ='S&C'!L4 -> 2024A | M4: ='S&C'!M4 -> 2025A | ... T4: ='S&C'!T4 -> 2032E
B5: Income Statement
B6: Revenue | H6: ='S&C'!H5 -> 17858 | I6: ='S&C'!I5 -> 19628 | J6: ='S&C'!J5 -> 20752 | K6: ='S&C'!K5 -> 23196 | L6: ='S&C'!L5 -> 24878 | M6: ='S&C'!M5 -> 27450 | N6: ='S&C'!N5 -> 29504.545 | O6: ='S&C'!O5 -> 31735.358 | ... T6: ='S&C'!T5 -> 46072.498
B7: Cost of goods sold | H7: ='S&C'!H7 -> 12408 | I7: ='S&C'!I7 -> 13293 | J7: ='S&C'!J7 -> 13865 | K7: ='S&C'!K7 -> 14762 | L7: ='S&C'!L7 -> 15375 | M7: ='S&C'!M7 -> 17131 | N7: ='S&C'!N7 -> 18383.696 | O7: ='S&C'!O7 -> 19741.936 | ... T7: ='S&C'!T7 -> 29025.674
B8: Gross profit | H8: =H6-H7 -> 5450 | I8: =I6-I7 -> 6335 | J8: =J6-J7 -> 6887 | K8: =K6-K7 -> 8434 | L8: =L6-L7 -> 9503 | M8: =M6-M7 -> 10319 | N8: =N6-N7 -> 11120.849 | O8: =O6-O7 -> 11993.422 | ... T8: =T6-T7 -> 17046.824
C9: YoY | H9: =H8/G8-1 -> #DIV/0! | I9: =I8/H8-1 -> 0.16238532 | J9: =J8/I8-1 -> 0.087134964 | K9: =K8/J8-1 -> 0.22462611 | L9: =L8/K8-1 -> 0.12674887 | M9: =M8/L8-1 -> 0.085867621 | N9: =N8/M8-1 -> 0.077706057 | O9: =O8/N8-1 -> 0.078462828 | ... T9: =T8/S8-1 -> 0.078637818
C10: Gross margin | H10: =H8/H6 -> 0.30518535 | I10: =I8/I6 -> 0.32275321 | J10: =J8/J6 -> 0.33187163 | K10: =K8/K6 -> 0.36359717 | L10: =L8/L6 -> 0.38198408 | M10: =M8/M6 -> 0.37591985 | N10: =N8/N6 -> 0.37691985 | O10: =O8/O6 -> 0.37791985 | ... T10: =T8/T6 -> 0.37
B11: Other income | H11: 0 | I11: 0 | J11: 0 | K11: 0 | L11: 0 | M11: 0 | N11: 0 | O11: 0 | P11: 0 | Q11: 0 | R11: 0 | S11: 0 | T11: 0
B12: Other gains | H12: 221 | I12: 617 | J12: 24 | K12: 0 | L12: =K12 -> 0 | M12: =L12 -> 0 | N12: =M12 -> 0 | O12: =N12 -> 0 | P12: =O12 -> 0 | Q12: =P12 -> 0 | R12: =Q12 -> 0 | S12: =R12 -> 0 | T12: =S12 -> 0
B13: Selling and administrative expenses | H13: 3075 | I13: 3256 | J13: 3227 | K13: 3795 | L13: 4077 | M13: 4311 | N13: =N6*N15 -> 4425.6817 | O13: =O6*O15 -> 4760.3038 | P13: =P6*P15 -> 5123.7913 | Q13: =Q6*Q15 -> 5516.8058 | R13: =R6*R15 -> 5944.179 | S13: =S6*S15 -> 6407.0391 | T13: =T6*T15 -> 6910.8747
C14: YoY | H14: =H13/G13-1 -> #DIV/0! | I14: =I13/H13-1 -> 0.058861789 | J14: =J13/I13-1 -> -0.0089066339 | K14: =K13/J13-1 -> 0.17601487 | L14: =L13/K13-1 -> 0.0743083 | M14: =M13/L13-1 -> 0.057395143 | N14: =N13/M13-1 -> 0.026602122 | O14: =O13/N13-1 -> 0.075609147 | ... T14: =T13/S13-1 -> 0.078637818
C15: % of revenue | H15: =H13/H$6 -> 0.17219173 | I15: =I13/I$6 -> 0.16588547 | J15: =J13/J$6 -> 0.15550308 | K15: =K13/K$6 -> 0.16360579 | L15: =L13/L$6 -> 0.16387973 | M15: =M13/M$6 -> 0.15704918 | N15: 0.15 | O15: 0.15 | P15: 0.15 | Q15: 0.15 | R15: 0.15 | S15: 0.15 | T15: 0.15
B16: R&D expenses | H16: 551 | I16: 616 | J16: 665 | K16: 754 | L16: 794 | M16: 797 | N16: =N18*N6 -> 856.65291 | O16: =O18*O6 -> 921.42371 | P16: =P18*P6 -> 991.78182 | Q16: =Q18*Q6 -> 1067.8553 | R16: =R18*R6 -> 1150.5794 | S16: =S18*S6 -> 1240.1725 | T16: =T18*T6 -> 1337.6969
C17: YoY | H17: =H16/G16-1 -> #DIV/0! | I17: =I16/H16-1 -> 0.11796733 | J17: =J16/I16-1 -> 0.079545455 | K17: =K16/J16-1 -> 0.13383459 | L17: =L16/K16-1 -> 0.053050398 | M17: =M16/L16-1 -> 0.0037783375 | N17: =N16/M16-1 -> 0.074846812 | O17: =O16/N16-1 -> 0.075609147 | ... T17: =T16/S16-1 -> 0.078637818
C18: % of revenue | H18: =H16/H$6 -> 0.030854519 | I18: =I16/I$6 -> 0.031383738 | J18: =J16/J$6 -> 0.032045104 | K18: =K16/K$6 -> 0.032505604 | L18: =L16/L$6 -> 0.031915749 | M18: =M16/M$6 -> 0.029034608 | N18: =M18 -> 0.029034608 | O18: =N18 -> 0.029034608 | P18: =O18 -> 0.029034608 | Q18: =P18 -> 0.029034608 | R18: =Q18 -> 0.029034608 | S18: =R18 -> 0.029034608 | T18: =S18 -> 0.029034608
B19: Finance expenses | H19: 149 | I19: 144 | J19: 144 | K19: 151 | L19: 130 | M19: 241 | N19: 0 | O19: 0 | P19: 0 | Q19: 0 | R19: 0 | S19: 0 | T19: 0
B20: Operating profit | H20: =H8+H11+H12-H13-H16-H19 -> 1896 | I20: =I8+I11+I12-I13-I16-I19 -> 2936 | J20: =J8+J11+J12-J13-J16-J19 -> 2875 | K20: =K8+K11+K12-K13-K16-K19 -> 3734 | L20: =L8+L11+L12-L13-L16-L19 -> 4502 | M20: =M8+M11+M12-M13-M16-M19 -> 4970 | N20: =N8+N11+N12-N13-N16-N19 -> 5838.5141 | O20: =O8+O11+O12-O13-O16-O19 -> 6311.6946 | ... T20: =T8+T11+T12-T13-T16-T19 -> 8798.2526
C21: YoY | H21: =H20/G20-1 -> #DIV/0! | I21: =I20/H20-1 -> 0.54852321 | J21: =J20/I20-1 -> -0.020776567 | K21: =K20/J20-1 -> 0.29878261 | L21: =L20/K20-1 -> 0.20567756 | M21: =M20/L20-1 -> 0.1039538 | N21: =N20/M20-1 -> 0.17475134 | O21: =O20/N20-1 -> 0.081044666 | ... T21: =T20/S20-1 -> 0.078637818
C22: Operating margin | H22: =H20/H$6 -> 0.1061709 | I22: =I20/I$6 -> 0.14958223 | J22: =J20/J$6 -> 0.13854086 | K22: =K20/K$6 -> 0.16097603 | L22: =L20/L$6 -> 0.1809631 | M22: =M20/M$6 -> 0.18105647 | N22: =N20/N$6 -> 0.19788525 | O22: =O20/O$6 -> 0.19888525 | ... T22: =T20/T$6 -> 0.19096539
D23: Electrical Americas | K23: 2675 | L23: 3455
D24: Electrical Global | K24: 1176 | L24: 1149
D25: Aerospace | K25: 780 | L25: 859
D26: Vehicle | K26: 482 | L26: 502
D27: eMobility | K27: -21 | L27: =--7 -> 7
B28: EBITDA | H28: =H20+H140+H141 -> 1896 | I28: =I20+I140+I141 -> 2936 | J28: =J20+J140+J141 -> 3389 | K28: =K20+K140+K141 -> 4554 | L28: =L20+L140+L141 -> 5423 | M28: =M20+M140+M141 -> 5976 | N28: =N20+N140+N141 -> 6608.0704 | O28: =O20+O140+O141 -> 7117.7672 | ... T28: =T20+T140+T141 -> 9792.9067
C29: YoY | H29: =H28/G28-1 -> #DIV/0! | I29: =I28/H28-1 -> 0.54852321 | J29: =J28/I28-1 -> 0.15429155 | K29: =K28/J28-1 -> 0.34375922 | L29: =L28/K28-1 -> 0.19082126 | M29: =M28/L28-1 -> 0.10197308 | N29: =N28/M28-1 -> 0.10576815 | O29: =O28/N28-1 -> 0.077132461 | ... T29: =T28/S28-1 -> 0.074613625
C30: EBITDA margin | H30: =H28/H$6 -> 0.1061709 | I30: =I28/I$6 -> 0.14958223 | J30: =J28/J$6 -> 0.16330956 | K30: =K28/K$6 -> 0.19632695 | L30: =L28/L$6 -> 0.21798376 | M30: =M28/M$6 -> 0.21770492 | N30: =N28/N$6 -> 0.22396788 | O30: =O28/O$6 -> 0.22428507 | ... T30: =T28/T$6 -> 0.21255428
B32: Finance costs | N32: -140 | O32: -140 | P32: -140 | Q32: -140 | R32: -140 | S32: -140 | T32: -140
B33: Share of profits/losses of associates | H33: 0 | I33: 0 | J33: 0 | K33: 93 | L33: 64 | M33: -37 | N33: 0 | O33: 0 | P33: 0 | Q33: 0 | R33: 0 | S33: 0 | T33: 0
B34: Profit before taxation | H34: =H20+H32+H33 -> 1896 | I34: =I20+I32+I33 -> 2936 | J34: =J20+J32+J33 -> 2875 | K34: =K20+K32+K33 -> 3827 | L34: =L20+L32+L33 -> 4566 | M34: =M20+M32+M33 -> 4933 | N34: =N20+N32+N33 -> 5698.5141 | O34: =O20+O32+O33 -> 6171.6946 | ... T34: =T20+T32+T33 -> 8658.2526
C35: YoY | H35: =H34/G34-1 -> #DIV/0! | I35: =I34/H34-1 -> 0.54852321 | J35: =J34/I34-1 -> -0.020776567 | K35: =K34/J34-1 -> 0.33113043 | L35: =L34/K34-1 -> 0.19310165 | M35: =M34/L34-1 -> 0.080376697 | N35: =N34/M34-1 -> 0.15518227 | O35: =O34/N34-1 -> 0.083035756 | ... T35: =T34/S34-1 -> 0.080011092
C36: EBT margin | H36: =H34/H$6 -> 0.1061709 | I36: =I34/I$6 -> 0.14958223 | J36: =J34/J$6 -> 0.13854086 | K36: =K34/K$6 -> 0.16498534 | L36: =L34/L$6 -> 0.18353565 | M36: =M34/M$6 -> 0.17970856 | N36: =N34/N$6 -> 0.19314021 | O36: =O34/O$6 -> 0.19447376 | ... T36: =T34/T$6 -> 0.1879267
B37: Taxation | H37: 331 | I37: 750 | J37: 445 | K37: 604 | L37: 768 | M37: 841 | N37: =N34*N38 -> 971.50829 | O37: =O34*O38 -> 1052.1782 | P37: =P34*P38 -> 1140.1665 | Q37: =Q34*Q38 -> 1235.7226 | R37: =R34*R38 -> 1266.2821 | S37: =S34*S38 -> 1366.7432 | T37: =T34*T38 -> 1476.0978
C38: Effective tax rate | H38: =H37/H34 -> 0.17457806 | I38: =I37/I34 -> 0.25544959 | J38: =J37/J34 -> 0.15478261 | K38: =K37/K34 -> 0.15782597 | L38: =L37/L34 -> 0.16819974 | M38: =M37/M34 -> 0.17048449 | N38: =M38 -> 0.17048449 | O38: =N38 -> 0.17048449 | P38: =O38 -> 0.17048449 | Q38: =P38 -> 0.17048449 | R38: =Q38 -> 0.17048449 | S38: =R38 -> 0.17048449 | T38: =S38 -> 0.17048449
B39: Profit for the year | H39: =H34-H37 -> 1565 | I39: =I34-I37 -> 2186 | J39: =J34-J37 -> 2430 | K39: =K34-K37 -> 3223 | L39: =L34-L37 -> 3798 | M39: =M34-M37 -> 4092 | N39: =N34-N37 -> 4727.0059 | O39: =O34-O37 -> 5119.5164 | ... T39: =T34-T37 -> 7182.1548
C40: Minority interest | H40: -5 | I40: -2 | J40: -4 | K40: -5 | L40: -4 | M40: -3 | N40: =-N39*N41 -> -3.4655468 | O40: =-O39*O41 -> -3.7533111 | P40: =-P39*P41 -> -4.0671814 | Q40: =-Q39*Q41 -> -4.4080474 | R40: =-R39*R41 -> -4.5170585 | S40: =-S39*S41 -> -4.8754216 | T40: =-T39*T41 -> -5.2655094
C41: % of profit for the year | H41: =-H40/H39 -> 0.0031948882 | I41: =-I40/I39 -> 0.00091491308 | J41: =-J40/J39 -> 0.0016460905 | K41: =-K40/K39 -> 0.0015513497 | L41: =-L40/L39 -> 0.0010531859 | M41: =-M40/M39 -> 0.00073313783 | N41: =M41 -> 0.00073313783 | O41: =N41 -> 0.00073313783 | P41: =O41 -> 0.00073313783 | Q41: =P41 -> 0.00073313783 | R41: =Q41 -> 0.00073313783 | S41: =R41 -> 0.00073313783 | T41: =S41 -> 0.00073313783
...

Sheet DCF
B3: (all in USD mn unless otherwise noted)
B4: Free cashflow forecast | K4: ='S&C'!K4 -> 2023A | L4: ='S&C'!L4 -> 2024A | M4: ='S&C'!M4 -> 2025A | N4: ='S&C'!N4 -> 2026E | O4: ='S&C'!O4 -> 2027E | P4: ='S&C'!P4 -> 2028E | Q4: ='S&C'!Q4 -> 2029E | R4: ='S&C'!R4 -> 2030E | ... T4: ='S&C'!T4 -> 2032E
C5: Net Revenue | K5: ='S&C'!K5 -> 23196 | L5: ='S&C'!L5 -> 24878 | M5: ='S&C'!M5 -> 27450 | N5: ='S&C'!N5 -> 29504.545 | O5: ='S&C'!O5 -> 31735.358 | P5: ='S&C'!P5 -> 34158.609 | Q5: ='S&C'!Q5 -> 36778.706 | R5: ='S&C'!R5 -> 39627.86 | ... T5: ='S&C'!T5 -> 46072.498
D6: YoY | K6: ='S&C'!K6 -> 0.11777178 | L6: ='S&C'!L6 -> 0.072512502 | M6: ='S&C'!M6 -> 0.10338452 | N6: ='S&C'!N6 -> 0.074846812 | O6: ='S&C'!O6 -> 0.075609147 | P6: ='S&C'!P6 -> 0.076358051 | Q6: ='S&C'!Q6 -> 0.076703858 | R6: ='S&C'!R6 -> 0.077467497 | ... T6: ='S&C'!T6 -> 0.078637818
C7: EBIT | K7: ='PL-CF-BS'!K20 -> 3734 | L7: ='PL-CF-BS'!L20 -> 4502 | M7: ='PL-CF-BS'!M20 -> 4970 | N7: ='PL-CF-BS'!N20 -> 5838.5141 | O7: ='PL-CF-BS'!O20 -> 6311.6946 | P7: ='PL-CF-BS'!P20 -> 6827.8019 | Q7: ='PL-CF-BS'!Q20 -> 7388.2993 | R7: ='PL-CF-BS'!R20 -> 7567.5498 | ... T7: ='PL-CF-BS'!T20 -> 8798.2526
D8: YoY | K8: ='PL-CF-BS'!K21 -> 0.29878261 | L8: ='PL-CF-BS'!L21 -> 0.20567756 | M8: ='PL-CF-BS'!M21 -> 0.1039538 | N8: ='PL-CF-BS'!N21 -> 0.17475134 | O8: ='PL-CF-BS'!O21 -> 0.081044666 | P8: ='PL-CF-BS'!P21 -> 0.081770006 | Q8: ='PL-CF-BS'!Q21 -> 0.082090468 | R8: ='PL-CF-BS'!R21 -> 0.024261397 | ... T8: ='PL-CF-BS'!T21 -> 0.078637818
D9: EBIT Margin | K9: ='PL-CF-BS'!K22 -> 0.16097603 | L9: ='PL-CF-BS'!L22 -> 0.1809631 | M9: ='PL-CF-BS'!M22 -> 0.18105647 | N9: ='PL-CF-BS'!N22 -> 0.19788525 | O9: ='PL-CF-BS'!O22 -> 0.19888525 | P9: ='PL-CF-BS'!P22 -> 0.19988525 | Q9: ='PL-CF-BS'!Q22 -> 0.20088525 | R9: ='PL-CF-BS'!R22 -> 0.19096539 | ... T9: ='PL-CF-BS'!T22 -> 0.19096539
C10: EBIT*(1 - t) | K10: =K7*(1-'PL-CF-BS'!K38) -> 3144.6778 | L10: =L7*(1-'PL-CF-BS'!L38) -> 3744.7648 | M10: =M7*(1-'PL-CF-BS'!M38) -> 4122.6921 | N10: =N7*(1-'PL-CF-BS'!N38) -> 4843.138 | O10: =O7*(1-'PL-CF-BS'!O38) -> 5235.6485 | P10: =P7*(1-'PL-CF-BS'!P38) -> 5663.7675 | Q10: =Q7*(1-'PL-CF-BS'!Q38) -> 6128.7089 | R10: =R7*(1-'PL-CF-BS'!R38) -> 6277.3999 | ... T10: =T7*(1-'PL-CF-BS'!T38) -> 7298.287
C11: + | D11: Depreciation and Amortization | K11: ='PL-CF-BS'!K140+'PL-CF-BS'!K141 -> 820 | L11: ='PL-CF-BS'!L140+'PL-CF-BS'!L141 -> 921 | M11: ='PL-CF-BS'!M140+'PL-CF-BS'!M141 -> 1006 | N11: ='PL-CF-BS'!N140+'PL-CF-BS'!N141 -> 769.5563 | O11: ='PL-CF-BS'!O140+'PL-CF-BS'!O141 -> 806.07261 | P11: ='PL-CF-BS'!P140+'PL-CF-BS'!P141 -> 842.98891 | Q11: ='PL-CF-BS'!Q140+'PL-CF-BS'!Q141 -> 880.30522 | R11: ='PL-CF-BS'!R140+'PL-CF-BS'!R141 -> 918.02152 | ... T11: ='PL-CF-BS'!T140+'PL-CF-BS'!T141 -> 994.65413
C12: - | D12: Change in working capital | K12: ='PL-CF-BS'!K68 -> -372 | L12: ='PL-CF-BS'!L68 -> -349 | M12: ='PL-CF-BS'!M68 -> -572.68214 | N12: ='PL-CF-BS'!N68 -> 115.43325 | O12: ='PL-CF-BS'!O68 -> -1003.2871 | P12: ='PL-CF-BS'!P68 -> 38.921342 | Q12: ='PL-CF-BS'!Q68 -> -1083.8132 | R12: ='PL-CF-BS'!R68 -> 66.909369 | ... T12: ='PL-CF-BS'!T68 -> 50.265205
C13: - | D13: Capex | K13: ='PL-CF-BS'!K73 -> -757 | L13: ='PL-CF-BS'!L73 -> -808 | M13: ='PL-CF-BS'!M73 -> -919 | N13: ='PL-CF-BS'!N73 -> -1029 | O13: ='PL-CF-BS'!O73 -> -1039 | P13: ='PL-CF-BS'!P73 -> -1049 | Q13: ='PL-CF-BS'!Q73 -> -1059 | R13: ='PL-CF-BS'!R73 -> -1069 | ... T13: ='PL-CF-BS'!T73 -> -1089
C14: Free Cash Flows | K14: =SUM(K10:K13) -> 2835.6778 | L14: =SUM(L10:L13) -> 3508.7648 | M14: =SUM(M10:M13) -> 3637.0099 | N14: =SUM(N10:N13) -> 4699.1276 | O14: =SUM(O10:O13) -> 3999.434 | P14: =SUM(P10:P13) -> 5496.6778 | Q14: =SUM(Q10:Q13) -> 4866.2009 | R14: =SUM(R10:R13) -> 6193.3308 | ... T14: =SUM(T10:T13) -> 7254.2063
D15: YoY | K15: - | L15: =L14/K14-1 -> 0.2373637 | M15: =M14/L14-1 -> 0.036549941 | N15: =N14/M14-1 -> 0.29203045 | O15: =O14/N14-1 -> -0.14889861 | P15: =P14/O14-1 -> 0.37436392 | Q15: =Q14/P14-1 -> -0.11470145 | R15: =R14/Q14-1 -> 0.27272403 | S15: =S14/R14-1 -> -0.15044823 | T15: =T14/S14-1 -> 0.37871905
B16: DCF Analysis
C17: PV of FCF | K17: {=NPV(T25,N14:T14)} -> 28733.293 | R17: Tax rate | T17: 0.17
C18: Terminal value | K18: =T14*(1+T26)/(T25-T26) -> 196368.79 | R18: Debt ratio | T18: 0.55
C19: PV of terminal value | K19: =K18/(1+T25)^7 -> 123860.09 | R19: Beta | T19: 1.1
C20: Enterprise Value | K20: =K17+K19 -> 152593.38 | R20: Risk free rate | T20: 0.04
C21: Net Cash/(Debt), Minority interests | K21: ='PL-CF-BS'!M94+'PL-CF-BS'!M95-'PL-CF-BS'!M113-'PL-CF-BS'!M114-'PL-CF-BS'!M137 -> -378 | R21: Risk premium | T21: 0.055
C22: Equity Value | K22: =K20+K21 -> 152215.38 | R22: Equity cost | T22: =T20+T21*T19 -> 0.1005
C23: Equity value per share (HK$) | K23: =(K22/'PL-CF-BS'!K49/'Other ASPT'!K5)*(1+T26) -> 391.17226 | R23: Debt cost | T23: 0.05
R24: Debt cost (After tax) | T24: =T23*(1-T17) -> 0.0415
R25: WACC | T25: =T24*T18+T22*(1-T18) -> 0.06805 | V25: 354
R26: Perpetual Growth | T26: 0.03 | V26: =K23/V25-1 -> 0.10500637
H29: Equity value per share ($)
H30: Perpetual Growth | K30: =L30-0.5% -> 0.01 | L30: =M30-0.5% -> 0.015 | M30: =N30-0.5% -> 0.02 | N30: =O30-0.5% -> 0.025 | O30: =T26 -> 0.03 | P30: =O30+0.5% -> 0.035 | Q30: =P30+0.5% -> 0.04 | R30: =Q30+0.5% -> 0.045
H31: WACC | J31: =J32-0.5% -> 0.05305 | K31: {=(NPV($J31,$N$14:$T$14)+($T$14*(1+K$30)/($J31-K$30))/(1+$J31)^7+$K$21)/'Other ASPT'!$K$5/'PL-CF-BS'!$K$49} -> 370.68221 | L31: {=(NPV($J31,$N$14:$T$14)+($T$14*(1+L$30)/($J31-L$30))/(1+$J31)^7+$K$21)/'Other ASPT'!$K$5/'PL-CF-BS'!$K$49} -> 411.1967 | M31: {=(NPV($J31,$N$14:$T$14)+($T$14*(1+M$30)/($J31-M$30))/(1+$J31)^7+$K$21)/'Other ASPT'!$K$5/'PL-CF-BS'!$K$49} -> 463.96974 | N31: {=(NPV($J31,$N$14:$T$14)+($T$14*(1+N$30)/($J31-N$30))/(1+$J31)^7+$K$21)/'Other ASPT'!$K$5/'PL-CF-BS'!$K$49} -> 535.5567 | O31: {=(NPV($J31,$N$14:$T$14)+($T$14*(1+O$30)/($J31-O$30))/(1+$J31)^7+$K$21)/'Other ASPT'!$K$5/'PL-CF-BS'!$K$49} -> 638.20091 | P31: {=(NPV($J31,$N$14:$T$14)+($T$14*(1+P$30)/($J31-P$30))/(1+$J31)^7+$K$21)/'Other ASPT'!$K$5/'PL-CF-BS'!$K$49} -> 797.71171 | Q31: {=(NPV($J31,$N$14:$T$14)+($T$14*(1+Q$30)/($J31-Q$30))/(1+$J31)^7+$K$21)/'Other ASPT'!$K$5/'PL-CF-BS'!$K$49} -> 1079.453 | R31: {=(NPV($J31,$N$14:$T$14)+($T$14*(1+R$30)/($J31-R$30))/(1+$J31)^7+$K$21)/'Other ASPT'!$K$5/'PL-CF-BS'!$K$49} -> 1711.1835
J32: =J33-0.5% -> 0.05805 | K32: {=(NPV($J32,$N$14:$T$14)+($T$14*(1+K$30)/($J32-K$30))/(1+$J32)^7+$K$21)/'Other ASPT'!$K$5/'PL-CF-BS'!$K$49} -> 329.82153 | L32: {=(NPV($J32,$N$14:$T$14)+($T$14*(1+L$30)/($J32-L$30))/(1+$J32)^7+$K$21)/'Other ASPT'!$K$5/'PL-CF-BS'!$K$49} -> 361.00529 | M32: {=(NPV($J32,$N$14:$T$14)+($T$14*(1+M$30)/($J32-M$30))/(1+$J32)^7+$K$21)/'Other ASPT'!$K$5/'PL-CF-BS'!$K$49} -> 400.38453 | N32: {=(NPV($J32,$N$14:$T$14)+($T$14*(1+N$30)/($J32-N$30))/(1+$J32)^7+$K$21)/'Other ASPT'!$K$5/'PL-CF-BS'!$K$49} -> 451.6788 | O32: {=(NPV($J32,$N$14:$T$14)+($T$14*(1+O$30)/($J32-O$30))/(1+$J32)^7+$K$21)/'Other ASPT'!$K$5/'PL-CF-BS'!$K$49} -> 521.25981 | P32: {=(NPV($J32,$N$14:$T$14)+($T$14*(1+P$30)/($J32-P$30))/(1+$J32)^7+$K$21)/'Other ASPT'!$K$5/'PL-CF-BS'!$K$49} -> 621.02781 | Q32: {=(NPV($J32,$N$14:$T$14)+($T$14*(1+Q$30)/($J32-Q$30))/(1+$J32)^7+$K$21)/'Other ASPT'!$K$5/'PL-CF-BS'!$K$49} -> 776.06893 | R32: {=(NPV($J32,$N$14:$T$14)+($T$14*(1+R$30)/($J32-R$30))/(1+$J32)^7+$K$21)/'Other ASPT'!$K$5/'PL-CF-BS'!$K$49} -> 1049.9155
J33: =J34-0.5% -> 0.06305 | K33: {=(NPV($J33,$N$14:$T$14)+($T$14*(1+K$30)/($J33-K$30))/(1+$J33)^7+$K$21)/'Other ASPT'!$K$5/'PL-CF-BS'!$K$49} -> 296.7214 | L33: {=(NPV($J33,$N$14:$T$14)+($T$14*(1+L$30)/($J33-L$30))/(1+$J33)^7+$K$21)/'Other ASPT'!$K$5/'PL-CF-BS'!$K$49} -> 321.32119 | M33: {=(NPV($J33,$N$14:$T$14)+($T$14*(1+M$30)/($J33-M$30))/(1+$J33)^7+$K$21)/'Other ASPT'!$K$5/'PL-CF-BS'!$K$49} -> 351.6352 | N33: {=(NPV($J33,$N$14:$T$14)+($T$14*(1+N$30)/($J33-N$30))/(1+$J33)^7+$K$21)/'Other ASPT'!$K$5/'PL-CF-BS'!$K$49} -> 389.91611 | O33: {=(NPV($J33,$N$14:$T$14)+($T$14*(1+O$30)/($J33-O$30))/(1+$J33)^7+$K$21)/'Other ASPT'!$K$5/'PL-CF-BS'!$K$49} -> 439.77975 | P33: {=(NPV($J33,$N$14:$T$14)+($T$14*(1+P$30)/($J33-P$30))/(1+$J33)^7+$K$21)/'Other ASPT'!$K$5/'PL-CF-BS'!$K$49} -> 507.42008 | Q33: {=(NPV($J33,$N$14:$T$14)+($T$14*(1+Q$30)/($J33-Q$30))/(1+$J33)^7+$K$21)/'Other ASPT'!$K$5/'PL-CF-BS'!$K$49} -> 604.40545 | R33: {=(NPV($J33,$N$14:$T$14)+($T$14*(1+R$30)/($J33-R$30))/(1+$J33)^7+$K$21)/'Other ASPT'!$K$5/'PL-CF-BS'!$K$49} -> 755.12233
J34: =T25 -> 0.06805 | K34: {=(NPV($J34,$N$14:$T$14)+($T$14*(1+K$30)/($J34-K$30))/(1+$J34)^7+$K$21)/'Other ASPT'!$K$5/'PL-CF-BS'!$K$49} -> 269.37464 | L34: {=(NPV($J34,$N$14:$T$14)+($T$14*(1+L$30)/($J34-L$30))/(1+$J34)^7+$K$21)/'Other ASPT'!$K$5/'PL-CF-BS'!$K$49} -> 289.17144 | M34: {=(NPV($J34,$N$14:$T$14)+($T$14*(1+M$30)/($J34-M$30))/(1+$J34)^7+$K$21)/'Other ASPT'!$K$5/'PL-CF-BS'!$K$49} -> 313.08829 | N34: {=(NPV($J34,$N$14:$T$14)+($T$14*(1+N$30)/($J34-N$30))/(1+$J34)^7+$K$21)/'Other ASPT'!$K$5/'PL-CF-BS'!$K$49} -> 342.56073 | O34: {=(NPV($J34,$N$14:$T$14)+($T$14*(1+O$30)/($J34-O$30))/(1+$J34)^7+$K$21)/'Other ASPT'!$K$5/'PL-CF-BS'!$K$49} -> 379.77889 | P34: {=(NPV($J34,$N$14:$T$14)+($T$14*(1+P$30)/($J34-P$30))/(1+$J34)^7+$K$21)/'Other ASPT'!$K$5/'PL-CF-BS'!$K$49} -> 428.25821 | Q34: {=(NPV($J34,$N$14:$T$14)+($T$14*(1+Q$30)/($J34-Q$30))/(1+$J34)^7+$K$21)/'Other ASPT'!$K$5/'PL-CF-BS'!$K$49} -> 494.02072 | R34: {=(NPV($J34,$N$14:$T$14)+($T$14*(1+R$30)/($J34-R$30))/(1+$J34)^7+$K$21)/'Other ASPT'!$K$5/'PL-CF-BS'!$K$49} -> 588.3136
J35: =J34+0.5% -> 0.07305 | K35: {=(NPV($J35,$N$14:$T$14)+($T$14*(1+K$30)/($J35-K$30))/(1+$J35)^7+$K$21)/'Other ASPT'!$K$5/'PL-CF-BS'!$K$49} -> 246.41082 | L35: {=(NPV($J35,$N$14:$T$14)+($T$14*(1+L$30)/($J35-L$30))/(1+$J35)^7+$K$21)/'Other ASPT'!$K$5/'PL-CF-BS'!$K$49} -> 262.60746 | M35: {=(NPV($J35,$N$14:$T$14)+($T$14*(1+M$30)/($J35-M$30))/(1+$J35)^7+$K$21)/'Other ASPT'!$K$5/'PL-CF-BS'!$K$49} -> 281.8572 | N35: {=(NPV($J35,$N$14:$T$14)+($T$14*(1+N$30)/($J35-N$30))/(1+$J35)^7+$K$21)/'Other ASPT'!$K$5/'PL-CF-BS'!$K$49} -> 305.11313 | O35: {=(NPV($J35,$N$14:$T$14)+($T$14*(1+O$30)/($J35-O$30))/(1+$J35)^7+$K$21)/'Other ASPT'!$K$5/'PL-CF-BS'!$K$49} -> 333.77113 | P35: {=(NPV($J35,$N$14:$T$14)+($T$14*(1+P$30)/($J35-P$30))/(1+$J35)^7+$K$21)/'Other ASPT'!$K$5/'PL-CF-BS'!$K$49} -> 369.9608 | Q35: {=(NPV($J35,$N$14:$T$14)+($T$14*(1+Q$30)/($J35-Q$30))/(1+$J35)^7+$K$21)/'Other ASPT'!$K$5/'PL-CF-BS'!$K$49} -> 417.10045 | R35: {=(NPV($J35,$N$14:$T$14)+($T$14*(1+R$30)/($J35-R$30))/(1+$J35)^7+$K$21)/'Other ASPT'!$K$5/'PL-CF-BS'!$K$49} -> 481.04567
J36: =J35+0.5% -> 0.07805 | K36: {=(NPV($J36,$N$14:$T$14)+($T$14*(1+K$30)/($J36-K$30))/(1+$J36)^7+$K$21)/'Other ASPT'!$K$5/'PL-CF-BS'!$K$49} -> 226.86235 | L36: {=(NPV($J36,$N$14:$T$14)+($T$14*(1+L$30)/($J36-L$30))/(1+$J36)^7+$K$21)/'Other ASPT'!$K$5/'PL-CF-BS'!$K$49} -> 240.29883 | M36: {=(NPV($J36,$N$14:$T$14)+($T$14*(1+M$30)/($J36-M$30))/(1+$J36)^7+$K$21)/'Other ASPT'!$K$5/'PL-CF-BS'!$K$49} -> 256.04995 | N36: {=(NPV($J36,$N$14:$T$14)+($T$14*(1+N$30)/($J36-N$30))/(1+$J36)^7+$K$21)/'Other ASPT'!$K$5/'PL-CF-BS'!$K$49} -> 274.77018 | O36: {=(NPV($J36,$N$14:$T$14)+($T$14*(1+O$30)/($J36-O$30))/(1+$J36)^7+$K$21)/'Other ASPT'!$K$5/'PL-CF-BS'!$K$49} -> 297.3864 | P36: {=(NPV($J36,$N$14:$T$14)+($T$14*(1+P$30)/($J36-P$30))/(1+$J36)^7+$K$21)/'Other ASPT'!$K$5/'PL-CF-BS'!$K$49} -> 325.25609 | Q36: {=(NPV($J36,$N$14:$T$14)+($T$14*(1+Q$30)/($J36-Q$30))/(1+$J36)^7+$K$21)/'Other ASPT'!$K$5/'PL-CF-BS'!$K$49} -> 360.45028 | R36: {=(NPV($J36,$N$14:$T$14)+($T$14*(1+R$30)/($J36-R$30))/(1+$J36)^7+$K$21)/'Other ASPT'!$K$5/'PL-CF-BS'!$K$49} -> 406.29324
J37: =J36+0.5% -> 0.08305 | K37: {=(NPV($J37,$N$14:$T$14)+($T$14*(1+K$30)/($J37-K$30))/(1+$J37)^7+$K$21)/'Other ASPT'!$K$5/'PL-CF-BS'!$K$49} -> 210.02661 | L37: {=(NPV($J37,$N$14:$T$14)+($T$14*(1+L$30)/($J37-L$30))/(1+$J37)^7+$K$21)/'Other ASPT'!$K$5/'PL-CF-BS'!$K$49} -> 221.30619 | M37: {=(NPV($J37,$N$14:$T$14)+($T$14*(1+M$30)/($J37-M$30))/(1+$J37)^7+$K$21)/'Other ASPT'!$K$5/'PL-CF-BS'!$K$49} -> 234.37476 | N37: {=(NPV($J37,$N$14:$T$14)+($T$14*(1+N$30)/($J37-N$30))/(1+$J37)^7+$K$21)/'Other ASPT'!$K$5/'PL-CF-BS'!$K$49} -> 249.69458 | O37: {=(NPV($J37,$N$14:$T$14)+($T$14*(1+O$30)/($J37-O$30))/(1+$J37)^7+$K$21)/'Other ASPT'!$K$5/'PL-CF-BS'!$K$49} -> 267.90222 | P37: {=(NPV($J37,$N$14:$T$14)+($T$14*(1+P$30)/($J37-P$30))/(1+$J37)^7+$K$21)/'Other ASPT'!$K$5/'PL-CF-BS'!$K$49} -> 289.89916 | Q37: {=(NPV($J37,$N$14:$T$14)+($T$14*(1+Q$30)/($J37-Q$30))/(1+$J37)^7+$K$21)/'Other ASPT'!$K$5/'PL-CF-BS'!$K$49} -> 317.00573 | R37: {=(NPV($J37,$N$14:$T$14)+($T$14*(1+R$30)/($J37-R$30))/(1+$J37)^7+$K$21)/'Other ASPT'!$K$5/'PL-CF-BS'!$K$49} -> 351.23624
H40: % change from DCF TP upon WACC/perpetual growth change
H41: Perpetual Growth | K41: =K30 -> 0.01 | L41: =L30 -> 0.015 | M41: =M30 -> 0.02 | N41: =N30 -> 0.025 | O41: =O30 -> 0.03 | P41: =P30 -> 0.035 | Q41: =Q30 -> 0.04 | R41: =R30 -> 0.045
H42: WACC | J42: =J31 -> 0.05305 | K42: =K31/$O$34-1 -> -0.023952574 | L42: =L31/$O$34-1 -> 0.08272659 | M42: =M31/$O$34-1 -> 0.22168387 | N42: =N31/$O$34-1 -> 0.41018028 | O42: =O31/$O$34-1 -> 0.68045388 | P42: =P31/$O$34-1 -> 1.1004635 | Q42: =Q31/$O$34-1 -> 1.8423197 | R42: =R31/$O$34-1 -> 3.5057363
J43: =J32 -> 0.05805 | K43: =K32/$O$34-1 -> -0.13154327 | L43: =L32/$O$34-1 -> -0.04943296 | M43: =M32/$O$34-1 -> 0.054256929 | N43: =N32/$O$34-1 -> 0.18932046 | O43: =O32/$O$34-1 -> 0.37253498 | P43: =P32/$O$34-1 -> 0.6352352 | Q43: =Q32/$O$34-1 -> 1.0434757 | R43: =R32/$O$34-1 -> 1.7645442
J44: =J33 -> 0.06305 | K44: =K33/$O$34-1 -> -0.21869958 | L44: =L33/$O$34-1 -> -0.15392562 | M44: =M33/$O$34-1 -> -0.074105447 | N44: =N33/$O$34-1 -> 0.026692435 | O44: =O33/$O$34-1 -> 0.15798892 | P44: =P33/$O$34-1 -> 0.33609342 | Q44: =Q33/$O$34-1 -> 0.59146669 | R44: =R33/$O$34-1 -> 0.98832098
J45: =J34 -> 0.06805 | K45: =K34/$O$34-1 -> -0.29070666 | L45: =L34/$O$34-1 -> -0.23857947 | M45: =M34/$O$34-1 -> -0.17560376 | N45: =N34/$O$34-1 -> -0.097999543 | O45: =O34/$O$34-1 -> 0 | P45: =P34/$O$34-1 -> 0.12765145 | Q45: =Q34/$O$34-1 -> 0.30081143 | R45: =R34/$O$34-1 -> 0.54909506
J46: =J35 -> 0.07305 | K46: =K35/$O$34-1 -> -0.35117295 | L46: =L35/$O$34-1 -> -0.30852538 | M46: =M35/$O$34-1 -> -0.25783868 | N46: =N35/$O$34-1 -> -0.19660324 | O46: =O35/$O$34-1 -> -0.12114354 | P46: =P35/$O$34-1 -> -0.025852121 | Q46: =Q35/$O$34-1 -> 0.098271803 | R46: =R35/$O$34-1 -> 0.26664668
...

Sheet SumFS
C3: (all in USD mn unless otherwise noted)
I4: ='S&C'!I4 -> 2021A | J4: ='S&C'!J4 -> 2022A | K4: ='S&C'!K4 -> 2023A | L4: ='S&C'!L4 -> 2024A | M4: ='S&C'!M4 -> 2025A | N4: ='S&C'!N4 -> 2026E | O4: ='S&C'!O4 -> 2027E | P4: ='S&C'!P4 -> 2028E
B5: 损益表 | C5: Income Statement
B6: 营业收入 | C6: Revenue | I6: ='PL-CF-BS'!I6 -> 19628 | J6: ='PL-CF-BS'!J6 -> 20752 | K6: ='PL-CF-BS'!K6 -> 23196 | L6: ='PL-CF-BS'!L6 -> 24878 | M6: ='PL-CF-BS'!M6 -> 27450 | N6: ='PL-CF-BS'!N6 -> 29504.545 | O6: ='PL-CF-BS'!O6 -> 31735.358 | P6: ='PL-CF-BS'!P6 -> 34158.609
B7: 营业成本 | C7: Cost of Sales | I7: ='PL-CF-BS'!I7 -> 13293 | J7: ='PL-CF-BS'!J7 -> 13865 | K7: ='PL-CF-BS'!K7 -> 14762 | L7: ='PL-CF-BS'!L7 -> 15375 | M7: ='PL-CF-BS'!M7 -> 17131 | N7: ='PL-CF-BS'!N7 -> 18383.696 | O7: ='PL-CF-BS'!O7 -> 19741.936 | P7: ='PL-CF-BS'!P7 -> 21215.234
B8: 其他收入 | C8: Other Income | I8: ='PL-CF-BS'!I11 -> 0 | J8: ='PL-CF-BS'!J11 -> 0 | K8: ='PL-CF-BS'!K11 -> 0 | L8: ='PL-CF-BS'!L11 -> 0 | M8: ='PL-CF-BS'!M11 -> 0 | O8: ='PL-CF-BS'!O11 -> 0 | P8: ='PL-CF-BS'!P11 -> 0
B9: 销售费用 | C9: Distribution costs | I9: ='PL-CF-BS'!I13 -> 3256 | J9: ='PL-CF-BS'!J13 -> 3227 | K9: ='PL-CF-BS'!K13 -> 3795 | L9: ='PL-CF-BS'!L13 -> 4077 | M9: ='PL-CF-BS'!M13 -> 4311 | N9: ='PL-CF-BS'!N13 -> 4425.6817 | O9: ='PL-CF-BS'!O13 -> 4760.3038 | P9: ='PL-CF-BS'!P13 -> 5123.7913
B10: 管理费用 | C10: Administrative expenses | I10: ='PL-CF-BS'!I16 -> 616 | J10: ='PL-CF-BS'!J16 -> 665 | K10: ='PL-CF-BS'!K16 -> 754 | L10: ='PL-CF-BS'!L16 -> 794 | M10: ='PL-CF-BS'!M16 -> 797 | N10: ='PL-CF-BS'!N16 -> 856.65291 | O10: ='PL-CF-BS'!O16 -> 921.42371 | P10: ='PL-CF-BS'!P16 -> 991.78182
B11: 财务费用 | C11: Finance Income | I11: ='PL-CF-BS'!I32 -> 0 | J11: ='PL-CF-BS'!J32 -> 0 | K11: ='PL-CF-BS'!K32 -> 0 | L11: ='PL-CF-BS'!L32 -> 0 | M11: ='PL-CF-BS'!M32 -> 0 | N11: ='PL-CF-BS'!N32 -> -140 | O11: ='PL-CF-BS'!O32 -> -140 | P11: ='PL-CF-BS'!P32 -> -140
B12: 税前利润 | C12: Profit before taxation | I12: ='PL-CF-BS'!I34 -> 2936 | J12: ='PL-CF-BS'!J34 -> 2875 | K12: ='PL-CF-BS'!K34 -> 3827 | L12: ='PL-CF-BS'!L34 -> 4566 | M12: ='PL-CF-BS'!M34 -> 4933 | N12: ='PL-CF-BS'!N34 -> 5698.5141 | O12: ='PL-CF-BS'!O34 -> 6171.6946 | P12: ='PL-CF-BS'!P34 -> 6687.8019
B13: 所得税 | C13: Taxation | I13: ='PL-CF-BS'!I37 -> 750 | J13: ='PL-CF-BS'!J37 -> 445 | K13: ='PL-CF-BS'!K37 -> 604 | L13: ='PL-CF-BS'!L37 -> 768 | M13: ='PL-CF-BS'!M37 -> 841 | N13: ='PL-CF-BS'!N37 -> 971.50829 | O13: ='PL-CF-BS'!O37 -> 1052.1782 | P13: ='PL-CF-BS'!P37 -> 1140.1665
B14: 净利润 | C14: Net profit | I14: ='PL-CF-BS'!I42 -> 2184 | J14: ='PL-CF-BS'!J42 -> 2426 | K14: ='PL-CF-BS'!K42 -> 3218 | L14: ='PL-CF-BS'!L42 -> 3794 | M14: ='PL-CF-BS'!M42 -> 4089 | N14: ='PL-CF-BS'!N42 -> 4723.5403 | O14: ='PL-CF-BS'!O42 -> 5115.763 | P14: ='PL-CF-BS'!P42 -> 5543.5682
B15: 现金流量表 | C15: Cash Flow Statement
B16: 经营活动现金流 | C16: Operating cashflow | I16: ='PL-CF-BS'!I70 -> 2163 | J16: ='PL-CF-BS'!J70 -> 2533 | K16: ='PL-CF-BS'!K70 -> 3624 | L16: ='PL-CF-BS'!L70 -> 4327 | M16: ='PL-CF-BS'!M70 -> 4472 | N16: ='PL-CF-BS'!N70 -> 5711.9954 | O16: ='PL-CF-BS'!O70 -> 5022.3018 | P16: ='PL-CF-BS'!P70 -> 6529.5456
B17: 投资活动现金流 | C17: Investment cashflow | I17: ='PL-CF-BS'!I76 -> -1764 | J17: ='PL-CF-BS'!J76 -> -1200 | K17: ='PL-CF-BS'!K76 -> -2575 | L17: ='PL-CF-BS'!L76 -> -271 | M17: ='PL-CF-BS'!M76 -> -1101 | N17: ='PL-CF-BS'!N76 -> -1529 | O17: ='PL-CF-BS'!O76 -> -1539 | P17: ='PL-CF-BS'!P76 -> -1549
B18: 融资活动现金流 | C18: Financing cashflow | I18: ='PL-CF-BS'!I85 -> -535 | J18: ='PL-CF-BS'!J85 -> -1340 | K18: ='PL-CF-BS'!K85 -> -871 | L18: ='PL-CF-BS'!L85 -> -3936 | M18: ='PL-CF-BS'!M85 -> -3173 | N18: ='PL-CF-BS'!N85 -> -3396 | O18: ='PL-CF-BS'!O85 -> -4048.3264 | P18: ='PL-CF-BS'!P85 -> -4404.2946
B19: 货币资金增加额 | C19: Net cash change | I19: ='PL-CF-BS'!I87 -> -136 | J19: ='PL-CF-BS'!J87 -> -7 | K19: ='PL-CF-BS'!K87 -> 178 | L19: ='PL-CF-BS'!L87 -> 120 | M19: ='PL-CF-BS'!M87 -> 198 | N19: ='PL-CF-BS'!N87 -> 786.99541 | O19: ='PL-CF-BS'!O87 -> -565.02455 | P19: ='PL-CF-BS'!P87 -> 576.251
B20: 货币资金期初余额 | C20: Cash BB | I20: ='PL-CF-BS'!I89 -> 438 | J20: ='PL-CF-BS'!J89 -> 297 | K20: ='PL-CF-BS'!K89 -> 294 | L20: ='PL-CF-BS'!L89 -> 488 | M20: ='PL-CF-BS'!M89 -> 556 | N20: ='PL-CF-BS'!N89 -> 623 | O20: ='PL-CF-BS'!O89 -> 1278.9954 | P20: ='PL-CF-BS'!P89 -> 582.97086
B21: 货币资金期末余额 | C21: Cash EB | I21: ='PL-CF-BS'!I90 -> 297 | J21: ='PL-CF-BS'!J90 -> 294 | K21: ='PL-CF-BS'!K90 -> 488 | L21: ='PL-CF-BS'!L90 -> 556 | M21: ='PL-CF-BS'!M90 -> 623 | N21: ='PL-CF-BS'!N90 -> 1278.9954 | O21: ='PL-CF-BS'!O90 -> 582.97086 | P21: ='PL-CF-BS'!P90 -> 1028.2219
B22: 资产负债表 | C22: Balance Statement
B23: 流动资产 | C23: Current Assets
B24: 货币资金 | C24: Cash | I24: ='PL-CF-BS'!I94 -> 297 | J24: ='PL-CF-BS'!J94 -> 294 | K24: ='PL-CF-BS'!K94 -> 488 | L24: ='PL-CF-BS'!L94 -> 555 | M24: ='PL-CF-BS'!M94 -> 622 | N24: ='PL-CF-BS'!N94 -> 1278.9954 | O24: ='PL-CF-BS'!O94 -> 582.97086 | P24: ='PL-CF-BS'!P94 -> 1028.2219
B25: 短期存款 | C25: Term deposits / Structured deposits | I25: ='PL-CF-BS'!I95 -> 271 | J25: ='PL-CF-BS'!J95 -> 261 | K25: ='PL-CF-BS'!K95 -> 2121 | L25: ='PL-CF-BS'!L95 -> 1525 | M25: ='PL-CF-BS'!M95 -> 181 | N25: ='PL-CF-BS'!N95 -> 381 | O25: ='PL-CF-BS'!O95 -> 581 | P25: ='PL-CF-BS'!P95 -> 781
B26: 应收账款 | C26: A/R receivables | I26: ='PL-CF-BS'!I96 -> 3297 | J26: ='PL-CF-BS'!J96 -> 4076 | K26: ='PL-CF-BS'!K96 -> 4475 | L26: ='PL-CF-BS'!L96 -> 4619 | M26: ='PL-CF-BS'!M96 -> 5387 | N26: ='PL-CF-BS'!N96 -> 5362.0135 | O26: ='PL-CF-BS'!O96 -> 6114.8832 | P26: ='PL-CF-BS'!P96 -> 6238.367
B27: 存货 | C27: Inventories | I27: ='PL-CF-BS'!I97 -> 2969 | J27: ='PL-CF-BS'!J97 -> 3430 | K27: ='PL-CF-BS'!K97 -> 3739 | L27: ='PL-CF-BS'!L97 -> 4228 | M27: ='PL-CF-BS'!M97 -> 4721 | N27: ='PL-CF-BS'!N97 -> 4482.5999 | O27: ='PL-CF-BS'!O97 -> 4813.7872 | P27: ='PL-CF-BS'!P97 -> 5173.0296
B28: 其他应收款 | C28: Other receivables | I28: ='PL-CF-BS'!I98 -> 677 | J28: ='PL-CF-BS'!J98 -> 685 | K28: ='PL-CF-BS'!K98 -> 851 | L28: ='PL-CF-BS'!L98 -> 874 | M28: ='PL-CF-BS'!M98 -> 1444 | N28: ='PL-CF-BS'!N98 -> 976.87061 | O28: ='PL-CF-BS'!O98 -> 1050.731 | P28: ='PL-CF-BS'!P98 -> 1130.9627
B29: 可供出售金融资产 | C29: Available-for-sale financial assets | I29: ='PL-CF-BS'!I99 -> 0 | J29: ='PL-CF-BS'!J99 -> 0 | K29: ='PL-CF-BS'!K99 -> 0 | L29: ='PL-CF-BS'!L99 -> 0 | M29: ='PL-CF-BS'!M99 -> 0 | N29: ='PL-CF-BS'!N99 -> 100 | O29: ='PL-CF-BS'!O99 -> 200 | P29: ='PL-CF-BS'!P99 -> 300
B30: 其他资产 | C30: Others | I30: ='PL-CF-BS'!I100 -> 0 | J30: ='PL-CF-BS'!J100 -> 0 | K30: ='PL-CF-BS'!K100 -> #REF! | L30: ='PL-CF-BS'!L100 -> 0 | M30: ='PL-CF-BS'!M100 -> 0 | N30: ='PL-CF-BS'!N100 -> 100 | O30: ='PL-CF-BS'!O100 -> 200 | P30: ='PL-CF-BS'!P100 -> 300
I31: ='PL-CF-BS'!I101 -> 7511 | J31: ='PL-CF-BS'!J101 -> 8746 | K31: ='PL-CF-BS'!K101 -> #REF! | L31: ='PL-CF-BS'!L101 -> 11801 | M31: ='PL-CF-BS'!M101 -> 12355 | N31: ='PL-CF-BS'!N101 -> 12681.479 | O31: ='PL-CF-BS'!O101 -> 13543.372 | P31: ='PL-CF-BS'!P101 -> 14951.581
B32: 非流动资产 | C32: Non-current Assets
B33: 长期存款及预付款 | C33: Good will | I33: ='PL-CF-BS'!I103 -> 14751 | J33: ='PL-CF-BS'!J103 -> 14796 | K33: ='PL-CF-BS'!K103 -> 14977 | L33: ='PL-CF-BS'!L103 -> 14713 | M33: ='PL-CF-BS'!M103 -> 15769 | N33: ='PL-CF-BS'!N103 -> 15769 | O33: ='PL-CF-BS'!O103 -> 15769 | P33: ='PL-CF-BS'!P103 -> 15769
B34: 固定资产净值 | C34: Net fixed assets | I34: ='PL-CF-BS'!I104 -> 3064 | J34: ='PL-CF-BS'!J104 -> 3146 | K34: ='PL-CF-BS'!K104 -> 3530 | L34: ='PL-CF-BS'!L104 -> 3729 | M34: ='PL-CF-BS'!M104 -> 4316 | N34: ='PL-CF-BS'!N104 -> 5109.0437 | O34: ='PL-CF-BS'!O104 -> 5675.1311 | P34: ='PL-CF-BS'!P104 -> 6206.2622
B35: 无形资产 | C35: Intangible assets | I35: ='PL-CF-BS'!I105 -> 5855 | J35: ='PL-CF-BS'!J105 -> 5485 | K35: ='PL-CF-BS'!K105 -> 5091 | L35: ='PL-CF-BS'!L105 -> 4657 | M35: ='PL-CF-BS'!M105 -> 5054 | N35: ='PL-CF-BS'!N105 -> 3518.4 | O35: ='PL-CF-BS'!O105 -> 3185.24 | P35: ='PL-CF-BS'!P105 -> 2860.12
B36: 土地使用权 | C36: Other long-term investment | I36: ='PL-CF-BS'!I106 -> 0 | J36: ='PL-CF-BS'!J106 -> 0 | K36: ='PL-CF-BS'!K106 -> 0 | L36: ='PL-CF-BS'!L106 -> 0 | M36: ='PL-CF-BS'!M106 -> 0 | N36: ='PL-CF-BS'!N106 -> 0 | O36: ='PL-CF-BS'!O106 -> 0 | P36: ='PL-CF-BS'!P106 -> 0
B37: 递延事项和其他资产 | C37: Other assets | I37: ='PL-CF-BS'!I107 -> 2846 | J37: ='PL-CF-BS'!J107 -> 2841 | K37: ='PL-CF-BS'!K107 -> 3159 | L37: ='PL-CF-BS'!L107 -> 3481 | M37: ='PL-CF-BS'!M107 -> 3756 | N37: ='PL-CF-BS'!N107 -> 4056 | O37: ='PL-CF-BS'!O107 -> 4356 | P37: ='PL-CF-BS'!P107 -> 4656
I38: ='PL-CF-BS'!I108 -> 26516 | J38: ='PL-CF-BS'!J108 -> 26268 | K38: ='PL-CF-BS'!K108 -> 26757 | L38: ='PL-CF-BS'!L108 -> 26580 | M38: ='PL-CF-BS'!M108 -> 28895 | N38: ='PL-CF-BS'!N108 -> 28452.444 | O38: ='PL-CF-BS'!O108 -> 28985.371 | P38: ='PL-CF-BS'!P108 -> 29491.382
B39: 总资产 | C39: Total Assets | I39: ='PL-CF-BS'!I110 -> 34027 | J39: ='PL-CF-BS'!J110 -> 35014 | K39: ='PL-CF-BS'!K110 -> #REF! | L39: ='PL-CF-BS'!L110 -> 38381 | M39: ='PL-CF-BS'!M110 -> 41250 | N39: ='PL-CF-BS'!N110 -> 41133.923 | O39: ='PL-CF-BS'!O110 -> 42528.743 | P39: ='PL-CF-BS'!P110 -> 44442.963
B40: 流动负债 | C40: Current Liabilities
B41: 短期借款 | C41: Short term borrowings | I41: ='PL-CF-BS'!I113 -> 1748 | J41: ='PL-CF-BS'!J113 -> 334 | K41: ='PL-CF-BS'!K113 -> 1025 | L41: ='PL-CF-BS'!L113 -> 674 | M41: ='PL-CF-BS'!M113 -> 1137 | N41: ='PL-CF-BS'!N113 -> -28 | O41: ='PL-CF-BS'!O113 -> -379 | P41: ='PL-CF-BS'!P113 -> -730
B42: 应付账款 | C42: Payables to suppliers | I42: ='PL-CF-BS'!I115 -> 2797 | J42: ='PL-CF-BS'!J115 -> 3072 | K42: ='PL-CF-BS'!K115 -> 3365 | L42: ='PL-CF-BS'!L115 -> 3678 | M42: ='PL-CF-BS'!M115 -> 4168 | N42: ='PL-CF-BS'!N115 -> 4224.2407 | O42: ='PL-CF-BS'!O115 -> 4384.2707 | P42: ='PL-CF-BS'!P115 -> 4866.6749
...

Sheet 营收预测
G12: 单位：百万usd
G13: 年份 | H13: 2020A | I13: 2021A | J13: 2022A | K13: 2023A | L13: 2024A | M13: 2025A | N13: 2026E | O13: 2027E | P13: 2028E | Q13: 2029E | R13: 2030E | S13: 2031E | T13: 2032E
G14: Revenue
G15: Electrical Americans | H15: 6680 | I15: 7242 | J15: 8497 | K15: 10098 | L15: 11436 | M15: 13276 | N15: =M15*(1+N16) -> 14603.6 | O15: =N15*(1+O16) -> 16063.96 | P15: =O15*(1+P16) -> 17670.356 | Q15: =P15*(1+Q16) -> 19437.392 | R15: =Q15*(1+R16) -> 21381.131 | S15: =R15*(1+S16) -> 23519.244 | T15: =S15*(1+T16) -> 25871.168
G16: yoy | I16: =I15/H15-1 -> 0.084131737 | J16: =J15/I15-1 -> 0.17329467 | K16: =K15/J15-1 -> 0.18841944 | L16: =L15/K15-1 -> 0.13250149 | M16: =M15/L15-1 -> 0.16089542 | N16: 0.1 | O16: 0.1 | P16: 0.1 | Q16: 0.1 | R16: 0.1 | S16: 0.1 | T16: 0.1
G17: Electrical Global | H17: 4703 | I17: 5516 | J17: 5848 | K17: 6084 | L17: 6248 | M17: 6815 | N17: =M17*(1+N18) -> 7121.675 | O17: =N17*(1+O18) -> 7442.1504 | P17: =O17*(1+P18) -> 7777.0471 | Q17: =P17*(1+Q18) -> 8127.0143 | R17: =Q17*(1+R18) -> 8492.7299 | S17: =R17*(1+S18) -> 8874.9028 | T17: =S17*(1+T18) -> 9274.2734
G18: yoy | I18: =I17/H17-1 -> 0.17286838 | J18: =J17/I17-1 -> 0.060188542 | K18: =K17/J17-1 -> 0.040355677 | L18: =L17/K17-1 -> 0.02695595 | M18: =M17/L17-1 -> 0.09074904 | N18: 0.045 | O18: 0.045 | P18: 0.045 | Q18: 0.045 | R18: 0.045 | S18: 0.045 | T18: 0.045
G19: Aerospace | H19: 2223 | I19: 2648 | J19: 3039 | K19: 3413 | L19: 3744 | M19: 4249 | N19: =M19*(1+N20) -> 4588.92 | O19: =N19*(1+O20) -> 4956.0336 | P19: =O19*(1+P20) -> 5352.5163 | Q19: =P19*(1+Q20) -> 5780.7176 | R19: =Q19*(1+R20) -> 6243.175 | S19: =R19*(1+S20) -> 6742.629 | T19: =S19*(1+T20) -> 7282.0393
G20: yoy | I20: =I19/H19-1 -> 0.19118309 | J20: =J19/I19-1 -> 0.14765861 | K20: =K19/J19-1 -> 0.1230668 | L20: =L19/K19-1 -> 0.096982127 | M20: =M19/L19-1 -> 0.13488248 | N20: 0.08 | O20: 0.08 | P20: 0.08 | Q20: 0.08 | R20: 0.08 | S20: 0.08 | T20: 0.08
G21: Vehicle | H21: 2118 | I21: 2579 | J21: 2830 | K21: 2965 | L21: 2790 | M21: 2505 | N21: =M21*(1+N22) -> 2555.1 | O21: =N21*(1+O22) -> 2606.202 | P21: =O21*(1+P22) -> 2658.326 | Q21: =P21*(1+Q22) -> 2698.2009 | R21: =Q21*(1+R22) -> 2738.6739 | S21: =R21*(1+S22) -> 2766.0607 | T21: =S21*(1+T22) -> 2793.7213
G22: yoy | I22: =I21/H21-1 -> 0.21765817 | J22: =J21/I21-1 -> 0.097324544 | K22: =K21/J21-1 -> 0.04770318 | L22: =L21/K21-1 -> -0.059021922 | M22: =M21/L21-1 -> -0.10215054 | N22: 0.02 | O22: 0.02 | P22: 0.02 | Q22: 0.015 | R22: 0.015 | S22: 0.01 | T22: 0.01
G23: eMobility | H23: 292 | I23: 343 | J23: 538 | K23: 636 | L23: 662 | M23: 605 | N23: =M23*(1+N24) -> 635.25 | O23: =N23*(1+O24) -> 667.0125 | P23: =O23*(1+P24) -> 700.36312 | Q23: =P23*(1+Q24) -> 735.38128 | R23: =Q23*(1+R24) -> 772.15035 | S23: =R23*(1+S24) -> 810.75786 | T23: =S23*(1+T24) -> 851.29576
G24: yoy | I24: =I23/H23-1 -> 0.17465753 | J24: =J23/I23-1 -> 0.56851312 | K24: =K23/J23-1 -> 0.18215613 | L24: =L23/K23-1 -> 0.040880503 | M24: =M23/L23-1 -> -0.086102719 | N24: 0.05 | O24: 0.05 | P24: 0.05 | Q24: 0.05 | R24: 0.05 | S24: 0.05 | T24: 0.05
G25: Hydraulics | H25: 1842 | I25: 1300 | J25: 0 | K25: 0 | L25: -2 | M25: 0 | N25: 0 | O25: 0 | P25: 0 | Q25: 0 | R25: 0 | S25: 0 | T25: 0
G26: yoy
G27: Total | H27: =H15+H17+H19+H21+H23+H25 -> 17858 | I27: =I15+I17+I19+I21+I23+I25 -> 19628 | J27: =J15+J17+J19+J21+J23+J25 -> 20752 | K27: =K15+K17+K19+K21+K23+K25 -> 23196 | L27: =L15+L17+L19+L21+L23+L25 -> 24878 | M27: =M15+M17+M19+M21+M23+M25 -> 27450 | N27: =N15+N17+N19+N21+N23+N25 -> 29504.545 | O27: =O15+O17+O19+O21+O23+O25 -> 31735.358 | ... T27: =T15+T17+T19+T21+T23+T25 -> 46072.498
G28: yoy | I28: =I27/H27-1 -> 0.099115242 | J28: =J27/I27-1 -> 0.057265131 | K28: =K27/J27-1 -> 0.11777178 | L28: =L27/K27-1 -> 0.072512502 | M28: =M27/L27-1 -> 0.10338452 | N28: =N27/M27-1 -> 0.074846812 | O28: =O27/N27-1 -> 0.075609147 | P28: =P27/O27-1 -> 0.076358051 | ... T28: =T27/S27-1 -> 0.078637818
G29: Cost
G30: Total | H30: 12408 | I30: 13293 | J30: 13865 | K30: 14762 | L30: 15375 | M30: 17131 | N30: =N27*(1-N33) -> 18383.696 | O30: =O27*(1-O33) -> 19741.936 | P30: =P27*(1-P33) -> 21215.234 | Q30: =Q27*(1-Q33) -> 22805.745 | R30: =R27*(1-R33) -> 24965.552 | S30: =S27*(1-S33) -> 26909.564 | T30: =T27*(1-T33) -> 29025.674
G31: yoy | I31: =I30/H30-1 -> 0.071324952 | J31: =J30/I30-1 -> 0.043030166 | K31: =K30/J30-1 -> 0.064695276 | L31: =L30/K30-1 -> 0.041525539 | M31: =M30/L30-1 -> 0.11421138 | N31: =N30/M30-1 -> 0.073124523 | O31: =O30/N30-1 -> 0.073882869 | P31: =P30/O30-1 -> 0.074627795 | ... T31: =T30/S30-1 -> 0.078637818
G32: GPM
G33: Total | H33: =1-H30/H27 -> 0.30518535 | I33: =1-I30/I27 -> 0.32275321 | J33: =1-J30/J27 -> 0.33187163 | K33: =1-K30/K27 -> 0.36359717 | L33: =1-L30/L27 -> 0.38198408 | M33: =1-M30/M27 -> 0.37591985 | N33: =M33+0.001 -> 0.37691985 | O33: =N33+0.001 -> 0.37791985 | P33: =O33+0.001 -> 0.37891985 | Q33: =P33+0.001 -> 0.37991985 | R33: 0.37 | S33: 0.37 | T33: 0.37
G42: 年份 | H42: 2020A | I42: 2021A | J42: 2022A | K42: 2023A | L42: 2024E
G43: Electrical Americans | H43: 6680 | I43: 7242 | J43: 8497 | K43: 10098 | L43: 11208.78
G44: Electrical Global | H44: 4703 | I44: 5516 | J44: 5848 | K44: 6084 | L44: 6357.78
G45: Aerospace | H45: 2223 | I45: 2648 | J45: 3039 | K45: 3413 | L45: 3788.43
G46: Vehicle | H46: 2118 | I46: 2579 | J46: 2830 | K46: 2965 | L46: 2994.65
G47: eMobility | H47: 292 | I47: 343 | J47: 538 | K47: 636 | L47: 826.8
G48: others | H48: 1842 | I48: 1300 | J48: 0 | K48: 0 | L48: 0
G53: 年份 | H53: Electrical Americans | I53: Electrical Global | J53: Aerospace | K53: Vehicle | L53: eMobility | M53: others
G54: 2020A | H54: 6680 | I54: 4703 | J54: 2223 | K54: 2118 | L54: 292 | M54: 1842
G55: 2021A | H55: 7242 | I55: 5516 | J55: 2648 | K55: 2579 | L55: 343 | M55: 1300
G56: 2022A | H56: 8497 | I56: 5848 | J56: 3039 | K56: 2830 | L56: 538 | M56: 0
G57: 2023A | H57: 10098 | I57: 6084 | J57: 3413 | K57: 2965 | L57: 636 | M57: 0
G58: 2024E | H58: 11208.78 | I58: 6357.78 | J58: 3788.43 | K58: 2994.65 | L58: 826.8 | M58: 0
H62: 2020 | I62: 2021 | J62: 2022 | K62: 2023
G63: Gross Margin | H63: 0.30518535 | I63: 0.32275321 | J63: 0.33187163 | K63: 0.36359717
G64: Operating margin | H64: 0.10611491 | I64: 0.15488078 | J64: 0.14721473 | K64: 0.16748577
G65: Net margin | H65: 0.07895621 | I65: 0.10923171 | J65: 0.11863917 | K65: 0.13873082
G66: ROE | H66: 0.18888145 | I66: 0.13680886 | J66: 0.14720918 | K66: 0.17842094
...

Sheet S&C
B1: Eaton
B2: S&C
B3: (all in Rmb mn unless otherwise noted)
F4: 2018A | G4: 2019A | H4: 2020A | I4: 2021A | J4: 2022A | K4: 2023A | L4: 2024A | M4: 2025A | N4: 2026E | O4: 2027E | P4: 2028E | Q4: 2029E | R4: 2030E | S4: 2031E | T4: 2032E
B5: Revenue | H5: =营收预测!H27 -> 17858 | I5: =营收预测!I27 -> 19628 | J5: =营收预测!J27 -> 20752 | K5: =营收预测!K27 -> 23196 | L5: =营收预测!L27 -> 24878 | M5: =营收预测!M27 -> 27450 | N5: =营收预测!N27 -> 29504.545 | O5: =营收预测!O27 -> 31735.358 | ... T5: =营收预测!T27 -> 46072.498
C6: +/- | H6: =H5/G5-1 -> #DIV/0! | I6: =I5/H5-1 -> 0.099115242 | J6: =J5/I5-1 -> 0.057265131 | K6: =K5/J5-1 -> 0.11777178 | L6: =L5/K5-1 -> 0.072512502 | M6: =M5/L5-1 -> 0.10338452 | N6: =N5/M5-1 -> 0.074846812 | O6: =O5/N5-1 -> 0.075609147 | ... T6: =T5/S5-1 -> 0.078637818
B7: Cost of goods sold | H7: =营收预测!H30 -> 12408 | I7: =营收预测!I30 -> 13293 | J7: =营收预测!J30 -> 13865 | K7: =营收预测!K30 -> 14762 | L7: =营收预测!L30 -> 15375 | M7: =营收预测!M30 -> 17131 | N7: =营收预测!N30 -> 18383.696 | O7: =营收预测!O30 -> 19741.936 | ... T7: =营收预测!T30 -> 29025.674
C8: +/- | H8: =H7/G7-1 -> #DIV/0! | I8: =I7/H7-1 -> 0.071324952 | J8: =J7/I7-1 -> 0.043030166 | K8: =K7/J7-1 -> 0.064695276 | L8: =L7/K7-1 -> 0.041525539 | M8: =M7/L7-1 -> 0.11421138 | N8: =N7/M7-1 -> 0.073124523 | O8: =O7/N7-1 -> 0.073882869 | ... T8: =T7/S7-1 -> 0.078637818
Q9: CAGR | R9: =(R5/M5)^(1/5)-1 -> 0.076196695
B10: Revenue
C11: Category A
C12: Category B
C13: Category C
C15: =C11 -> Category A
C16: =C12 -> Category B
C17: =C13 -> Category C
B19: Retail network (store #)
C20: =C11 -> Category A
C21: =C12 -> Category B
C22: =C13 -> Category C
B24: Retail network growth
C25: =C11 -> Category A
C26: =C12 -> Category B
C27: =C13 -> Category C
B29: SSSG
C30: =C11 -> Category A
C31: =C12 -> Category B
C32: =C13 -> Category C
B34: Gross margin
C35: =C11 -> Category A
C36: =C12 -> Category B
C37: =C13 -> Category C
B39: Gross profit
C40: =C11 -> Category A
C41: =C12 -> Category B
C42: =C13 -> Category C

Sheet Other ASPT
B1: ='S&C'!B1 -> Eaton
B2: Other Assumptions
B3: ='S&C'!B3 -> (all in Rmb mn unless otherwise noted) | F3: ='PL-CF-BS'!F2 -> 0 | G3: ='PL-CF-BS'!G2 -> 0 | H3: ='PL-CF-BS'!H2 -> 0 | I3: ='PL-CF-BS'!I2 -> 0 | J3: ='PL-CF-BS'!J2 -> 0 | K3: ='PL-CF-BS'!K2 -> #REF! | L3: ='PL-CF-BS'!L2 -> -1 | M3: ='PL-CF-BS'!M2 -> -1 | ... T3: ='PL-CF-BS'!T2 -> -752.31786
F4: ='S&C'!F4 -> 2018A | G4: ='S&C'!G4 -> 2019A | H4: ='S&C'!H4 -> 2020A | I4: ='S&C'!I4 -> 2021A | J4: ='S&C'!J4 -> 2022A | K4: ='S&C'!K4 -> 2023A | L4: ='S&C'!L4 -> 2024A | M4: ='S&C'!M4 -> 2025A | ... T4: ='S&C'!T4 -> 2032E
B5: HK$/Rmb exchange rate | F5: 1 | G5: 1 | H5: 1 | I5: 1 | J5: 1 | K5: 1 | L5: 1 | M5: 1 | N5: 1 | O5: 1 | P5: 1 | Q5: 1 | R5: 1 | S5: 1 | T5: 1
B7: Working Capital
B8: Accounts receivables | F8: ='PL-CF-BS'!F96 -> 0 | G8: ='PL-CF-BS'!G96 -> 0 | H8: ='PL-CF-BS'!H96 -> 2904 | I8: ='PL-CF-BS'!I96 -> 3297 | J8: ='PL-CF-BS'!J96 -> 4076 | K8: ='PL-CF-BS'!K96 -> 4475 | L8: ='PL-CF-BS'!L96 -> 4619 | M8: =(M9*2/365*'PL-CF-BS'!M6-'Other ASPT'!L8) -> 5308.1233 | N8: =(N9*2/365*'PL-CF-BS'!N6-'Other ASPT'!M8) -> 5362.0135 | O8: =(O9*2/365*'PL-CF-BS'!O6-'Other ASPT'!N8) -> 6114.8832 | P8: =(P9*2/365*'PL-CF-BS'!P6-'Other ASPT'!O8) -> 6238.367 | Q8: =(Q9*2/365*'PL-CF-BS'!Q6-'Other ASPT'!P8) -> 7062.4252 | R8: =(R9*2/365*'PL-CF-BS'!R6-'Other ASPT'!Q8) -> 7268.7461 | S8: =(S9*2/365*'PL-CF-BS'!S6-'Other ASPT'!R8) -> 8178.3619 | T8: =(T9*2/365*'PL-CF-BS'!T6-'Other ASPT'!S8) -> 8483.473
C9: Turnover days | G9: =AVERAGE(F8:G8)/'PL-CF-BS'!G6*365 -> #DIV/0! | H9: =AVERAGE(G8:H8)/'PL-CF-BS'!H6*365 -> 29.677455 | I9: =AVERAGE(H8:I8)/'PL-CF-BS'!I6*365 -> 57.656537 | J9: =AVERAGE(I8:J8)/'PL-CF-BS'!J6*365 -> 64.840618 | K9: =AVERAGE(J8:K8)/'PL-CF-BS'!K6*365 -> 67.277009 | L9: 66 | M9: =L9 -> 66 | N9: =M9 -> 66 | O9: =N9 -> 66 | P9: =O9 -> 66 | Q9: =P9 -> 66 | R9: =Q9 -> 66 | S9: =R9 -> 66 | T9: =S9 -> 66
B10: Inventory | F10: ='PL-CF-BS'!F97 -> 0 | G10: ='PL-CF-BS'!G97 -> 0 | H10: ='PL-CF-BS'!H97 -> 2109 | I10: ='PL-CF-BS'!I97 -> 2969 | J10: ='PL-CF-BS'!J97 -> 3430 | K10: ='PL-CF-BS'!K97 -> 3739 | L10: ='PL-CF-BS'!L97 -> 4228 | M10: =-M11/365*'PL-CF-BS'!M7 -> 4177.1479 | N10: =-N11/365*'PL-CF-BS'!N7 -> 4482.5999 | O10: =-O11/365*'PL-CF-BS'!O7 -> 4813.7872 | P10: =-P11/365*'PL-CF-BS'!P7 -> 5173.0296 | Q10: =-Q11/365*'PL-CF-BS'!Q7 -> 5560.8529 | R10: =-R11/365*'PL-CF-BS'!R7 -> 6087.4907 | S10: =-S11/365*'PL-CF-BS'!S7 -> 6561.5102 | T10: =-T11/365*'PL-CF-BS'!T7 -> 7077.493
C11: Turnover days | G11: =-AVERAGE(F10:G10)/'PL-CF-BS'!G7*365 -> #DIV/0! | H11: =-AVERAGE(G10:H10)/'PL-CF-BS'!H7*365 -> -31.019705 | I11: =-AVERAGE(H10:I10)/'PL-CF-BS'!I7*365 -> -69.716016 | J11: =-AVERAGE(I10:J10)/'PL-CF-BS'!J7*365 -> -84.227732 | K11: =-AVERAGE(J10:K10)/'PL-CF-BS'!K7*365 -> -88.629081 | L11: -89 | M11: =L11 -> -89 | N11: =M11 -> -89 | O11: =N11 -> -89 | P11: =O11 -> -89 | Q11: =P11 -> -89 | R11: =Q11 -> -89 | S11: =R11 -> -89 | T11: =S11 -> -89
B12: Other receivables, deposits and prepayments | F12: ='PL-CF-BS'!F98 -> 0 | G12: ='PL-CF-BS'!G98 -> 0 | H12: ='PL-CF-BS'!H98 -> 576 | I12: ='PL-CF-BS'!I98 -> 677 | J12: ='PL-CF-BS'!J98 -> 685 | K12: ='PL-CF-BS'!K98 -> 851 | L12: ='PL-CF-BS'!L98 -> 874 | M12: =M13/365*'PL-CF-BS'!M6 -> 908.84635 | N12: =N13/365*'PL-CF-BS'!N6 -> 976.87061 | O12: =O13/365*'PL-CF-BS'!O6 -> 1050.731 | P12: =P13/365*'PL-CF-BS'!P6 -> 1130.9627 | Q12: =Q13/365*'PL-CF-BS'!Q6 -> 1217.7119 | R12: =R13/365*'PL-CF-BS'!R6 -> 1312.045 | S12: =S13/365*'PL-CF-BS'!S6 -> 1414.2111 | T12: =T13/365*'PL-CF-BS'!T6 -> 1525.4216
C13: Turnover days | G13: =AVERAGE(F12:G12)/'PL-CF-BS'!G6*365 -> #DIV/0! | H13: =AVERAGE(G12:H12)/'PL-CF-BS'!H6*365 -> 5.8864375 | I13: =AVERAGE(H12:I12)/'PL-CF-BS'!I6*365 -> 11.650321 | J13: =AVERAGE(I12:J12)/'PL-CF-BS'!J6*365 -> 11.977882 | K13: =AVERAGE(J12:K12)/'PL-CF-BS'!K6*365 -> 12.084842 | L13: =K13 -> 12.084842 | M13: =L13 -> 12.084842 | N13: =M13 -> 12.084842 | O13: =N13 -> 12.084842 | P13: =O13 -> 12.084842 | Q13: =P13 -> 12.084842 | R13: =Q13 -> 12.084842 | S13: =R13 -> 12.084842 | T13: =S13 -> 12.084842
B15: Accounts payables | F15: ='PL-CF-BS'!F115 -> 0 | G15: ='PL-CF-BS'!G115 -> 0 | H15: ='PL-CF-BS'!H115 -> 1987 | I15: ='PL-CF-BS'!I115 -> 2797 | J15: ='PL-CF-BS'!J115 -> 3072 | K15: ='PL-CF-BS'!K115 -> 3365 | L15: ='PL-CF-BS'!L115 -> 3678 | M15: =-2*M16/365*'PL-CF-BS'!M7-L15 -> 3792.0072 | N15: =-2*N16/365*'PL-CF-BS'!N7-M15 -> 4224.2407 | O15: =-2*O16/365*'PL-CF-BS'!O7-N15 -> 4384.2707 | P15: =-2*P16/365*'PL-CF-BS'!P7-O15 -> 4866.6749 | Q15: =-2*Q16/365*'PL-CF-BS'!Q7-P15 -> 5077.8164 | R15: =-2*R16/365*'PL-CF-BS'!R7-Q15 -> 5808.463 | S15: =-2*S16/365*'PL-CF-BS'!S7-R15 -> 5925.507 | T15: =-2*T16/365*'PL-CF-BS'!T7-S15 -> 6731.1968
C16: Turnover days | G16: =-AVERAGE(F15:G15)/'PL-CF-BS'!G7*365 -> #DIV/0! | H16: =-AVERAGE(G15:H15)/'PL-CF-BS'!H7*365 -> -29.225298 | I16: =-AVERAGE(H15:I15)/'PL-CF-BS'!I7*365 -> -65.679681 | J16: =-AVERAGE(I15:J15)/'PL-CF-BS'!J7*365 -> -77.251533 | K16: =-AVERAGE(J15:K15)/'PL-CF-BS'!K7*365 -> -79.579495 | L16: =K16 -> -79.579495 | M16: =L16 -> -79.579495 | N16: =M16 -> -79.579495 | O16: =N16 -> -79.579495 | P16: =O16 -> -79.579495 | Q16: =P16 -> -79.579495 | R16: =Q16 -> -79.579495 | S16: =R16 -> -79.579495 | T16: =S16 -> -79.579495
B17: Note payables | F17: ='PL-CF-BS'!F116 -> 0 | G17: ='PL-CF-BS'!G116 -> 0 | H17: ='PL-CF-BS'!H116 -> 0 | I17: ='PL-CF-BS'!I116 -> 0 | J17: ='PL-CF-BS'!J116 -> 0 | L17: 0 | M17: 0 | N17: 0 | O17: 0 | P17: 0 | Q17: 0 | R17: 0 | S17: 0 | T17: 0
C18: Turnover days
B19: Other payables, accruals and other current liabilities | F19: ='PL-CF-BS'!F117 -> 0 | G19: ='PL-CF-BS'!G117 -> 0 | H19: ='PL-CF-BS'!H117 -> 351 | I19: ='PL-CF-BS'!I117 -> 501 | J19: ='PL-CF-BS'!J117 -> 467 | K19: ='PL-CF-BS'!K117 -> 676 | L19: ='PL-CF-BS'!L117 -> 670 | M19: =-2*M20/365*'PL-CF-BS'!M7-L19 -> 656.42819 | N19: =-2*N20/365*'PL-CF-BS'!N7-M19 -> 766.99443 | O19: =-2*O20/365*'PL-CF-BS'!O7-N19 -> 761.59474 | P19: =-2*P20/365*'PL-CF-BS'!P7-O19 -> 881.06967 | Q19: =-2*Q20/365*'PL-CF-BS'!Q7-P19 -> 884.74572 | R19: =-2*R20/365*'PL-CF-BS'!R7-Q19 -> 1048.3003 | S19: =-2*S20/365*'PL-CF-BS'!S7-R19 -> 1035.2678 | T19: =-2*T20/365*'PL-CF-BS'!T7-S19 -> 1212.1476
C20: Turnover days | G20: 38.693902 | H20: 33.662597 | I20: =-AVERAGE(H19:I19)/'PL-CF-BS'!I7*365 -> -11.697134 | J20: =-AVERAGE(I19:J19)/'PL-CF-BS'!J7*365 -> -12.741435 | K20: =-AVERAGE(J19:K19)/'PL-CF-BS'!K7*365 -> -14.130707 | L20: =K20 -> -14.130707 | M20: =L20 -> -14.130707 | N20: =M20 -> -14.130707 | O20: =N20 -> -14.130707 | P20: =O20 -> -14.130707 | Q20: =P20 -> -14.130707 | R20: =Q20 -> -14.130707 | S20: =R20 -> -14.130707 | T20: =S20 -> -14.130707
B21: Amount due to related parties | F21: ='PL-CF-BS'!F118 -> 0 | G21: ='PL-CF-BS'!G118 -> 0 | H21: ='PL-CF-BS'!H118 -> 0 | I21: ='PL-CF-BS'!I118 -> 0 | J21: ='PL-CF-BS'!J118 -> 0 | K21: 0 | L21: 0 | M21: 0 | N21: 0 | O21: 0 | P21: 0 | Q21: 0 | R21: 0 | S21: 0 | T21: 0
B24: Change of working capital | G24: =(G15+G17+G19+G21-G8-G10-G12)-(F15+F17+F19+F21-F8-F10-F12) -> 0 | H24: =(H15+H17+H19+H21-H8-H10-H12)-(G15+G17+G19+G21-G8-G10-G12) -> -3251 | I24: =(I15+I17+I19+I21-I8-I10-I12)-(H15+H17+H19+H21-H8-H10-H12) -> -394 | J24: =(J15+J17+J19+J21-J8-J10-J12)-(I15+I17+I19+I21-I8-I10-I12) -> -1007 | K24: =(K15+K17+K19+K21-K8-K10-K12)-(J15+J17+J19+J21-J8-J10-J12) -> -372 | L24: =(L15+L17+L19+L21-L8-L10-L12)-(K15+K17+K19+K21-K8-K10-K12) -> -349 | M24: =(M15+M17+M19+M21-M8-M10-M12)-(L15+L17+L19+L21-L8-L10-L12) -> -572.68214 | N24: =(N15+N17+N19+N21-N8-N10-N12)-(M15+M17+M19+M21-M8-M10-M12) -> 115.43325 | ... T24: =(T15+T17+T19+T21-T8-T10-T12)-(S15+S17+S19+S21-S8-S10-S12) -> 50.265205
B26: Debt
B27: Long-term loan
C28: Beginning | G28: =F30 -> 0 | H28: =G30 -> 0 | I28: =H30 -> 7010 | J28: =I30 -> 6831 | K28: =J30 -> 8321 | L28: =K30 -> 8244 | M28: =L30 -> 8478 | N28: =M30 -> 8528 | ... T28: =S30 -> 8828
C29: Change | G29: =G30-G28 -> 0 | H29: =H30-H28 -> 7010 | I29: =I30-I28 -> -179 | J29: =J30-J28 -> 1490 | K29: =K30-K28 -> -77 | L29: 50 | M29: =L29 -> 50 | N29: =M29 -> 50 | O29: =N29 -> 50 | P29: =O29 -> 50 | Q29: =P29 -> 50 | R29: =Q29 -> 50 | S29: =R29 -> 50 | T29: =S29 -> 50
C30: Ending | F30: ='PL-CF-BS'!F124 -> 0 | G30: ='PL-CF-BS'!G124 -> 0 | H30: ='PL-CF-BS'!H124 -> 7010 | I30: ='PL-CF-BS'!I124 -> 6831 | J30: ='PL-CF-BS'!J124 -> 8321 | K30: ='PL-CF-BS'!K124 -> 8244 | L30: ='PL-CF-BS'!L124 -> 8478 | M30: =M28+M29 -> 8528 | N30: =N28+N29 -> 8578 | O30: =O28+O29 -> 8628 | P30: =P28+P29 -> 8678 | Q30: =Q28+Q29 -> 8728 | R30: =R28+R29 -> 8778 | S30: =S28+S29 -> 8828 | T30: =T28+T29 -> 8878
C31: Interest expense | K31: =-K45*AVERAGE(K28,K30) -> 0 | L31: =-L45*AVERAGE(L28,L30) -> 0 | M31: =-M45*AVERAGE(M28,M30) -> 0 | N31: =-N45*AVERAGE(N28,N30) -> 0 | O31: =-O45*AVERAGE(O28,O30) -> 0 | P31: =-P45*AVERAGE(P28,P30) -> 0 | Q31: =-Q45*AVERAGE(Q28,Q30) -> 0 | R31: =-R45*AVERAGE(R28,R30) -> 0 | ... T31: =-T45*AVERAGE(T28,T30) -> 0
B32: Short-term loan
C34: Beginning | G34: =F36 -> 0 | H34: =G36 -> 0 | I34: =H36 -> 1048 | J34: =I36 -> 1748 | K34: =J36 -> 334 | L34: =K36 -> 1025 | M34: =L36 -> 674 | N34: =M36 -> 323 | ... T34: =S36 -> -1783
C35: Change | G35: =G36-G34 -> 0 | H35: =H36-H34 -> 1048 | I35: =I36-I34 -> 700 | J35: =J36-J34 -> -1414 | K35: =K36-K34 -> 691 | L35: =L36-L34 -> -351 | M35: =L35 -> -351 | N35: =M35 -> -351 | O35: =N35 -> -351 | P35: =O35 -> -351 | Q35: =P35 -> -351 | R35: =Q35 -> -351 | S35: =R35 -> -351 | T35: =S35 -> -351
C36: Ending | F36: ='PL-CF-BS'!F113 -> 0 | G36: ='PL-CF-BS'!G113 -> 0 | H36: ='PL-CF-BS'!H113 -> 1048 | I36: ='PL-CF-BS'!I113 -> 1748 | J36: ='PL-CF-BS'!J113 -> 334 | K36: ='PL-CF-BS'!K113 -> 1025 | L36: ='PL-CF-BS'!L113 -> 674 | M36: =M35+M34 -> 323 | N36: =N35+N34 -> -28 | O36: =O35+O34 -> -379 | P36: =P35+P34 -> -730 | Q36: =Q35+Q34 -> -1081 | R36: =R35+R34 -> -1432 | S36: =S35+S34 -> -1783 | T36: =T35+T34 -> -2134
C37: Interest expense | F37: ='PL-CF-BS'!F154 -> 0 | G37: ='PL-CF-BS'!G154 -> 0 | H37: ='PL-CF-BS'!H154 -> -149 | I37: ='PL-CF-BS'!I154 -> -144 | J37: ='PL-CF-BS'!J154 -> -144 | K37: ='PL-CF-BS'!K154 -> -151 | L37: ='PL-CF-BS'!L154 -> #REF! | M37: =-M46*AVERAGE(M34,M36,M28,M30) -> -151.66553 | N37: =-N46*AVERAGE(N34,N36,N28,N30) -> -146.59401 | O37: =-O46*AVERAGE(O34,O36,O28,O30) -> -141.52248 | P37: =-P46*AVERAGE(P34,P36,P28,P30) -> -136.45096 | Q37: =-Q46*AVERAGE(Q34,Q36,Q28,Q30) -> -131.37944 | R37: =-R46*AVERAGE(R34,R36,R28,R30) -> -126.30791 | S37: =-S46*AVERAGE(S34,S36,S28,S30) -> -121.23639 | T37: =-T46*AVERAGE(T34,T36,T28,T30) -> -116.16486
B39: Cash & equivalent
C40: Cash | F40: ='PL-CF-BS'!F94 -> 0 | G40: ='PL-CF-BS'!G94 -> 0 | H40: ='PL-CF-BS'!H94 -> 438 | I40: ='PL-CF-BS'!I94 -> 297 | J40: ='PL-CF-BS'!J94 -> 294 | K40: ='PL-CF-BS'!K94 -> 488 | L40: ='PL-CF-BS'!L94 -> 555 | M40: ='PL-CF-BS'!M94 -> 622 | ... T40: ='PL-CF-BS'!T94 -> 1900.6882
C41: Deposit | F41: ='PL-CF-BS'!F95 -> 0 | G41: ='PL-CF-BS'!G95 -> 0 | H41: ='PL-CF-BS'!H95 -> 664 | I41: ='PL-CF-BS'!I95 -> 271 | J41: ='PL-CF-BS'!J95 -> 261 | K41: ='PL-CF-BS'!K95 -> 2121 | L41: ='PL-CF-BS'!L95 -> 1525 | M41: ='PL-CF-BS'!M95 -> 181 | ... T41: ='PL-CF-BS'!T95 -> 1581
