Workbook
Name \b: #REF!
Name \c: #REF!
Name \d: #REF!
Name \e: #REF!
Name \f: #REF!
Name \g: #REF!
Name \h: #REF!
Name \i: #REF!
Name \j: #N/A
Name \k: #REF!
Name \l: #REF!
Name \m: #REF!
Name \p: #REF!
Name \q: #REF!
Name \s: #REF!
Name \u: #REF!
Name \v: #N/A
Name \x: #REF!
Name \z: #REF!
Name _______DAT1: #REF!
Name _______DAT2: #REF!
Name _______DAT3: #REF!
Name _______DAT4: #REF!
Name _______DAT5: #REF!
Name _______DAT6: #REF!
Name _______DAT7: #REF!
Name _______DAT8: #REF!
Name _______DCF2: #REF!
Name _______EPS94: #REF!
Name _______EPS95: #REF!
Name _______EPS96: #REF!
Name _______EPS97: #REF!
Name _______EPS98: #REF!
Name _______rev1997: #REF!
Name _______rev1999: #REF!
Name _______rev2000: #REF!
Name _______rev2001: #REF!
Name _______rev2002: #REF!
Name _______rev2003: #REF!
Name _______REV89: #REF!
Name _______REV90: #REF!
Name _______REV91: #REF!
Name _______REV92: #REF!
Name _______REV93: #REF!
Name _______REV94: #REF!
Name _______REV95: #REF!
Name _______REV96: #REF!
Name _______REV97: #REF!
Name _______REV98: #REF!
Name ______DAT1: #REF!
Name ______DAT2: #REF!
Name ______DAT3: #REF!
Name ______DAT4: #REF!
Name ______DAT5: #REF!
Name ______DAT6: #REF!
Name ______DAT7: #REF!
Name ______DAT8: #REF!
Name ______DCF2: #REF!
Name ______EPS94: #REF!
Name ______EPS95: #REF!

Sheet XN
A1: Code | B1: 2507 HK | C1: Please enter the ticker in B1, e.g. 700 HK
A2: Last annual report | B2: 45657 | C2: Please enter the date in B2, e.g. 2020/3/31
A3: Start year | B3: 2024
A4: Currency | B4: US$
A5: Unit | B5: mn
A6: =B4&" "&B5 -> US$ mn | B6: =TEXT(DATE($B$3,MONTH($B$2),DAY($B$2)),"mmm-yy")&IF($B$3>YEAR($B$2),"E","A") -> Dec-24A | C6: =TEXT(DATE($B$3+1,MONTH($B$2),DAY($B$2)),"mmm-yy")&IF($B$3+1>YEAR($B$2),"E","A") -> Dec-25E | D6: =TEXT(DATE($B$3+2,MONTH($B$2),DAY($B$2)),"mmm-yy")&IF($B$3+2>YEAR($B$2),"E","A") -> Dec-26E | E6: =TEXT(DATE($B$3+3,MONTH($B$2),DAY($B$2)),"mmm-yy")&IF($B$3+3>YEAR($B$2),"E","A") -> Dec-27E
A7: P&L
A8: Revenue | B8: ='PL-CF-BS'!J6 -> 1197.133 | C8: ='PL-CF-BS'!K6 -> 1354.37 | D8: ='PL-CF-BS'!L6 -> 1522.2509 | E8: ='PL-CF-BS'!M6 -> 1676.6468
A9: (+/-) | B9: ='PL-CF-BS'!J7 -> 0.1212176 | C9: ='PL-CF-BS'!K7 -> 0.13134464 | D9: ='PL-CF-BS'!L7 -> 0.12395496 | E9: ='PL-CF-BS'!M7 -> 0.1014261
A10: Net profit | B10: ='PL-CF-BS'!J66 -> 120.742 | C10: ='PL-CF-BS'!K66 -> 138.90152 | D10: ='PL-CF-BS'!L66 -> 156.28551 | E10: ='PL-CF-BS'!M66 -> 178.92095
A11: (+/-) | B11: ='PL-CF-BS'!J67 -> 0.32473887 | C11: ='PL-CF-BS'!K67 -> 0.1503994 | D11: ='PL-CF-BS'!L67 -> 0.12515335 | E11: ='PL-CF-BS'!M67 -> 0.14483384
A12: ="Diluted EPS ("&B4&")" -> Diluted EPS (US$) | B12: ='PL-CF-BS'!J79 -> 0.32990625 | C12: ='PL-CF-BS'!K79 -> 0.37951236 | D12: ='PL-CF-BS'!L79 -> 0.4270096 | E12: ='PL-CF-BS'!M79 -> 0.48885504
A13: GPM | B13: ='PL-CF-BS'!J166 -> 0.34545034 | C13: ='PL-CF-BS'!K166 -> 0.35226711 | D13: ='PL-CF-BS'!L166 -> 0.35105923 | E13: ='PL-CF-BS'!M166 -> 0.35434578 | F13: e.g. 50.5%
A14: ROE | B14: ='PL-CF-BS'!J171 -> 0.19236741 | C14: ='PL-CF-BS'!K171 -> 0.16673001 | D14: ='PL-CF-BS'!L171 -> 0.16908445 | E14: ='PL-CF-BS'!M171 -> 0.17271499 | F14: e.g. 50.5%
A15: EBITDA | B15: ='PL-CF-BS'!J45 -> 197.745 | C15: ='PL-CF-BS'!K45 -> 213.5458 | D15: ='PL-CF-BS'!L45 -> 238.21723 | E15: ='PL-CF-BS'!M45 -> 269.09286
A16: EBIT | B16: ='DCF '!F7 -> 152.769 | C16: ='DCF '!G7 -> 173.293 | D16: ='DCF '!H7 -> 195.5859 | E16: ='DCF '!I7 -> 224.34181
A17: Interest Revenue | B17: ='PL-CF-BS'!J50 -> 0 | C17: ='PL-CF-BS'!K50 -> 0 | D17: ='PL-CF-BS'!L50 -> 0 | E17: ='PL-CF-BS'!M50 -> 0
A18: Interest Expense | B18: ='PL-CF-BS'!J49 -> 0 | C18: ='PL-CF-BS'!K49 -> 0 | D18: ='PL-CF-BS'!L49 -> 0 | E18: ='PL-CF-BS'!M49 -> 0
A19: Operating Profit | B19: ='PL-CF-BS'!J41 -> 152.769 | C19: ='PL-CF-BS'!K41 -> 173.293 | D19: ='PL-CF-BS'!L41 -> 195.5859 | E19: ='PL-CF-BS'!M41 -> 224.34181
A20: Gross Profit | B20: ='PL-CF-BS'!J9 -> 413.55 | C20: ='PL-CF-BS'!K9 -> 477.1 | D20: ='PL-CF-BS'!L9 -> 534.40022 | E20: ='PL-CF-BS'!M9 -> 594.11273
A21: Depreciation | B21: ='PL-CF-BS'!J90 -> 44.976 | C21: ='PL-CF-BS'!K90 -> 40.2528 | D21: ='PL-CF-BS'!L90 -> 42.63133 | E21: ='PL-CF-BS'!M90 -> 44.751046
A22: Pre-Tax Profit | B22: ='PL-CF-BS'!J59 -> 147.624 | C22: ='PL-CF-BS'!K59 -> 169.693 | D22: ='PL-CF-BS'!L59 -> 190.59 | E22: ='PL-CF-BS'!M59 -> 219.53249
A23: Balance Sheet
A24: Total Assets | B24: ='PL-CF-BS'!J132 -> 1363.221 | C24: ='PL-CF-BS'!K132 -> 1460.561 | D24: ='PL-CF-BS'!L132 -> 1589.6496 | E24: ='PL-CF-BS'!M132 -> 1783.2465
A25: Total Liabilities | B25: ='PL-CF-BS'!J148 -> 581.27 | C25: ='PL-CF-BS'!K148 -> 576.302 | D25: ='PL-CF-BS'!L148 -> 621.9306 | E25: ='PL-CF-BS'!M148 -> 671.24606
A26: Shareholder Equity | B26: ='PL-CF-BS'!J160 -> 781.951 | C26: ='PL-CF-BS'!K160 -> 884.234 | D26: ='PL-CF-BS'!L160 -> 964.37493 | E26: ='PL-CF-BS'!M160 -> 1107.4886
A27: Total Equity | B27: ='PL-CF-BS'!J160 -> 781.951 | C27: ='PL-CF-BS'!K156 -> 884.234 | D27: ='PL-CF-BS'!L156 -> 964.37493 | E27: ='PL-CF-BS'!M156 -> 1107.4886
A28: Cash Flow
A29: Profit before tax | B29: =B22 -> 147.624 | C29: =C22 -> 169.693 | D29: =D22 -> 190.59 | E29: =E22 -> 219.53249
A30: Net Cash from operations | B30: ='PL-CF-BS'!J93 -> 164.531 | C30: ='PL-CF-BS'!K93 -> 146 | D30: ='PL-CF-BS'!L93 -> 152.31158 | E30: ='PL-CF-BS'!M93 -> 178.54121
A31: Net Cash from investment activity | B31: ='PL-CF-BS'!J99 -> -193.385 | C31: ='PL-CF-BS'!K99 -> -171.2 | D31: ='PL-CF-BS'!L99 -> -163.1551 | E31: ='PL-CF-BS'!M99 -> -193.03349
A32: Net Cash from financing activity | B32: ='PL-CF-BS'!J109 -> 173.818 | C32: ='PL-CF-BS'!K109 -> -87.1 | D32: ='PL-CF-BS'!L109 -> 13.233667 | E32: ='PL-CF-BS'!M109 -> 24.048222
A33: Net change in Cash | B33: ='PL-CF-BS'!J111 -> 144.964 | C33: ='PL-CF-BS'!K111 -> -112.3 | D33: ='PL-CF-BS'!L111 -> 2.3901425 | E33: ='PL-CF-BS'!M111 -> 9.5559484
A34: Implied cash at end of period | B34: ='PL-CF-BS'!J112 -> 246.869 | C34: ='PL-CF-BS'!K112 -> 391.837 | D34: ='PL-CF-BS'!L112 -> 279.537 | E34: ='PL-CF-BS'!M112 -> 281.92714
A35: Free Cash Flow | B35: ='DCF '!F14 -> 103.98889 | C35: ='DCF '!G14 -> -54.09667 | D35: ='DCF '!H14 -> 78.60262 | E35: ='DCF '!I14 -> 89.664304
A40: EPS | B40: =B12 -> 0.32990625 | C40: =C12 -> 0.37951236 | D40: =D12 -> 0.4270096 | E40: =E12 -> 0.48885504
A41: EPS1 | B41: =IF(A43-YEAR($B$2)>=0,VLOOKUP((A43-B3+1),A45:B48,2,FALSE),"na") -> 0.4270096
A42: EPS2 | B42: =IF(A43-YEAR($B$2)>=0,VLOOKUP((A43-B3+2),A45:B48,2,FALSE),"na") -> 0.48885504
A43: =YEAR(TODAY()) -> 2026
A44: =YEAR(TODAY()) -> 2026
...

Sheet XN-output
B2: 资产负债表（百万美元） | C2: =K17 -> 2023 | D2: =L17 -> 2024 | E2: =M17 -> 2025E | F2: =N17 -> 2026E | G2: =O17 -> 2027E | H2: 2028E | J2: 利润表（百万美元） | K2: =K17 -> 2023 | L2: =L17 -> 2024 | M2: =M17 -> 2025E | N2: =N17 -> 2026E | O2: =O17 -> 2027E | P2: 2028E | R2: BS (USD mn) | S2: =C2 -> 2023 | T2: =D2 -> 2024 | U2: =E2 -> 2025E | V2: =F2 -> 2026E | W2: =G2 -> 2027E | X2: 2028E | Z2: IS (USD mn) | AA2: =K2 -> 2023 | AB2: =L2 -> 2024 | AC2: =M2 -> 2025E | AD2: =N2 -> 2026E | AE2: =O2 -> 2027E | AF2: 2028E
B3: 现金及现金等价物 | C3: ='PL-CF-BS'!I117 -> 246.869 | D3: ='PL-CF-BS'!J117 -> 391.837 | E3: ='PL-CF-BS'!K117 -> 279.5 | F3: ='PL-CF-BS'!L117 -> 281.92714 | G3: ='PL-CF-BS'!M117 -> 291.48309 | H3: ='PL-CF-BS'!N117 -> 303.74833 | J3: 营业收入 | K3: ='PL-CF-BS'!I6 -> 1067.708 | L3: ='PL-CF-BS'!J6 -> 1197.133 | M3: ='PL-CF-BS'!K6 -> 1354.37 | N3: ='PL-CF-BS'!L6 -> 1522.2509 | O3: ='PL-CF-BS'!M6 -> 1676.6468 | P3: ='PL-CF-BS'!N6 -> 1844.3115 | R3: Cash and equivalents | S3: =C3 -> 246.869 | T3: =D3 -> 391.837 | U3: =E3 -> 279.5 | V3: =F3 -> 281.92714 | W3: =G3 -> 291.48309 | X3: =H3 -> 303.74833 | Z3: Revenue | AA3: =K3 -> 1067.708 | AB3: =L3 -> 1197.133 | AC3: =M3 -> 1354.37 | AD3: =N3 -> 1522.2509 | AE3: =O3 -> 1676.6468 | AF3: =P3 -> 1844.3115
B4: 应收款项 | C4: ='PL-CF-BS'!I118 -> 9.669 | D4: ='PL-CF-BS'!J118 -> 15.244 | E4: ='PL-CF-BS'!K118 -> 16.0062 | F4: ='PL-CF-BS'!L118 -> 16.80651 | G4: ='PL-CF-BS'!M118 -> 17.646836 | H4: ='PL-CF-BS'!N118 -> 18.529177 | J4: 营业成本 | K4: ='PL-CF-BS'!I8 -> 703.016 | L4: ='PL-CF-BS'!J8 -> 783.583 | M4: ='PL-CF-BS'!K8 -> 877.27 | N4: ='PL-CF-BS'!L8 -> 987.85065 | O4: ='PL-CF-BS'!M8 -> 1082.5341 | P4: ='PL-CF-BS'!N8 -> 1185.3749 | R4: Accounts receivable | S4: =C4 -> 9.669 | T4: =D4 -> 15.244 | U4: =E4 -> 16.0062 | V4: =F4 -> 16.80651 | W4: =G4 -> 17.646836 | X4: =H4 -> 18.529177 | Z4: Cost of sales | AA4: =K4 -> 703.016 | AB4: =L4 -> 783.583 | AC4: =M4 -> 877.27 | AD4: =N4 -> 987.85065 | AE4: =O4 -> 1082.5341 | AF4: =P4 -> 1185.3749
B5: 存货净额 | C5: ='PL-CF-BS'!I119 -> 134.566 | D5: ='PL-CF-BS'!J119 -> 167.353 | E5: ='PL-CF-BS'!K119 -> 192.45595 | F5: ='PL-CF-BS'!L119 -> 221.32434 | G5: ='PL-CF-BS'!M119 -> 254.52299 | H5: ='PL-CF-BS'!N119 -> 292.70144 | J5: 毛利 | K5: ='PL-CF-BS'!I9 -> 364.692 | L5: ='PL-CF-BS'!J9 -> 413.55 | M5: ='PL-CF-BS'!K9 -> 477.1 | N5: ='PL-CF-BS'!L9 -> 534.40022 | O5: ='PL-CF-BS'!M9 -> 594.11273 | P5: ='PL-CF-BS'!N9 -> 658.93667 | R5: Inventories | S5: =C5 -> 134.566 | T5: =D5 -> 167.353 | U5: =E5 -> 192.45595 | V5: =F5 -> 221.32434 | W5: =G5 -> 254.52299 | X5: =H5 -> 292.70144 | Z5: Gross Profit | AA5: =K5 -> 364.692 | AB5: =L5 -> 413.55 | AC5: =M5 -> 477.1 | AD5: =N5 -> 534.40022 | AE5: =O5 -> 594.11273 | AF5: =P5 -> 658.93667
B6: 其他流动资产 | C6: ='PL-CF-BS'!I120 -> 0 | D6: ='PL-CF-BS'!J120 -> 103 | E6: ='PL-CF-BS'!K120 -> 34.333333 | F6: ='PL-CF-BS'!L120 -> 45.777778 | G6: ='PL-CF-BS'!M120 -> 61.037037 | H6: ='PL-CF-BS'!N120 -> 47.049383 | J6: 销售费用 | K6: ='PL-CF-BS'!I12 -> 106.766 | L6: ='PL-CF-BS'!J12 -> 123.53 | M6: ='PL-CF-BS'!K12 -> 144.1 | N6: ='PL-CF-BS'!L12 -> 160.59747 | O6: ='PL-CF-BS'!M12 -> 175.37726 | P6: ='PL-CF-BS'!N12 -> 194.39044 | R6: Other current assets | S6: =C6 -> 0 | T6: =D6 -> 103 | U6: =E6 -> 34.333333 | V6: =F6 -> 45.777778 | W6: =G6 -> 61.037037 | X6: =H6 -> 47.049383 | Z6: Sales expenses | AA6: =K6 -> 106.766 | AB6: =L6 -> 123.53 | AC6: =M6 -> 144.1 | AD6: =N6 -> 160.59747 | AE6: =O6 -> 175.37726 | AF6: =P6 -> 194.39044
B7: 流动资产合计 | C7: ='PL-CF-BS'!I122 -> 426.542 | D7: ='PL-CF-BS'!J122 -> 723.59 | E7: ='PL-CF-BS'!K122 -> 747.3 | F7: ='PL-CF-BS'!L122 -> 813.34074 | G7: ='PL-CF-BS'!M122 -> 896.94542 | H7: ='PL-CF-BS'!N122 -> 961.50934 | J7: 管理费用 | K7: ='PL-CF-BS'!I22 -> 135.184 | L7: ='PL-CF-BS'!J22 -> 141.279 | M7: ='PL-CF-BS'!K22 -> 163.1 | N7: ='PL-CF-BS'!L22 -> 181.14785 | O7: ='PL-CF-BS'!M22 -> 197.84433 | P7: ='PL-CF-BS'!N22 -> 217.62876 | R7: Total current assets | S7: =C7 -> 426.542 | T7: =D7 -> 723.59 | U7: =E7 -> 747.3 | V7: =F7 -> 813.34074 | W7: =G7 -> 896.94542 | X7: =H7 -> 961.50934 | Z7: SG&A expenses | AA7: =K7 -> 135.184 | AB7: =L7 -> 141.279 | AC7: =M7 -> 163.1 | AD7: =N7 -> 181.14785 | AE7: =O7 -> 197.84433 | AF7: =P7 -> 217.62876
B8: ='PL-CF-BS'!B125 -> LT Investments & Receivables | C8: ='PL-CF-BS'!I125 -> 383.46 | D8: ='PL-CF-BS'!J125 -> 406.582 | E8: ='PL-CF-BS'!K125 -> 613.261 | F8: ='PL-CF-BS'!L125 -> 631.65883 | G8: ='PL-CF-BS'!M125 -> 650.60859 | H8: ='PL-CF-BS'!N125 -> 670.12685 | J8: 财务费用 | K8: ='PL-CF-BS'!I48 -> 5.529 | L8: ='PL-CF-BS'!J48 -> 5.145 | M8: ='PL-CF-BS'!K48 -> 3.6 | N8: ='PL-CF-BS'!L48 -> 4.9959 | O8: ='PL-CF-BS'!M48 -> 4.809315 | P8: ='PL-CF-BS'!N48 -> 4.6918253 | R8: ='PL-CF-BS'!B125 -> LT Investments & Receivables | S8: =C8 -> 383.46 | T8: =D8 -> 406.582 | U8: =E8 -> 613.261 | V8: =F8 -> 631.65883 | W8: =G8 -> 650.60859 | X8: =H8 -> 670.12685 | Z8: Financial expenses | AA8: =K8 -> 5.529 | AB8: =L8 -> 5.145 | AC8: =M8 -> 3.6 | AD8: =N8 -> 4.9959 | AE8: =O8 -> 4.809315 | AF8: =P8 -> 4.6918253
B9: 长期股权投资 | C9: ='PL-CF-BS'!I124 -> 197.933 | D9: ='PL-CF-BS'!J124 -> 233.049 | E9: ='PL-CF-BS'!K124 -> 100 | F9: ='PL-CF-BS'!L124 -> 144.65 | G9: ='PL-CF-BS'!M124 -> 235.6925 | H9: ='PL-CF-BS'!N124 -> 358.84713 | J9: 其他费用/（-收入） | K9: ='PL-CF-BS'!I54 -> 0 | L9: ='PL-CF-BS'!J54 -> 0 | M9: ='PL-CF-BS'!K54 -> 0 | N9: ='PL-CF-BS'!L54 -> 0 | O9: ='PL-CF-BS'!M54 -> 0 | P9: ='PL-CF-BS'!N54 -> 0 | R9: ='PL-CF-BS'!B124 -> Property, Plant & Equip, Net | S9: =C9 -> 197.933 | T9: =D9 -> 233.049 | U9: =E9 -> 100 | V9: =F9 -> 144.65 | W9: =G9 -> 235.6925 | X9: =H9 -> 358.84713 | Z9: Other expenses/(-) revenue | AA9: =K9 -> 0 | AB9: =L9 -> 0 | AC9: =M9 -> 0 | AD9: =N9 -> 0 | AE9: =O9 -> 0 | AF9: =P9 -> 0
B10: 无形资产 | J10: 营业外净收支 | K10: ='PL-CF-BS'!I58 -> 0 | L10: ='PL-CF-BS'!J58 -> 0 | M10: ='PL-CF-BS'!K58 -> 0 | N10: ='PL-CF-BS'!L58 -> 0 | O10: ='PL-CF-BS'!M58 -> 0 | P10: ='PL-CF-BS'!N58 -> 0 | R10: Intangible assets | S10: =C10 -> 0 | T10: =D10 -> 0 | U10: =E10 -> 0 | V10: =F10 -> 0 | W10: =G10 -> 0 | X10: =H10 -> 0 | Z10: Net non-operating income | AA10: =K10 -> 0 | AB10: =L10 -> 0 | AC10: =M10 -> 0 | AD10: =N10 -> 0 | AE10: =O10 -> 0 | AF10: =P10 -> 0
B11: 其他非流动资产 | C11: ='PL-CF-BS'!I126 -> 0 | D11: ='PL-CF-BS'!J126 -> 0 | E11: ='PL-CF-BS'!K126 -> 0 | F11: ='PL-CF-BS'!L126 -> 0 | G11: ='PL-CF-BS'!M126 -> 0 | H11: ='PL-CF-BS'!N126 -> 0 | J11: 利润总额 | K11: ='PL-CF-BS'!I59 -> 118.585 | L11: ='PL-CF-BS'!J59 -> 147.624 | M11: ='PL-CF-BS'!K59 -> 169.693 | N11: ='PL-CF-BS'!L59 -> 190.59 | O11: ='PL-CF-BS'!M59 -> 219.53249 | P11: ='PL-CF-BS'!N59 -> 245.48388 | R11: other non-current assets | S11: =C11 -> 0 | T11: =D11 -> 0 | U11: =E11 -> 0 | V11: =F11 -> 0 | W11: =G11 -> 0 | X11: =H11 -> 0 | Z11: Pre-tax profit | AA11: =K11 -> 118.585 | AB11: =L11 -> 147.624 | AC11: =M11 -> 169.693 | AD11: =N11 -> 190.59 | AE11: =O11 -> 219.53249 | AF11: =P11 -> 245.48388
B12: 非流动资产合计 | C12: ='PL-CF-BS'!I130 -> 581.393 | D12: ='PL-CF-BS'!J130 -> 639.631 | E12: ='PL-CF-BS'!K130 -> 713.261 | F12: ='PL-CF-BS'!L130 -> 776.30883 | G12: ='PL-CF-BS'!M130 -> 886.30109 | H12: ='PL-CF-BS'!N130 -> 1028.974 | J12: 所得税费用 | K12: ='PL-CF-BS'!I60 -> 27.442 | L12: ='PL-CF-BS'!J60 -> 26.878 | M12: ='PL-CF-BS'!K60 -> 31.393205 | N12: ='PL-CF-BS'!L60 -> 34.3062 | O12: ='PL-CF-BS'!M60 -> 40.613511 | P12: ='PL-CF-BS'!N60 -> 46.641936 | R12: Total non-current assets | S12: =C12 -> 581.393 | T12: =D12 -> 639.631 | U12: =E12 -> 713.261 | V12: =F12 -> 776.30883 | W12: =G12 -> 886.30109 | X12: =H12 -> 1028.974 | Z12: Tax | AA12: =K12 -> 27.442 | AB12: =L12 -> 26.878 | AC12: =M12 -> 31.393205 | AD12: =N12 -> 34.3062 | AE12: =O12 -> 40.613511 | AF12: =P12 -> 46.641936
B13: 资产总计 | C13: ='PL-CF-BS'!I132 -> 1007.935 | D13: ='PL-CF-BS'!J132 -> 1363.221 | E13: ='PL-CF-BS'!K132 -> 1460.561 | F13: ='PL-CF-BS'!L132 -> 1589.6496 | G13: ='PL-CF-BS'!M132 -> 1783.2465 | H13: ='PL-CF-BS'!N132 -> 1990.4833 | J13: 净利润 | K13: ='PL-CF-BS'!I66 -> 91.144 | L13: ='PL-CF-BS'!J66 -> 120.742 | M13: ='PL-CF-BS'!K66 -> 138.90152 | N13: ='PL-CF-BS'!L66 -> 156.28551 | O13: ='PL-CF-BS'!M66 -> 178.92095 | P13: ='PL-CF-BS'!N66 -> 198.84412 | R13: Total assets | S13: =C13 -> 1007.935 | T13: =D13 -> 1363.221 | U13: =E13 -> 1460.561 | V13: =F13 -> 1589.6496 | W13: =G13 -> 1783.2465 | X13: =H13 -> 1990.4833 | Z13: Net profit | AA13: =K13 -> 91.144 | AB13: =L13 -> 120.742 | AC13: =M13 -> 138.90152 | AD13: =N13 -> 156.28551 | AE13: =O13 -> 178.92095 | AF13: =P13 -> 198.84412
J14: 少数股东损益 | K14: ='PL-CF-BS'!I64 -> -0.001 | L14: ='PL-CF-BS'!J64 -> 0.004 | M14: ='PL-CF-BS'!K64 -> -0.0015239788 | N14: ='PL-CF-BS'!L64 -> -0.0017147098 | O14: ='PL-CF-BS'!M64 -> -0.0019630579 | P14: ='PL-CF-BS'!N64 -> -0.002181648 | R14: Short-term borrowing | S14: =C15 -> 11.801 | T14: =D15 -> 15.532 | U14: =E15 -> 41.1 | V14: =F15 -> 45.21 | W14: =G15 -> 49.731 | X14: =H15 -> 54.7041 | Z14: Minority interests | AA14: =K14 -> -0.001 | AB14: =L14 -> 0.004 | AC14: =M14 -> -0.0015239788 | AD14: =N14 -> -0.0017147098 | AE14: =O14 -> -0.0019630579 | AF14: =P14 -> -0.002181648
B15: 短期借款 | C15: ='PL-CF-BS'!I138 -> 11.801 | D15: ='PL-CF-BS'!J138 -> 15.532 | E15: ='PL-CF-BS'!K138 -> 41.1 | F15: ='PL-CF-BS'!L138 -> 45.21 | G15: ='PL-CF-BS'!M138 -> 49.731 | H15: ='PL-CF-BS'!N138 -> 54.7041 | J15: 归母净利润 | K15: ='PL-CF-BS'!I66 -> 91.144 | L15: ='PL-CF-BS'!J66 -> 120.742 | M15: ='PL-CF-BS'!K66 -> 138.90152 | N15: ='PL-CF-BS'!L66 -> 156.28551 | O15: ='PL-CF-BS'!M66 -> 178.92095 | P15: ='PL-CF-BS'!N66 -> 198.84412 | R15: Account payable | S15: =C16 -> 42.428 | T15: =D16 -> 50.739 | U15: =E16 -> 40 | V15: =F16 -> 44 | W15: =G16 -> 48.4 | X15: =H16 -> 53.24 | Z15: Net profit attribute to shareholders | AA15: =K15 -> 91.144 | AB15: =L15 -> 120.742 | AC15: =M15 -> 138.90152 | AD15: =N15 -> 156.28551 | AE15: =O15 -> 178.92095 | AF15: =P15 -> 198.84412
B16: 应付款项 | C16: ='PL-CF-BS'!I135 -> 42.428 | D16: ='PL-CF-BS'!J135 -> 50.739 | E16: ='PL-CF-BS'!K135 -> 40 | F16: ='PL-CF-BS'!L135 -> 44 | G16: ='PL-CF-BS'!M135 -> 48.4 | H16: ='PL-CF-BS'!N135 -> 53.24 | R16: Other current liabilities | S16: =C17 -> 0 | T16: =D17 -> 0 | U16: =E17 -> 0 | V16: =F17 -> 0 | W16: =G17 -> 0 | X16: =H17 -> 0
B17: 其他流动负债 | C17: ='PL-CF-BS'!I139 -> 0 | D17: ='PL-CF-BS'!J139 -> 0 | E17: ='PL-CF-BS'!K139 -> 0 | F17: ='PL-CF-BS'!L139 -> 0 | G17: ='PL-CF-BS'!M139 -> 0 | H17: ='PL-CF-BS'!N139 -> 0 | J17: 财务指标 | K17: 2023 | L17: 2024 | M17: 2025E | N17: 2026E | O17: 2027E | P17: 2028E | R17: Total current liabilities | S17: =C18 -> 386.97 | T17: =D18 -> 448.034 | U17: =E18 -> 457.1 | V17: =F18 -> 502.81 | W17: =G18 -> 553.091 | X17: =H18 -> 608.4001 | Z17: Financial Ratios | AA17: =K17 -> 2023 | AB17: =L17 -> 2024 | AC17: =M17 -> 2025E | AD17: =N17 -> 2026E | AE17: =O17 -> 2027E | AF17: 2028E
B18: 流动负债合计 | C18: ='PL-CF-BS'!I141 -> 386.97 | D18: ='PL-CF-BS'!J141 -> 448.034 | E18: ='PL-CF-BS'!K141 -> 457.1 | F18: ='PL-CF-BS'!L141 -> 502.81 | G18: ='PL-CF-BS'!M141 -> 553.091 | H18: ='PL-CF-BS'!N141 -> 608.4001 | J18: 盈利能力 | R18: Long-term debt | S18: =C19 -> 55.949 | T18: =D19 -> 40.416 | U18: =E19 -> 32.416 | V18: =F19 -> 23.656 | W18: =G19 -> 13.144 | X18: =H19 -> 2.02 | Z18: Profitability ratios
B19: 长期借款及应付债券 | C19: ='PL-CF-BS'!I143 -> 55.949 | D19: ='PL-CF-BS'!J143 -> 40.416 | E19: ='PL-CF-BS'!K143 -> 32.416 | F19: ='PL-CF-BS'!L143 -> 23.656 | G19: ='PL-CF-BS'!M143 -> 13.144 | H19: ='PL-CF-BS'!N143 -> 2.02 | J19: ROE | K19: ='PL-CF-BS'!I171 -> 0.21144451 | L19: ='PL-CF-BS'!J171 -> 0.19236741 | M19: ='PL-CF-BS'!K171 -> 0.16673001 | N19: ='PL-CF-BS'!L171 -> 0.16908445 | O19: ='PL-CF-BS'!M171 -> 0.17271499 | P19: ='PL-CF-BS'!N171 -> 0.16786159 | R19: Other non-current liabilities | S19: =C20 -> 91.64 | T19: =D20 -> 92.82 | U19: =E20 -> 86.786 | V19: =F20 -> 95.4646 | W19: =G20 -> 105.01106 | X19: =H20 -> 115.51217 | Z19: ROE | AA19: =K19 -> 0.21144451 | AB19: =L19 -> 0.19236741 | AC19: =M19 -> 0.16673001 | AD19: =N19 -> 0.16908445 | AE19: =O19 -> 0.17271499 | AF19: =P19 -> 0.16786159
B20: 其他长期负债 | C20: ='PL-CF-BS'!I144+'PL-CF-BS'!I145 -> 91.64 | D20: ='PL-CF-BS'!J144+'PL-CF-BS'!J145 -> 92.82 | E20: ='PL-CF-BS'!K144+'PL-CF-BS'!K145 -> 86.786 | F20: ='PL-CF-BS'!L144+'PL-CF-BS'!L145 -> 95.4646 | G20: ='PL-CF-BS'!M144+'PL-CF-BS'!M145 -> 105.01106 | H20: ='PL-CF-BS'!N144+'PL-CF-BS'!N145 -> 115.51217 | J20: 毛利率 | K20: ='PL-CF-BS'!I166 -> 0.3415653 | L20: ='PL-CF-BS'!J166 -> 0.34545034 | M20: ='PL-CF-BS'!K166 -> 0.35226711 | N20: ='PL-CF-BS'!L166 -> 0.35105923 | O20: ='PL-CF-BS'!M166 -> 0.35434578 | P20: ='PL-CF-BS'!N166 -> 0.35728057 | R20: Total non-current liabilities | S20: =C21 -> 147.589 | T20: =D21 -> 133.236 | U20: =E21 -> 119.202 | V20: =F21 -> 119.1206 | W20: =G21 -> 118.15506 | X20: =H21 -> 117.53217 | Z20: Gross profit margin | AA20: =K20 -> 0.3415653 | AB20: =L20 -> 0.34545034 | AC20: =M20 -> 0.35226711 | AD20: =N20 -> 0.35105923 | AE20: =O20 -> 0.35434578 | AF20: =P20 -> 0.35728057
B21: 长期负债合计 | C21: ='PL-CF-BS'!I146 -> 147.589 | D21: ='PL-CF-BS'!J146 -> 133.236 | E21: ='PL-CF-BS'!K146 -> 119.202 | F21: ='PL-CF-BS'!L146 -> 119.1206 | G21: ='PL-CF-BS'!M146 -> 118.15506 | H21: ='PL-CF-BS'!N146 -> 117.53217 | J21: 营业利润率 | K21: ='PL-CF-BS'!I168 -> 0.2253219 | L21: ='PL-CF-BS'!J168 -> 0.21783795 | M21: ='PL-CF-BS'!K168 -> 0.2243161 | N21: ='PL-CF-BS'!L168 -> 0.22257456 | O21: ='PL-CF-BS'!M168 -> 0.22054192 | P21: ='PL-CF-BS'!N168 -> 0.22163337 | R21: Total liabilities | S21: =C22 -> 534.559 | T21: =D22 -> 581.27 | U21: =E22 -> 576.302 | V21: =F22 -> 621.9306 | W21: =G22 -> 671.24606 | X21: =H22 -> 725.93227 | Z21: Operating profit margin | AA21: =K21 -> 0.2253219 | AB21: =L21 -> 0.21783795 | AC21: =M21 -> 0.2243161 | AD21: =N21 -> 0.22257456 | AE21: =O21 -> 0.22054192 | AF21: =P21 -> 0.22163337
B22: 负债合计 | C22: ='PL-CF-BS'!I148 -> 534.559 | D22: ='PL-CF-BS'!J148 -> 581.27 | E22: ='PL-CF-BS'!K148 -> 576.302 | F22: ='PL-CF-BS'!L148 -> 621.9306 | G22: ='PL-CF-BS'!M148 -> 671.24606 | H22: ='PL-CF-BS'!N148 -> 725.93227 | J22: 归母净利率 | K22: ='PL-CF-BS'!I170 -> 0.085364163 | L22: ='PL-CF-BS'!J170 -> 0.1008593 | M22: ='PL-CF-BS'!K170 -> 0.10255803 | N22: ='PL-CF-BS'!L170 -> 0.10266738 | O22: ='PL-CF-BS'!M170 -> 0.10671356 | P22: ='PL-CF-BS'!N170 -> 0.10781482 | R22: Capital | S22: =C23 -> 155.482 | T22: =D23 -> 343.315 | U22: =E23 -> 350.1813 | V22: =F23 -> 357.18493 | W22: =G23 -> 364.32862 | X22: =H23 -> 371.6152 | Z22: Net profit margin | AA22: =K22 -> 0.085364163 | AB22: =L22 -> 0.1008593 | AC22: =M22 -> 0.10255803 | AD22: =N22 -> 0.10266738 | AE22: =O22 -> 0.10671356 | AF22: =P22 -> 0.10781482
B23: 股本 | C23: ='PL-CF-BS'!I152 -> 155.482 | D23: ='PL-CF-BS'!J152 -> 343.315 | E23: ='PL-CF-BS'!K152 -> 350.1813 | F23: ='PL-CF-BS'!L152 -> 357.18493 | G23: ='PL-CF-BS'!M152 -> 364.32862 | H23: ='PL-CF-BS'!N152 -> 371.6152 | J23: 成长能力 | R23: Total shareholders' equity | S23: =C24 -> 473.376 | T23: =D24 -> 781.951 | U23: =E24 -> 884.234 | V23: =F24 -> 964.37493 | W23: =G24 -> 1107.4886 | X23: =H24 -> 1261.6552 | Z23: Growth rates
B24: 股东权益 | C24: ='PL-CF-BS'!I160 -> 473.376 | D24: ='PL-CF-BS'!J160 -> 781.951 | E24: ='PL-CF-BS'!K160 -> 884.234 | F24: ='PL-CF-BS'!L160 -> 964.37493 | G24: ='PL-CF-BS'!M160 -> 1107.4886 | H24: ='PL-CF-BS'!N160 -> 1261.6552 | I24: ='PL-CF-BS'!M156 -> 1107.4886 | J24: 营业收入增长率 | K24: ='PL-CF-BS'!I7 -> 0.19419472 | L24: ='PL-CF-BS'!J7 -> 0.1212176 | M24: ='PL-CF-BS'!K7 -> 0.13134464 | N24: ='PL-CF-BS'!L7 -> 0.12395496 | O24: ='PL-CF-BS'!M7 -> 0.1014261 | P24: ='PL-CF-BS'!N7 -> 0.1 | R24: Total liabilities & shareholders' equity | S24: =C25 -> 1007.935 | T24: =D25 -> 1363.221 | U24: =E25 -> 1460.536 | V24: =F25 -> 1586.3055 | W24: =G25 -> 1778.7347 | X24: =H25 -> 1987.5875 | Z24: Revenue growth rate | AA24: =K24 -> 0.19419472 | AB24: =L24 -> 0.1212176 | AC24: =M24 -> 0.13134464 | AD24: =N24 -> 0.12395496 | AE24: =O24 -> 0.1014261 | AF24: =P24 -> 0.1
B25: 负债和股东权益总计 | C25: ='PL-CF-BS'!I160+'PL-CF-BS'!I148 -> 1007.935 | D25: ='PL-CF-BS'!J160+'PL-CF-BS'!J148 -> 1363.221 | E25: ='PL-CF-BS'!K160+'PL-CF-BS'!K148 -> 1460.536 | F25: ='PL-CF-BS'!L160+'PL-CF-BS'!L148 -> 1586.3055 | G25: ='PL-CF-BS'!M160+'PL-CF-BS'!M148 -> 1778.7347 | H25: ='PL-CF-BS'!N160+'PL-CF-BS'!N148 -> 1987.5875 | J25: 营业利润增长率 | K25: ='PL-CF-BS'!I10 -> 0.22326502 | L25: ='PL-CF-BS'!J10 -> 0.13397058 | M25: ='PL-CF-BS'!K10 -> 0.15366945 | N25: ='PL-CF-BS'!L10 -> 0.12010107 | O25: ='PL-CF-BS'!M10 -> 0.11173743 | P25: ='PL-CF-BS'!N10 -> 0.10911051 | Z25: Operating profit growth rate | AA25: =K25 -> 0.22326502 | AB25: =L25 -> 0.13397058 | AC25: =M25 -> 0.15366945 | AD25: =N25 -> 0.12010107 | AE25: =O25 -> 0.11173743 | AF25: =P25 -> 0.10911051
J26: 净利润增长率 | K26: ='PL-CF-BS'!I67 -> 0.034857052 | L26: ='PL-CF-BS'!J67 -> 0.32473887 | M26: ='PL-CF-BS'!K67 -> 0.1503994 | N26: ='PL-CF-BS'!L67 -> 0.12515335 | O26: ='PL-CF-BS'!M67 -> 0.14483384 | P26: ='PL-CF-BS'!N67 -> 0.11135183 | R26: CF/S (USD mn) | S26: =C27 -> 2023 | T26: =D27 -> 2024 | U26: =E27 -> 2025E | V26: =F27 -> 2026E | W26: =G27 -> 2027E | X26: 2028E | Z26: Net profit growth rate | AA26: =K26 -> 0.034857052 | AB26: =L26 -> 0.32473887 | AC26: =M26 -> 0.1503994 | AD26: =N26 -> 0.12515335 | AE26: =O26 -> 0.14483384 | AF26: =P26 -> 0.11135183
B27: 现金流量表（百万美元） | C27: =K17 -> 2023 | D27: =L17 -> 2024 | E27: =M17 -> 2025E | F27: =N17 -> 2026E | G27: =O17 -> 2027E | H27: 2028E | J27: 偿债能力 | R27: Net profit | S27: =C28 -> 91.144 | T27: =D28 -> 120.742 | U27: =E28 -> 138.90152 | V27: =F28 -> 156.28551 | W27: =G28 -> 178.92095 | X27: =H28 -> 198.84412 | Z27: Liquidity & Solvency ratio
B28: 净利润 | C28: ='PL-CF-BS'!I66 -> 91.144 | D28: ='PL-CF-BS'!J66 -> 120.742 | E28: ='PL-CF-BS'!K66 -> 138.90152 | F28: ='PL-CF-BS'!L66 -> 156.28551 | G28: ='PL-CF-BS'!M66 -> 178.92095 | H28: ='PL-CF-BS'!N66 -> 198.84412 | J28: 流动比 | K28: ='PL-CF-BS'!I122/'PL-CF-BS'!I141 -> 1.1022612 | L28: ='PL-CF-BS'!J122/'PL-CF-BS'!J141 -> 1.6150337 | M28: ='PL-CF-BS'!K122/'PL-CF-BS'!K141 -> 1.634872 | N28: ='PL-CF-BS'!L122/'PL-CF-BS'!L141 -> 1.6175906 | O28: ='PL-CF-BS'!M122/'PL-CF-BS'!M141 -> 1.6216959 | P28: ='PL-CF-BS'!N122/'PL-CF-BS'!N141 -> 1.5803898 | R28: Depreciation & amortization | S28: =C29 -> 36.575 | T28: =D29 -> 44.976 | U28: =E29 -> 40.2528 | V28: =F29 -> 42.63133 | W28: =G29 -> 44.751046 | X28: =H29 -> 46.799564 | Z28: Current ratio | AA28: =K28 -> 1.1022612 | AB28: =L28 -> 1.6150337 | AC28: =M28 -> 1.634872 | AD28: =N28 -> 1.6175906 | AE28: =O28 -> 1.6216959 | AF28: =P28 -> 1.5803898
B29: 折旧摊销 | C29: ='PL-CF-BS'!I90 -> 36.575 | D29: ='PL-CF-BS'!J90 -> 44.976 | E29: ='PL-CF-BS'!K90 -> 40.2528 | F29: ='PL-CF-BS'!L90 -> 42.63133 | G29: ='PL-CF-BS'!M90 -> 44.751046 | H29: ='PL-CF-BS'!N90 -> 46.799564 | J29: 速动比 | K29: =('PL-CF-BS'!I122-'PL-CF-BS'!I119)/'PL-CF-BS'!I141 -> 0.75451844 | L29: =('PL-CF-BS'!J122-'PL-CF-BS'!J119)/'PL-CF-BS'!J141 -> 1.2415062 | M29: =('PL-CF-BS'!K122-'PL-CF-BS'!K119)/'PL-CF-BS'!K141 -> 1.2138352 | N29: =('PL-CF-BS'!L122-'PL-CF-BS'!L119)/'PL-CF-BS'!L141 -> 1.1774157 | O29: =('PL-CF-BS'!M122-'PL-CF-BS'!M119)/'PL-CF-BS'!M141 -> 1.1615131 | P29: =('PL-CF-BS'!N122-'PL-CF-BS'!N119)/'PL-CF-BS'!N141 -> 1.0992896 | R29: Net working capital | S29: =C30 -> 32.421 | T29: =D30 -> 27.975 | U29: =E30 -> -141.7168 | V29: =F30 -> -22.013289 | W29: =G30 -> -28.328407 | X29: =H30 -> -2.0483413 | Z29: Quick ratio | AA29: =K29 -> 0.75451844 | AB29: =L29 -> 1.2415062 | AC29: =M29 -> 1.2138352 | AD29: =N29 -> 1.1774157 | AE29: =O29 -> 1.1615131 | AF29: =P29 -> 1.0992896
B30: 营运资金变动 | C30: ='PL-CF-BS'!I91 -> 32.421 | D30: ='PL-CF-BS'!J91 -> 27.975 | E30: ='PL-CF-BS'!K91 -> -141.7168 | F30: ='PL-CF-BS'!L91 -> -22.013289 | G30: ='PL-CF-BS'!M91 -> -28.328407 | H30: ='PL-CF-BS'!N91 -> -2.0483413 | R30: Others | S30: =C31 -> -46.848 | T30: =D31 -> -29.162 | U30: =E31 -> 5.7472 | V30: =F31 -> -24.59198 | W30: =G31 -> -16.802373 | X30: =H31 -> -12.476504
B31: 其他 | C31: ='PL-CF-BS'!I92 -> -46.848 | D31: ='PL-CF-BS'!J92 -> -29.162 | E31: ='PL-CF-BS'!K92 -> 5.7472 | F31: ='PL-CF-BS'!L92 -> -24.59198 | G31: ='PL-CF-BS'!M92 -> -16.802373 | H31: ='PL-CF-BS'!N92 -> -12.476504 | J31: 每股指标与估值 | K31: =K17 -> 2023 | L31: =L17 -> 2024 | M31: =M17 -> 2025E | N31: =N17 -> 2026E | O31: =O17 -> 2027E | P31: =P17 -> 2028E | R31: Cash flow from operations | S31: =C32 -> 113.292 | T31: =D32 -> 164.531 | U31: =E32 -> 146 | V31: =F32 -> 152.31158 | W31: =G32 -> 178.54121 | X31: =H32 -> 231.11884 | Z31: Valuation | AA31: =K31 -> 2023 | AB31: =L31 -> 2024 | AC31: =M31 -> 2025E | AD31: =N31 -> 2026E | AE31: =O31 -> 2027E | AF31: 2028E
B32: 经营活动现金流 | C32: ='PL-CF-BS'!I93 -> 113.292 | D32: ='PL-CF-BS'!J93 -> 164.531 | E32: ='PL-CF-BS'!K93 -> 146 | F32: ='PL-CF-BS'!L93 -> 152.31158 | G32: ='PL-CF-BS'!M93 -> 178.54121 | H32: ='PL-CF-BS'!N93 -> 231.11884 | J32: 每股指标 | R32: CAPEX | S32: =C33 -> -90.331 | T32: =D33 -> -92.705 | U32: =E33 -> -93 | V32: =F33 -> -100.44 | W32: =G33 -> -108.4752 | X32: =H33 -> -117.15322 | Z32: Per share
B33: 资本支出 | C33: ='PL-CF-BS'!I96 -> -90.331 | D33: ='PL-CF-BS'!J96 -> -92.705 | E33: ='PL-CF-BS'!K96 -> -93 | F33: ='PL-CF-BS'!L96 -> -100.44 | G33: ='PL-CF-BS'!M96 -> -108.4752 | H33: ='PL-CF-BS'!N96 -> -117.15322 | J33: EPS | K33: ='PL-CF-BS'!I75 -> 0.58620419 | L33: ='PL-CF-BS'!J75 -> 0.32990625 | M33: ='PL-CF-BS'!K75 -> 0.37952396 | N33: ='PL-CF-BS'!L75 -> 0.4270096 | O33: ='PL-CF-BS'!M75 -> 0.48885504 | P33: ='PL-CF-BS'!N75 -> 0.54328995 | R33: Others | S33: =C34 -> 0 | T33: =D34 -> -103 | U33: =E34 -> -78.8188 | V33: =F34 -> -63.63658 | W33: =G34 -> -85.909383 | X33: =H34 -> -79.927667 | Z33: EPS | AA33: =K33 -> 0.58620419 | AB33: =L33 -> 0.32990625 | AC33: =M33 -> 0.37952396 | AD33: =N33 -> 0.4270096 | AE33: =O33 -> 0.48885504 | AF33: =P33 -> 0.54328995
B34: 其他 | C34: ='PL-CF-BS'!I98 -> 0 | D34: ='PL-CF-BS'!J98 -> -103 | E34: ='PL-CF-BS'!K98 -> -78.8188 | F34: ='PL-CF-BS'!L98 -> -63.63658 | G34: ='PL-CF-BS'!M98 -> -85.909383 | H34: ='PL-CF-BS'!N98 -> -79.927667 | J34: BVPS | K34: ='PL-CF-BS'!I156/'PL-CF-BS'!I72 -> 3.0445778 | L34: ='PL-CF-BS'!J156/'PL-CF-BS'!J72 -> 2.1365434 | M34: ='PL-CF-BS'!K156/'PL-CF-BS'!K72 -> 2.4160137 | N34: ='PL-CF-BS'!L156/'PL-CF-BS'!L72 -> 2.6349042 | O34: ='PL-CF-BS'!M156/'PL-CF-BS'!M72 -> 3.0259252 | P34: ='PL-CF-BS'!N156/'PL-CF-BS'!N72 -> 3.4471453 | R34: Cash flow from investing activities | S34: =C35 -> -90.637 | T34: =D35 -> -193.385 | U34: =E35 -> -171.2 | V34: =F35 -> -163.1551 | W34: =G35 -> -193.03349 | X34: =H35 -> -196.0689 | Z34: BVPS | AA34: =K34 -> 3.0445778 | AB34: =L34 -> 2.1365434 | AC34: =M34 -> 2.4160137 | AD34: =N34 -> 2.6349042 | AE34: =O34 -> 3.0259252 | AF34: =P34 -> 3.4471453
B35: 投资活动现金流 | C35: ='PL-CF-BS'!I99 -> -90.637 | D35: ='PL-CF-BS'!J99 -> -193.385 | E35: ='PL-CF-BS'!K99 -> -171.2 | F35: ='PL-CF-BS'!L99 -> -163.1551 | G35: ='PL-CF-BS'!M99 -> -193.03349 | H35: ='PL-CF-BS'!N99 -> -196.0689 | J35: 估值 | R35: Debt financing | S35: =C36 -> -3.629 | T35: =D36 -> -3.927 | U35: =E36 -> -6 | V35: =F36 -> -6.36 | W35: =G36 -> -7.632 | X35: =H36 -> -8.0136 | Z35: Valuation ratios
B36: 债务融资 | C36: ='PL-CF-BS'!I106 -> -3.629 | D36: ='PL-CF-BS'!J106 -> -3.927 | E36: ='PL-CF-BS'!K106 -> -6 | F36: ='PL-CF-BS'!L106 -> -6.36 | G36: ='PL-CF-BS'!M106 -> -7.632 | H36: ='PL-CF-BS'!N106 -> -8.0136 | J36: P/E | K36: =K40/K33 -> 8.9690799 | L36: =L40/L33 -> 15.943923 | M36: =M40/M33 -> 13.859468 | N36: =N40/N33 -> 12.318224 | O36: =O40/O33 -> 10.759836 | P36: =P40/P33 -> 9.6817547 | R36: Others | S36: ='PL-CF-BS'!I104+'PL-CF-BS'!I107+'PL-CF-BS'!I108 -> -15.41 | T36: ='PL-CF-BS'!J104+'PL-CF-BS'!J107+'PL-CF-BS'!J108 -> 177.745 | U36: ='PL-CF-BS'!K104+'PL-CF-BS'!K107+'PL-CF-BS'!K108 -> -79.1 | V36: ='PL-CF-BS'!L104+'PL-CF-BS'!L107+'PL-CF-BS'!L108 -> 21.993667 | W36: ='PL-CF-BS'!M104+'PL-CF-BS'!M107+'PL-CF-BS'!M108 -> 34.560222 | X36: ='PL-CF-BS'!N104+'PL-CF-BS'!N107+'PL-CF-BS'!N108 -> -11.660704 | Z36: P/E | AA36: =K36 -> 8.9690799 | AB36: =L36 -> 15.943923 | AC36: =M36 -> 13.859468 | AD36: =N36 -> 12.318224 | AE36: =O36 -> 10.759836 | AF36: =P36 -> 9.6817547
B37: 筹资活动现金流 | C37: ='PL-CF-BS'!I109 -> -19.039 | D37: ='PL-CF-BS'!J109 -> 173.818 | E37: ='PL-CF-BS'!K109 -> -87.1 | F37: ='PL-CF-BS'!L109 -> 13.233667 | G37: ='PL-CF-BS'!M109 -> 24.048222 | H37: ='PL-CF-BS'!N109 -> -22.784704 | J37: P/B | K37: =K40/K34 -> 1.7269101 | L37: =L40/L34 -> 2.4619205 | M37: =M40/M34 -> 2.17714 | N37: =N40/N34 -> 1.9962775 | O37: =O40/O34 -> 1.7383113 | P37: =P40/P34 -> 1.5259003 | R37: Cash flow from financing activities | S37: =C37 -> -19.039 | T37: =D37 -> 173.818 | U37: =E37 -> -87.1 | V37: =F37 -> 13.233667 | W37: =G37 -> 24.048222 | X37: =H37 -> -22.784704 | Z37: P/B | AA37: =K37 -> 1.7269101 | AB37: =L37 -> 2.4619205 | AC37: =M37 -> 2.17714 | AD37: =N37 -> 1.9962775 | AE37: =O37 -> 1.7383113 | AF37: =P37 -> 1.5259003
B38: 现金净增加额 | C38: =C32+C35+C37 -> 3.616 | D38: =D32+D35+D37 -> 144.964 | E38: =E32+E35+E37 -> -112.3 | F38: =F32+F35+F37 -> 2.3901425 | G38: =G32+G35+G37 -> 9.5559484 | H38: =H32+H35+H37 -> 12.265236 | J38: P/S | K38: =K40*'PL-CF-BS'!I72/'PL-CF-BS'!I6 -> 0.765638 | L38: =L40*'PL-CF-BS'!J72/'PL-CF-BS'!J6 -> 1.608093 | M38: =M40*'PL-CF-BS'!K72/'PL-CF-BS'!K6 -> 1.4213998 | N38: =N40*'PL-CF-BS'!L72/'PL-CF-BS'!L6 -> 1.2646798 | O38: =O40*'PL-CF-BS'!M72/'PL-CF-BS'!M6 -> 1.1482203 | P38: =P40*'PL-CF-BS'!N72/'PL-CF-BS'!N6 -> 1.0438367 | R38: Total cash generated | S38: =C38 -> 3.616 | T38: =D38 -> 144.964 | U38: =E38 -> -112.3 | V38: =F38 -> 2.3901425 | W38: =G38 -> 9.5559484 | X38: =H38 -> 12.265236 | Z38: P/S | AA38: =K38 -> 0.765638 | AB38: =L38 -> 1.608093 | AC38: =M38 -> 1.4213998 | AD38: =N38 -> 1.2646798 | AE38: =O38 -> 1.1482203 | AF38: =P38 -> 1.0438367
K40: =K41/K42 -> 5.2577122 | L40: 5.26 | M40: 5.26 | N40: 5.26 | O40: 5.26 | P40: 5.26
K41: 41.16
K42: 7.8285

Sheet PL-CF-BS
B2: Financial Statements | F2: =F132-F148-F160 -> -0.041 | G2: =G132-G148-G160 -> -0.062 | H2: =H132-H148-H160 -> -0.021 | I2: =I132-I148-I160 -> 0 | J2: =J132-J148-J160 -> 0 | K2: =K132-K148-K160 -> 0.025 | L2: =L132-L148-L160 -> 3.3440452 | M2: =M132-M148-M160 -> 4.5118329 | ... R2: =R132-R148-R160 -> -150.93278
B3: ( in USD mn)
F4: 2020 | G4: 2021 | H4: 2022 | I4: 2023 | J4: 2024 | K4: 2025E | L4: 2026E | M4: 2027E | N4: 2028E | O4: 2029E | P4: 2030E | Q4: 2031E | R4: 2032E
B5: Income Statement
B6: Revenue | F6: =PL!B4 -> 586.463 | G6: =PL!C4 -> 738.13 | H6: =PL!D4 -> 894.082 | I6: =PL!E4 -> 1067.708 | J6: =PL!F4 -> 1197.133 | K6: 1354.37 | L6: =forecast!H23 -> 1522.2509 | M6: =forecast!I23 -> 1676.6468 | N6: =M6*(1+N7) -> 1844.3115 | O6: =N6*(1+O7) -> 2010.2996 | P6: =O6*(1+P7) -> 2171.1235 | Q6: =P6*(1+Q7) -> 2344.8134 | R6: =Q6*(1+R7) -> 2532.3985
B7: yoy | G7: =G6/F6-1 -> 0.25861308 | H7: =H6/G6-1 -> 0.21127986 | I7: =I6/H6-1 -> 0.19419472 | J7: =J6/I6-1 -> 0.1212176 | K7: =K6/J6-1 -> 0.13134464 | L7: =L6/K6-1 -> 0.12395496 | M7: =M6/L6-1 -> 0.1014261 | N7: 0.1 | O7: 0.09 | P7: 0.08 | Q7: 0.08 | R7: 0.08
B8: Cost of goods sold and service | F8: =-PL!B5 -> 401.131 | G8: =-PL!C5 -> 495.855 | H8: =-PL!D5 -> 595.952 | I8: =-PL!E5 -> 703.016 | J8: =-PL!F5 -> 783.583 | K8: =K6-K9 -> 877.27 | L8: =forecast!H25 -> 987.85065 | M8: =forecast!I25 -> 1082.5341 | N8: =M8*1.095 -> 1185.3749 | O8: =N8*1.075 -> 1274.278 | P8: =O8*1.075 -> 1369.8488 | Q8: =P8*1.065 -> 1458.889 | R8: =Q8*1.065 -> 1553.7168
B9: Gross profit | F9: =F6-F8 -> 185.332 | G9: =G6-G8 -> 242.275 | H9: =H6-H8 -> 298.13 | I9: =I6-I8 -> 364.692 | J9: =J6-J8 -> 413.55 | K9: 477.1 | L9: =L6-L8 -> 534.40022 | M9: =M6-M8 -> 594.11273 | N9: =N6-N8 -> 658.93667 | O9: =O6-O8 -> 736.0216 | P9: =P6-P8 -> 801.27471 | Q9: =Q6-Q8 -> 885.92442 | R9: =R6-R8 -> 978.68171
C10: YoY | G10: =G9/F9-1 -> 0.30724861 | H10: =H9/G9-1 -> 0.2305438 | I10: =I9/H9-1 -> 0.22326502 | J10: =J9/I9-1 -> 0.13397058 | K10: =K9/J9-1 -> 0.15366945 | L10: =L9/K9-1 -> 0.12010107 | M10: =M9/L9-1 -> 0.11173743 | N10: =N9/M9-1 -> 0.10911051 | ... R10: =R9/Q9-1 -> 0.10470113
C11: Gross margin | F11: =F9/F6 -> 0.31601653 | G11: =G9/G6 -> 0.32822809 | H11: =H9/H6 -> 0.33344816 | I11: =I9/I6 -> 0.3415653 | J11: =J9/J6 -> 0.34545034 | K11: =K9/K6 -> 0.35226711 | L11: =L9/L6 -> 0.35105923 | M11: =M9/M6 -> 0.35434578 | ... R11: =R9/R6 -> 0.38646434
B12: Selling | F12: =-(PL!B7+PL!B8) -> 133.703 | G12: =-PL!C7 -> 66.391 | H12: =-PL!D7 -> 88.29 | I12: =-PL!E7 -> 106.766 | J12: =-PL!F7 -> 123.53 | K12: 144.1 | L12: =L14+L16+L18+L20 -> 160.59747 | M12: =M14+M16+M18+M20 -> 175.37726 | N12: =N14+N16+N18+N20 -> 194.39044 | O12: =O14+O16+O18+O20 -> 211.88557 | P12: =P14+P16+P18+P20 -> 228.83642 | Q12: =Q14+Q16+Q18+Q20 -> 247.14333 | R12: =R14+R16+R18+R20 -> 266.9148
B13: Selling rate | F13: =F12/F6 -> 0.22798199 | G13: =G12/G6 -> 0.089944861 | H13: =H12/H6 -> 0.098749332 | I13: =I12/I6 -> 0.099995504 | J13: =J12/J6 -> 0.1031882 | K13: =K12/K6 -> 0.10639633 | L13: =L12/L6 -> 0.1055 | M13: =M12/M6 -> 0.1046 | ... R13: =R12/R6 -> 0.1054
C14: ——Staff Costs | G14: 35.71 | H14: 48.07 | I14: 65.79 | J14: =J15*J$6 -> 79.010778 | K14: =K15*K$6 -> 94.8059 | L14: =L15*L$6 -> 109.60206 | M14: =M15*M$6 -> 121.0539 | N14: =N15*N$6 -> 134.63474 | O14: =O15*O$6 -> 146.75187 | P14: =P15*P$6 -> 158.49202 | Q14: =Q15*Q$6 -> 171.17138 | R14: =R15*R$6 -> 184.86509
D15: rate | G15: =G14/G$6 -> 0.048379012 | H15: =H14/H$6 -> 0.053764644 | I15: =I14/I$6 -> 0.06161797 | J15: 0.066 | K15: 0.07 | L15: 0.072 | M15: 0.0722 | N15: 0.073 | O15: 0.073 | P15: 0.073 | Q15: 0.073 | R15: 0.073
C16: ——Facilities and Equipment | G16: 8.71 | H16: 13.02 | I16: 15.05 | J16: =J17*J$6 -> 16.759862 | K16: =K17*K$6 -> 18.554869 | L16: =L17*L$6 -> 20.550387 | M16: =M17*M$6 -> 22.467068 | N16: =N17*N$6 -> 24.713774 | O16: =O17*O$6 -> 26.938014 | P16: =P17*P$6 -> 29.093055 | Q16: =Q17*Q$6 -> 31.4205 | R16: =R17*R$6 -> 33.93414
D17: rate | G17: =G16/G$6 -> 0.011800089 | H17: =H16/H$6 -> 0.014562423 | I17: =I16/I$6 -> 0.014095614 | J17: 0.014 | K17: 0.0137 | L17: 0.0135 | M17: 0.0134 | N17: =M17 -> 0.0134 | O17: =N17 -> 0.0134 | P17: =O17 -> 0.0134 | Q17: =P17 -> 0.0134 | R17: =Q17 -> 0.0134
C18: ——External Sales and Professional Services Fees | G18: 14.8 | H18: 18.54 | I18: 21.79 | J18: =J19*J$6 -> 24.182087 | K18: =K19*K$6 -> 27.0874 | L18: =L19*L$6 -> 27.400516 | M18: =M19*M$6 -> 28.502996 | N18: =N19*N$6 -> 31.353296 | O18: =O19*O$6 -> 34.175093 | P18: =P19*P$6 -> 36.9091 | Q18: =Q19*Q$6 -> 39.861828 | R18: =R19*R$6 -> 43.050774
D19: rate | G19: =G18/G$6 -> 0.020050669 | H19: =H18/H$6 -> 0.020736353 | I19: =I18/I$6 -> 0.020408201 | J19: 0.0202 | K19: 0.02 | L19: 0.018 | M19: 0.017 | N19: =M19 -> 0.017 | O19: =N19 -> 0.017 | P19: =O19 -> 0.017 | Q19: =P19 -> 0.017 | R19: =Q19 -> 0.017
C20: ——Others | G20: 7.17 | H20: 8.65 | I20: 4.13 | J20: =J21*J$6 -> 3.5772734 | K20: =K21*K$6 -> 2.70874 | L20: =L21*L$6 -> 3.0445018 | M20: =M21*M$6 -> 3.3532937 | N20: =N21*N$6 -> 3.6886231 | O20: =O21*O$6 -> 4.0205991 | P20: =P21*P$6 -> 4.3422471 | Q20: =Q21*Q$6 -> 4.6896268 | R20: =R21*R$6 -> 5.064797
D21: rate | G21: =G20/G$6 -> 0.0097137361 | H21: =H20/H$6 -> 0.0096747278 | I21: =I20/I$6 -> 0.0038680988 | J21: =J13-J15-J17-J19 -> 0.0029882005 | K21: 0.002 | L21: 0.002 | M21: 0.002 | N21: 0.002 | O21: 0.002 | P21: 0.002 | Q21: 0.002 | R21: 0.002
B22: General & Admin | F22: =-PL!B8 -> 77.965 | G22: =-PL!C8 -> 93.661 | H22: =-PL!D8 -> 102.486 | I22: =-PL!E8 -> 135.184 | J22: =-PL!F8 -> 141.279 | K22: 163.1 | L22: =L24+L26+L28+L30+L32 -> 181.14785 | M22: =M24+M26+M28+M30+M32 -> 197.84433 | N22: =N24+N26+N28+N30+N32 -> 217.62876 | O22: =O24+O26+O28+O30+O32 -> 237.21535 | P22: =P24+P26+P28+P30+P32 -> 256.19258 | Q22: =Q24+Q26+Q28+Q30+Q32 -> 276.68798 | R22: =R24+R26+R28+R30+R32 -> 298.82302
B23: General & Admin rate | F23: =F22/F6 -> 0.13294104 | G23: =G22/G6 -> 0.12688957 | H23: =H22/H6 -> 0.11462707 | I23: =I22/I6 -> 0.1266114 | J23: =J22/J6 -> 0.11801446 | K23: =K22/K6 -> 0.12042499 | L23: =L22/L6 -> 0.119 | M23: =M22/M6 -> 0.118 | ... R23: =R22/R6 -> 0.118
C24: ——Staff Costs | G24: 55.26 | H24: 60.27 | I24: 75.61 | J24: =J25*J$6 -> 80.207911 | K24: =K25*K$6 -> 88.03405 | L24: =L25*L$6 -> 100.46856 | M24: =M25*M$6 -> 117.36528 | N24: =N25*N$6 -> 129.10181 | O24: =O25*O$6 -> 140.72097 | P24: =P25*P$6 -> 151.97865 | Q24: =Q25*Q$6 -> 164.13694 | R24: =R25*R$6 -> 177.26789
D25: rate | G25: =G24/G$6 -> 0.074864861 | H25: =H24/H$6 -> 0.067409924 | I25: =I24/I$6 -> 0.070815242 | J25: 0.067 | K25: 0.065 | L25: 0.066 | M25: 0.07 | N25: =M25 -> 0.07 | O25: =N25 -> 0.07 | P25: =O25 -> 0.07 | Q25: =P25 -> 0.07 | R25: =Q25 -> 0.07
C26: ——Facilities and Equipment | G26: 18.41 | H26: 22.7 | I26: 26.54 | J26: =J27*J$6 -> 28.731192 | K26: =K27*K$6 -> 29.79614 | L26: =L27*L$6 -> 45.667526 | M26: =M27*M$6 -> 46.946112 | N26: =N27*N$6 -> 51.640723 | O26: =O27*O$6 -> 56.288388 | P26: =P27*P$6 -> 60.791459 | Q26: =Q27*Q$6 -> 65.654776 | R26: =R27*R$6 -> 70.907158
D27: rate | G27: =G26/G$6 -> 0.024941406 | H27: =H26/H$6 -> 0.02538917 | I27: =I26/I$6 -> 0.024856983 | J27: 0.024 | K27: 0.022 | L27: 0.03 | M27: 0.028 | N27: =M27 -> 0.028 | O27: =N27 -> 0.028 | P27: =O27 -> 0.028 | Q27: =P27 -> 0.028 | R27: =Q27 -> 0.028
C28: ——Insurance and Product Liability | G28: 8.96 | H28: 8.54 | I28: 17.9 | J28: =J29*J$6 -> 15.562729 | K28: =K29*K$6 -> 16.25244 | L28: =L29*L$6 -> 22.833763 | M28: =M29*M$6 -> 20.119762 | N28: =N29*N$6 -> 22.131738 | O28: =O29*O$6 -> 24.123595 | P28: =P29*P$6 -> 26.053482 | Q28: =Q29*Q$6 -> 28.137761 | R28: =R29*R$6 -> 30.388782
D29: rate | G29: =G28/G$6 -> 0.012138783 | H29: =H28/H$6 -> 0.0095516966 | I29: =I28/I$6 -> 0.016764883 | J29: 0.013 | K29: 0.012 | L29: 0.015 | M29: 0.012 | N29: =M29 -> 0.012 | O29: =N29 -> 0.012 | P29: =O29 -> 0.012 | Q29: =P29 -> 0.012 | R29: =Q29 -> 0.012
C30: ——External Professional Services Fees | G30: 6.37 | H30: 7.12 | I30: 11.42 | J30: =J31*J$6 -> 11.97133 | K30: =K31*K$6 -> 10.83496 | L30: =L31*L$6 -> 9.1335053 | M30: =M31*M$6 -> 10.059881 | N30: =N31*N$6 -> 11.065869 | O30: =O31*O$6 -> 12.061797 | P30: =P31*P$6 -> 13.026741 | Q30: =Q31*Q$6 -> 14.06888 | R30: =R31*R$6 -> 15.194391
D31: rate | G31: =G30/G$6 -> 0.0086299161 | H31: =H30/H$6 -> 0.0079634754 | I31: =I30/I$6 -> 0.010695808 | J31: 0.01 | K31: 0.008 | L31: 0.006 | M31: =L31 -> 0.006 | N31: =M31 -> 0.006 | O31: =N31 -> 0.006 | P31: =O31 -> 0.006 | Q31: =P31 -> 0.006 | R31: =Q31 -> 0.006
C32: ——Others | G32: 4.67 | H32: 3.86 | I32: 3.71 | J32: =J33*J$6 -> 4.805838 | K32: =K33*K$6 -> 4.06311 | L32: =L33*L$6 -> 3.0445018 | M32: =M33*M$6 -> 3.3532937 | N32: =N33*N$6 -> 3.6886231 | O32: =O33*O$6 -> 4.0205991 | P32: =P33*P$6 -> 4.3422471 | Q32: =Q33*Q$6 -> 4.6896268 | R32: =R33*R$6 -> 5.064797
D33: rate | G33: =G32/G$6 -> 0.0063267988 | H33: =H32/H$6 -> 0.0043172774 | I33: =I32/I$6 -> 0.0034747328 | J33: =J23-J25-J27-J29-J31 -> 0.0040144562 | K33: 0.003 | L33: 0.002 | M33: 0.002 | N33: =M33 -> 0.002 | O33: =N33 -> 0.002 | P33: =O33 -> 0.002 | Q33: =P33 -> 0.002 | R33: =Q33 -> 0.002
B34: Research & Development
B35: Depreciation & Amortization
B36: Other Operating Expense
B37: Other Operating Income | F37: =PL!B10 -> 1.147 | G37: =PL!C10 -> 7.486 | H37: =PL!D10 -> 4.779 | I37: =PL!E10 -> 1.372 | J37: =PL!F10 -> 4.028 | K37: =AVERAGE(H37:J37) -> 3.393 | L37: =AVERAGE(I37:K37) -> 2.931 | M37: =AVERAGE(J37:L37) -> 3.4506667 | N37: =AVERAGE(K37:M37) -> 3.2582222 | O37: =AVERAGE(L37:N37) -> 3.2132963 | P37: =AVERAGE(M37:O37) -> 3.3073951 | Q37: =AVERAGE(N37:P37) -> 3.2596379 | R37: =AVERAGE(O37:Q37) -> 3.2601097
B38: Operating expenses | F38: =F12+F22-F37 -> 210.521 | G38: =G12+G22-G37 -> 152.566 | H38: =H12+H22-H37 -> 185.997 | I38: =I12+I22-I37 -> 240.578 | J38: =J12+J22-J37 -> 260.781 | K38: =K12+K22-K37 -> 303.807 | L38: =L12+L22-L37 -> 338.81432 | M38: =M12+M22-M37 -> 369.77092 | ... R38: =R12+R22-R37 -> 562.47771
C39: YoY | G39: =G38/F38-1 -> -0.2752932 | H39: =H38/G38-1 -> 0.21912484 | I39: =I38/H38-1 -> 0.29345097 | J39: =J38/I38-1 -> 0.083976922 | K39: =K38/J38-1 -> 0.16498901 | L39: =L38/K38-1 -> 0.11522882 | M39: =M38/L38-1 -> 0.091367446 | N39: =N38/M38-1 -> 0.1054438 | ... R39: =R38/Q38-1 -> 0.080500026
C40: % of revenue | F40: =F38/F6 -> 0.35896723 | G40: =G38/G6 -> 0.20669259 | H40: =H38/H6 -> 0.20803125 | I40: =I38/I6 -> 0.2253219 | J40: =J38/J6 -> 0.21783795 | K40: =K38/K6 -> 0.2243161 | L40: =L38/L6 -> 0.22257456 | M40: =M38/M6 -> 0.22054192 | ... R40: =R38/R6 -> 0.22211264
B41: Operating profit | F41: =F9-F38 -> -25.189 | G41: =G9-G38 -> 89.709 | H41: =H9-H38 -> 112.133 | I41: =I9-I38 -> 124.114 | J41: =J9-J38 -> 152.769 | K41: =K9-K38 -> 173.293 | L41: =L9-L38 -> 195.5859 | M41: =M9-M38 -> 224.34181 | ... R41: =R9-R38 -> 416.204
...

Sheet forecast
A1: 产品名称 | B1: 类型 | C1: 主要型号 | D1: 2024年交付量 | E1: 特点简介
A2: SR2X系列 | B2: 单引擎活塞飞机 | C2: SR20、SR22、SR22T | D2: 630架 | E2: 全球最畅销的单引擎活塞飞机之一，具备高性能、舒适性和安全性，适用于私人飞行和短途商务出行。
A3: 愿景喷气机 | B3: 单发喷气式飞机 | C3: SF50 | D3: 101架 | E3: 世界上第一款私人驾驶单发喷气机，具备高速、高效和便捷操作的特点，广受高端客户欢迎。
A7: 截至2020年、 2021年及2022年12月31日止年度，我們分別交付420、528及629架飛機
A9: 仅有数据单价拆分，无成本
A10: SR2X系列 | B10: 2020 | C10: 2021 | D10: 2022 | E10: 2023 | F10: 2024
A11: 收入（mn USD） | B11: 290.468 | C11: 384.638 | D11: 492.825 | E11: 613.304 | F11: =F12*F13 -> 693
A12: 交付量（架） | B12: 347 | C12: 442 | D12: 539 | E12: 612 | F12: 630
A13: 均价（mn USD） | B13: =B11/B12 -> 0.83708357 | C13: =C11/C12 -> 0.87022172 | D13: =D11/D12 -> 0.9143321 | E13: =E11/E12 -> 1.0021307 | F13: 1.1
A15: 愿景喷气机 | B15: 2020 | C15: 2021 | D15: 2022 | E15: 2023 | F15: 2024
A16: 收入（mn USD） | B16: 197.822 | C16: 234.974 | D16: 266.915 | E16: 302.314 | F16: =F17*F18 -> 343.4
A17: 交付量（架） | B17: 73 | C17: 86 | D17: 90 | E17: 96 | F17: 101
A18: 均价（mn USD） | B18: =B16/B17 -> 2.7098904 | C18: =C16/C17 -> 2.7322558 | D18: =D16/D17 -> 2.9657222 | E18: =E16/E17 -> 3.1491042 | F18: 3.4
C21: 2021 | D21: 2022 | E21: 2023 | F21: 2024 | G21: 2025E | H21: 2026E | I21: 2027E
A22: TOTAL（mn USD）
A23: TOTAL SALES | B23: =B29+B64 -> 586.463 | C23: =C29+C64 -> 738.13 | D23: =D29+D64 -> 894.082 | E23: =E29+E64 -> 1067.708 | F23: =F29+F64 -> 1197.133 | G23: =G29+G64 -> 1376.8649 | H23: =H29+H64 -> 1522.2509 | I23: =I29+I64 -> 1676.6468
A24: yoy | C24: =C23/B23-1 -> 0.25861308 | D24: =D23/C23-1 -> 0.21127986 | E24: =E23/D23-1 -> 0.19419472 | F24: =F23/E23-1 -> 0.1212176 | G24: =G23/F23-1 -> 0.15013531 | H24: =H23/G23-1 -> 0.10559202 | I24: =I23/H23-1 -> 0.1014261
A25: COGS | B25: =B60+B67 -> 401.131 | C25: =C60+C67 -> 495.855 | D25: =D60+D67 -> 595.952 | E25: =E60+E67 -> 703.016 | F25: =-PL!F5 -> 783.583 | G25: =G60+G67 -> 900.16047 | H25: =H60+H67 -> 987.85065 | I25: =I60+I67 -> 1082.5341
A26: GP | B26: =B23-B25 -> 185.332 | C26: =C23-C25 -> 242.275 | D26: =D23-D25 -> 298.13 | E26: =E23-E25 -> 364.692 | F26: =F23-F25 -> 413.55 | G26: =G23-G25 -> 476.70446 | H26: =H23-H25 -> 534.40022 | I26: =I23-I25 -> 594.11273
A27: GPM | C27: =C26/C23 -> 0.32822809 | D27: =D26/D23 -> 0.33344816 | E27: =E26/E23 -> 0.3415653 | F27: =F26/F23 -> 0.34545034 | G27: =G26/G23 -> 0.34622456 | H27: =H26/H23 -> 0.35105923 | I27: =I26/I23 -> 0.35434578
A28: Aircraft Part（mn USD）
A29: Aircraft Sales (mn USD) | B29: ='产品 -wind'!B8 -> 488.29 | C29: ='产品 -wind'!C8 -> 619.612 | D29: ='产品 -wind'!D8 -> 759.74 | E29: ='产品 -wind'!E8 -> 915.654 | F29: ='产品 -wind'!F8 -> 1023.914 | G29: =G31+G39 -> 1174.1987 | H29: =H31+H39 -> 1279.0514 | I29: =I31+I39 -> 1382.3755
A30: yoy | C30: =C29/B29-1 -> 0.26894264 | D30: =D29/C29-1 -> 0.22615443 | E30: =E29/D29-1 -> 0.20522021 | F30: =F29/E29-1 -> 0.11823243 | G30: =G29/F29-1 -> 0.14677473 | H30: =H29/G29-1 -> 0.089297237 | I30: =I29/H29-1 -> 0.080781803
A31: SR2X Series | C31: =SUM(C33:C37) -> 384.638 | D31: =SUM(D33:D37) -> 493.43927 | E31: =SUM(E33:E37) -> 613.53283 | F31: =F42*F49 -> 693 | G31: =G42*G49 -> 801.9055 | H31: =H42*H49 -> 873.3923 | I31: =I42*I49 -> 949.35283
A32: yoy | D32: =D31/C31-1 -> 0.28286668 | E32: =E31/D31-1 -> 0.24338062 | F32: =F31/E31-1 -> 0.12952391 | G32: =G31/F31-1 -> 0.15715079 | H32: =H31/G31-1 -> 0.089146165 | I32: =I31/H31-1 -> 0.086971831
A33: —SR20 | C33: 42.618 | D33: 57.049 | E33: 69.69
A34: yoy | D34: =D33/C33-1 -> 0.33861279 | E34: =E33/D33-1 -> 0.22158145
A35: —SR22 | C35: 111.92 | D35: 142.772 | E35: 138.667
A36: yoy | D36: =D35/C35-1 -> 0.27566119 | E36: =E35/D35-1 -> -0.028752136
A37: —SR22T | C37: 230.1 | D37: 293.004 | E37: 404.983
A38: yoy | D38: =D37/C37-1 -> 0.27337679 | E38: =E37/D37-1 -> 0.38217567
A39: Vision Jet | C39: 234.974 | D39: 266.915 | E39: 302.314 | F39: =F46*F57 -> 343.4 | G39: =G46*G57 -> 372.2932 | H39: =H46*H57 -> 405.6591 | I39: =I46*I57 -> 433.02265
A40: yoy | D40: =D39/C39-1 -> 0.13593419 | E40: =E39/D39-1 -> 0.13262275 | F40: =F39/E39-1 -> 0.13590505 | G40: =G39/F39-1 -> 0.084138614 | H40: =H39/G39-1 -> 0.089622642 | I40: =I39/H39-1 -> 0.067454545
A41: —Delivery（units） | B41: 420 | C41: 528 | D41: 629 | E41: 708 | F41: 731 | G41: =G42+G46 -> 797 | H41: =H42+H46 -> 820 | I41: =I42+I46 -> 849
A42: SR2X Series | C42: =SUM(C43:C45) -> 442 | D42: =SUM(D43:D45) -> 539 | E42: =SUM(E43:E45) -> 612 | F42: 630 | G42: 691 | H42: 710 | I42: 735
A43: —SR20 | C43: 81 | D43: 100 | E43: 115
A44: —SR22 | C44: 131 | D44: 159 | E44: 142
A45: —SR22T | C45: 230 | D45: 280 | E45: 355
A46: Vision Jet | C46: 86 | D46: 90 | E46: 96 | F46: 101 | G46: 106 | H46: 110 | I46: 114
A47: —Average Price (mn USD) | B47: =B29/B41 -> 1.1625952 | C47: =C29/C41 -> 1.1735076 | D47: =D29/D41 -> 1.2078537 | E47: =E29/E41 -> 1.2932966 | F47: =F29/F41 -> 1.4007031 | G47: =F47*(1+G48) -> 1.5127594 | H47: =G47*(1+H48) -> 1.6337801 | I47: =H47*(1+I48) -> 1.7644826
...

Sheet DCF 
A1: 1
C2: Discounted Cash Flow
C3: USD mn
C4: Free cashflow forecast | E4: 2023 | F4: 2024 | G4: 2025E | H4: 2026E | I4: 2027E | J4: 2028E | K4: 2029E | L4: 2030E | M4: 2031E | N4: 2032E
C5: Net Revenue | E5: ='PL-CF-BS'!I6 -> 1067.708 | F5: ='PL-CF-BS'!J6 -> 1197.133 | G5: ='PL-CF-BS'!K6 -> 1354.37 | H5: ='PL-CF-BS'!L6 -> 1522.2509 | I5: ='PL-CF-BS'!M6 -> 1676.6468 | J5: ='PL-CF-BS'!N6 -> 1844.3115 | K5: ='PL-CF-BS'!O6 -> 2010.2996 | L5: ='PL-CF-BS'!P6 -> 2171.1235 | ... N5: ='PL-CF-BS'!R6 -> 2532.3985
D6: YoY | F6: =F5/E5-1 -> 0.1212176 | G6: =G5/F5-1 -> 0.13134464 | H6: =H5/G5-1 -> 0.12395496 | I6: =I5/H5-1 -> 0.1014261 | J6: =J5/I5-1 -> 0.1 | K6: =K5/J5-1 -> 0.09 | L6: =L5/K5-1 -> 0.08 | M6: =M5/L5-1 -> 0.08 | N6: =N5/M5-1 -> 0.08
C7: EBIT | E7: ='PL-CF-BS'!I41-'PL-CF-BS'!I58 -> 124.114 | F7: ='PL-CF-BS'!J41-'PL-CF-BS'!J58 -> 152.769 | G7: ='PL-CF-BS'!K41-'PL-CF-BS'!K58 -> 173.293 | H7: ='PL-CF-BS'!L41-'PL-CF-BS'!L58 -> 195.5859 | I7: ='PL-CF-BS'!M41-'PL-CF-BS'!M58 -> 224.34181 | J7: ='PL-CF-BS'!N41-'PL-CF-BS'!N58 -> 250.1757 | K7: ='PL-CF-BS'!O41-'PL-CF-BS'!O58 -> 290.13397 | L7: ='PL-CF-BS'!P41-'PL-CF-BS'!P58 -> 319.55311 | ... N7: ='PL-CF-BS'!R41-'PL-CF-BS'!R58 -> 416.204
D8: YoY | F8: =F7/E7-1 -> 0.23087645 | G8: =G7/F7-1 -> 0.13434663 | H8: =H7/G7-1 -> 0.12864282 | I8: =I7/H7-1 -> 0.14702445 | J8: =J7/I7-1 -> 0.11515415 | K8: =K7/J7-1 -> 0.15972083 | L8: =L7/K7-1 -> 0.10139848 | M8: =M7/L7-1 -> 0.14332401 | N8: =N7/M7-1 -> 0.139184
D9: EBIT Margin | E9: =E7/E5 -> 0.11624339 | F9: =F7/F5 -> 0.12761239 | G9: =G7/G5 -> 0.127951 | H9: =H7/H5 -> 0.12848467 | I9: =I7/I5 -> 0.13380385 | J9: =J7/J5 -> 0.1356472 | K9: =K7/K5 -> 0.14432375 | L9: =L7/L5 -> 0.14718329 | ... N9: =N7/N5 -> 0.1643517
C10: EBIT*(1 - t) | E10: =E7*(1-$L$16) -> 100.53234 | F10: =F7*(1-$L$16) -> 123.74289 | G10: =G7*(1-$L$16) -> 140.36733 | H10: =H7*(1-$L$16) -> 158.42458 | I10: =I7*(1-$L$16) -> 181.71687 | J10: =J7*(1-$L$16) -> 202.64232 | K10: =K7*(1-$L$16) -> 235.00852 | L10: =L7*(1-$L$16) -> 258.83802 | ... N10: =N7*(1-$L$16) -> 337.12524
C11: + | D11: Depreciation and Amortization | E11: ='PL-CF-BS'!I90 -> 36.575 | F11: ='PL-CF-BS'!J90 -> 44.976 | G11: ='PL-CF-BS'!K90 -> 40.2528 | H11: ='PL-CF-BS'!L90 -> 42.63133 | I11: ='PL-CF-BS'!M90 -> 44.751046 | J11: ='PL-CF-BS'!N90 -> 46.799564 | K11: ='PL-CF-BS'!O90 -> 49.200045 | L11: ='PL-CF-BS'!P90 -> 51.608573 | ... N11: ='PL-CF-BS'!R90 -> 56.80826
C12: - | D12: Change in working capital | E12: ='PL-CF-BS'!I91 -> 32.421 | F12: ='PL-CF-BS'!J91 -> 27.975 | G12: ='PL-CF-BS'!K91 -> -141.7168 | H12: ='PL-CF-BS'!L91 -> -22.013289 | I12: ='PL-CF-BS'!M91 -> -28.328407 | J12: ='PL-CF-BS'!N91 -> -2.0483413 | K12: ='PL-CF-BS'!O91 -> -23.787201 | L12: ='PL-CF-BS'!P91 -> -25.535393 | ... N12: ='PL-CF-BS'!R91 -> -107.78128
C13: - | D13: Capex | E13: ='PL-CF-BS'!I96 -> -90.331 | F13: ='PL-CF-BS'!J96 -> -92.705 | G13: ='PL-CF-BS'!K96 -> -93 | H13: ='PL-CF-BS'!L96 -> -100.44 | I13: ='PL-CF-BS'!M96 -> -108.4752 | J13: ='PL-CF-BS'!N96 -> -117.15322 | K13: ='PL-CF-BS'!O96 -> -126.52547 | L13: ='PL-CF-BS'!P96 -> -136.64751 | ... N13: ='PL-CF-BS'!R96 -> -150.65388
C14: Free Cash Flows | E14: =SUM(E10:E13) -> 79.19734 | F14: =SUM(F10:F13) -> 103.98889 | G14: =SUM(G10:G13) -> -54.09667 | H14: =SUM(H10:H13) -> 78.60262 | I14: =SUM(I10:I13) -> 89.664304 | J14: =SUM(J10:J13) -> 130.24032 | K14: =SUM(K10:K13) -> 133.89589 | L14: =SUM(L10:L13) -> 148.26369 | ... N14: =SUM(N10:N13) -> 135.49834
C15: DCF Analysis
D16: PV of FCF | E16: =NPV(L24,I14:N14)+H14 -> 656.12091 | K16: Tax rate | L16: 0.19
D17: Terminal value | E17: =N14*(1+L25)/(L24-L25) -> 2389.9728 | K17: Debt ratio | L17: 0.34
D18: PV of terminal value | E18: =E17/(1+L24)^6 -> 1524.387 | K18: Beta | L18: 0.81
D19: Enterprise Value | E19: =E16+E18 -> 2180.5079 | K19: Risk free rate | L19: 0.03
D20: Net Cash/(Debt), Minority interests | E20: ='PL-CF-BS'!L117-'PL-CF-BS'!L136 -> 273.12714 | K20: Risk premium | L20: 0.09
D21: Equity Value | E21: =E19+E20 -> 2453.635 | K21: Equity cost | L21: =L19+L18*L20 -> 0.1029
D22: Equity value per share | E22: =E21/'PL-CF-BS'!J72 -> 6.7041256 | K22: Debt cost | L22: 0.036
K23: Debt cost (After tax) | L23: =L22*(1-L16) -> 0.02916
K24: WACC | L24: =L23*L17+L21*(1-L17) -> 0.0778284
K25: Perpetual Growth | L25: 0.02
E28: Equity value per share (USD)
E29: Perpetual Growth | H29: =I29-0.1% -> 0.017 | I29: =J29-0.1% -> 0.018 | J29: =K29-0.1% -> 0.019 | K29: =L25 -> 0.02 | L29: =K29+0.1% -> 0.021 | M29: =L29+0.1% -> 0.022
E30: WACC | G30: =G31-0.1% -> 0.0748284 | H30: =($E$20+(NPV($G30,$I$14:$N$14)+$H$14)+((($N$14*(1+H$29)/($G30-H$29)))/(1+$G30)^6))/'PL-CF-BS'!$J$72 -> 6.7770869 | I30: =($E$20+(NPV($G30,$I$14:$N$14)+$H$14)+((($N$14*(1+I$29)/($G30-I$29)))/(1+$G30)^6))/'PL-CF-BS'!$J$72 -> 6.855622 | J30: =($E$20+(NPV($G30,$I$14:$N$14)+$H$14)+((($N$14*(1+J$29)/($G30-J$29)))/(1+$G30)^6))/'PL-CF-BS'!$J$72 -> 6.9369706 | K30: =($E$20+(NPV($G30,$I$14:$N$14)+$H$14)+((($N$14*(1+K$29)/($G30-K$29)))/(1+$G30)^6))/'PL-CF-BS'!$J$72 -> 7.0212865 | L30: =($E$20+(NPV($G30,$I$14:$N$14)+$H$14)+((($N$14*(1+L$29)/($G30-L$29)))/(1+$G30)^6))/'PL-CF-BS'!$J$72 -> 7.1087352 | M30: =($E$20+(NPV($G30,$I$14:$N$14)+$H$14)+((($N$14*(1+M$29)/($G30-M$29)))/(1+$G30)^6))/'PL-CF-BS'!$J$72 -> 7.1994946
G31: =G32-0.1% -> 0.0758284 | H31: =($E$20+(NPV($G31,$I$14:$N$14)+$H$14)+((($N$14*(1+H$29)/($G31-H$29)))/(1+$G31)^6))/'PL-CF-BS'!$J$72 -> 6.6771225 | I31: =($E$20+(NPV($G31,$I$14:$N$14)+$H$14)+((($N$14*(1+I$29)/($G31-I$29)))/(1+$G31)^6))/'PL-CF-BS'!$J$72 -> 6.7526357 | J31: =($E$20+(NPV($G31,$I$14:$N$14)+$H$14)+((($N$14*(1+J$29)/($G31-J$29)))/(1+$G31)^6))/'PL-CF-BS'!$J$72 -> 6.8308065 | K31: =($E$20+(NPV($G31,$I$14:$N$14)+$H$14)+((($N$14*(1+K$29)/($G31-K$29)))/(1+$G31)^6))/'PL-CF-BS'!$J$72 -> 6.9117777 | L31: =($E$20+(NPV($G31,$I$14:$N$14)+$H$14)+((($N$14*(1+L$29)/($G31-L$29)))/(1+$G31)^6))/'PL-CF-BS'!$J$72 -> 6.9957025 | M31: =($E$20+(NPV($G31,$I$14:$N$14)+$H$14)+((($N$14*(1+M$29)/($G31-M$29)))/(1+$G31)^6))/'PL-CF-BS'!$J$72 -> 7.0827455
G32: =G33-0.1% -> 0.0768284 | H32: =($E$20+(NPV($G32,$I$14:$N$14)+$H$14)+((($N$14*(1+H$29)/($G32-H$29)))/(1+$G32)^6))/'PL-CF-BS'!$J$72 -> 6.5805017 | I32: =($E$20+(NPV($G32,$I$14:$N$14)+$H$14)+((($N$14*(1+I$29)/($G32-I$29)))/(1+$G32)^6))/'PL-CF-BS'!$J$72 -> 6.6531523 | J32: =($E$20+(NPV($G32,$I$14:$N$14)+$H$14)+((($N$14*(1+J$29)/($G32-J$29)))/(1+$G32)^6))/'PL-CF-BS'!$J$72 -> 6.7283155 | K32: =($E$20+(NPV($G32,$I$14:$N$14)+$H$14)+((($N$14*(1+K$29)/($G32-K$29)))/(1+$G32)^6))/'PL-CF-BS'!$J$72 -> 6.806124 | L32: =($E$20+(NPV($G32,$I$14:$N$14)+$H$14)+((($N$14*(1+L$29)/($G32-L$29)))/(1+$G32)^6))/'PL-CF-BS'!$J$72 -> 6.88672 | M32: =($E$20+(NPV($G32,$I$14:$N$14)+$H$14)+((($N$14*(1+M$29)/($G32-M$29)))/(1+$G32)^6))/'PL-CF-BS'!$J$72 -> 6.9702558
G33: =L24 -> 0.0778284 | H33: =($E$20+(NPV($G33,$I$14:$N$14)+$H$14)+((($N$14*(1+H$29)/($G33-H$29)))/(1+$G33)^6))/'PL-CF-BS'!$J$72 -> 6.4870596 | I33: =($E$20+(NPV($G33,$I$14:$N$14)+$H$14)+((($N$14*(1+I$29)/($G33-I$29)))/(1+$G33)^6))/'PL-CF-BS'!$J$72 -> 6.5569962 | J33: =($E$20+(NPV($G33,$I$14:$N$14)+$H$14)+((($N$14*(1+J$29)/($G33-J$29)))/(1+$G33)^6))/'PL-CF-BS'!$J$72 -> 6.6293104 | K33: =($E$20+(NPV($G33,$I$14:$N$14)+$H$14)+((($N$14*(1+K$29)/($G33-K$29)))/(1+$G33)^6))/'PL-CF-BS'!$J$72 -> 6.7041256 | L33: =($E$20+(NPV($G33,$I$14:$N$14)+$H$14)+((($N$14*(1+L$29)/($G33-L$29)))/(1+$G33)^6))/'PL-CF-BS'!$J$72 -> 6.7815738 | M33: =($E$20+(NPV($G33,$I$14:$N$14)+$H$14)+((($N$14*(1+M$29)/($G33-M$29)))/(1+$G33)^6))/'PL-CF-BS'!$J$72 -> 6.8617965
G34: =G33+0.1% -> 0.0788284 | H34: =($E$20+(NPV($G34,$I$14:$N$14)+$H$14)+((($N$14*(1+H$29)/($G34-H$29)))/(1+$G34)^6))/'PL-CF-BS'!$J$72 -> 6.396642 | I34: =($E$20+(NPV($G34,$I$14:$N$14)+$H$14)+((($N$14*(1+I$29)/($G34-I$29)))/(1+$G34)^6))/'PL-CF-BS'!$J$72 -> 6.4640033 | J34: =($E$20+(NPV($G34,$I$14:$N$14)+$H$14)+((($N$14*(1+J$29)/($G34-J$29)))/(1+$G34)^6))/'PL-CF-BS'!$J$72 -> 6.5336163 | K34: =($E$20+(NPV($G34,$I$14:$N$14)+$H$14)+((($N$14*(1+K$29)/($G34-K$29)))/(1+$G34)^6))/'PL-CF-BS'!$J$72 -> 6.605596 | L34: =($E$20+(NPV($G34,$I$14:$N$14)+$H$14)+((($N$14*(1+L$29)/($G34-L$29)))/(1+$G34)^6))/'PL-CF-BS'!$J$72 -> 6.680065 | M34: =($E$20+(NPV($G34,$I$14:$N$14)+$H$14)+((($N$14*(1+M$29)/($G34-M$29)))/(1+$G34)^6))/'PL-CF-BS'!$J$72 -> 6.757155
G35: =G34+0.1% -> 0.0798284 | H35: =($E$20+(NPV($G35,$I$14:$N$14)+$H$14)+((($N$14*(1+H$29)/($G35-H$29)))/(1+$G35)^6))/'PL-CF-BS'!$J$72 -> 6.3091045 | I35: =($E$20+(NPV($G35,$I$14:$N$14)+$H$14)+((($N$14*(1+I$29)/($G35-I$29)))/(1+$G35)^6))/'PL-CF-BS'!$J$72 -> 6.37402 | J35: =($E$20+(NPV($G35,$I$14:$N$14)+$H$14)+((($N$14*(1+J$29)/($G35-J$29)))/(1+$G35)^6))/'PL-CF-BS'!$J$72 -> 6.4410699 | K35: =($E$20+(NPV($G35,$I$14:$N$14)+$H$14)+((($N$14*(1+K$29)/($G35-K$29)))/(1+$G35)^6))/'PL-CF-BS'!$J$72 -> 6.5103612 | L35: =($E$20+(NPV($G35,$I$14:$N$14)+$H$14)+((($N$14*(1+L$29)/($G35-L$29)))/(1+$G35)^6))/'PL-CF-BS'!$J$72 -> 6.5820082 | M35: =($E$20+(NPV($G35,$I$14:$N$14)+$H$14)+((($N$14*(1+M$29)/($G35-M$29)))/(1+$G35)^6))/'PL-CF-BS'!$J$72 -> 6.6561331
G36: =G35+0.1% -> 0.0808284 | H36: =($E$20+(NPV($G36,$I$14:$N$14)+$H$14)+((($N$14*(1+H$29)/($G36-H$29)))/(1+$G36)^6))/'PL-CF-BS'!$J$72 -> 6.2243116 | I36: =($E$20+(NPV($G36,$I$14:$N$14)+$H$14)+((($N$14*(1+I$29)/($G36-I$29)))/(1+$G36)^6))/'PL-CF-BS'!$J$72 -> 6.2869027 | J36: =($E$20+(NPV($G36,$I$14:$N$14)+$H$14)+((($N$14*(1+J$29)/($G36-J$29)))/(1+$G36)^6))/'PL-CF-BS'!$J$72 -> 6.3515184 | K36: =($E$20+(NPV($G36,$I$14:$N$14)+$H$14)+((($N$14*(1+K$29)/($G36-K$29)))/(1+$G36)^6))/'PL-CF-BS'!$J$72 -> 6.4182587 | L36: =($E$20+(NPV($G36,$I$14:$N$14)+$H$14)+((($N$14*(1+L$29)/($G36-L$29)))/(1+$G36)^6))/'PL-CF-BS'!$J$72 -> 6.48723 | M36: =($E$20+(NPV($G36,$I$14:$N$14)+$H$14)+((($N$14*(1+M$29)/($G36-M$29)))/(1+$G36)^6))/'PL-CF-BS'!$J$72 -> 6.5585462
E37: % change from DCF TP upon WACC/perpetual growth change
E38: Perpetual Growth | H38: =H29 -> 0.017 | I38: =I29 -> 0.018 | J38: =J29 -> 0.019 | K38: =K29 -> 0.02 | L38: =L29 -> 0.021 | M38: =M29 -> 0.022
E39: WACC | G39: =G30 -> 0.0748284 | H39: =H30/$K$33-1 -> 0.010883047 | I39: =I30/$K$33-1 -> 0.022597492 | J39: =J30/$K$33-1 -> 0.034731597 | K39: =K30/$K$33-1 -> 0.047308322 | L39: =L30/$K$33-1 -> 0.060352338 | M39: =M30/$K$33-1 -> 0.073890179
G40: =G31 -> 0.0758284 | H40: =H31/$K$33-1 -> -0.004027834 | I40: =I31/$K$33-1 -> 0.0072358581 | J40: =J31/$K$33-1 -> 0.018895961 | K40: =K31/$K$33-1 -> 0.030973776 | L40: =L31/$K$33-1 -> 0.043492159 | M40: =M31/$K$33-1 -> 0.056475663
G41: =G32 -> 0.0768284 | H41: =H32/$K$33-1 -> -0.018439972 | I41: =I32/$K$33-1 -> -0.0076032716 | J41: =J32/$K$33-1 -> 0.0036082172 | K41: =K32/$K$33-1 -> 0.015214279 | L41: =L32/$K$33-1 -> 0.027236118 | M41: =M32/$K$33-1 -> 0.039696482
G42: =G33 -> 0.0778284 | H42: =H33/$K$33-1 -> -0.032377967 | I42: =I33/$K$33-1 -> -0.021946098 | J42: =J33/$K$33-1 -> -0.011159576 | K42: =K33/$K$33-1 -> 0 | L42: =L33/$K$33-1 -> 0.011552322 | M42: =M33/$K$33-1 -> 0.023518495
...

Sheet PL
B1: 2020-12-31 | C1: 2021-12-31 | D1: 2022-12-31 | E1: 2023-12-31 | F1: 2024-12-31
A2: 报告期 | B2: 年报 | C2: 年报 | D2: 年报 | E2: 年报 | F2: 年报
A3: 报表类型 | B3: 合并报表 | C3: 合并报表 | D3: 合并报表 | E3: 合并报表 | F3: 合并报表
A4: 营业收入 | B4: 586.463 | C4: 738.13 | D4: 894.082 | E4: 1067.708 | F4: 1197.133
A5: 营业成本 | B5: -401.131 | C5: -495.855 | D5: -595.952 | E5: -703.016 | F5: -783.583
A6: 毛利 | B6: 185.332 | C6: 242.275 | D6: 298.13 | E6: 364.692 | F6: 413.55
A7: 销售费用 | B7: -55.738 | C7: -66.391 | D7: -88.29 | E7: -106.766 | F7: -123.53
A8: 管理费用 | B8: -77.965 | C8: -93.661 | D8: -102.486 | E8: -135.184 | F8: -141.279
A9: 利润-不包括已实现的净损益 | B9: 51.629 | C9: 82.223 | D9: 107.354 | E9: 122.742 | F9: 148.741
A10: 其他经营净收益 | B10: 1.147 | C10: 7.486 | D10: 4.779 | E10: 1.372 | F10: 4.028
A11: 营业利润 | B11: 52.776 | C11: 89.709 | D11: 112.133 | E11: 124.114 | F11: 152.769
A12: 财务费用 | B12: -6.172 | C12: -3.509 | D12: -3.199 | E12: -5.529 | F12: -5.145
A13: 除税前溢利 | B13: 46.604 | C13: 86.2 | D13: 108.934 | E13: 118.585 | F13: 147.624
A14: 所得税 | B14: -10.488 | C14: -13.797 | D14: -20.858 | E14: -27.442 | F14: -26.878
A15: 净利润(含少数股东权益) | B15: 36.116 | C15: 72.403 | D15: 88.076 | E15: 91.143 | F15: 120.746
... A23: 职工薪酬 | B23: -141.948 | C23: -167.343 | D23: -206.667 | E23: -254.299 | F23: -281.033
