Workbook
Name \b: #REF!
Name \c: #REF!
Name \d: #REF!
Name \e: #REF!
Name \f: #REF!
Name \g: #REF!
Name \h: #REF!
Name \i: #REF!
Name \j: #N/A
Name \k: #REF!
Name \l: #REF!
Name \m: #REF!
Name \p: #REF!
Name \q: #REF!
Name \s: #REF!
Name \u: #REF!
Name \v: #N/A
Name \x: #REF!
Name \z: #REF!
Name _______DAT1: #REF!
Name _______DAT2: #REF!
Name _______DAT3: #REF!
Name _______DAT4: #REF!
Name _______DAT5: #REF!
Name _______DAT6: #REF!
Name _______DAT7: #REF!
Name _______DAT8: #REF!
Name _______DCF2: #REF!
Name _______EPS94: #REF!
Name _______EPS95: #REF!
Name _______EPS96: #REF!
Name _______EPS97: #REF!
Name _______EPS98: #REF!
Name _______rev1997: #REF!
Name _______rev1999: #REF!
Name _______rev2000: #REF!
Name _______rev2001: #REF!
Name _______rev2002: #REF!
Name _______rev2003: #REF!
Name _______REV89: #REF!
Name _______REV90: #REF!
Name _______REV91: #REF!
Name _______REV92: #REF!
Name _______REV93: #REF!
Name _______REV94: #REF!
Name _______REV95: #REF!
Name _______REV96: #REF!
Name _______REV97: #REF!
Name _______REV98: #REF!
Name ______DAT1: #REF!
Name ______DAT2: #REF!
Name ______DAT3: #REF!
Name ______DAT4: #REF!
Name ______DAT5: #REF!
Name ______DAT6: #REF!
Name ______DAT7: #REF!
Name ______DAT8: #REF!
Name ______DCF2: #REF!
Name ______EPS94: #REF!
Name ______EPS95: #REF!

Sheet XN
A1: Code | B1: OR | C1: Please enter the ticker in B1, e.g. 700 HK
A2: Last annual report | B2: 45657 | C2: Please enter the date in B2, e.g. 2020/3/31
A3: Start year | B3: 2024
A4: Currency | B4: US$
A5: Unit | B5: mn
A6: =B4&" "&B5 -> US$ mn | B6: =TEXT(DATE($B$3,MONTH($B$2),DAY($B$2)),"mmm-yy")&IF($B$3>YEAR($B$2),"E","A") -> Dec-24A | C6: =TEXT(DATE($B$3+1,MONTH($B$2),DAY($B$2)),"mmm-yy")&IF($B$3+1>YEAR($B$2),"E","A") -> Dec-25E | D6: =TEXT(DATE($B$3+2,MONTH($B$2),DAY($B$2)),"mmm-yy")&IF($B$3+2>YEAR($B$2),"E","A") -> Dec-26E | E6: =TEXT(DATE($B$3+3,MONTH($B$2),DAY($B$2)),"mmm-yy")&IF($B$3+3>YEAR($B$2),"E","A") -> Dec-27E
A7: P&L
A8: Revenue | B8: ='PL-CF-BS'!H6 -> 43486.8 | C8: ='PL-CF-BS'!I6 -> 44052 | D8: ='PL-CF-BS'!J6 -> 46055.159 | E8: ='PL-CF-BS'!K6 -> 48398.286
A9: (+/-) | B9: ='PL-CF-BS'!H7 -> 0.055950814 | C9: ='PL-CF-BS'!I7 -> 0.012997047 | D9: ='PL-CF-BS'!J7 -> 0.045472611 | E9: ='PL-CF-BS'!K7 -> 0.05087653
A10: Net profit | B10: ='PL-CF-BS'!H49 -> 6408.7 | C10: ='PL-CF-BS'!I49 -> 6127.2 | D10: ='PL-CF-BS'!J49 -> 6786.0987 | E10: ='PL-CF-BS'!K49 -> 7382.0999
A11: (+/-) | B11: ='PL-CF-BS'!H50 -> 0.036335705 | C11: ='PL-CF-BS'!I50 -> -0.043924665 | D11: ='PL-CF-BS'!J50 -> 0.10753668 | E11: ='PL-CF-BS'!K50 -> 0.08782678
A12: ="Diluted EPS ("&B4&")" -> Diluted EPS (US$) | B12: ='PL-CF-BS'!H62 -> 11.954781 | C12: ='PL-CF-BS'!I62 -> 11.444496 | D12: ='PL-CF-BS'!J62 -> 12.6952 | E12: ='PL-CF-BS'!K62 -> 13.829726
A13: GPM | B13: ='PL-CF-BS'!H165 -> 0.7418297 | C13: ='PL-CF-BS'!I165 -> 0.74318079 | D13: ='PL-CF-BS'!J165 -> 0.74418079 | E13: ='PL-CF-BS'!K165 -> 0.74718079 | F13: e.g. 50.5%
A14: ROE | B14: ='PL-CF-BS'!H170 -> 0.20604235 | C14: ='PL-CF-BS'!I170 -> 0.17998282 | D14: ='PL-CF-BS'!J170 -> 0.18762282 | E14: ='PL-CF-BS'!K170 -> 0.19010214 | F14: e.g. 50.5%
A15: EBITDA | B15: ='PL-CF-BS'!H26 -> 10105.1 | C15: ='PL-CF-BS'!I26 -> 10173.74 | D15: ='PL-CF-BS'!J26 -> 10899.278 | E15: ='PL-CF-BS'!K26 -> 11663.501
A16: EBIT | B16: ='DCF '!F7 -> 8249.8 | C16: ='DCF '!G7 -> 8386.5 | D16: ='DCF '!H7 -> 9024.139 | E16: ='DCF '!I7 -> 9732.3131
A17: Interest Revenue | B17: ='PL-CF-BS'!H31 -> 148.7 | C17: ='PL-CF-BS'!I31 -> 167.7 | D17: ='PL-CF-BS'!J31 -> 230 | E17: ='PL-CF-BS'!K31 -> 200
A18: Interest Expense | B18: ='PL-CF-BS'!H30 -> -373.4 | C18: ='PL-CF-BS'!I30 -> -365.8 | D18: ='PL-CF-BS'!J30 -> -366 | E18: ='PL-CF-BS'!K30 -> -259.04
A19: Operating Profit | B19: ='PL-CF-BS'!H22 -> 8249.8 | C19: ='PL-CF-BS'!I22 -> 8386.5 | D19: ='PL-CF-BS'!J22 -> 9024.139 | E19: ='PL-CF-BS'!K22 -> 9732.3131
A20: Gross Profit | B20: ='PL-CF-BS'!H9 -> 32259.8 | C20: ='PL-CF-BS'!I9 -> 32738.6 | D20: ='PL-CF-BS'!J9 -> 34273.365 | E20: ='PL-CF-BS'!K9 -> 36162.269
A21: Depreciation | B21: ='PL-CF-BS'!H73 -> 1855.3 | C21: ='PL-CF-BS'!I73 -> 1817.4 | D21: ='PL-CF-BS'!J73 -> 1900.0419 | E21: ='PL-CF-BS'!K73 -> 1996.7095
A22: Pre-Tax Profit | B22: ='PL-CF-BS'!H40 -> 8432.9 | C22: ='PL-CF-BS'!I40 -> 8502.3 | D22: ='PL-CF-BS'!J40 -> 9207.3175 | E22: ='PL-CF-BS'!K40 -> 10003.167
A23: Balance Sheet
A24: Total Assets | B24: ='PL-CF-BS'!H125 -> 56353.4 | C24: ='PL-CF-BS'!I125 -> 61821.2 | D24: ='PL-CF-BS'!J125 -> 66152.243 | E24: ='PL-CF-BS'!K125 -> 70538.685
A25: Total Liabilities | B25: ='PL-CF-BS'!H145 -> 23215.6 | C25: ='PL-CF-BS'!I145 -> 26817.4 | D25: ='PL-CF-BS'!J145 -> 28763.273 | E25: ='PL-CF-BS'!K145 -> 30254.089
A26: Shareholder Equity | B26: ='PL-CF-BS'!H159 -> 33137.8 | C26: ='PL-CF-BS'!I159 -> 35003.8 | D26: ='PL-CF-BS'!J159 -> 37388.97 | E26: ='PL-CF-BS'!K159 -> 40284.596
A27: Total Equity | B27: ='PL-CF-BS'!H159 -> 33137.8 | C27: ='PL-CF-BS'!I155 -> 34953.2 | D27: ='PL-CF-BS'!J155 -> 37384.47 | E27: ='PL-CF-BS'!K155 -> 40280.096
A28: Cash Flow
A29: Profit before tax | B29: =B22 -> 8432.9 | C29: =C22 -> 8502.3 | D29: =D22 -> 9207.3175 | E29: =E22 -> 10003.167
A30: Net Cash from operations | B30: ='PL-CF-BS'!H76 -> 8286 | C30: ='PL-CF-BS'!I76 -> 8656.9 | D30: ='PL-CF-BS'!J76 -> 8495.086 | E30: ='PL-CF-BS'!K76 -> 9071.6143
A31: Net Cash from investment activity | B31: ='PL-CF-BS'!H84 -> -3703.9 | C31: ='PL-CF-BS'!I84 -> -1407.2 | D31: ='PL-CF-BS'!J84 -> -3188.9738 | E31: ='PL-CF-BS'!K84 -> -2909.6715
A32: Net Cash from financing activity | B32: ='PL-CF-BS'!H98 -> -4785.05 | C32: ='PL-CF-BS'!I98 -> -1397.8 | D32: ='PL-CF-BS'!J98 -> -2884.7118 | E32: ='PL-CF-BS'!K98 -> -3235.0188
A33: Net change in Cash | B33: ='PL-CF-BS'!H100 -> -235.7 | C33: ='PL-CF-BS'!I100 -> 5812.7 | D33: ='PL-CF-BS'!J100 -> 2421.4004 | E33: ='PL-CF-BS'!K100 -> 2926.9241
A34: Implied cash at end of period | B34: ='PL-CF-BS'!H101 -> 4288 | C34: ='PL-CF-BS'!I101 -> 4052.3 | D34: ='PL-CF-BS'!J101 -> 9865 | E34: ='PL-CF-BS'!K101 -> 12286.4
A35: Free Cash Flow | B35: ='DCF '!F14 -> 6174.35 | C35: ='DCF '!G14 -> 6939.375 | D35: ='DCF '!H14 -> 6823.3844 | E35: ='DCF '!I14 -> 7243.6666
A40: EPS | B40: =B12 -> 11.954781 | C40: =C12 -> 11.444496 | D40: =D12 -> 12.6952 | E40: =E12 -> 13.829726
A41: EPS1 | B41: =IF(A43-YEAR($B$2)>=0,VLOOKUP((A43-B3+1),A45:B48,2,FALSE),"na") -> 12.6952
A42: EPS2 | B42: =IF(A43-YEAR($B$2)>=0,VLOOKUP((A43-B3+2),A45:B48,2,FALSE),"na") -> 13.829726
A43: =YEAR(TODAY()) -> 2026
A44: =YEAR(TODAY()) -> 2026
...

Sheet XN-output
B2: 资产负债表（百万美元） | C2: =K18 -> 2023 | D2: =L18 -> 2024 | E2: =M18 -> 2025 | F2: =N18 -> 2026E | G2: =O18 -> 2027E | H2: 2028E | J2: 利润表（百万美元） | K2: =K18 -> 2023 | L2: =L18 -> 2024 | M2: =M18 -> 2025 | N2: =N18 -> 2026E | O2: =O18 -> 2027E | P2: 2028E | R2: BS (Euro mn) | S2: =C2 -> 2023 | T2: =D2 -> 2024 | U2: =E2 -> 2025 | V2: =F2 -> 2026E | W2: =G2 -> 2027E | X2: 2028E | Z2: IS (Euro mn) | AA2: =K2 -> 2023 | AB2: =L2 -> 2024 | AC2: =M2 -> 2025 | AD2: =N2 -> 2026E | AE2: =O2 -> 2027E | AF2: 2028E
B3: 现金及现金等价物 | C3: ='PL-CF-BS'!G111 -> 4288 | D3: ='PL-CF-BS'!H111 -> 4052.3 | E3: ='PL-CF-BS'!I111 -> 9865 | F3: ='PL-CF-BS'!J111 -> 12286.4 | G3: ='PL-CF-BS'!K111 -> 15213.324 | H3: ='PL-CF-BS'!L111 -> 19654.289 | J3: 营业收入 | K3: ='PL-CF-BS'!G6 -> 41182.6 | L3: ='PL-CF-BS'!H6 -> 43486.8 | M3: ='PL-CF-BS'!I6 -> 44052 | N3: ='PL-CF-BS'!J6 -> 46055.159 | O3: ='PL-CF-BS'!K6 -> 48398.286 | P3: ='PL-CF-BS'!L6 -> 50952.563 | R3: Cash and Cash Equivalents | T3: =D3 -> 4052.3 | U3: =E3 -> 9865 | V3: =F3 -> 12286.4 | W3: =G3 -> 15213.324 | X3: =H3 -> 19654.289 | Z3: Revenue | AA3: =K3 -> 41182.6 | AB3: =L3 -> 43486.8 | AC3: =M3 -> 44052 | AD3: =N3 -> 46055.159 | AE3: =O3 -> 48398.286 | AF3: =P3 -> 50952.563
B4: 应收款项 | C4: ='PL-CF-BS'!G108 -> 5092.7 | D4: ='PL-CF-BS'!H108 -> 5601.8 | E4: ='PL-CF-BS'!I108 -> 5500.3 | F4: ='PL-CF-BS'!J108 -> 5775.649 | G4: ='PL-CF-BS'!K108 -> 6082.9872 | H4: ='PL-CF-BS'!L108 -> 6429.813 | J4: 营业成本 | K4: ='PL-CF-BS'!G8 -> 10767 | L4: ='PL-CF-BS'!H8 -> 11227 | M4: ='PL-CF-BS'!I8 -> 11313.4 | N4: ='PL-CF-BS'!J8 -> 11781.795 | O4: ='PL-CF-BS'!K8 -> 12236.017 | P4: ='PL-CF-BS'!L8 -> 12728.929 | R4: Accounts Receivable | T4: =D4 -> 5601.8 | U4: =E4 -> 5500.3 | V4: =F4 -> 5775.649 | W4: =G4 -> 6082.9872 | X4: =H4 -> 6429.813 | Z4: Cost of Revenue | AA4: =K4 -> 10767 | AB4: =L4 -> 11227 | AC4: =M4 -> 11313.4 | AD4: =N4 -> 11781.795 | AE4: =O4 -> 12236.017 | AF4: =P4 -> 12728.929
B5: 存货净额 | C5: ='PL-CF-BS'!G107 -> 4482.4 | D5: ='PL-CF-BS'!H107 -> 4630.1 | E5: ='PL-CF-BS'!I107 -> 4543.3 | F5: ='PL-CF-BS'!J107 -> 4894.1616 | G5: ='PL-CF-BS'!K107 -> 5138.8791 | H5: ='PL-CF-BS'!L107 -> 5376.1661 | J5: 毛利 | K5: ='PL-CF-BS'!G9 -> 30415.6 | L5: ='PL-CF-BS'!H9 -> 32259.8 | M5: ='PL-CF-BS'!I9 -> 32738.6 | N5: ='PL-CF-BS'!J9 -> 34273.365 | O5: ='PL-CF-BS'!K9 -> 36162.269 | P5: ='PL-CF-BS'!L9 -> 38223.633 | R5: Net Inventories | T5: =D5 -> 4630.1 | U5: =E5 -> 4543.3 | V5: =F5 -> 4894.1616 | W5: =G5 -> 5138.8791 | X5: =H5 -> 5376.1661 | Z5: Gross Profit | AA5: =K5 -> 30415.6 | AB5: =L5 -> 32259.8 | AC5: =M5 -> 32738.6 | AD5: =N5 -> 34273.365 | AE5: =O5 -> 36162.269 | AF5: =P5 -> 38223.633
B6: 其他流动资产 | C6: ='PL-CF-BS'!G109 -> 2270.6 | D6: ='PL-CF-BS'!H109 -> 1955.3 | E6: ='PL-CF-BS'!I109 -> 2063.8 | F6: ='PL-CF-BS'!J109 -> 2063.8 | G6: ='PL-CF-BS'!K109 -> 2063.8 | H6: ='PL-CF-BS'!L109 -> 2063.8 | J6: 研究与创新费用 | K6: ='PL-CF-BS'!G12 -> 1288.9 | L6: ='PL-CF-BS'!H12 -> 1354.7 | M6: ='PL-CF-BS'!I12 -> 1380.6 | N6: ='PL-CF-BS'!J12 -> 1427.7099 | O6: ='PL-CF-BS'!K12 -> 1500.3469 | P6: ='PL-CF-BS'!L12 -> 1579.5294 | R6: Other Current Assets | T6: =D6 -> 1955.3 | U6: =E6 -> 2063.8 | V6: =F6 -> 2063.8 | W6: =G6 -> 2063.8 | X6: =H6 -> 2063.8 | Z6: Research and Innovation Expenses | AA6: =K6 -> 1288.9 | AB6: =L6 -> 1354.7 | AC6: =M6 -> 1380.6 | AD6: =N6 -> 1427.7099 | AE6: =O6 -> 1500.3469 | AF6: =P6 -> 1579.5294
B7: 流动资产合计 | C7: ='PL-CF-BS'!G113 -> 16325.3 | D7: ='PL-CF-BS'!H113 -> 16473.6 | E7: ='PL-CF-BS'!I113 -> 22198.4 | F7: ='PL-CF-BS'!J113 -> 25246.011 | G7: ='PL-CF-BS'!K113 -> 28724.991 | H7: ='PL-CF-BS'!L113 -> 33750.069 | J7: 广告及促销费用 | K7: ='PL-CF-BS'!G14 -> 13356.6 | L7: ='PL-CF-BS'!H14 -> 14008.9 | M7: ='PL-CF-BS'!I14 -> 14177.8 | N7: ='PL-CF-BS'!J14 -> 14645.541 | O7: ='PL-CF-BS'!K14 -> 15342.257 | P7: ='PL-CF-BS'!L14 -> 16151.962 | R7: Total Current Assets | T7: =D7 -> 16473.6 | U7: =E7 -> 22198.4 | V7: =F7 -> 25246.011 | W7: =G7 -> 28724.991 | X7: =H7 -> 33750.069 | Z7: Advertising and Promotion Expenses | AA7: =K7 -> 13356.6 | AB7: =L7 -> 14008.9 | AC7: =M7 -> 14177.8 | AD7: =N7 -> 14645.541 | AE7: =O7 -> 15342.257 | AF7: =P7 -> 16151.962
B8: 其他无形资产 | C8: ='PL-CF-BS'!G116 -> 4287.2 | D8: ='PL-CF-BS'!H116 -> 4594.8 | E8: ='PL-CF-BS'!I116 -> 5072 | F8: ='PL-CF-BS'!J116 -> 5072 | G8: ='PL-CF-BS'!K116 -> 5072 | H8: ='PL-CF-BS'!L116 -> 5072 | J8: 管理费用 | K8: ='PL-CF-BS'!G16 -> 7626.7 | L8: ='PL-CF-BS'!H16 -> 8208.7 | M8: ='PL-CF-BS'!I16 -> 8288.3 | N8: ='PL-CF-BS'!J16 -> 8704.4251 | O8: ='PL-CF-BS'!K16 -> 9098.8778 | P8: ='PL-CF-BS'!L16 -> 9528.1292 | R8: Other Intangible Assets | T8: =D8 -> 4594.8 | U8: =E8 -> 5072 | V8: =F8 -> 5072 | W8: =G8 -> 5072 | X8: =H8 -> 5072 | Z8: Administrative Expenses | AA8: =K9 -> -64.6 | AB8: =L8 -> 8208.7 | AC8: =M8 -> 8288.3 | AD8: =N8 -> 8704.4251 | AE8: =O8 -> 9098.8778 | AF8: =P8 -> 9528.1292
B9: 商誉 | C9: ='PL-CF-BS'!G115 -> 13102.6 | D9: ='PL-CF-BS'!H115 -> 13382 | E9: ='PL-CF-BS'!I115 -> 14469.7 | F9: ='PL-CF-BS'!J115 -> 16160.583 | G9: ='PL-CF-BS'!K115 -> 17582.694 | H9: ='PL-CF-BS'!L115 -> 19429.226 | J9: 财务费用 | K9: ='PL-CF-BS'!G29 -> -64.6 | L9: ='PL-CF-BS'!H29 -> -224.7 | M9: ='PL-CF-BS'!I29 -> -198.1 | N9: ='PL-CF-BS'!J29 -> -136 | O9: ='PL-CF-BS'!K29 -> -59.04 | P9: ='PL-CF-BS'!L29 -> -89.04 | R9: Goodwill | T9: =D9 -> 13382 | U9: =E9 -> 14469.7 | V9: =F9 -> 16160.583 | W9: =G9 -> 17582.694 | X9: =H9 -> 19429.226 | Z9: Finance Costs | AA9: =K10 -> 0 | AB9: =L9 -> -224.7 | AC9: =M9 -> -198.1 | AD9: =N9 -> -136 | AE9: =O9 -> -59.04 | AF9: =P9 -> -89.04
B10: 其他无形资产使用权资产 | C10: ='PL-CF-BS'!F117 -> 1482.7 | D10: ='PL-CF-BS'!G117 -> 1692.4 | E10: ='PL-CF-BS'!H117 -> 1763.2 | F10: ='PL-CF-BS'!I117 -> 1663.2 | G10: ='PL-CF-BS'!J117 -> 1663.2 | H10: ='PL-CF-BS'!K117 -> 1663.2 | J10: 其他费用/（-收入） | K10: ='PL-CF-BS'!G35 -> 0 | L10: ='PL-CF-BS'!H35 -> 0 | M10: ='PL-CF-BS'!I35 -> 0 | N10: ='PL-CF-BS'!J35 -> 0 | O10: ='PL-CF-BS'!K35 -> 0 | P10: ='PL-CF-BS'!L35 -> 0 | R10: Right-of-Use Assets | T10: =D10 -> 1692.4 | U10: =E10 -> 1763.2 | V10: =F10 -> 1663.2 | W10: =G10 -> 1663.2 | X10: =H10 -> 1663.2 | Z10: Other Expenses / (Income) | AA10: =K11 -> 0 | AB10: =L10 -> 0 | AC10: =M10 -> 0 | AD10: =N10 -> 0 | AE10: =O10 -> 0 | AF10: =P10 -> 0
B11: 不动产、厂房及设备 | C11: ='PL-CF-BS'!F118 -> 3481.7 | D11: ='PL-CF-BS'!G118 -> 3867.7 | E11: ='PL-CF-BS'!H118 -> 4202 | F11: ='PL-CF-BS'!I118 -> 4211.9 | G11: ='PL-CF-BS'!J118 -> 3947.0652 | H11: ='PL-CF-BS'!K118 -> 3677.6383 | J11: 营业外净收支 | K11: ='PL-CF-BS'!G39 -> 0 | L11: ='PL-CF-BS'!H39 -> 0 | M11: ='PL-CF-BS'!I39 -> 0 | N11: ='PL-CF-BS'!J39 -> 0 | O11: ='PL-CF-BS'!K39 -> 0 | P11: ='PL-CF-BS'!L39 -> 0 | R11: Property, Plant and Equipment (PPE) | T11: =D11 -> 3867.7 | U11: =E11 -> 4202 | V11: =F11 -> 4211.9 | W11: =G11 -> 3947.0652 | X11: =H11 -> 3677.6383 | Z11: Net Non-operating Income / (Loss) | AA11: =K12 -> 8000.9 | AB11: =L11 -> 0 | AC11: =M11 -> 0 | AD11: =N11 -> 0 | AE11: =O11 -> 0 | AF11: =P11 -> 0
B12: 非流动金融资产 | C12: ='PL-CF-BS'!F119 -> 11652.8 | D12: ='PL-CF-BS'!G119 -> 11631.6 | E12: ='PL-CF-BS'!H119 -> 14838.1 | F12: ='PL-CF-BS'!I119 -> 12867.3 | G12: ='PL-CF-BS'!J119 -> 12730.183 | H12: ='PL-CF-BS'!K119 -> 12490.461 | J12: 利润总额 | K12: ='PL-CF-BS'!G40 -> 8000.9 | L12: ='PL-CF-BS'!H40 -> 8432.9 | M12: ='PL-CF-BS'!I40 -> 8502.3 | N12: ='PL-CF-BS'!J40 -> 9207.3175 | O12: ='PL-CF-BS'!K40 -> 10003.167 | P12: ='PL-CF-BS'!L40 -> 10735.891 | R12: Non-current Financial Assets | T12: =D12 -> 11631.6 | U12: =E12 -> 14838.1 | V12: =F12 -> 12867.3 | W12: =G12 -> 12730.183 | X12: =H12 -> 12490.461 | Z12: Total Profit | AA12: =K13 -> 1810.6 | AB12: =L12 -> 8432.9 | AC12: =M12 -> 8502.3 | AD12: =N12 -> 9207.3175 | AE12: =O12 -> 10003.167 | AF12: =P12 -> 10735.891
B13: 对联营企业的投资 | C13: ='PL-CF-BS'!F120 -> 18.4 | D13: ='PL-CF-BS'!G120 -> 27 | E13: ='PL-CF-BS'!H120 -> 126.4 | F13: ='PL-CF-BS'!I120 -> 376 | G13: ='PL-CF-BS'!J120 -> 370.5 | H13: ='PL-CF-BS'!K120 -> 365 | J13: 所得税费用 | K13: ='PL-CF-BS'!G41 -> 1810.6 | L13: ='PL-CF-BS'!H41 -> 2015.1 | M13: ='PL-CF-BS'!I41 -> 2363.1 | N13: ='PL-CF-BS'!J41 -> 2409.2187 | O13: ='PL-CF-BS'!K41 -> 2609.067 | P13: ='PL-CF-BS'!L41 -> 2791.8224 | R13: Investment in Associates | T13: =D13 -> 27 | U13: =E13 -> 126.4 | V13: =F13 -> 376 | W13: =G13 -> 370.5 | X13: =H13 -> 365 | Z13: Income Tax Expense | AA13: =K14 -> 6184 | AB13: =L13 -> 2015.1 | AC13: =M13 -> 2363.1 | AD13: =N13 -> 2409.2187 | AE13: =O13 -> 2609.067 | AF13: =P13 -> 2791.8224
B14: 递延税项资产 | C14: ='PL-CF-BS'!F121 -> 801.1 | D14: ='PL-CF-BS'!G121 -> 921.2 | E14: ='PL-CF-BS'!H121 -> 973.3 | F14: ='PL-CF-BS'!I121 -> 962.7 | G14: ='PL-CF-BS'!J121 -> 962.7 | H14: ='PL-CF-BS'!K121 -> 962.7 | J14: 净利润 | K14: ='PL-CF-BS'!G49 -> 6184 | L14: ='PL-CF-BS'!H49 -> 6408.7 | M14: ='PL-CF-BS'!I49 -> 6127.2 | N14: ='PL-CF-BS'!J49 -> 6786.0987 | O14: ='PL-CF-BS'!K49 -> 7382.0999 | P14: ='PL-CF-BS'!L49 -> 7932.0682 | R14: Deferred Tax Assets | T14: =D14 -> 921.2 | U14: =E14 -> 973.3 | V14: =F14 -> 962.7 | W14: =G14 -> 962.7 | X14: =H14 -> 962.7 | Z14: Net Profit | AA14: =K15 -> -6.5 | AB14: =L14 -> 6408.7 | AC14: =M14 -> 6127.2 | AD14: =N14 -> 6786.0987 | AE14: =O14 -> 7382.0999 | AF14: =P14 -> 7932.0682
B15: 非流动资产合计 | C15: ='PL-CF-BS'!G123 -> 35529.7 | D15: ='PL-CF-BS'!H123 -> 39879.8 | E15: ='PL-CF-BS'!I123 -> 39622.8 | F15: ='PL-CF-BS'!J123 -> 40906.232 | G15: ='PL-CF-BS'!K123 -> 41813.694 | H15: ='PL-CF-BS'!L123 -> 42407.635 | J15: 少数股东损益 | K15: ='PL-CF-BS'!G47 -> -6.5 | L15: ='PL-CF-BS'!H47 -> -7.8 | M15: ='PL-CF-BS'!I47 -> -6.5 | N15: ='PL-CF-BS'!J47 -> -6.5 | O15: ='PL-CF-BS'!K47 -> -6.5 | P15: ='PL-CF-BS'!L47 -> -6.5 | R15: Total Non-current Assets | T15: =D15 -> 39879.8 | U15: =E15 -> 39622.8 | V15: =F15 -> 40906.232 | W15: =G15 -> 41813.694 | X15: =H15 -> 42407.635 | Z15: Minority Interest | AA15: =K16 -> 6184 | AB15: =L15 -> -7.8 | AC15: =M15 -> -6.5 | AD15: =N15 -> -6.5 | AE15: =O15 -> -6.5 | AF15: =P15 -> -6.5
B16: 资产总计 | C16: ='PL-CF-BS'!G125 -> 51855 | D16: ='PL-CF-BS'!H125 -> 56353.4 | E16: ='PL-CF-BS'!I125 -> 61821.2 | F16: ='PL-CF-BS'!J125 -> 66152.243 | G16: ='PL-CF-BS'!K125 -> 70538.685 | H16: ='PL-CF-BS'!L125 -> 76157.704 | J16: 归母净利润 | K16: ='PL-CF-BS'!G49 -> 6184 | L16: ='PL-CF-BS'!H49 -> 6408.7 | M16: ='PL-CF-BS'!I49 -> 6127.2 | N16: ='PL-CF-BS'!J49 -> 6786.0987 | O16: ='PL-CF-BS'!K49 -> 7382.0999 | P16: ='PL-CF-BS'!L49 -> 7932.0682 | R16: Total Assets | T16: =D16 -> 56353.4 | U16: =E16 -> 61821.2 | V16: =F16 -> 66152.243 | W16: =G16 -> 70538.685 | X16: =H16 -> 76157.704 | Z16: Net Profit Attributable to Owners of the Parent | AB16: =L16 -> 6408.7 | AC16: =M16 -> 6127.2 | AD16: =N16 -> 6786.0987 | AE16: =O16 -> 7382.0999 | AF16: =P16 -> 7932.0682
T17: =D17 -> 0 | U17: =E17 -> 0 | V17: =F17 -> 0 | W17: =G17 -> 0 | X17: =H17 -> 0
B18: 应付账款 | C18: ='PL-CF-BS'!G128 -> 6347 | D18: ='PL-CF-BS'!H128 -> 6468.3 | E18: ='PL-CF-BS'!I128 -> 6727.7 | F18: ='PL-CF-BS'!J128 -> 7155.0559 | G18: ='PL-CF-BS'!K128 -> 7392.1166 | H18: ='PL-CF-BS'!L128 -> 7764.6223 | J18: 财务指标 | K18: 2023 | L18: 2024 | M18: 2025 | N18: 2026E | O18: 2027E | P18: 2028E | R18: Accounts Payable | T18: =D18 -> 6468.3 | U18: =E18 -> 6727.7 | V18: =F18 -> 7155.0559 | W18: =G18 -> 7392.1166 | X18: =H18 -> 7764.6223 | Z18: Financial Ratios | AA18: =K18 -> 2023 | AB18: =L18 -> 2024 | AC18: =M18 -> 2025 | AD18: =N18 -> 2026E | AE18: =O18 -> 2027E | AF18: 2028E
B19: 负债及费用准备金其他流动负债 | C19: ='PL-CF-BS'!G129 -> 977.1 | D19: ='PL-CF-BS'!H129 -> 1093.1 | E19: ='PL-CF-BS'!I129 -> 1117.7 | F19: ='PL-CF-BS'!J129 -> 1117.7 | G19: ='PL-CF-BS'!K129 -> 1117.7 | H19: ='PL-CF-BS'!L129 -> 1117.7 | J19: 盈利能力 | R19: Provisions and Other Current Liabilities | T19: =D19 -> 1093.1 | U19: =E19 -> 1117.7 | V19: =F19 -> 1117.7 | W19: =G19 -> 1117.7 | X19: =H19 -> 1117.7 | Z19: Profitability ratios
B20: 其他流动负债 | C20: ='PL-CF-BS'!G130 -> 4816.1 | D20: ='PL-CF-BS'!H130 -> 4949.6 | E20: ='PL-CF-BS'!I130 -> 4782.9 | F20: ='PL-CF-BS'!J130 -> 4782.9 | G20: ='PL-CF-BS'!K130 -> 4782.9 | H20: ='PL-CF-BS'!L130 -> 4782.9 | J20: ROE | K20: ='PL-CF-BS'!G170 -> 0.21986461 | L20: ='PL-CF-BS'!H170 -> 0.20604235 | M20: ='PL-CF-BS'!I170 -> 0.17998282 | N20: ='PL-CF-BS'!J170 -> 0.18762282 | O20: ='PL-CF-BS'!K170 -> 0.19010214 | P20: ='PL-CF-BS'!L170 -> 0.18910157 | R20: Other Current Liabilities | T20: =D20 -> 4949.6 | U20: =E20 -> 4782.9 | V20: =F20 -> 4782.9 | W20: =G20 -> 4782.9 | X20: =H20 -> 4782.9 | Z20: ROE | AA20: =K20 -> 0.21986461 | AB20: =L20 -> 0.20604235 | AC20: =M20 -> 0.17998282 | AD20: =N20 -> 0.18762282 | AE20: =O20 -> 0.19010214 | AF20: =P20 -> 0.18910157
B21: 所得税 | C21: ='PL-CF-BS'!G131 -> 208.1 | D21: ='PL-CF-BS'!H131 -> 275.1 | E21: ='PL-CF-BS'!I131 -> 254.8 | F21: ='PL-CF-BS'!J131 -> 254.8 | G21: ='PL-CF-BS'!K131 -> 254.8 | H21: ='PL-CF-BS'!L131 -> 254.8 | J21: 毛利率 | K21: ='PL-CF-BS'!G165 -> 0.73855463 | L21: ='PL-CF-BS'!H165 -> 0.7418297 | M21: ='PL-CF-BS'!I165 -> 0.74318079 | N21: ='PL-CF-BS'!J165 -> 0.74418079 | O21: ='PL-CF-BS'!K165 -> 0.74718079 | P21: ='PL-CF-BS'!L165 -> 0.75018079 | R21: Income Tax Payable | T21: =D21 -> 275.1 | U21: =E21 -> 254.8 | V21: =F21 -> 254.8 | W21: =G21 -> 254.8 | X21: =H21 -> 254.8 | Z21: Gross profit margin | AA21: =K21 -> 0.73855463 | AB21: =L21 -> 0.7418297 | AC21: =M21 -> 0.74318079 | AD21: =N21 -> 0.74418079 | AE21: =O21 -> 0.74718079 | AF21: =P21 -> 0.75018079
B22: 当前借款及债务 | C22: ='PL-CF-BS'!G132 -> 2091.5 | D22: ='PL-CF-BS'!H132 -> 1381.3 | E22: ='PL-CF-BS'!I132 -> 2048.9 | F22: ='PL-CF-BS'!J132 -> 979.13333 | G22: ='PL-CF-BS'!K132 -> -172.65556 | H22: ='PL-CF-BS'!L132 -> -1116.4074 | I22: ='PL-CF-BS'!M132 -> -2171.5099 | J22: 营业利润率 | K22: ='PL-CF-BS'!G167 -> 0.5517403 | L22: ='PL-CF-BS'!H167 -> 0.55212156 | M22: ='PL-CF-BS'!I167 -> 0.5528035 | N22: ='PL-CF-BS'!J167 -> 0.54823881 | O22: ='PL-CF-BS'!K167 -> 0.54609282 | P22: ='PL-CF-BS'!L167 -> 0.54442077 | R22: Current Borrowings and Debt | T22: =D22 -> 1381.3 | U22: =E22 -> 2048.9 | V22: =F22 -> 979.13333 | W22: =G22 -> -172.65556 | X22: =H22 -> -1116.4074 | Z22: Operating profit margin | AA22: =K22 -> 0.5517403 | AB22: =L22 -> 0.55212156 | AC22: =M22 -> 0.5528035 | AD22: =N22 -> 0.54823881 | AE22: =O22 -> 0.54609282 | AF22: =P22 -> 0.54442077
B23: 当前租赁债务 | C23: ='PL-CF-BS'!G133 -> 459.8 | D23: ='PL-CF-BS'!H133 -> 468.6 | E23: ='PL-CF-BS'!I133 -> 434.5 | F23: ='PL-CF-BS'!J133 -> 434.5 | G23: ='PL-CF-BS'!K133 -> 434.5 | H23: ='PL-CF-BS'!L133 -> 434.5 | J23: 归母净利率 | K23: ='PL-CF-BS'!G169 -> 0.1501605 | L23: ='PL-CF-BS'!H169 -> 0.14737116 | M23: ='PL-CF-BS'!I169 -> 0.13909017 | N23: ='PL-CF-BS'!J169 -> 0.1473472 | O23: ='PL-CF-BS'!K169 -> 0.15252813 | P23: ='PL-CF-BS'!L169 -> 0.15567555 | R23: Current Lease Liabilities | T23: =D23 -> 468.6 | U23: =E23 -> 434.5 | V23: =F23 -> 434.5 | W23: =G23 -> 434.5 | X23: =H23 -> 434.5 | Z23: Net profit margin | AA23: =K23 -> 0.1501605 | AB23: =L23 -> 0.14737116 | AC23: =M23 -> 0.13909017 | AD23: =N23 -> 0.1473472 | AE23: =O23 -> 0.15252813 | AF23: =P23 -> 0.15567555
B24: 流动负债合计 | C24: ='PL-CF-BS'!G136 -> 14899.6 | D24: ='PL-CF-BS'!H136 -> 14636 | E24: ='PL-CF-BS'!I136 -> 15366.5 | F24: ='PL-CF-BS'!J136 -> 14724.089 | G24: ='PL-CF-BS'!K136 -> 13809.361 | H24: ='PL-CF-BS'!L136 -> 13238.115 | I24: ='PL-CF-BS'!K155 -> 40280.096 | J24: 成长能力 | R24: Total Current Liabilities | T24: =D24 -> 14636 | U24: =E24 -> 15366.5 | V24: =F24 -> 14724.089 | W24: =G24 -> 13809.361 | X24: =H24 -> 13238.115 | Z24: Growth rates
B25: 员工退休义务准备金 | C25: ='PL-CF-BS'!G138 -> 562 | D25: ='PL-CF-BS'!H138 -> 668.9 | E25: ='PL-CF-BS'!I138 -> 684 | F25: ='PL-CF-BS'!J138 -> 684 | G25: ='PL-CF-BS'!K138 -> 684 | H25: ='PL-CF-BS'!L138 -> 684 | J25: 营业收入增长率 | K25: ='PL-CF-BS'!G7 -> 0.076368179 | L25: ='PL-CF-BS'!H7 -> 0.055950814 | M25: ='PL-CF-BS'!I7 -> 0.012997047 | N25: ='PL-CF-BS'!J7 -> 0.045472611 | O25: ='PL-CF-BS'!K7 -> 0.05087653 | P25: ='PL-CF-BS'!L7 -> 0.052776175 | R25: Employee Retirement Benefit Obligations | T25: =D25 -> 668.9 | U25: =E25 -> 684 | V25: =F25 -> 684 | W25: =G25 -> 684 | X25: =H25 -> 684 | Z25: Revenue growth rate | AA25: =K25 -> 0.076368179 | AB25: =L25 -> 0.055950814 | AC25: =M25 -> 0.012997047 | AD25: =N25 -> 0.045472611 | AE25: =O25 -> 0.05087653 | AF25: =P25 -> 0.052776175
B26: 负债及费用及其他项目的准备金 | C26: ='PL-CF-BS'!G139 -> 68.8 | D26: ='PL-CF-BS'!H139 -> 76.8 | E26: ='PL-CF-BS'!I139 -> 84.5 | F26: ='PL-CF-BS'!J139 -> 84.5 | G26: ='PL-CF-BS'!K139 -> 84.5 | H26: ='PL-CF-BS'!L139 -> 84.5 | J26: 营业利润增长率 | K26: ='PL-CF-BS'!G10 -> 0.098698493 | L26: ='PL-CF-BS'!H10 -> 0.060633359 | M26: ='PL-CF-BS'!I10 -> 0.014842002 | N26: ='PL-CF-BS'!J10 -> 0.046879365 | O26: ='PL-CF-BS'!K10 -> 0.055112906 | P26: ='PL-CF-BS'!L10 -> 0.057003169 | R26: Provisions and Other Liabilities | T26: =D26 -> 76.8 | U26: =E26 -> 84.5 | V26: =F26 -> 84.5 | W26: =G26 -> 84.5 | X26: =H26 -> 84.5 | Z26: Operating profit growth rate | AA26: =K26 -> 0.098698493 | AB26: =L26 -> 0.060633359 | AC26: =M26 -> 0.014842002 | AD26: =N26 -> 0.046879365 | AE26: =O26 -> 0.055112906 | AF26: =P26 -> 0.057003169
B27: 递延税项负债 | C27: ='PL-CF-BS'!G140 -> 1102.2 | D27: ='PL-CF-BS'!H140 -> 1188.8 | E27: ='PL-CF-BS'!I140 -> 1249.8 | F27: ='PL-CF-BS'!J140 -> 1249.8 | G27: ='PL-CF-BS'!K140 -> 1249.8 | H27: ='PL-CF-BS'!L140 -> 1249.8 | J27: 净利润增长率 | K27: ='PL-CF-BS'!G50 -> 0.083657519 | L27: ='PL-CF-BS'!H50 -> 0.036335705 | M27: ='PL-CF-BS'!I50 -> -0.043924665 | N27: ='PL-CF-BS'!J50 -> 0.10753668 | O27: ='PL-CF-BS'!K50 -> 0.08782678 | P27: ='PL-CF-BS'!L50 -> 0.074500252 | R27: Deferred Tax Liabilities | T27: =D27 -> 1188.8 | U27: =E27 -> 1249.8 | V27: =F27 -> 1249.8 | W27: =G27 -> 1249.8 | X27: =H27 -> 1249.8 | Z27: Net profit growth rate | AA27: =K27 -> 0.083657519 | AB27: =L27 -> 0.036335705 | AC27: =M27 -> -0.043924665 | AD27: =N27 -> 0.10753668 | AE27: =O27 -> 0.08782678 | AF27: =P27 -> 0.074500252
B28: 非流动负债及债务 | C28: ='PL-CF-BS'!G141 -> 4746.7 | D28: ='PL-CF-BS'!H141 -> 5187.1 | E28: ='PL-CF-BS'!I141 -> 8069.7 | F28: ='PL-CF-BS'!J141 -> 11110.8 | G28: ='PL-CF-BS'!K141 -> 13976.567 | H28: ='PL-CF-BS'!L141 -> 17290.422 | J28: 偿债能力 | R28: Non-current Borrowings and Debt | T28: =D28 -> 5187.1 | U28: =E28 -> 8069.7 | V28: =F28 -> 11110.8 | W28: =G28 -> 13976.567 | X28: =H28 -> 17290.422 | Z28: Liquidity & Solvency ratio
B29: 非流动租赁债务 | C29: ='PL-CF-BS'!G142 -> 1394.2 | D29: ='PL-CF-BS'!H142 -> 1458 | E29: ='PL-CF-BS'!I142 -> 1362.9 | F29: ='PL-CF-BS'!J142 -> 910.08333 | G29: ='PL-CF-BS'!K142 -> 449.86111 | H29: ='PL-CF-BS'!L142 -> -5.6851852 | J29: 流动比 | K29: ='PL-CF-BS'!G113/'PL-CF-BS'!G136 -> 1.0956871 | L29: ='PL-CF-BS'!H113/'PL-CF-BS'!H136 -> 1.1255534 | M29: ='PL-CF-BS'!I113/'PL-CF-BS'!I136 -> 1.444597 | N29: ='PL-CF-BS'!J113/'PL-CF-BS'!J136 -> 1.7146059 | O29: ='PL-CF-BS'!K113/'PL-CF-BS'!K136 -> 2.0801101 | P29: ='PL-CF-BS'!L113/'PL-CF-BS'!L136 -> 2.5494618 | R29: Non-current Lease Liabilities | T29: =D29 -> 1458 | U29: =E29 -> 1362.9 | V29: =F29 -> 910.08333 | W29: =G29 -> 449.86111 | X29: =H29 -> -5.6851852 | Z29: Current ratio | AA29: =K29 -> 1.0956871 | AB29: =L29 -> 1.1255534 | AC29: =M29 -> 1.444597 | AD29: =N29 -> 1.7146059 | AE29: =O29 -> 2.0801101 | AF29: =P29 -> 2.5494618
B30: 长期负债合计 | C30: ='PL-CF-BS'!G143 -> 7873.9 | D30: ='PL-CF-BS'!H143 -> 8579.6 | E30: ='PL-CF-BS'!I143 -> 11450.9 | F30: ='PL-CF-BS'!J143 -> 14039.183 | G30: ='PL-CF-BS'!K143 -> 16444.728 | H30: ='PL-CF-BS'!L143 -> 19303.037 | J30: 速动比 | K30: =('PL-CF-BS'!G113-'PL-CF-BS'!G108)/'PL-CF-BS'!G136 -> 0.75388601 | L30: =('PL-CF-BS'!H113-'PL-CF-BS'!H108)/'PL-CF-BS'!H136 -> 0.74281224 | M30: =('PL-CF-BS'!I113-'PL-CF-BS'!I108)/'PL-CF-BS'!I136 -> 1.086656 | N30: =('PL-CF-BS'!J113-'PL-CF-BS'!J108)/'PL-CF-BS'!J136 -> 1.3223475 | O30: =('PL-CF-BS'!K113-'PL-CF-BS'!K108)/'PL-CF-BS'!K136 -> 1.6396127 | P30: =('PL-CF-BS'!L113-'PL-CF-BS'!L108)/'PL-CF-BS'!L136 -> 2.0637572 | R30: Total Non-current Liabilities | T30: =D30 -> 8579.6 | U30: =E30 -> 11450.9 | V30: =F30 -> 14039.183 | W30: =G30 -> 16444.728 | X30: =H30 -> 19303.037 | Z30: Quick ratio | AA30: =K30 -> 0.75388601 | AB30: =L30 -> 0.74281224 | AC30: =M30 -> 1.086656 | AD30: =N30 -> 1.3223475 | AE30: =O30 -> 1.6396127 | AF30: =P30 -> 2.0637572
B31: 负债合计 | C31: ='PL-CF-BS'!G145 -> 22773.5 | D31: ='PL-CF-BS'!H145 -> 23215.6 | E31: ='PL-CF-BS'!I145 -> 26817.4 | F31: ='PL-CF-BS'!J145 -> 28763.273 | G31: ='PL-CF-BS'!K145 -> 30254.089 | H31: ='PL-CF-BS'!L145 -> 32541.152 | R31: Total Liabilities | T31: =D31 -> 23215.6 | U31: =E31 -> 26817.4 | V31: =F31 -> 28763.273 | W31: =G31 -> 30254.089 | X31: =H31 -> 32541.152
B32: 股本 | C32: ='PL-CF-BS'!G148 -> 106.9 | D32: ='PL-CF-BS'!H148 -> 106.9 | E32: ='PL-CF-BS'!I148 -> 106.8 | F32: ='PL-CF-BS'!J148 -> 152.46667 | G32: ='PL-CF-BS'!K148 -> 212.85556 | H32: ='PL-CF-BS'!L148 -> 270.07407 | J32: 每股指标与估值 | K32: =K18 -> 2023 | L32: =L18 -> 2024 | M32: =M18 -> 2025 | N32: =N18 -> 2026E | O32: =O18 -> 2027E | P32: 2028E | R32: Share Capital | T32: =D32 -> 106.9 | U32: =E32 -> 106.8 | V32: =F32 -> 152.46667 | W32: =G32 -> 212.85556 | X32: =H32 -> 270.07407 | Z32: Valuation | AA32: =K32 -> 2023 | AB32: =L32 -> 2024 | AC32: =M32 -> 2025 | AD32: =N32 -> 2026E | AE32: =O32 -> 2027E | AF32: 2028E
B33: 额外实收资本 | C33: ='PL-CF-BS'!G149 -> 3370.2 | D33: ='PL-CF-BS'!H149 -> 3444.3 | E33: ='PL-CF-BS'!I149 -> 3509.8 | F33: ='PL-CF-BS'!J149 -> 3509.8 | G33: ='PL-CF-BS'!K149 -> 3444.3 | H33: ='PL-CF-BS'!L149 -> 3444.3 | J33: 每股指标 | R33: Additional Paid-in Capital | T33: =D33 -> 3444.3 | U33: =E33 -> 3509.8 | V33: =F33 -> 3509.8 | W33: =G33 -> 3444.3 | X33: =H33 -> 3444.3 | Z33: Per share
B34: 其他储备金 | C34: ='PL-CF-BS'!G150 -> 13799.1 | D34: ='PL-CF-BS'!H150 -> 16144.8 | E34: ='PL-CF-BS'!I150 -> 18166.5 | F34: ='PL-CF-BS'!J150 -> 18166.5 | G34: ='PL-CF-BS'!K150 -> 18166.5 | H34: ='PL-CF-BS'!L150 -> 18166.5 | J34: EPS | K34: ='PL-CF-BS'!G58 -> 11.549062 | L34: ='PL-CF-BS'!H58 -> 11.994302 | M34: ='PL-CF-BS'!I58 -> 11.48238 | N34: ='PL-CF-BS'!J58 -> 12.749256 | O34: ='PL-CF-BS'!K58 -> 13.901774 | P34: ='PL-CF-BS'!L58 -> 14.970541 | R34: Other Reserves | T34: =D34 -> 16144.8 | U34: =E34 -> 18166.5 | V34: =F34 -> 18166.5 | W34: =G34 -> 18166.5 | X34: =H34 -> 18166.5 | Z34: EPS | AA34: =K34 -> 11.549062 | AB34: =L34 -> 11.994302 | AC34: =M34 -> 11.48238 | AD34: =N34 -> 12.749256 | AE34: =O34 -> 13.901774 | AF34: =P34 -> 14.970541
B35: 其他综合收益 | C35: ='PL-CF-BS'!G153 -> 12307.8 | D35: ='PL-CF-BS'!H153 -> 13686.5 | E35: ='PL-CF-BS'!I153 -> 13919.3 | F35: ='PL-CF-BS'!J153 -> 15804.904 | G35: ='PL-CF-BS'!K153 -> 18705.64 | H35: ='PL-CF-BS'!L153 -> 21980.378 | J35: BVPS | K35: ='PL-CF-BS'!G155/'PL-CF-BS'!G55 -> 54.298332 | L35: ='PL-CF-BS'!H155/'PL-CF-BS'!H55 -> 62.011145 | M35: ='PL-CF-BS'!I155/'PL-CF-BS'!I55 -> 65.50234 | N35: ='PL-CF-BS'!J155/'PL-CF-BS'!J55 -> 70.235371 | O35: ='PL-CF-BS'!K155/'PL-CF-BS'!K55 -> 75.854404 | P35: ='PL-CF-BS'!L155/'PL-CF-BS'!L55 -> 82.310943 | R35: Other Comprehensive Income (OCI) | T35: =D35 -> 13686.5 | U35: =E35 -> 13919.3 | V35: =F35 -> 15804.904 | W35: =G35 -> 18705.64 | X35: =H35 -> 21980.378 | Z35: BVPS | AA35: =K35 -> 54.298332 | AB35: =L35 -> 62.011145 | AC35: =M35 -> 65.50234 | AD35: =N35 -> 70.235371 | AE35: =O35 -> 75.854404 | AF35: =P35 -> 82.310943
B36: 归属于公司所有者的净利润 | C36: ='PL-CF-BS'!#REF! -> #REF! | D36: ='PL-CF-BS'!#REF! -> #REF! | E36: ='PL-CF-BS'!#REF! -> #REF! | F36: ='PL-CF-BS'!#REF! -> #REF! | G36: ='PL-CF-BS'!#REF! -> #REF! | H36: ='PL-CF-BS'!#REF! -> #REF! | J36: 估值 | R36: Net Income Attributable to Owners of the Company | T36: =T37+T38 -> 33142.3 | U36: =U37+U38 -> 35054.4 | V36: =V37+V38 -> 37393.47 | W36: =W37+W38 -> 40289.096 | X36: =X37+X38 -> 43621.052 | Z36: Valuation ratios
B37: 归母股东权益 | C37: ='PL-CF-BS'!G159 -> 29081.6 | D37: ='PL-CF-BS'!H159 -> 33137.8 | E37: ='PL-CF-BS'!I159 -> 35003.8 | F37: ='PL-CF-BS'!J159 -> 37388.97 | G37: ='PL-CF-BS'!K159 -> 40284.596 | H37: ='PL-CF-BS'!L159 -> 43616.552 | J37: P/E | K37: =K41/K34 -> 31.331549 | L37: =L41/L34 -> 30.16849 | M37: =M41/M34 -> 31.5135 | N37: =N41/N34 -> 28.382049 | O37: =O41/O34 -> 26.029052 | P37: =P41/P34 -> 24.170803 | R37: Equity Attributable to Owners of the Company | T37: =D37 -> 33137.8 | U37: =E37 -> 35003.8 | V37: =F37 -> 37388.97 | W37: =G37 -> 40284.596 | X37: =H37 -> 43616.552 | Z37: P/E | AA37: =K37 -> 31.331549 | AB37: =L37 -> 30.16849 | AC37: =M37 -> 31.5135 | AD37: =N37 -> 28.382049 | AE37: =O37 -> 26.029052 | AF37: =P37 -> 24.170803
B38: 少数股东权益 | C38: ='PL-CF-BS'!G158 -> 7.3 | D38: ='PL-CF-BS'!H158 -> 4.5 | E38: ='PL-CF-BS'!I158 -> 50.6 | F38: ='PL-CF-BS'!J158 -> 4.5 | G38: ='PL-CF-BS'!K158 -> 4.5 | H38: ='PL-CF-BS'!L158 -> 4.5 | J38: P/B | K38: =K41/K35 -> 6.6641089 | L38: =L41/L35 -> 5.8352414 | M38: =M41/M35 -> 5.5242301 | N38: =N41/N35 -> 5.1519625 | O38: =O41/O35 -> 4.7703229 | P38: =P41/P35 -> 4.3961348 | R38: Non-controlling Interests | T38: =D38 -> 4.5 | U38: =E38 -> 50.6 | V38: =F38 -> 4.5 | W38: =G38 -> 4.5 | X38: =H38 -> 4.5 | Z38: P/B | AA38: =K38 -> 6.6641089 | AB38: =L38 -> 5.8352414 | AC38: =M38 -> 5.5242301 | AD38: =N38 -> 5.1519625 | AE38: =O38 -> 4.7703229 | AF38: =P38 -> 4.3961348
B39: 权益总计 | C39: ='PL-CF-BS'!G159 -> 29081.6 | D39: ='PL-CF-BS'!H159 -> 33137.8 | E39: ='PL-CF-BS'!I159 -> 35003.8 | F39: ='PL-CF-BS'!J159 -> 37388.97 | G39: ='PL-CF-BS'!K159 -> 40284.596 | H39: ='PL-CF-BS'!L159 -> 43616.552 | J39: P/S | K39: =K41*'PL-CF-BS'!G55/'PL-CF-BS'!G6 -> 4.7047613 | L39: =L41*'PL-CF-BS'!H55/'PL-CF-BS'!H6 -> 4.4459653 | M39: =M41*'PL-CF-BS'!I55/'PL-CF-BS'!I6 -> 4.383218 | N39: =N41*'PL-CF-BS'!J55/'PL-CF-BS'!J6 -> 4.1820155 | O39: =O41*'PL-CF-BS'!K55/'PL-CF-BS'!K6 -> 3.9701625 | P39: =P41*'PL-CF-BS'!L55/'PL-CF-BS'!L6 -> 3.762803 | R39: Total Equity | T39: =D39 -> 33137.8 | U39: =E39 -> 35003.8 | V39: =F39 -> 37388.97 | W39: =G39 -> 40284.596 | X39: =H39 -> 43616.552 | Z39: P/S | AA39: =K39 -> 4.7047613 | AB39: =L39 -> 4.4459653 | AC39: =M39 -> 4.383218 | AD39: =N39 -> 4.1820155 | AE39: =O39 -> 3.9701625 | AF39: =P39 -> 3.762803
B40: 负债和股东权益总计 | C40: ='PL-CF-BS'!G159+'PL-CF-BS'!G145 -> 51855.1 | D40: ='PL-CF-BS'!H159+'PL-CF-BS'!H145 -> 56353.4 | E40: ='PL-CF-BS'!I159+'PL-CF-BS'!I145 -> 61821.2 | F40: ='PL-CF-BS'!J159+'PL-CF-BS'!J145 -> 66152.243 | G40: ='PL-CF-BS'!K159+'PL-CF-BS'!K145 -> 70538.685 | H40: ='PL-CF-BS'!L159+'PL-CF-BS'!L145 -> 76157.704 | R40: Total Liabilities and Equity | T40: =D40 -> 56353.4 | U40: =E40 -> 61821.2 | V40: =F40 -> 66152.243 | W40: =G40 -> 70538.685 | X40: =H40 -> 76157.704
K41: 361.85 | L41: 361.85 | M41: 361.85 | N41: 361.85 | O41: 361.85 | P41: 361.85
...

Sheet DCF 
A1: 1
C2: Discounted Cash Flow
C3: CNY mn
C4: Free cashflow forecast | E4: 2023 | F4: 2024 | G4: 2025E | H4: 2026E | I4: 2027E | J4: 2028E | K4: 2029E | L4: 2030E | M4: 2031E | N4: 2032E
C5: Net Revenue | E5: ='PL-CF-BS'!G6 -> 41182.6 | F5: ='PL-CF-BS'!H6 -> 43486.8 | G5: ='PL-CF-BS'!I6 -> 44052 | H5: ='PL-CF-BS'!J6 -> 46055.159 | I5: ='PL-CF-BS'!K6 -> 48398.286 | J5: ='PL-CF-BS'!L6 -> 50952.563 | K5: ='PL-CF-BS'!M6 -> 53661.992 | L5: ='PL-CF-BS'!N6 -> 56524.137 | ... N5: ='PL-CF-BS'!P6 -> 62743.114
D6: YoY | F6: =F5/E5-1 -> 0.055950814 | G6: =G5/F5-1 -> 0.012997047 | H6: =H5/G5-1 -> 0.045472611 | I6: =I5/H5-1 -> 0.05087653 | J6: =J5/I5-1 -> 0.052776175 | K6: =K5/J5-1 -> 0.05317553 | L6: =L5/K5-1 -> 0.05333654 | M6: =M5/L5-1 -> 0.053496771 | N6: =N5/M5-1 -> 0.053656185
C7: EBIT | E7: ='PL-CF-BS'!G22-'PL-CF-BS'!G39 -> 7693.4 | F7: ='PL-CF-BS'!H22-'PL-CF-BS'!H39 -> 8249.8 | G7: ='PL-CF-BS'!I22-'PL-CF-BS'!I39 -> 8386.5 | H7: ='PL-CF-BS'!J22-'PL-CF-BS'!J39 -> 9024.139 | I7: ='PL-CF-BS'!K22-'PL-CF-BS'!K39 -> 9732.3131 | J7: ='PL-CF-BS'!L22-'PL-CF-BS'!L39 -> 10484 | K7: ='PL-CF-BS'!M22-'PL-CF-BS'!M39 -> 11277.434 | L7: ='PL-CF-BS'!N22-'PL-CF-BS'!N39 -> 12132.973 | ... N7: ='PL-CF-BS'!P22-'PL-CF-BS'!P39 -> 14022.345
D8: YoY | F8: =F7/E7-1 -> 0.07232173 | G8: =G7/F7-1 -> 0.016570099 | H8: =H7/G7-1 -> 0.076031597 | I8: =I7/H7-1 -> 0.078475535 | J8: =J7/I7-1 -> 0.077236197 | K8: =K7/J7-1 -> 0.075680455 | L8: =L7/K7-1 -> 0.075862946 | M8: =M7/L7-1 -> 0.075167178 | N8: =N7/M7-1 -> 0.07492317
D9: EBIT Margin | E9: =E7/E5 -> 0.18681191 | F9: =F7/F5 -> 0.18970814 | G9: =G7/G5 -> 0.19037728 | H9: =H7/H5 -> 0.19594198 | I9: =I7/I5 -> 0.20108797 | J9: =J7/J5 -> 0.20576001 | K9: =K7/K5 -> 0.21015682 | L9: =L7/L5 -> 0.21465119 | ... N9: =N7/N5 -> 0.2234882
C10: EBIT*(1 - t) | E10: =E7*(1-年度版model!B68) -> 5337.3549 | F10: =F7*(1-$L$16) -> 6187.35 | G10: =G7*(1-$L$16) -> 6289.875 | H10: =H7*(1-$L$16) -> 6768.1042 | I10: =I7*(1-$L$16) -> 7299.2348 | J10: =J7*(1-$L$16) -> 7863 | K10: =K7*(1-$L$16) -> 8458.0754 | L10: =L7*(1-$L$16) -> 9099.7299 | M10: =M7*(1-$L$16) -> 9783.7309 | N10: =N7*(1-$L$16) -> 10516.759
C11: + | D11: Depreciation and Amortization | E11: ='PL-CF-BS'!G73 -> 1715 | F11: ='PL-CF-BS'!H73 -> 1855.3 | G11: ='PL-CF-BS'!I73 -> 1817.4 | H11: ='PL-CF-BS'!J73 -> 1900.0419 | I11: ='PL-CF-BS'!K73 -> 1996.7095 | J11: ='PL-CF-BS'!L73 -> 2102.0882 | K11: ='PL-CF-BS'!M73 -> 2213.8678 | L11: ='PL-CF-BS'!N73 -> 2331.9478 | ... N11: ='PL-CF-BS'!P73 -> 2588.5167
C12: - | D12: Change in working capital | E12: ='PL-CF-BS'!G74 -> -394.9 | F12: ='PL-CF-BS'!H74 -> -226.6 | G12: ='PL-CF-BS'!I74 -> 327.4 | H12: ='PL-CF-BS'!J74 -> -198.85467 | I12: ='PL-CF-BS'!K74 -> -314.99508 | J12: ='PL-CF-BS'!L74 -> -211.60712 | K12: ='PL-CF-BS'!M74 -> -117.9108 | L12: ='PL-CF-BS'!N74 -> -253.44116 | ... N12: ='PL-CF-BS'!P74 -> -241.04194
C13: - | D13: Capex | E13: ='PL-CF-BS'!G79 -> -1488.7 | F13: ='PL-CF-BS'!H79 -> -1641.7 | G13: ='PL-CF-BS'!I79 -> -1495.3 | H13: ='PL-CF-BS'!J79 -> -1645.9071 | I13: ='PL-CF-BS'!K79 -> -1737.2826 | J13: ='PL-CF-BS'!L79 -> -1825.7441 | K13: ='PL-CF-BS'!M79 -> -1897.0787 | L13: ='PL-CF-BS'!N79 -> -2018.1644 | ... N13: ='PL-CF-BS'!P79 -> -2236.5603
C14: Free Cash Flows | E14: =SUM(E10:E13) -> 5168.7549 | F14: =SUM(F10:F13) -> 6174.35 | G14: =SUM(G10:G13) -> 6939.375 | H14: =SUM(H10:H13) -> 6823.3844 | I14: =SUM(I10:I13) -> 7243.6666 | J14: =SUM(J10:J13) -> 7927.7369 | K14: =SUM(K10:K13) -> 8656.9538 | L14: =SUM(L10:L13) -> 9160.0723 | ... N14: =SUM(N10:N13) -> 10627.673
C15: DCF Analysis
D16: PV of FCF | E16: =NPV(L24,I14:N14)+H14 -> 49046.311 | K16: Tax rate | L16: 0.25
D17: Terminal value | E17: =N14*(1+L25)/(L24-L25) -> 257222.32 | K17: Debt ratio | L17: 0.1
D18: PV of terminal value | E18: =E17/(1+L24)^6 -> 173967.26 | K18: Beta | L18: 0.9
D19: Enterprise Value | E19: =E16+E18 -> 223013.57 | K19: Risk free rate | L19: 0.02
D20: Net Cash/(Debt), Minority interests | E20: =-年度版model!H163 -> -5225.6146 | K20: Risk premium | L20: 0.06
D21: Equity Value | E21: =E19+E20 -> 217787.96 | K21: Equity cost | L21: =L19+L18*L20 -> 0.074
D22: Equity value per share (EUR) | E22: =E21/'PL-CF-BS'!H55 -> 407.60445 | K22: Debt cost | L22: 0.01
K23: Debt cost (After tax) | L23: =L22*(1-L16) -> 0.0075
K24: WACC | L24: =L23*L17+L21*(1-L17) -> 0.06735
K25: Perpetual Growth | L25: 0.025
E28: Equity value per share (USD)
E29: Perpetual Growth | H29: =I29-0.1% -> 0.022 | I29: =J29-0.1% -> 0.023 | J29: =K29-0.1% -> 0.024 | K29: =L25 -> 0.025 | L29: =K29+0.1% -> 0.026 | M29: =L29+0.1% -> 0.027
E30: WACC | G30: =G31-0.1% -> 0.06435 | H30: =($E$20+(NPV($G30,$I$14:$N$14)+$H$14)+((($N$14*(1+H$29)/($G30-H$29)))/(1+$G30)^6))/'PL-CF-BS'!$H$55 -> 412.97017 | I30: =($E$20+(NPV($G30,$I$14:$N$14)+$H$14)+((($N$14*(1+I$29)/($G30-I$29)))/(1+$G30)^6))/'PL-CF-BS'!$H$55 -> 421.28574 | J30: =($E$20+(NPV($G30,$I$14:$N$14)+$H$14)+((($N$14*(1+J$29)/($G30-J$29)))/(1+$G30)^6))/'PL-CF-BS'!$H$55 -> 430.01348 | K30: =($E$20+(NPV($G30,$I$14:$N$14)+$H$14)+((($N$14*(1+K$29)/($G30-K$29)))/(1+$G30)^6))/'PL-CF-BS'!$H$55 -> 439.18482 | L30: =($E$20+(NPV($G30,$I$14:$N$14)+$H$14)+((($N$14*(1+L$29)/($G30-L$29)))/(1+$G30)^6))/'PL-CF-BS'!$H$55 -> 448.83445 | M30: =($E$20+(NPV($G30,$I$14:$N$14)+$H$14)+((($N$14*(1+M$29)/($G30-M$29)))/(1+$G30)^6))/'PL-CF-BS'!$H$55 -> 459.0008
G31: =G32-0.1% -> 0.06535 | H31: =($E$20+(NPV($G31,$I$14:$N$14)+$H$14)+((($N$14*(1+H$29)/($G31-H$29)))/(1+$G31)^6))/'PL-CF-BS'!$H$55 -> 403.27698 | I31: =($E$20+(NPV($G31,$I$14:$N$14)+$H$14)+((($N$14*(1+I$29)/($G31-I$29)))/(1+$G31)^6))/'PL-CF-BS'!$H$55 -> 411.17175 | J31: =($E$20+(NPV($G31,$I$14:$N$14)+$H$14)+((($N$14*(1+J$29)/($G31-J$29)))/(1+$G31)^6))/'PL-CF-BS'!$H$55 -> 419.44836 | K31: =($E$20+(NPV($G31,$I$14:$N$14)+$H$14)+((($N$14*(1+K$29)/($G31-K$29)))/(1+$G31)^6))/'PL-CF-BS'!$H$55 -> 428.13522 | L31: =($E$20+(NPV($G31,$I$14:$N$14)+$H$14)+((($N$14*(1+L$29)/($G31-L$29)))/(1+$G31)^6))/'PL-CF-BS'!$H$55 -> 437.26359 | M31: =($E$20+(NPV($G31,$I$14:$N$14)+$H$14)+((($N$14*(1+M$29)/($G31-M$29)))/(1+$G31)^6))/'PL-CF-BS'!$H$55 -> 446.86803
G32: =G33-0.1% -> 0.06635 | H32: =($E$20+(NPV($G32,$I$14:$N$14)+$H$14)+((($N$14*(1+H$29)/($G32-H$29)))/(1+$G32)^6))/'PL-CF-BS'!$H$55 -> 394.02192 | I32: =($E$20+(NPV($G32,$I$14:$N$14)+$H$14)+((($N$14*(1+I$29)/($G32-I$29)))/(1+$G32)^6))/'PL-CF-BS'!$H$55 -> 401.52538 | J32: =($E$20+(NPV($G32,$I$14:$N$14)+$H$14)+((($N$14*(1+J$29)/($G32-J$29)))/(1+$G32)^6))/'PL-CF-BS'!$H$55 -> 409.3832 | K32: =($E$20+(NPV($G32,$I$14:$N$14)+$H$14)+((($N$14*(1+K$29)/($G32-K$29)))/(1+$G32)^6))/'PL-CF-BS'!$H$55 -> 417.62108 | L32: =($E$20+(NPV($G32,$I$14:$N$14)+$H$14)+((($N$14*(1+L$29)/($G32-L$29)))/(1+$G32)^6))/'PL-CF-BS'!$H$55 -> 426.26728 | M32: =($E$20+(NPV($G32,$I$14:$N$14)+$H$14)+((($N$14*(1+M$29)/($G32-M$29)))/(1+$G32)^6))/'PL-CF-BS'!$H$55 -> 435.35293
G33: =L24 -> 0.06735 | H33: =($E$20+(NPV($G33,$I$14:$N$14)+$H$14)+((($N$14*(1+H$29)/($G33-H$29)))/(1+$G33)^6))/'PL-CF-BS'!$H$55 -> 385.17599 | I33: =($E$20+(NPV($G33,$I$14:$N$14)+$H$14)+((($N$14*(1+I$29)/($G33-I$29)))/(1+$G33)^6))/'PL-CF-BS'!$H$55 -> 392.315 | J33: =($E$20+(NPV($G33,$I$14:$N$14)+$H$14)+((($N$14*(1+J$29)/($G33-J$29)))/(1+$G33)^6))/'PL-CF-BS'!$H$55 -> 399.78338 | K33: =($E$20+(NPV($G33,$I$14:$N$14)+$H$14)+((($N$14*(1+K$29)/($G33-K$29)))/(1+$G33)^6))/'PL-CF-BS'!$H$55 -> 407.60445 | L33: =($E$20+(NPV($G33,$I$14:$N$14)+$H$14)+((($N$14*(1+L$29)/($G33-L$29)))/(1+$G33)^6))/'PL-CF-BS'!$H$55 -> 415.80381 | M33: =($E$20+(NPV($G33,$I$14:$N$14)+$H$14)+((($N$14*(1+M$29)/($G33-M$29)))/(1+$G33)^6))/'PL-CF-BS'!$H$55 -> 424.40959
G34: =G33+0.1% -> 0.06835 | H34: =($E$20+(NPV($G34,$I$14:$N$14)+$H$14)+((($N$14*(1+H$29)/($G34-H$29)))/(1+$G34)^6))/'PL-CF-BS'!$H$55 -> 376.7127 | I34: =($E$20+(NPV($G34,$I$14:$N$14)+$H$14)+((($N$14*(1+I$29)/($G34-I$29)))/(1+$G34)^6))/'PL-CF-BS'!$H$55 -> 383.51175 | J34: =($E$20+(NPV($G34,$I$14:$N$14)+$H$14)+((($N$14*(1+J$29)/($G34-J$29)))/(1+$G34)^6))/'PL-CF-BS'!$H$55 -> 390.61742 | K34: =($E$20+(NPV($G34,$I$14:$N$14)+$H$14)+((($N$14*(1+K$29)/($G34-K$29)))/(1+$G34)^6))/'PL-CF-BS'!$H$55 -> 398.05091 | L34: =($E$20+(NPV($G34,$I$14:$N$14)+$H$14)+((($N$14*(1+L$29)/($G34-L$29)))/(1+$G34)^6))/'PL-CF-BS'!$H$55 -> 405.83545 | M34: =($E$20+(NPV($G34,$I$14:$N$14)+$H$14)+((($N$14*(1+M$29)/($G34-M$29)))/(1+$G34)^6))/'PL-CF-BS'!$H$55 -> 413.99651
G35: =G34+0.1% -> 0.06935 | H35: =($E$20+(NPV($G35,$I$14:$N$14)+$H$14)+((($N$14*(1+H$29)/($G35-H$29)))/(1+$G35)^6))/'PL-CF-BS'!$H$55 -> 368.60781 | I35: =($E$20+(NPV($G35,$I$14:$N$14)+$H$14)+((($N$14*(1+I$29)/($G35-I$29)))/(1+$G35)^6))/'PL-CF-BS'!$H$55 -> 375.08929 | J35: =($E$20+(NPV($G35,$I$14:$N$14)+$H$14)+((($N$14*(1+J$29)/($G35-J$29)))/(1+$G35)^6))/'PL-CF-BS'!$H$55 -> 381.85661 | K35: =($E$20+(NPV($G35,$I$14:$N$14)+$H$14)+((($N$14*(1+K$29)/($G35-K$29)))/(1+$G35)^6))/'PL-CF-BS'!$H$55 -> 388.92911 | L35: =($E$20+(NPV($G35,$I$14:$N$14)+$H$14)+((($N$14*(1+L$29)/($G35-L$29)))/(1+$G35)^6))/'PL-CF-BS'!$H$55 -> 396.32791 | M35: =($E$20+(NPV($G35,$I$14:$N$14)+$H$14)+((($N$14*(1+M$29)/($G35-M$29)))/(1+$G35)^6))/'PL-CF-BS'!$H$55 -> 404.07612
G36: =G35+0.1% -> 0.07035 | H36: =($E$20+(NPV($G36,$I$14:$N$14)+$H$14)+((($N$14*(1+H$29)/($G36-H$29)))/(1+$G36)^6))/'PL-CF-BS'!$H$55 -> 360.83908 | I36: =($E$20+(NPV($G36,$I$14:$N$14)+$H$14)+((($N$14*(1+I$29)/($G36-I$29)))/(1+$G36)^6))/'PL-CF-BS'!$H$55 -> 367.02348 | J36: =($E$20+(NPV($G36,$I$14:$N$14)+$H$14)+((($N$14*(1+J$29)/($G36-J$29)))/(1+$G36)^6))/'PL-CF-BS'!$H$55 -> 373.47474 | K36: =($E$20+(NPV($G36,$I$14:$N$14)+$H$14)+((($N$14*(1+K$29)/($G36-K$29)))/(1+$G36)^6))/'PL-CF-BS'!$H$55 -> 380.21051 | L36: =($E$20+(NPV($G36,$I$14:$N$14)+$H$14)+((($N$14*(1+L$29)/($G36-L$29)))/(1+$G36)^6))/'PL-CF-BS'!$H$55 -> 387.25003 | M36: =($E$20+(NPV($G36,$I$14:$N$14)+$H$14)+((($N$14*(1+M$29)/($G36-M$29)))/(1+$G36)^6))/'PL-CF-BS'!$H$55 -> 394.61433
E37: % change from DCF TP upon WACC/perpetual growth change
E38: Perpetual Growth | H38: =H29 -> 0.022 | I38: =I29 -> 0.023 | J38: =J29 -> 0.024 | K38: =K29 -> 0.025 | L38: =L29 -> 0.026 | M38: =M29 -> 0.027
E39: WACC | G39: =G30 -> 0.06435 | H39: =H30/$K$33-1 -> 0.013164033 | I39: =I30/$K$33-1 -> 0.03356511 | J39: =J30/$K$33-1 -> 0.054977392 | K39: =K30/$K$33-1 -> 0.077477974 | L39: =L30/$K$33-1 -> 0.10115199 | M39: =M30/$K$33-1 -> 0.12609369
G40: =G31 -> 0.06535 | H40: =H31/$K$33-1 -> -0.010616829 | I40: =I31/$K$33-1 -> 0.0087518619 | J40: =J31/$K$33-1 -> 0.02905737 | K40: =K31/$K$33-1 -> 0.050369347 | L40: =L31/$K$33-1 -> 0.072764525 | M40: =M31/$K$33-1 -> 0.096327638
G41: =G32 -> 0.06635 | H41: =H32/$K$33-1 -> -0.033322825 | I41: =I32/$K$33-1 -> -0.01491414 | J41: =J32/$K$33-1 -> 0.004363903 | K41: =K32/$K$33-1 -> 0.024574379 | L41: =L32/$K$33-1 -> 0.045786614 | M41: =M32/$K$33-1 -> 0.06807698
G42: =G33 -> 0.06735 | H42: =H33/$K$33-1 -> -0.055025072 | I42: =I33/$K$33-1 -> -0.037510515 | J42: =J33/$K$33-1 -> -0.019187905 | K42: =K33/$K$33-1 -> 0 | L42: =L33/$K$33-1 -> 0.020115977 | M42: =M33/$K$33-1 -> 0.041229029
...

Sheet Sheet1

Sheet PL-CF-BS
B2: Financial Statements | F2: =F125-F145-F159 -> 0 | G2: =G125-G145-G159 -> -0.1 | H2: =H125-H145-H159 -> 0 | I2: =I125-I145-I159 -> 0 | J2: =J125-J145-J159 -> 0 | K2: =K125-K145-K159 -> 0 | L2: =L125-L145-L159 -> 0 | M2: =M125-M145-M159 -> 0 | ... P2: =P125-P145-P159 -> 0
B3: ( in EUR mn)
F4: 2022 | G4: 2023 | H4: 2024 | I4: 2025 | J4: 2026E | K4: 2027E | L4: 2028E | M4: 2029E | N4: 2030E | O4: 2031E | P4: 2032E
B5: Income Statement
B6: Revenue | F6: =年度版model!E2 -> 38260.7 | G6: =年度版model!F2 -> 41182.6 | H6: =年度版model!G2 -> 43486.8 | I6: =年度版model!H2 -> 44052 | J6: =年度版model!I2 -> 46055.159 | K6: =年度版model!J2 -> 48398.286 | L6: =年度版model!K2 -> 50952.563 | M6: =年度版model!L2 -> 53661.992 | ... P6: =年度版model!O2 -> 62743.114
B7: yoy | F7: =F6/#REF!-1 -> #REF! | G7: =G6/F6-1 -> 0.076368179 | H7: =H6/G6-1 -> 0.055950814 | I7: =I6/H6-1 -> 0.012997047 | J7: =J6/I6-1 -> 0.045472611 | K7: =K6/J6-1 -> 0.05087653 | L7: =L6/K6-1 -> 0.052776175 | M7: =M6/L6-1 -> 0.05317553 | N7: =N6/M6-1 -> 0.05333654 | ... P7: =P6/O6-1 -> 0.053656185
B8: Cost of goods sold and service | F8: =-年度版model!E16 -> 10577.4 | G8: =-年度版model!F16 -> 10767 | H8: =-年度版model!G16 -> 11227 | I8: =-年度版model!H16 -> 11313.4 | J8: =-年度版model!I16 -> 11781.795 | K8: =-年度版model!J16 -> 12236.017 | L8: =-年度版model!K16 -> 12728.929 | M8: =-年度版model!L16 -> 13244.811 | ... P8: =-年度版model!O16 -> 14921.518
B9: Gross profit | F9: =F6-F8 -> 27683.3 | G9: =G6-G8 -> 30415.6 | H9: =H6-H8 -> 32259.8 | I9: =I6-I8 -> 32738.6 | J9: =J6-J8 -> 34273.365 | K9: =K6-K8 -> 36162.269 | L9: =L6-L8 -> 38223.633 | M9: =M6-M8 -> 40417.181 | ... P9: =P6-P8 -> 47821.596
C10: YoY | F10: =F9/#REF!-1 -> #REF! | G10: =G9/F9-1 -> 0.098698493 | H10: =H9/G9-1 -> 0.060633359 | I10: =I9/H9-1 -> 0.014842002 | J10: =J9/I9-1 -> 0.046879365 | K10: =K9/J9-1 -> 0.055112906 | L10: =L9/K9-1 -> 0.057003169 | M10: =M9/L9-1 -> 0.057387217 | N10: =N9/M9-1 -> 0.057532092 | ... P10: =P9/O9-1 -> 0.057819842
C11: Gross margin | F11: =F9/F6 -> 0.723544 | G11: =G9/G6 -> 0.73855463 | H11: =H9/H6 -> 0.7418297 | I11: =I9/I6 -> 0.74318079 | J11: =J9/J6 -> 0.74418079 | K11: =K9/K6 -> 0.74718079 | L11: =L9/L6 -> 0.75018079 | M11: =M9/M6 -> 0.75318079 | ... P11: =P9/P6 -> 0.76218079
B12: Research and innovation expenses | F12: =-年度版model!E23 -> 1138.6 | G12: =-年度版model!F23 -> 1288.9 | H12: =-年度版model!G23 -> 1354.7 | I12: =-年度版model!H23 -> 1380.6 | J12: =-年度版model!I23 -> 1427.7099 | K12: =-年度版model!J23 -> 1500.3469 | L12: =-年度版model!K23 -> 1579.5294 | M12: =-年度版model!L23 -> 1663.5218 | ... P12: =-年度版model!O23 -> 1945.0365
B13: R&I rate | F13: =F12/F6 -> 0.029758996 | G13: =G12/G6 -> 0.031297198 | H13: =H12/H6 -> 0.031151982 | I13: =I12/I6 -> 0.031340234 | J13: =J12/J6 -> 0.031 | K13: =K12/K6 -> 0.031 | L13: =L12/L6 -> 0.031 | M13: =M12/M6 -> 0.031 | ... P13: =P12/P6 -> 0.031
B14: Advertising and promotion expenses | F14: =-年度版model!E27 -> 12059 | G14: =-年度版model!F27 -> 13356.6 | H14: =-年度版model!G27 -> 14008.9 | I14: =-年度版model!H27 -> 14177.8 | J14: =-年度版model!I27 -> 14645.541 | K14: =-年度版model!J27 -> 15342.257 | L14: =-年度版model!K27 -> 16151.962 | M14: =-年度版model!L27 -> 17010.851 | ... P14: =-年度版model!O27 -> 19889.567
B15: Advertising rate | F15: =F14/F6 -> 0.31517981 | G15: =G14/G6 -> 0.32432629 | H15: =H14/H6 -> 0.32214143 | I15: =I14/I6 -> 0.32184237 | J15: =J14/J6 -> 0.318 | K15: =K14/K6 -> 0.317 | L15: =L14/L6 -> 0.317 | M15: =M14/M6 -> 0.317 | ... P15: =P14/P6 -> 0.317
B16: Selling, general and admnistrative expenses | F16: =-年度版model!E31 -> 7028.8 | G16: =-年度版model!F31 -> 7626.7 | H16: =-年度版model!G31 -> 8208.7 | I16: =-年度版model!H31 -> 8288.3 | J16: =-年度版model!I31 -> 8704.4251 | K16: =-年度版model!J31 -> 9098.8778 | L16: =-年度版model!K31 -> 9528.1292 | M16: =-年度版model!L31 -> 9981.1305 | ... P16: =-年度版model!O31 -> 11481.99
B17: Administrating rate | F17: =F16/F$6 -> 0.18370809 | G17: =G16/G$6 -> 0.18519229 | H17: =H16/H$6 -> 0.18876303 | I17: =I16/I$6 -> 0.1881481 | J17: =J16/J$6 -> 0.189 | K17: =K16/K$6 -> 0.188 | L17: =L16/L$6 -> 0.187 | M17: =M16/M$6 -> 0.186 | ... P17: =P16/P$6 -> 0.183
B18: Other Operating Income and Expense | F18: =-年度版model!E52 -> 241.5 | G18: =-年度版model!F52 -> 449.9 | H18: =-年度版model!G52 -> 437.7 | I18: =-年度版model!H52 -> 505.4 | J18: =-年度版model!I52 -> 471.55 | K18: =-年度版model!J52 -> 488.475 | L18: =-年度版model!K52 -> 480.0125 | M18: =-年度版model!L52 -> 484.24375 | ... P18: =-年度版model!O52 -> 482.65703
B19: Operating expenses | F19: =F12+F14+F16+F18 -> 20467.9 | G19: =G12+G14+G16+G18 -> 22722.1 | H19: =H12+H14+H16+H18 -> 24010 | I19: =I12+I14+I16+I18 -> 24352.1 | J19: =J12+J14+J16+J18 -> 25249.226 | K19: =K12+K14+K16+K18 -> 26429.956 | L19: =L12+L14+L16+L18 -> 27739.633 | M19: =M12+M14+M16+M18 -> 29139.748 | ... P19: =P12+P14+P16+P18 -> 33799.251
C20: YoY | G20: =G19/F19-1 -> 0.11013343 | H20: =H19/G19-1 -> 0.0566805 | I20: =I19/H19-1 -> 0.01424823 | J20: =J19/I19-1 -> 0.036839771 | K20: =K19/J19-1 -> 0.046763041 | L20: =L19/K19-1 -> 0.049552753 | M20: =M19/L19-1 -> 0.050473416 | N20: =N19/M19-1 -> 0.050437831 | ... P20: =P19/O19-1 -> 0.050882852
C21: % of revenue | F21: =F19/F6 -> 0.53495885 | G21: =G19/G6 -> 0.5517403 | H21: =H19/H6 -> 0.55212156 | I21: =I19/I6 -> 0.5528035 | J21: =J19/J6 -> 0.54823881 | K21: =K19/K6 -> 0.54609282 | L21: =L19/L6 -> 0.54442077 | M21: =M19/M6 -> 0.54302396 | ... P21: =P19/P6 -> 0.53869259
B22: Operating profit | F22: =年度版model!E54 -> 7215.3 | G22: =年度版model!F54 -> 7693.4 | H22: =年度版model!G54 -> 8249.8 | I22: =年度版model!H54 -> 8386.5 | J22: =年度版model!I54 -> 9024.139 | K22: =年度版model!J54 -> 9732.3131 | L22: =年度版model!K54 -> 10484 | M22: =年度版model!L54 -> 11277.434 | ... P22: =年度版model!O54 -> 14022.345
C23: YoY | G23: =G22/F22-1 -> 0.066261971 | H23: =H22/G22-1 -> 0.07232173 | I23: =I22/H22-1 -> 0.016570099 | J23: =J22/I22-1 -> 0.076031597 | K23: =K22/J22-1 -> 0.078475535 | L23: =L22/K22-1 -> 0.077236197 | M23: =M22/L22-1 -> 0.075680455 | N23: =N22/M22-1 -> 0.075862946 | ... P23: =P22/O22-1 -> 0.07492317
C24: Operating margin | F24: =F22/F6 -> 0.18858254 | G24: =G22/G6 -> 0.18681191 | H24: =H22/H$6 -> 0.18970814 | I24: =I22/I$6 -> 0.19037728 | J24: =J22/J$6 -> 0.19594198 | K24: =K22/K$6 -> 0.20108797 | L24: =L22/L$6 -> 0.20576001 | M24: =M22/M$6 -> 0.21015682 | N24: =N22/N$6 -> 0.21465119 | O24: =O22/O$6 -> 0.21906656 | P24: =P22/P$6 -> 0.2234882
B25: DD&A | F25: =F73 -> 1536.1 | G25: =G73 -> 1715 | H25: =H73 -> 1855.3 | I25: =AVERAGE(F25:H25)*1.05 -> 1787.24 | J25: =AVERAGE(G25:I25)*1.05 -> 1875.139 | K25: =AVERAGE(H25:J25)*1.05 -> 1931.1877 | L25: =AVERAGE(I25:K25)*1.1 -> 2050.9744 | M25: =AVERAGE(J25:L25)*1.1 -> 2147.6771 | N25: =AVERAGE(K25:M25)*1.1 -> 2247.6077 | O25: =AVERAGE(L25:N25)*1.1 -> 2363.6284 | P25: =AVERAGE(M25:O25)*1.1 -> 2478.2681
B26: EBITDA | F26: =F22+F25 -> 8751.4 | G26: =G22+G25 -> 9408.4 | H26: =H22+H25 -> 10105.1 | I26: =I22+I25 -> 10173.74 | J26: =J22+J25 -> 10899.278 | K26: =K22+K25 -> 11663.501 | L26: =L22+L25 -> 12534.974 | M26: =M22+M25 -> 13425.111 | ... P26: =P22+P25 -> 16500.614
C27: YoY | G27: =G26/F26-1 -> 0.075073702 | H27: =H26/G26-1 -> 0.074050848 | I27: =I26/H26-1 -> 0.0067926097 | J27: =J26/I26-1 -> 0.071314776 | K27: =K26/J26-1 -> 0.070116827 | L27: =L26/K26-1 -> 0.074718016 | M27: =M26/L26-1 -> 0.071012233 | N27: =N26/M26-1 -> 0.07117036 | ... P27: =P26/O26-1 -> 0.07087019
C28: EBITDA margin | F28: =F26/F$6 -> 0.22873079 | G28: =G26/G$6 -> 0.22845571 | H28: =H26/H$6 -> 0.23237166 | I28: =I26/I$6 -> 0.23094842 | J28: =J26/J$6 -> 0.23665705 | K28: =K26/K$6 -> 0.24098995 | L28: =L26/L$6 -> 0.24601264 | M28: =M26/M$6 -> 0.25017914 | ... P28: =P26/P$6 -> 0.26298684
C29: Finance cost, net | F29: =年度版model!E57 -> -0.6 | G29: =年度版model!F57 -> -64.6 | H29: =年度版model!G57 -> -224.7 | I29: =年度版model!H57 -> -198.1 | J29: =年度版model!I57 -> -136 | K29: =年度版model!J57 -> -59.04 | L29: =年度版model!K57 -> -89.04 | M29: =年度版model!L57 -> -89.04 | ... P29: =年度版model!O57 -> 714.34208
B30: + Interest Expense | F30: =年度版model!E58 -> -70.4 | G30: =年度版model!F58 -> -226.7 | H30: =年度版model!G58 -> -373.4 | I30: =年度版model!H58 -> -365.8 | J30: =年度版model!I58 -> -366 | K30: =年度版model!J58 -> -259.04 | L30: =年度版model!K58 -> -259.04 | M30: =年度版model!L58 -> -259.04 | ... P30: =年度版model!O58 -> -259.04
B31: - Interest Income | F31: =年度版model!E59 -> 69.8 | G31: =年度版model!F59 -> 162.1 | H31: =年度版model!G59 -> 148.7 | I31: =年度版model!H59 -> 167.7 | J31: =年度版model!I59 -> 230 | K31: =年度版model!J59 -> 200 | L31: =年度版model!K59 -> 170 | M31: =年度版model!L59 -> 170 | ... P31: =年度版model!O59 -> 170
B32: + Other Investment (Inc) Loss
B33: + Foreign Exch (Gain) Loss
B34: + (Income) Loss from Affiliates
B35: + Other Non-Op (Income) Loss
B36: Profit before taxation | F36: =年度版model!E64 -> 7610.6 | G36: =年度版model!F64 -> 8000.9 | H36: =年度版model!G64 -> 8432.9 | I36: =年度版model!H64 -> 8502.3 | J36: =年度版model!I64 -> 9207.3175 | K36: =年度版model!J64 -> 10003.167 | L36: =年度版model!K64 -> 10735.891 | M36: =年度版model!L64 -> 11540.692 | ... P36: =年度版model!O64 -> 15125.177
C37: YoY | G37: =G36/F36-1 -> 0.051283736 | H37: =H36/G36-1 -> 0.053993926 | I37: =I36/H36-1 -> 0.0082296719 | J37: =J36/I36-1 -> 0.082920797 | K37: =K36/J36-1 -> 0.086436629 | L37: =L36/K36-1 -> 0.073249169 | M37: =M36/L36-1 -> 0.074963675 | N37: =N36/M36-1 -> 0.075146991 | ... P37: =P36/O36-1 -> 0.13450155
C38: EBT margin | F38: =F36/F6 -> 0.19891429 | G38: =G36/G6 -> 0.19427865 | H38: =H36/H6 -> 0.19391861 | I38: =I36/I$6 -> 0.19300599 | J38: =J36/J$6 -> 0.19991935 | K38: =K36/K$6 -> 0.20668432 | L38: =L36/L$6 -> 0.21070364 | M38: =M36/M$6 -> 0.21506269 | N38: =N36/N$6 -> 0.21951579 | O38: =O36/O$6 -> 0.22388667 | P38: =P36/P$6 -> 0.24106514
B39: Abnormal (Losses) Gains
B40: Profit before taxation | F40: =F36-F39 -> 7610.6 | G40: =G36-G39 -> 8000.9 | H40: =H36-H39 -> 8432.9 | I40: =I36-I39 -> 8502.3 | J40: =J36-J39 -> 9207.3175 | K40: =K36-K39 -> 10003.167 | L40: =L36-L39 -> 10735.891 | M40: =M36-M39 -> 11540.692 | ... P40: =P36-P39 -> 15125.177
B41: Taxation | F41: =-年度版model!E67 -> 1899.4 | G41: =-年度版model!F67 -> 1810.6 | H41: =-年度版model!G67 -> 2015.1 | I41: =-年度版model!H67 -> 2363.1 | J41: =-年度版model!I67 -> 2409.2187 | K41: =-年度版model!J67 -> 2609.067 | L41: =-年度版model!K67 -> 2791.8224 | M41: =-年度版model!L67 -> 3001.1077 | ... P41: =-年度版model!O67 -> 3933.2376
...

Sheet 年度版model
A1: L'OREAL | B1: FY19 | C1: FY20 | D1: FY21 | E1: FY22 | F1: FY23 | G1: FY24 | H1: FY25 | I1: FY26e | J1: FY27e | K1: FY28e | L1: FY29e | M1: FY30e | N1: FY31e | O1: FY32e
A2: NET SALES | B2: 29873.6 | C2: 27992.1 | D2: 32287.181 | E2: 38260.7 | F2: 41182.6 | G2: 43486.8 | H2: 44052 | I2: =I4+I6+I8+I10 -> 46055.159 | J2: =J4+J6+J8+J10 -> 48398.286 | K2: =K4+K6+K8+K10 -> 50952.563 | L2: =L4+L6+L8+L10 -> 53661.992 | M2: =M4+M6+M8+M10 -> 56524.137 | N2: =N4+N6+N8+N10 -> 59547.996 | O2: =O4+O6+O8+O10 -> 62743.114
A3: yoy | C3: =C2/B2-1 -> -0.062982031 | D3: =D2/C2-1 -> 0.15343905 | E3: =E2/D2-1 -> 0.18501209 | F3: =F2/E2-1 -> 0.076368179 | G3: =G2/F2-1 -> 0.055950814 | H3: =H2/G2-1 -> 0.012997047 | I3: =I2/H2-1 -> 0.045472611 | J3: =J2/I2-1 -> 0.05087653 | ... O3: =O2/N2-1 -> 0.053656185
A4: -Professional Products | B4: 3441.9 | C4: 3097.3 | D4: 3783.9 | E4: 4476.8 | F4: 4653.9 | G4: 4886 | H4: 5163 | I4: =H4*(1+I5) -> 5630.4745 | J4: =I4*(1+J5) -> 5954.4886 | K4: =J4*(1+K5) -> 6297.1486 | L4: =K4*(1+L5) -> 6659.5275 | M4: =L4*(1+M5) -> 7042.76 | N4: =M4*(1+N5) -> 7448.0463 | O4: =N4*(1+O5) -> 7876.6553
A5: yoy | C5: =C4/B4-1 -> -0.10011912 | D5: =D4/C4-1 -> 0.22167694 | E5: =E4/D4-1 -> 0.18311795 | F5: =F4/E4-1 -> 0.039559507 | G5: =G4/F4-1 -> 0.04987215 | H5: =H4/G4-1 -> 0.056692591 | I5: 0.090543197 | J5: 0.057546503 | K5: 0.057546503 | L5: 0.057546503 | M5: 0.057546503 | N5: 0.057546503 | O5: 0.057546503
A6: -Consumer Products | B6: 12748.2 | C6: 11703.8 | D6: 12233.5 | E6: 14021.3 | F6: 15172.7 | G6: 15982 | H6: 16089.7 | I6: =H6*(1+I7) -> 16536.879 | J6: =I6*(1+J7) -> 17135.652 | K6: =J6*(1+K7) -> 17756.106 | L6: =K6*(1+L7) -> 18399.026 | M6: =L6*(1+M7) -> 19065.224 | N6: =M6*(1+N7) -> 19755.544 | O6: =N6*(1+O7) -> 20470.86
A7: yoy | C7: =C6/B6-1 -> -0.081925291 | D7: =D6/C6-1 -> 0.045258805 | E7: =E6/D6-1 -> 0.1461397 | F7: =F6/E6-1 -> 0.082117921 | G7: =G6/F6-1 -> 0.053339221 | H7: =H6/G6-1 -> 0.0067388312 | I7: 0.027792879 | J7: 0.036208357 | K7: 0.036208357 | L7: 0.036208357 | M7: 0.036208357 | N7: 0.036208357 | O7: 0.036208357
A8: -Luxury Products | B8: 11019.8 | C8: 10179.9 | D8: 12346.2 | E8: 14638.1 | F8: 14924 | G8: 15591 | H8: 15595.1 | I8: =H8*(1+I9) -> 16260.645 | J8: =I8*(1+J9) -> 17251.712 | K8: =J8*(1+K9) -> 18389.441 | L8: =K8*(1+L9) -> 19614.619 | M8: =L8*(1+M9) -> 20921.424 | N8: =M8*(1+N9) -> 22315.293 | O8: =N8*(1+O9) -> 23802.027
A9: yoy | C9: =C8/B8-1 -> -0.076217354 | D9: =D8/C8-1 -> 0.2128017 | E9: =E8/D8-1 -> 0.18563607 | F9: =F8/E8-1 -> 0.019531223 | G9: =G8/F8-1 -> 0.044693112 | H9: =H8/G8-1 -> 0.00026297223 | I9: 0.042676532 | J9: 0.060948802 | K9: 0.065948802 | L9: 0.066624002 | M9: 0.066624002 | N9: 0.066624002 | O9: 0.066624002
A10: -Dermatological Beauty | B10: 2663.7 | C10: 3011.1 | D10: 3924 | E10: 5124.5 | F10: 6432 | G10: 7027 | H10: 7204.1 | I10: =H10*(1+I11) -> 7627.161 | J10: =I10*(1+J11) -> 8056.4336 | K10: =J10*(1+K11) -> 8509.8665 | L10: =K10*(1+L11) -> 8988.8195 | M10: =L10*(1+M11) -> 9494.729 | N10: =M10*(1+N11) -> 10029.112 | O10: =N10*(1+O11) -> 10593.572
A11: yoy | C11: =C10/B10-1 -> 0.13042009 | D11: =D10/C10-1 -> 0.30317824 | E11: =E10/D10-1 -> 0.30593782 | F11: =F10/E10-1 -> 0.25514684 | G11: =G10/F10-1 -> 0.092506219 | H11: =H10/G10-1 -> 0.025202789 | I11: 0.058725038 | J11: 0.056282087 | K11: 0.056282087 | L11: 0.056282087 | M11: 0.056282087 | N11: 0.056282087 | O11: 0.056282087
A12: -Other Cosmetics Sales
A13: The Body Shop
A14: Galderma
A16: Cost of good sold - NOT A DRIVER | B16: -8064.7 | C16: -7532.3 | D16: -8433.3 | E16: -10577.4 | F16: -10767 | G16: -11227 | H16: -11313.4 | I16: =-(I2-I19) -> -11781.795 | J16: =-(J2-J19) -> -12236.017 | K16: =-(K2-K19) -> -12728.929 | L16: =-(L2-L19) -> -13244.811 | M16: =-(M2-M19) -> -13781.671 | N16: =-(N2-N19) -> -14340.302 | O16: =-(O2-O19) -> -14921.518
A17: - as % of sales | B17: 0.26996077 | C17: 0.26908664 | D17: 0.26119654 | E17: 0.276456 | F17: 0.26144537 | G17: 0.2581703 | H17: 0.2581703 | I17: 0.2571703 | J17: 0.2541703 | K17: 0.2511703 | L17: 0.2481703 | M17: 0.2451703 | N17: 0.2421703 | O17: 0.2391703
A19: Gross profit | B19: =B2+B16 -> 21808.9 | C19: =C2+C16 -> 20459.8 | D19: =D2+D16 -> 23853.881 | E19: =E2+E16 -> 27683.3 | F19: =F2+F16 -> 30415.6 | G19: =G2+G16 -> 32259.8 | H19: =H2+H16 -> 32738.6 | I19: =I20*I2 -> 34273.365 | J19: =J20*J2 -> 36162.269 | K19: =K20*K2 -> 38223.633 | L19: =L20*L2 -> 40417.181 | M19: =M20*M2 -> 42742.466 | N19: =N20*N2 -> 45207.694 | O19: =O20*O2 -> 47821.596
A20: - gross margin | B20: =B19/B2 -> 0.73003923 | C20: =C19/C2 -> 0.73091336 | D20: =D19/D2 -> 0.73880346 | E20: =E19/E2 -> 0.723544 | F20: =F19/F2 -> 0.73855463 | G20: =G19/G2 -> 0.7418297 | H20: =H19/H2 -> 0.74318079 | I20: =H20+I21 -> 0.74418079 | J20: =I20+J21 -> 0.74718079 | K20: =J20+K21 -> 0.75018079 | L20: =K20+L21 -> 0.75318079 | M20: =L20+M21 -> 0.75618079 | N20: =M20+N21 -> 0.75918079 | O20: =N20+O21 -> 0.76218079
A21: - gross margin progression | C21: =C20-B20 -> 0.00087413288 | D21: =D20-C20 -> 0.0078900951 | E21: =E20-D20 -> -0.015259458 | F21: =F20-E20 -> 0.01501063 | G21: =G20-F20 -> 0.0032750723 | H21: 0 | I21: 0.001 | J21: 0.003 | K21: 0.003 | L21: 0.003 | M21: 0.003 | N21: 0.003 | O21: 0.003
A23: Research and innovation expenses | B23: -985.3 | C23: -964.4 | D23: -1028.7 | E23: -1138.6 | F23: -1288.9 | G23: -1354.7 | H23: -1380.6 | I23: =-(I2*I25) -> -1427.7099 | J23: =-(J2*J25) -> -1500.3469 | K23: =-(K2*K25) -> -1579.5294 | L23: =-(L2*L25) -> -1663.5218 | M23: =-(M2*M25) -> -1752.2482 | N23: =-(N2*N25) -> -1845.9879 | O23: =-(O2*O25) -> -1945.0365
A24: - reported growth | B24: 0.077537183 | C24: -0.021211814 | D24: 0.066673579 | E24: 0.10683387 | F24: 0.13200422 | G24: 0.051051284 | H24: 0.0075880703 | I24: =(-I23)/(-H23)-1 -> 0.034122804 | J24: =(-J23)/(-I23)-1 -> 0.05087653 | K24: =(-K23)/(-J23)-1 -> 0.052776175 | L24: =(-L23)/(-K23)-1 -> 0.05317553 | M24: =(-M23)/(-L23)-1 -> 0.05333654 | N24: =(-N23)/(-M23)-1 -> 0.053496771 | O24: =(-O23)/(-N23)-1 -> 0.053656185
