Workbook
Name Beta: 'Key Info & Assumptions'!$B$22
Name CostOfDebtAfterTax: 'Key Info & Assumptions'!$B$20
Name CostOfDebtBeforeTax: 'Key Info & Assumptions'!$B$18
Name CostOfEquity: 'Key Info & Assumptions'!$B$25
Name CurrentTotalDebt: 'Key Info & Assumptions'!$B$26
Name EstimatedPeriods: 'Key Info & Assumptions'!$B$10
Name HistoricPeriods: 'Key Info & Assumptions'!$B$9
Name MarginalTaxRate: 'Key Info & Assumptions'!$B$19
Name MarketRiskPremium: 'Key Info & Assumptions'!$B$23
Name MarketValueOfEquity: 'Key Info & Assumptions'!$B$27
Name OtherRiskPremium: 'Key Info & Assumptions'!$B$24
Name ReportUnit: 'Key Info & Assumptions'!$B$13
Name RiskFreeRate: 'Key Info & Assumptions'!$B$16
Name SpreadOverRiskFreeRate: 'Key Info & Assumptions'!$B$17
Name TerminalEbitdaMultiples: 'Key Info & Assumptions'!$B$12
Name TerminalGrowthRate: 'Key Info & Assumptions'!$B$11
Name TotalCapital: 'Key Info & Assumptions'!$B$28
Name WACC: 'Key Info & Assumptions'!$B$31
Name WeightOfDebt: 'Key Info & Assumptions'!$B$29
Name WeightOfEquity: 'Key Info & Assumptions'!$B$30

Sheet XN
A1: Code | B1: 3393.HK | C1: Please enter the ticker in B1, e.g. 700 HK
A2: Last annual report | B2: 46022 | C2: Please enter the date in B2, e.g. 2020/3/31
A3: Start year | B3: 2024
A4: Currency | B4: Rmb
A5: Unit | B5: mn
A6: =B4&" "&B5 -> Rmb mn | B6: =TEXT(DATE($B$3+1,MONTH($B$2),DAY($B$2)),"mmm-yy")&IF($B$3+1>YEAR($B$2),"E","A") -> Dec-25A | C6: =TEXT(DATE($B$3+2,MONTH($B$2),DAY($B$2)),"mmm-yy")&IF($B$3+2>YEAR($B$2),"E","A") -> Dec-26E | D6: =TEXT(DATE($B$3+3,MONTH($B$2),DAY($B$2)),"mmm-yy")&IF($B$3+3>YEAR($B$2),"E","A") -> Dec-27E | E6: =TEXT(DATE($B$3+3,MONTH($B$2),DAY($B$2)),"mmm-yy")&IF($B$3+3>YEAR($B$2),"E","A") -> Dec-27E
A7: P&L
A8: Revenue | B8: ='PL-CF-BS'!F17 -> 1481.104 | C8: ='PL-CF-BS'!G17 -> 1873.1353 | D8: ='PL-CF-BS'!H17 -> 2226.9588 | E8: ='PL-CF-BS'!I17 -> 2622.4061
A9: (+/-) | B9: =Revenue!F3 -> 0.15567919 | C9: =Revenue!G3 -> 0.2251006 | D9: =Revenue!H3 -> 0.19174889 | E9: =Revenue!I3 -> 0.17138741
A10: Net profit | B10: ='PL-CF-BS'!F17 -> 1481.104 | C10: ='PL-CF-BS'!G17 -> 1873.1353 | D10: ='PL-CF-BS'!H17 -> 2226.9588 | E10: ='PL-CF-BS'!I17 -> 2622.4061
A11: (+/-) | B11: =IS!F53 -> 0.43773892 | C11: =IS!G53 -> 0.26468855 | D11: =IS!H53 -> 0.18889375 | E11: =IS!I53 -> 0.1775728
A12: ="Diluted EPS ("&B4&")" -> Diluted EPS (Rmb) | B12: ='PL-CF-BS'!F21 -> 1.07 | C12: ='PL-CF-BS'!G21 -> 1.0477297 | D12: ='PL-CF-BS'!H21 -> 1.3033439 | E12: ='PL-CF-BS'!I21 -> 1.5890285
A13: GPM | B13: =IS!F27 -> 0.35706667 | C13: =IS!G27 -> 0.3537084 | D13: =IS!H27 -> 0.3537084 | E13: =IS!I27 -> 0.3537084 | F13: e.g. 50.5%
A14: ROE | B14: =IS!F45 -> 0.23751788 | C14: =IS!G45 -> 0.2519254 | D14: =IS!H45 -> 0.25131065 | E14: =IS!I45 -> 0.24878822 | F14: e.g. 50.5%
A15: EBITDA | B15: =IS!F34 -> 2299.744 | C15: =IS!G34 -> 2382.8769 | D15: =IS!H34 -> 2908.5185 | E15: =IS!I34 -> 3480.5897
A16: EBIT | B16: =IS!F54 -> 1946.744 | C16: =IS!G54 -> 2144.1826 | D16: =IS!H54 -> 2555.3272 | E16: =IS!I54 -> 2993.2781
A17: Interest Revenue | B17: =IS!F11 -> -106.603 | C17: =IS!G11 -> 29.186942 | D17: =IS!H11 -> 28.578233 | E17: =IS!I11 -> 49.458643
A18: Interest Expense | B18: - | C18: - | D18: - | E18: -
A19: Operating Profit | B19: =IS!F10 -> 1899.101 | C19: =IS!G10 -> 2144.1826 | D19: =IS!H10 -> 2555.3272 | E19: =IS!I10 -> 2993.2781
A20: Gross Profit | B20: =IS!F52 -> 3596.92 | C20: =IS!G52 -> 4365.1443 | D20: =IS!H52 -> 5202.1558 | E20: =IS!I52 -> 6093.7398
A21: Depreciation | B21: =CFS!F4 -> 353 | C21: =CFS!G4 -> 238.69435 | D21: =CFS!H4 -> 353.19132 | E21: =CFS!I4 -> 487.31163
A22: Pre-Tax Profit | B22: =IS!F14 -> 1744.855 | C22: =IS!G14 -> 2173.3695 | D22: =IS!H14 -> 2583.9054 | E22: =IS!I14 -> 3042.7367
A23: Balance Sheet
A24: Total Assets | B24: =BS!F17 -> 17582.912 | C24: =BS!G17 -> 19902.079 | D24: =BS!H17 -> 22944.019 | E24: =BS!I17 -> 26325.265
A25: Total Liabilities | B25: =BS!F32 -> 9267.423 | C25: =BS!G32 -> 10007.649 | D25: =BS!H32 -> 11151.818 | E25: =BS!I32 -> 12298.299
A26: Shareholder Equity | B26: =BS!F40 -> 6235.758 | C26: =BS!G40 -> 7435.2775 | D26: =BS!H40 -> 8861.3787 | E26: =BS!I40 -> 10540.717
A27: Total Equity | B27: =BS!F42 -> 8315.489 | C27: =BS!G42 -> 9894.43 | D27: =BS!H42 -> 11792.202 | E27: =BS!I42 -> 14026.966
A28: Cash Flow
A29: Profit before tax | B29: =IS!F14 -> 1744.855 | C29: =IS!G14 -> 2173.3695 | D29: =IS!H14 -> 2583.9054 | E29: =IS!I14 -> 3042.7367
A30: Net Cash from operations | B30: =CFS!F12 -> 1835 | C30: =CFS!G12 -> 1235.2296 | D30: =CFS!H12 -> 2150.336 | E30: =CFS!I12 -> 2803.289
A31: Net Cash from investment activity | B31: =CFS!F22 -> -605 | C31: =CFS!G22 -> -960.74746 | D31: =CFS!H22 -> -1144.9697 | E31: =CFS!I22 -> -1341.2031
A32: Net Cash from financing activity | B32: =CFS!F30 -> -640 | C32: =CFS!G30 -> -294.19425 | D32: =CFS!H30 -> -329.18718 | E32: =CFS!I30 -> -387.64187
A33: Net change in Cash | B33: =CFS!F33 -> 590 | C33: =CFS!G33 -> -19.712089 | D33: =CFS!H33 -> 676.17909 | E33: =CFS!I33 -> 1074.4441
A34: Implied cash at end of period | B34: =CFS!F34 -> 3017 | C34: =CFS!G34 -> 2997.2879 | D34: =CFS!H34 -> 3673.467 | E34: =CFS!I34 -> 4747.9111
A35: Free Cash Flow | B35: =CFS!F37 -> 1834.104 | C35: =CFS!G37 -> 515.60706 | D35: =CFS!H37 -> 1300.1238 | E35: =CFS!I37 -> 1776.0614
A40: EPS | B40: =B12 -> 1.07 | C40: =C12 -> 1.0477297 | D40: =D12 -> 1.3033439 | E40: =E12 -> 1.5890285
A41: EPS1 | B41: =IF(A43-YEAR($B$2)>=0,VLOOKUP((A43-B3+1),A45:B48,2,FALSE),"na") -> 1.3033439
A42: EPS2 | B42: =IF(A43-YEAR($B$2)>=0,VLOOKUP((A43-B3+2),A45:B48,2,FALSE),"na") -> 1.5890285
A43: =YEAR(TODAY()) -> 2026
A44: =YEAR(TODAY()) -> 2026
...

Sheet PL-CF-BS
A1: 03393.HK in Millions CNY | B1: FY2021A | C1: FY2022A | D1: FY2023A | E1: FY2024A | F1: FY2025A | G1: FY2026E | H1: FY2027E | I1: FY2028E | J1: FY2029E | K1: FY2030E
A2: 损益表
A3: 营业收入 | B3: =IS!B3 -> 4590.762 | C3: =IS!C3 -> 5855.844 | D3: =IS!D3 -> 7252.272 | E3: =IS!E3 -> 8716.541 | F3: =IS!F3 -> 10073.525 | G3: =IS!G3 -> 12341.082 | H3: =IS!H3 -> 14707.47 | I3: =IS!I3 -> 17228.145 | ... K3: =IS!K3 -> 22613.098
A4: 销售成本 | B4: =IS!B4 -> -3091.992 | C4: =IS!C4 -> -3926.62 | D4: =IS!D4 -> -4671.521 | E4: =IS!E4 -> -5681.403 | F4: =IS!F4 -> -6476.605 | G4: =IS!G4 -> -7975.9373 | H4: =IS!H4 -> -9505.3144 | I4: =IS!I4 -> -11134.406 | ... K4: =IS!K4 -> -14614.655
A5: 研究与开发费用 | B5: =IS!B5 -> -424.476 | C5: =IS!C5 -> -577.443 | D5: =IS!D5 -> -681.375 | E5: =IS!E5 -> -730.404 | F5: =IS!F5 -> -734.177 | G5: =IS!G5 -> -1031.0164 | H5: =IS!H5 -> -1228.7126 | I5: =IS!I5 -> -1439.2985 | ... K5: =IS!K5 -> -1889.1759
A6: 一般和行政费用 | B6: =IS!B6 -> -177.407 | C6: =IS!C6 -> -215.652 | D6: =IS!D6 -> -327.358 | E6: =IS!E6 -> -367.796 | F6: =IS!F6 -> -413.202 | G6: =IS!G6 -> -528.00277 | H6: =IS!H6 -> -629.24671 | I6: =IS!I6 -> -737.09168 | ... K6: =IS!K6 -> -967.48232
A7: 销售和营销费用 | B7: =IS!B7 -> -437.708 | C7: =IS!C7 -> -512.914 | D7: =IS!D7 -> -649.479 | E7: =IS!E7 -> -737.643 | F7: =IS!F7 -> -788.91 | G7: =IS!G7 -> -1038.6916 | H7: =IS!H7 -> -1237.8596 | I7: =IS!I7 -> -1450.0131 | ... K7: =IS!K7 -> -1903.2396
A8: 其他营业成本 | B8: =IS!B8 -> 252.005 | C8: =IS!C8 -> 256.866 | D8: =IS!D8 -> 216.001 | E8: =IS!E8 -> 332.338 | F8: =IS!F8 -> 238.47 | G8: =IS!G8 -> 376.74908 | H8: =IS!H8 -> 448.9903 | I8: =IS!I8 -> 525.94159 | ... K8: =IS!K8 -> 690.33364
B9: =IS!B9 -> 0 | C9: =IS!C9 -> 0 | D9: =IS!D9 -> 0 | E9: =IS!E9 -> 0 | F9: =IS!F9 -> 0 | G9: =IS!G9 -> 0 | H9: =IS!H9 -> 0 | I9: =IS!I9 -> 0 | ... K9: =IS!K9 -> 0
A10: 营业利润 | B10: =IS!B10 -> 711.184 | C10: =IS!C10 -> 880.081 | D10: =IS!D10 -> 1138.54 | E10: =IS!E10 -> 1531.633 | F10: =IS!F10 -> 1899.101 | G10: =IS!G10 -> 2144.1826 | H10: =IS!H10 -> 2555.3272 | I10: =IS!I10 -> 2993.2781 | ... K10: =IS!K10 -> 3928.8785
A11: 利息费用 (净值) | B11: =IS!B11 -> -99.267 | C11: =IS!C11 -> -112.5 | D11: =IS!D11 -> -131.53 | E11: =IS!E11 -> -125.528 | F11: =IS!F11 -> -106.603 | G11: =IS!G11 -> 29.186942 | H11: =IS!H11 -> 28.578233 | I11: =IS!I11 -> 49.458643 | ... K11: =IS!K11 -> 130.03052
A12: 其他业务收入 (成本) | B12: =IS!B12 -> -139.184 | C12: =IS!C12 -> -185.147 | D12: =IS!D12 -> -146.278 | E12: =IS!E12 -> -198.517 | F12: =IS!F12 -> -47.643 | G12: =IS!G12 -> 0 | H12: =IS!H12 -> 0 | I12: =IS!I12 -> 0 | ... K12: =IS!K12 -> 0
B13: =IS!B13 -> 0 | C13: =IS!C13 -> 0 | D13: =IS!D13 -> 0 | E13: =IS!E13 -> 0 | F13: =IS!F13 -> 0 | G13: =IS!G13 -> 0 | H13: =IS!H13 -> 0 | I13: =IS!I13 -> 0 | ... K13: =IS!K13 -> 0
A14: 税前利润 | B14: =IS!B14 -> 472.733 | C14: =IS!C14 -> 582.434 | D14: =IS!D14 -> 860.732 | E14: =IS!E14 -> 1207.588 | F14: =IS!F14 -> 1744.855 | G14: =IS!G14 -> 2173.3695 | H14: =IS!H14 -> 2583.9054 | I14: =IS!I14 -> 3042.7367 | ... K14: =IS!K14 -> 4058.909
A15: 所得税费用 | B15: =IS!B15 -> -44.759 | C15: =IS!C15 -> -71.274 | D15: =IS!D15 -> -100.139 | E15: =IS!E15 -> -177.426 | F15: =IS!F15 -> -263.751 | G15: =IS!G15 -> -300.23425 | H15: =IS!H15 -> -356.94662 | I15: =IS!I15 -> -420.33063 | ... K15: =IS!K15 -> -560.70699
A17: 净利润 | B17: =IS!B17 -> 427.974 | C17: =IS!C17 -> 511.16 | D17: =IS!D17 -> 760.593 | E17: =IS!E17 -> 1030.162 | F17: =IS!F17 -> 1481.104 | G17: =IS!G17 -> 1873.1353 | H17: =IS!H17 -> 2226.9588 | I17: =IS!I17 -> 2622.4061 | ... K17: =IS!K17 -> 3498.202
A18: 归属于母公司股东的净利润 | B18: =IS!B18 -> 268.084 | C18: =IS!C18 -> 323.797 | D18: =IS!D18 -> 521.233 | E18: =IS!E18 -> 705.612 | F18: =IS!F18 -> 1058.246 | G18: =IS!G18 -> 1450.2773 | H18: =IS!H18 -> 1804.1008 | I18: =IS!I18 -> 2199.5481 | ... K18: =IS!K18 -> 3075.344
A19: 少数股东损益 | B19: =IS!B19 -> 159.89 | C19: =IS!C19 -> 187.363 | D19: =IS!D19 -> 239.36 | E19: =IS!E19 -> 324.55 | F19: =IS!F19 -> 422.858 | G19: =IS!G19 -> 422.858 | H19: =IS!H19 -> 422.858 | I19: =IS!I19 -> 422.858 | ... K19: =IS!K19 -> 422.858
A20: 每股收益 | B20: =IS!B20 -> 0.27 | C20: =IS!C20 -> 0.33 | D20: =IS!D20 -> 0.53 | E20: =IS!E20 -> 0.71 | F20: =IS!F20 -> 1.07 | G20: =IS!G20 -> 1.0477297 | H20: =IS!H20 -> 1.3033439 | I20: =IS!I20 -> 1.5890285 | ... K20: =IS!K20 -> 2.2217333
A21: 摊薄每股收益 | B21: =IS!B21 -> 0.27 | C21: =IS!C21 -> 0.33 | D21: =IS!D21 -> 0.53 | E21: =IS!E21 -> 0.71 | F21: =IS!F21 -> 1.07 | G21: =IS!G21 -> 1.0477297 | H21: =IS!H21 -> 1.3033439 | I21: =IS!I21 -> 1.5890285 | ... K21: =IS!K21 -> 2.2217333
A22: 加权平均流通股数 | B22: =IS!B22 -> 1585.0889 | C22: =IS!C22 -> 1548.9697 | D22: =IS!D22 -> 1435.0811 | E22: =IS!E22 -> 1450.9324 | F22: =IS!F22 -> 1384.2093 | G22: =IS!G22 -> 1384.2093 | H22: =IS!H22 -> 1384.2093 | I22: =IS!I22 -> 1384.2093 | ... K22: =IS!K22 -> 1384.2093
A23: 摊薄加权平均流通股数 | B23: =IS!B23 -> 1585.0889 | C23: =IS!C23 -> 1548.9697 | D23: =IS!D23 -> 1435.0811 | E23: =IS!E23 -> 1450.9324 | F23: =IS!F23 -> 1384.2093 | G23: =IS!G23 -> 1384.2093 | H23: =IS!H23 -> 1384.2093 | I23: =IS!I23 -> 1384.2093 | ... K23: =IS!K23 -> 1384.2093
A26: 03393.HK in Millions CNY | B26: FY2021A | C26: FY2022A | D26: FY2023A | E26: FY2024A | F26: FY2025A | G26: FY2026E | H26: FY2027E | I26: FY2028E | J26: FY2029E | K26: FY2030E
A27: 现金流量表
A28: 净利润 | B28: =CFS!B3 -> 427.974 | C28: =CFS!C3 -> 511.16 | D28: =CFS!D3 -> 760.593 | E28: =CFS!E3 -> 1030.162 | F28: =CFS!F3 -> 1481.104 | G28: =CFS!G3 -> 1873.1353 | H28: =CFS!H3 -> 2226.9588 | I28: =CFS!I3 -> 2622.4061 | ... K28: =CFS!K3 -> 3498.202
A29: 折旧和摊销 | B29: =CFS!B4 -> 219.222 | C29: =CFS!C4 -> 266.999 | D29: =CFS!D4 -> 276.812 | E29: =CFS!E4 -> 316 | F29: =CFS!F4 -> 353 | G29: =CFS!G4 -> 238.69435 | H29: =CFS!H4 -> 353.19132 | I29: =CFS!I4 -> 487.31163 | ... K29: =CFS!K4 -> 818.0635
A30: 所得税费用 | B30: =CFS!B5 -> 44.759 | C30: =CFS!C5 -> 71.274 | D30: =CFS!D5 -> 100.139 | E30: =CFS!E5 -> 0 | F30: =CFS!F5 -> 0 | G30: =CFS!G5 -> 300.23425 | H30: =CFS!H5 -> 356.94662 | I30: =CFS!I5 -> 420.33063 | ... K30: =CFS!K5 -> 560.70699
A31: 应收账款变动 | B31: =CFS!B6 -> -235.266 | C31: =CFS!C6 -> -450.818 | D31: =CFS!D6 -> -198.186 | E31: =CFS!E6 -> 0 | F31: =CFS!F6 -> 0 | G31: =CFS!G6 -> -983.979 | H31: =CFS!H6 -> -921.36123 | I31: =CFS!I6 -> -757.73813 | ... K31: =CFS!K6 -> -310.55354
A32: 存货变动 | B32: =CFS!B7 -> -488.616 | C32: =CFS!C7 -> -109.74 | D32: =CFS!D7 -> -117.801 | E32: =CFS!E7 -> 0 | F32: =CFS!F7 -> 0 | G32: =CFS!G7 -> -345.33796 | H32: =CFS!H7 -> -341.93159 | I32: =CFS!I7 -> -364.22525 | ... K32: =CFS!K7 -> -395.93853
A33: 应付账款变动 | B33: =CFS!B8 -> 266.913 | C33: =CFS!C8 -> 328.915 | D33: =CFS!D8 -> 277.42 | E33: =CFS!E8 -> 0 | F33: =CFS!F8 -> 0 | G33: =CFS!G8 -> 693.84186 | H33: =CFS!H8 -> 1128.2362 | I33: =CFS!I8 -> 1129.5101 | ... K33: =CFS!K8 -> 1262.232
A34: 其他营运资金变动 | B34: =CFS!B9 -> -127.886 | C34: =CFS!C9 -> 100.147 | D34: =CFS!D9 -> 149.214 | E34: =CFS!E9 -> 0 | F34: =CFS!F9 -> 0 | G34: =CFS!G9 -> 0 | H34: =CFS!H9 -> 0 | I34: =CFS!I9 -> 0 | ... K34: =CFS!K9 -> 0
A35: 其他非现金项目 | B35: =CFS!B10 -> 190.647 | C35: =CFS!C10 -> 220.35 | D35: =CFS!D10 -> 372.134 | E35: =CFS!E10 -> 0 | F35: =CFS!F10 -> 0 | G35: =CFS!G10 -> -241.1249 | H35: =CFS!H10 -> -294.75752 | I35: =CFS!I10 -> -313.97547 | ... K35: =CFS!K10 -> -341.31347
A36: 缴纳税金 | B36: =CFS!B11 -> -46.124 | C36: =CFS!C11 -> -75.057 | D36: =CFS!D11 -> -123.73 | E36: =CFS!E11 -> 0 | F36: =CFS!F11 -> 0 | G36: =CFS!G11 -> -300.23425 | H36: =CFS!H11 -> -356.94662 | I36: =CFS!I11 -> -420.33063 | ... K36: =CFS!K11 -> -560.70699
A37: 经营活动提供的净现金 | B37: =CFS!B12 -> 251.623 | C37: =CFS!C12 -> 863.23 | D37: =CFS!D12 -> 1496.595 | E37: =CFS!E12 -> 927 | F37: =CFS!F12 -> 1835 | G37: =CFS!G12 -> 1235.2296 | H37: =CFS!H12 -> 2150.336 | I37: =CFS!I12 -> 2803.289 | ... K37: =CFS!K12 -> 4530.692
A39: 投资购买 | B39: =CFS!B14 -> 0 | C39: =CFS!C14 -> -29.898 | D39: =CFS!D14 -> -33.267 | E39: =CFS!E14 -> 0 | F39: =CFS!F14 -> 0 | G39: =CFS!G14 -> 0 | H39: =CFS!H14 -> 0 | I39: =CFS!I14 -> 0 | ... K39: =CFS!K14 -> 0
A40: 投资销售/到期 | B40: =CFS!B15 -> 3.06 | C40: =CFS!C15 -> 0 | D40: =CFS!D15 -> 0 | E40: =CFS!E15 -> 0 | F40: =CFS!F15 -> 0 | G40: =CFS!G15 -> 0 | H40: =CFS!H15 -> 0 | I40: =CFS!I15 -> 0 | ... K40: =CFS!K15 -> 0
... A60: 期初现金 | B60: =CFS!B35 -> 1983.473 | C60: =CFS!C35 -> 2208.946 | D60: =CFS!D35 -> 1697.928 | E60: =CFS!E35 -> 2205 | F60: =CFS!F35 -> 2427 | G60: =CFS!G35 -> 3017 | H60: =CFS!H35 -> 2997.2879 | I60: =CFS!I35 -> 3673.467 | ... K60: =CFS!K35 -> 6282.66
A62: 03393.HK in Millions CNY | B62: FY2021A | C62: FY2022A | D62: FY2023A | E62: FY2024A | F62: FY2025A | G62: FY2026E | H62: FY2027E | I62: FY2028E | J62: FY2029E | K62: FY2030E
A63: 资产负债表
A64: 现金及现金等价物 | B64: =BS!B3 -> 2578.946 | C64: =BS!C3 -> 2027.928 | D64: =BS!D3 -> 2644.896 | E64: =BS!E3 -> 2790.3 | F64: =BS!F3 -> 3015.242 | G64: =BS!G3 -> 2995.5299 | H64: =BS!H3 -> 3671.709 | I64: =BS!I3 -> 4746.1531 | ... K64: =BS!K3 -> 8534.0736
...

Sheet DCF Summary
A1: =IS!A1 -> 03393.HK in Millions CNY | B1: FY2026E | C1: FY2027E | D1: FY2028E | E1: FY2029E | F1: FY2030E
A2: 自由现金流 | B2: =CFS!G37 -> 515.60706 | C2: =CFS!H37 -> 1300.1238 | D2: =CFS!I37 -> 1776.0614 | E2: =CFS!J37 -> 2314.5963 | F2: =CFS!K37 -> 3111.5863
A3: 折现期 | B3: 0.5 | C3: =B3+1 -> 1.5 | D3: =C3+1 -> 2.5 | E3: =D3+1 -> 3.5 | F3: =E3+1 -> 4.5
A4: 折现因子 | B4: =1/((1+WACC)^B3) -> 0.96188689 | C4: =1/((1+WACC)^C3) -> 0.88996314 | D4: =1/((1+WACC)^D3) -> 0.82341738 | E4: =1/((1+WACC)^E3) -> 0.76184749 | F4: =1/((1+WACC)^F3) -> 0.7048814
A5: 自由现金流的现值 | B5: =B2*B4 -> 495.95567 | C5: =C2*C4 -> 1157.0622 | D5: =D2*D4 -> 1462.4398 | E5: =E2*E4 -> 1763.3694 | F5: =F2*F4 -> 2193.2993
A7: 财报货币/股票货币 (CNY/HKD) | B7: 1.13405
A8: 企业价值到股权价值的转换 - 换算成股票货币HKD | B8: 终端增长率法 | D8: 息税折旧摊销前利润倍数 (EBITDA Multiples)
A9: 自由现金流的现值总和 | B9: =SUM(B5:F5)*B7 -> 8020.145 | C9: =B9/(B11) -> 0.13724802
A10: 终端价值的现值 | B10: =F2*(1+TerminalGrowthRate)/(WACC-TerminalGrowthRate)*F4*B7 -> 50415.272 | C10: =B10/(B11) -> 0.86275198
A11: 企业价值 | B11: =B9+B10 -> 58435.417 | C11: =C9+C10 -> 1
A12: - 总债务 | B12: =-BS!F64*B7 -> -2820.2701
A13: - 优先股 | B13: =-BS!F36*B7 -> 0
A14: - 少数股东权益 | B14: =-BS!F41*B7 -> -2358.5189
A15: + 现金及现金等价物 | B15: =BS!F3*B7 -> 3419.4352
A16: 隐含股权价值 | B16: =SUM(B11:B15) -> 56676.063
A17: 加权平均流通股数 | B17: =IS!F22 -> 1384.2093
A18: 隐含每股股权价值 | B18: =IFERROR(B16/B17,"") -> 40.944719
A19: 当前股价 at 2026-03-31 15:23:53 | B19: 28.4
A20: 涨幅/跌幅 | B20: =IFERROR(B18/B19,0)-1 -> 0.44171547

Sheet SumFS
A1: 03393.HK in Millions CNY | B1: FY2024A | C1: FY2025A | D1: FY2026E | E1: FY2027E | F1: FY2028E | H1: 03393.HK in Millions CNY | I1: FY2024A | J1: FY2025A | K1: FY2026E | L1: FY2027E | M1: FY2028E
A2: 损益表 | H2: 资产负债表
A3: 营业收入 | B3: =IS!E3 -> 8716.541 | C3: =IS!F3 -> 10073.525 | D3: =IS!G3 -> 12341.082 | E3: =IS!H3 -> 14707.47 | F3: =IS!I3 -> 17228.145 | H3: 现金及现金等价物 | I3: =BS!E3 -> 2790.3 | J3: =BS!F3 -> 3015.242 | K3: =BS!G3 -> 2995.5299 | L3: =BS!H3 -> 3671.709 | M3: =BS!I3 -> 4746.1531
A4: 销售成本 | B4: =IS!E4 -> -5681.403 | C4: =IS!F4 -> -6476.605 | D4: =IS!G4 -> -7975.9373 | E4: =IS!H4 -> -9505.3144 | F4: =IS!I4 -> -11134.406 | H4: 短期投资 | I4: =BS!E4 -> 564.547 | J4: =BS!F4 -> 416.832 | K4: =BS!G4 -> 416.832 | L4: =BS!H4 -> 416.832 | M4: =BS!I4 -> 416.832
A5: 研究与开发费用 | B5: =IS!E5 -> -730.404 | C5: =IS!F5 -> -734.177 | D5: =IS!G5 -> -1031.0164 | E5: =IS!H5 -> -1228.7126 | F5: =IS!I5 -> -1439.2985 | H5: 应收款 (净值) | I5: =BS!E5 -> 6681.631 | J5: =BS!F5 -> 8023.896 | K5: =BS!G5 -> 9007.875 | L5: =BS!H5 -> 9929.2362 | M5: =BS!I5 -> 10686.974
A6: 一般和行政费用 | B6: =IS!E6 -> -367.796 | C6: =IS!F6 -> -413.202 | D6: =IS!G6 -> -528.00277 | E6: =IS!H6 -> -629.24671 | F6: =IS!I6 -> -737.09168 | H6: 存货 | I6: =BS!E6 -> 1264.093 | J6: =BS!F6 -> 1437.888 | K6: =BS!G6 -> 1783.226 | L6: =BS!H6 -> 2125.1576 | M6: =BS!I6 -> 2489.3828
A7: 销售和营销费用 | B7: =IS!E7 -> -737.643 | C7: =IS!F7 -> -788.91 | D7: =IS!G7 -> -1038.6916 | E7: =IS!H7 -> -1237.8596 | F7: =IS!I7 -> -1450.0131 | H7: 其他流动资产 | I7: =BS!E7 -> 473.495 | J7: =BS!F7 -> 424.959 | K7: =BS!G7 -> 626.70172 | L7: =BS!H7 -> 746.87108 | M7: =BS!I7 -> 874.87538
A8: 其他营业成本 | B8: =IS!E8 -> 332.338 | C8: =IS!F8 -> 238.47 | D8: =IS!G8 -> 376.74908 | E8: =IS!H8 -> 448.9903 | F8: =IS!I8 -> 525.94159 | H8: 流动资产总额 | I8: =BS!E8 -> 11774.066 | J8: =BS!F8 -> 13318.817 | K8: =BS!G8 -> 14830.165 | L8: =BS!H8 -> 16889.806 | M8: =BS!I8 -> 19214.218
A10: 营业利润 | B10: =IS!E10 -> 1531.633 | C10: =IS!F10 -> 1899.101 | D10: =IS!G10 -> 2144.1826 | E10: =IS!H10 -> 2555.3272 | F10: =IS!I10 -> 2993.2781 | H10: 物业、厂房及设备 (净值) | I10: =BS!E10 -> 2167.583 | J10: =BS!F10 -> 2333.133 | K10: =BS!G10 -> 2899.9814 | L10: =BS!H10 -> 3521.9461 | M10: =BS!I10 -> 4193.0099
A11: 利息费用 (净值) | B11: =IS!E11 -> -125.528 | C11: =IS!F11 -> -106.603 | D11: =IS!G11 -> 29.186942 | E11: =IS!H11 -> 28.578233 | F11: =IS!I11 -> 49.458643 | H11: 商誉 | I11: =BS!E11 -> 330.636 | J11: =BS!F11 -> 330.636 | K11: =BS!G11 -> 330.636 | L11: =BS!H11 -> 330.636 | M11: =BS!I11 -> 330.636
A12: 其他业务收入 (成本) | B12: =IS!E12 -> -198.517 | C12: =IS!F12 -> -47.643 | D12: =IS!G12 -> 0 | E12: =IS!H12 -> 0 | F12: =IS!I12 -> 0 | H12: 无形资产 | I12: =BS!E12 -> 511.578 | J12: =BS!F12 -> 519.259 | K12: =BS!G12 -> 674.46372 | L12: =BS!H12 -> 844.27739 | M12: =BS!I12 -> 1027.1051
H13: 长期投资 | I13: =BS!E13 -> 9.426 | J13: =BS!F13 -> 10.373 | K13: =BS!G13 -> 10.373 | L13: =BS!H13 -> 10.373 | M13: =BS!I13 -> 10.373
A14: 税前利润 | B14: =IS!E14 -> 1207.588 | C14: =IS!F14 -> 1744.855 | D14: =IS!G14 -> 2173.3695 | E14: =IS!H14 -> 2583.9054 | F14: =IS!I14 -> 3042.7367 | H14: 递延税资产 | I14: =BS!E14 -> 153.786 | J14: =BS!F14 -> 162.867 | K14: =BS!G14 -> 162.867 | L14: =BS!H14 -> 162.867 | M14: =BS!I14 -> 162.867
A15: 所得税费用 | B15: =IS!E15 -> -177.426 | C15: =IS!F15 -> -263.751 | D15: =IS!G15 -> -300.23425 | E15: =IS!H15 -> -356.94662 | F15: =IS!I15 -> -420.33063 | H15: 其他非流动资产 | I15: =BS!E15 -> 779.823 | J15: =BS!F15 -> 907.827 | K15: =BS!G15 -> 993.59337 | L15: =BS!H15 -> 1184.1138 | M15: =BS!I15 -> 1387.056
H16: 非流动资产总额 | I16: =BS!E16 -> 3952.832 | J16: =BS!F16 -> 4264.095 | K16: =BS!G16 -> 5071.9145 | L16: =BS!H16 -> 6054.2133 | M16: =BS!I16 -> 7111.047
A17: 净利润 | B17: =IS!E17 -> 1030.162 | C17: =IS!F17 -> 1481.104 | D17: =IS!G17 -> 1873.1353 | E17: =IS!H17 -> 2226.9588 | F17: =IS!I17 -> 2622.4061 | H17: 资产总额 | I17: =BS!E17 -> 15726.898 | J17: =BS!F17 -> 17582.912 | K17: =BS!G17 -> 19902.079 | L17: =BS!H17 -> 22944.019 | M17: =BS!I17 -> 26325.265
A19: 03393.HK in Millions CNY | B19: FY2024A | C19: FY2025A | D19: FY2026E | E19: FY2027E | F19: FY2028E | H19: 应付账款 | I19: =BS!E19 -> 5619.291 | J19: =BS!F19 -> 6548.212 | K19: =BS!G19 -> 7242.0539 | L19: =BS!H19 -> 8370.2901 | M19: =BS!I19 -> 9499.8002
A20: 现金流量表 | H20: 短期债务 | I20: =BS!E20 -> 1615.723 | J20: =BS!F20 -> 1400.82 | K20: =BS!G20 -> 1400.82 | L20: =BS!H20 -> 1400.82 | M20: =BS!I20 -> 1400.82
A21: 净利润 | B21: =B17 -> 1030.162 | C21: =C17 -> 1481.104 | D21: =D17 -> 1873.1353 | E21: =E17 -> 2226.9588 | F21: =F17 -> 2622.4061 | H21: 应交税金 | I21: =BS!E21 -> 110.795 | J21: =BS!F21 -> 137.103 | K21: =BS!G21 -> 137.103 | L21: =BS!H21 -> 137.103 | M21: =BS!I21 -> 137.103
A22: 折旧和摊销 | B22: =CFS!E4 -> 316 | C22: =CFS!F4 -> 353 | D22: =CFS!G4 -> 238.69435 | E22: =CFS!H4 -> 353.19132 | F22: =CFS!I4 -> 487.31163 | H22: 其他流动负债 | I22: =BS!E23 -> 30.301 | J22: =BS!F23 -> 9.257 | K22: =BS!G23 -> 48.850145 | L22: =BS!H23 -> 58.217106 | M22: =BS!I23 -> 68.194785
A23: 经营活动提供的净现金 | B23: =CFS!E12 -> 927 | C23: =CFS!F12 -> 1835 | D23: =CFS!G12 -> 1235.2296 | E23: =CFS!H12 -> 2150.336 | F23: =CFS!I12 -> 2803.289 | H23: 流动负债总额 | I23: =BS!E24 -> 7376.11 | J23: =BS!F24 -> 8095.392 | K23: =BS!G24 -> 8828.827 | L23: =BS!H24 -> 9966.4302 | M23: =BS!I24 -> 11105.918
A24: 投资活动使用的净现金 | B24: =CFS!E22 -> -171 | C24: =CFS!F22 -> -605 | D24: =CFS!G22 -> -960.74746 | E24: =CFS!H22 -> -1144.9697 | F24: =CFS!I22 -> -1341.2031
A25: 筹资活动提供的净现金 | B25: =CFS!E30 -> -534 | C25: =CFS!F30 -> -640 | D25: =CFS!G30 -> -294.19425 | E25: =CFS!H30 -> -329.18718 | F25: =CFS!I30 -> -387.64187 | H25: 长期债务 | I25: =BS!E26 -> 971.473 | J25: =BS!F26 -> 1086.081 | K25: =BS!G26 -> 1086.081 | L25: =BS!H26 -> 1086.081 | M25: =BS!I26 -> 1086.081
A26: 外汇变动对现金的影响 | B26: 0 | C26: 0 | D26: 0 | E26: 0 | F26: 0 | H26: 递延税负债 | I26: =BS!E28 -> 38.872 | J26: =BS!F28 -> 45.686 | K26: =BS!G28 -> 45.686 | L26: =BS!H28 -> 45.686 | M26: =BS!I28 -> 45.686
A27: 现金净变化 | B27: =CFS!E33 -> 222 | C27: =CFS!F33 -> 590 | D27: =CFS!G33 -> -19.712089 | E27: =CFS!H33 -> 676.17909 | F27: =CFS!I33 -> 1074.4441 | H27: 租赁负债 | I27: =BS!E29 -> 19.515 | J27: =BS!F29 -> 12.816 | K27: =BS!G29 -> 12.816 | L27: =BS!H29 -> 12.816 | M27: =BS!I29 -> 12.816
A28: 期末现金 | B28: =CFS!E34 -> 2427 | C28: =CFS!F34 -> 3017 | D28: =CFS!G34 -> 2997.2879 | E28: =CFS!H34 -> 3673.467 | F28: =CFS!I34 -> 4747.9111 | H28: 非流动负债总额 | I28: =BS!E31 -> 1029.86 | J28: =BS!F31 -> 1172.031 | K28: =BS!G31 -> 1178.822 | L28: =BS!H31 -> 1185.3873 | M28: =BS!I31 -> 1192.3807
A29: 期初现金 | B29: =CFS!E35 -> 2205 | C29: =CFS!F35 -> 2427 | D29: =CFS!G35 -> 3017 | E29: =CFS!H35 -> 2997.2879 | F29: =CFS!I35 -> 3673.467 | H29: 负债总额 | I29: =BS!E32 -> 8405.97 | J29: =BS!F32 -> 9267.423 | K29: =BS!G32 -> 10007.649 | L29: =BS!H32 -> 11151.818 | M29: =BS!I32 -> 12298.299
A31: 03393.HK in Millions CNY | B31: FY2024A | C31: FY2025A | D31: FY2026E | E31: FY2027E | F31: FY2028E | H31: 实收资本 | I31: =BS!E34 -> 9.906 | J31: =BS!F34 -> 9.906 | K31: =BS!G34 -> 9.906 | L31: =BS!H34 -> 9.906 | M31: =BS!I34 -> 9.906
A32: 财务比例 | H32: 累计其他综合收益 (亏损) | I32: =BS!E38 -> 5422.701 | J32: =BS!F38 -> 6225.852 | K32: =BS!G38 -> 6225.852 | L32: =BS!H38 -> 6225.852 | M32: =BS!I38 -> 6225.852
A33: 收入增长率 | B33: =IS!E26 -> 0.20190487 | C33: =IS!F26 -> 0.15567919 | D33: =IS!G26 -> 0.2251006 | E33: =IS!H26 -> 0.19174889 | F33: =IS!I26 -> 0.17138741 | H33: 股东权益总额 | I33: =BS!E40 -> 5432.607 | J33: =BS!F40 -> 6235.758 | K33: =BS!G40 -> 7435.2775 | L33: =BS!H40 -> 8861.3787 | M33: =BS!I40 -> 10540.717
A34: 毛利率 | B34: =IS!E27 -> 0.34820441 | C34: =IS!F27 -> 0.35706667 | D34: =IS!G27 -> 0.3537084 | E34: =IS!H27 -> 0.3537084 | F34: =IS!I27 -> 0.3537084 | H34: 少数股东权益 | I34: =BS!E41 -> 1888.321 | J34: =BS!F41 -> 2079.731 | K34: =BS!G41 -> 2459.1525 | L34: =BS!H41 -> 2930.8229 | M34: =BS!I41 -> 3486.2492
A35: 营业利润率 | B35: =IS!E36 -> 0.17571569 | C35: =IS!F36 -> 0.18852398 | D35: =IS!G36 -> 0.17374349 | E35: =IS!H36 -> 0.17374349 | F35: =IS!I36 -> 0.17374349 | H35: 权益总额 | I35: =BS!E42 -> 7320.928 | J35: =BS!F42 -> 8315.489 | K35: =BS!G42 -> 9894.43 | L35: =BS!H42 -> 11792.202 | M35: =BS!I42 -> 14026.966
A36: 股本回报率 (ROE) | B36: =IS!E45 -> 0.18962572 | C36: =IS!F45 -> 0.23751788 | D36: =IS!G45 -> 0.2519254 | E36: =IS!H45 -> 0.25131065 | F36: =IS!I45 -> 0.24878822 | H36: 负债和权益总额 | I36: =BS!E43 -> 15726.898 | J36: =BS!F43 -> 17582.912 | K36: =BS!G43 -> 19902.079 | L36: =BS!H43 -> 22944.019 | M36: =BS!I43 -> 26325.265
A37: 资产周转率 | B37: =IS!E46 -> 0.55424414 | C37: =IS!F46 -> 0.57291562 | D37: =IS!G46 -> 0.62009007 | E37: =IS!H46 -> 0.64101543 | F37: =IS!I46 -> 0.6544339

Sheet Key Info & Assumptions
A1: 关键信息和假设
A2: 股票代码 | B2: 03393.HK
A3: 公司名称 | B3: Wasion Holdings Limited
A4: 国家或地区 | B4: HK
A5: 交易所 | B5: HKSE
A6: 行业 | B6: Industrials
A7: 子行业 | B7: Electrical Equipment & Parts
A8: 期间 | B8: Annual Reports
A9: 历史数据期间 | B9: 5
A10: 估算期间 | B10: 5
A11: 终端增长率 | B11: 0.03
A12: 终端息税折旧摊销前利润倍数 | B12: 6
A13: 报告单位 | B13: 1000000
A15: 加权平均资本成本 (WACC) 计算
A16: 无风险利率 | B16: 0.03088
A17: 无风险利率的溢价 | B17: 0
A18: 税前债务成本 | B18: =RiskFreeRate+SpreadOverRiskFreeRate -> 0.03088
A19: 边际税率 | B19: 0.165
A20: 税后债务成本 | B20: =CostOfDebtBeforeTax*(1-MarginalTaxRate) -> 0.0257848
A21: 无风险利率 | B21: =RiskFreeRate -> 0.03088
A22: 贝塔系数 | B22: 1
A23: 市场风险溢价 | B23: 0.0548
A24: 其他风险溢价 | B24: 0
A25: 股权成本 | B25: =RiskFreeRate+Beta*(MarketRiskPremium)+OtherRiskPremium -> 0.08568
A26: 总债务价值 | B26: =BS!F64 -> 2486.901
A27: 权益市场价值 | B27: =28140244370/ReportUnit -> 28140.244
A28: 总资本 | B28: =CurrentTotalDebt+MarketValueOfEquity -> 30627.145
A29: 债务权重 | B29: =CurrentTotalDebt/TotalCapital -> 0.081199242
A30: 股权权重 | B30: =MarketValueOfEquity/TotalCapital -> 0.91880076
A31: 加权平均资本成本 (WACC) | B31: =WeightOfDebt*CostOfDebtAfterTax+WeightOfEquity*CostOfEquity -> 0.080816555

Sheet Statements>>

Sheet IS
A1: ="03393.HK in "&IF(ReportUnit<1000, "", IF(ReportUnit<1000000, "Thousands", IF(ReportUnit<1000000000, "Millions", "Billions")))&" CNY" -> 03393.HK in Millions CNY | B1: FY2021A | C1: FY2022A | D1: FY2023A | E1: FY2024A | F1: FY2025A | G1: FY2026E | H1: FY2027E | I1: FY2028E | J1: FY2029E | K1: FY2030E
A2: 损益表
A3: 营业收入 | B3: =4590762000/ReportUnit -> 4590.762 | C3: =5855844000/ReportUnit -> 5855.844 | D3: =7252272000/ReportUnit -> 7252.272 | E3: =8716541000/ReportUnit -> 8716.541 | F3: =10073525000/ReportUnit -> 10073.525 | G3: =F3*(1+G26) -> 12341.082 | H3: =G3*(1+H26) -> 14707.47 | I3: =H3*(1+I26) -> 17228.145 | J3: =I3*(1+J26) -> 19872.946 | K3: =J3*(1+K26) -> 22613.098
A4: 销售成本 | B4: =-3091992000/ReportUnit -> -3091.992 | C4: =-3926620000/ReportUnit -> -3926.62 | D4: =-4671521000/ReportUnit -> -4671.521 | E4: =-5681403000/ReportUnit -> -5681.403 | F4: =-6476605000/ReportUnit -> -6476.605 | G4: =-G3+G52 -> -7975.9373 | H4: =-H3+H52 -> -9505.3144 | I4: =-I3+I52 -> -11134.406 | J4: =-J3+J52 -> -12843.718 | K4: =-K3+K52 -> -14614.655
A5: 研究与开发费用 | B5: =-424476000/ReportUnit -> -424.476 | C5: =-577443000/ReportUnit -> -577.443 | D5: =-681375000/ReportUnit -> -681.375 | E5: =-730404000/ReportUnit -> -730.404 | F5: =-734177000/ReportUnit -> -734.177 | G5: =G3*G28*-1 -> -1031.0164 | H5: =H3*H28*-1 -> -1228.7126 | I5: =I3*I28*-1 -> -1439.2985 | J5: =J3*J28*-1 -> -1660.2542 | K5: =K3*K28*-1 -> -1889.1759
A6: 一般和行政费用 | B6: =-177407000/ReportUnit -> -177.407 | C6: =-215652000/ReportUnit -> -215.652 | D6: =-327358000/ReportUnit -> -327.358 | E6: =-367796000/ReportUnit -> -367.796 | F6: =-413202000/ReportUnit -> -413.202 | G6: =G3*G29*-1 -> -528.00277 | H6: =H3*H29*-1 -> -629.24671 | I6: =I3*I29*-1 -> -737.09168 | J6: =J3*J29*-1 -> -850.24724 | K6: =K3*K29*-1 -> -967.48232
A7: 销售和营销费用 | B7: =-437708000/ReportUnit -> -437.708 | C7: =-512914000/ReportUnit -> -512.914 | D7: =-649479000/ReportUnit -> -649.479 | E7: =-737643000/ReportUnit -> -737.643 | F7: =-788910000/ReportUnit -> -788.91 | G7: =G3*G30*-1 -> -1038.6916 | H7: =H3*H30*-1 -> -1237.8596 | I7: =I3*I30*-1 -> -1450.0131 | J7: =J3*J30*-1 -> -1672.6137 | K7: =K3*K30*-1 -> -1903.2396
A8: 其他营业成本 | B8: =252005000/ReportUnit -> 252.005 | C8: =256866000/ReportUnit -> 256.866 | D8: =216001000/ReportUnit -> 216.001 | E8: =332338000/ReportUnit -> 332.338 | F8: =238470000/ReportUnit -> 238.47 | G8: =G3*G31*-1 -> 376.74908 | H8: =H3*H31*-1 -> 448.9903 | I8: =I3*I31*-1 -> 525.94159 | J8: =J3*J31*-1 -> 606.68217 | K8: =K3*K31*-1 -> 690.33364
A10: 营业利润 | B10: =711184000/ReportUnit -> 711.184 | C10: =880081000/ReportUnit -> 880.081 | D10: =1138540000/ReportUnit -> 1138.54 | E10: =1531633000/ReportUnit -> 1531.633 | F10: =1899101000/ReportUnit -> 1899.101 | G10: =G3+G4+G5+G6+G7+G8 -> 2144.1826 | H10: =H3+H4+H5+H6+H7+H8 -> 2555.3272 | I10: =I3+I4+I5+I6+I7+I8 -> 2993.2781 | J10: =J3+J4+J5+J6+J7+J8 -> 3452.795 | K10: =K3+K4+K5+K6+K7+K8 -> 3928.8785
A11: 利息费用 (净值) | B11: =-99267000/ReportUnit -> -99.267 | C11: =-112500000/ReportUnit -> -112.5 | D11: =-131530000/ReportUnit -> -131.53 | E11: =-125528000/ReportUnit -> -125.528 | F11: =-106603000/ReportUnit -> -106.603 | G11: =Cash!G20+Cash!G14 -> 29.186942 | H11: =Cash!H20+Cash!H14 -> 28.578233 | I11: =Cash!I20+Cash!I14 -> 49.458643 | J11: =Cash!J20+Cash!J14 -> 82.637476 | K11: =Cash!K20+Cash!K14 -> 130.03052
A12: 其他业务收入 (成本) | B12: =-139184000/ReportUnit -> -139.184 | C12: =-185147000/ReportUnit -> -185.147 | D12: =-146278000/ReportUnit -> -146.278 | E12: =-198517000/ReportUnit -> -198.517 | F12: =-47643000/ReportUnit -> -47.643 | G12: ='D&A'!G12+'D&A'!G34 -> 0 | H12: ='D&A'!H12+'D&A'!H34 -> 0 | I12: ='D&A'!I12+'D&A'!I34 -> 0 | J12: ='D&A'!J12+'D&A'!J34 -> 0 | K12: ='D&A'!K12+'D&A'!K34 -> 0
A14: 税前利润 | B14: =472733000/ReportUnit -> 472.733 | C14: =582434000/ReportUnit -> 582.434 | D14: =860732000/ReportUnit -> 860.732 | E14: =1207588000/ReportUnit -> 1207.588 | F14: =1744855000/ReportUnit -> 1744.855 | G14: =G10+G12+G11 -> 2173.3695 | H14: =H10+H12+H11 -> 2583.9054 | I14: =I10+I12+I11 -> 3042.7367 | J14: =J10+J12+J11 -> 3535.4324 | K14: =K10+K12+K11 -> 4058.909
A15: 所得税费用 | B15: =-44759000/ReportUnit -> -44.759 | C15: =-71274000/ReportUnit -> -71.274 | D15: =-100139000/ReportUnit -> -100.139 | E15: =-177426000/ReportUnit -> -177.426 | F15: =-263751000/ReportUnit -> -263.751 | G15: =Tax!G6 -> -300.23425 | H15: =Tax!H6 -> -356.94662 | I15: =Tax!I6 -> -420.33063 | J15: =Tax!J6 -> -488.39274 | K15: =Tax!K6 -> -560.70699
A17: 净利润 | B17: =427974000/ReportUnit -> 427.974 | C17: =511160000/ReportUnit -> 511.16 | D17: =760593000/ReportUnit -> 760.593 | E17: =1030162000/ReportUnit -> 1030.162 | F17: =1481104000/ReportUnit -> 1481.104 | G17: =G14+G15 -> 1873.1353 | H17: =H14+H15 -> 2226.9588 | I17: =I14+I15 -> 2622.4061 | J17: =J14+J15 -> 3047.0397 | K17: =K14+K15 -> 3498.202
A18: 归属于母公司股东的净利润 | B18: =268084000/ReportUnit -> 268.084 | C18: =323797000/ReportUnit -> 323.797 | D18: =521233000/ReportUnit -> 521.233 | E18: =705612000/ReportUnit -> 705.612 | F18: =1058246000/ReportUnit -> 1058.246 | G18: =G17-G19 -> 1450.2773 | H18: =H17-H19 -> 1804.1008 | I18: =I17-I19 -> 2199.5481 | J18: =J17-J19 -> 2624.1817 | K18: =K17-K19 -> 3075.344
A19: 少数股东损益 | B19: =159890000/ReportUnit -> 159.89 | C19: =187363000/ReportUnit -> 187.363 | D19: =239360000/ReportUnit -> 239.36 | E19: =324550000/ReportUnit -> 324.55 | F19: =422858000/ReportUnit -> 422.858 | G19: =F19 -> 422.858 | H19: =G19 -> 422.858 | I19: =H19 -> 422.858 | J19: =I19 -> 422.858 | K19: =J19 -> 422.858
A20: 每股收益 | B20: 0.27 | C20: 0.33 | D20: 0.53 | E20: 0.71 | F20: 1.07 | G20: =IFERROR(G18/G22,0) -> 1.0477297 | H20: =IFERROR(H18/H22,0) -> 1.3033439 | I20: =IFERROR(I18/I22,0) -> 1.5890285 | J20: =IFERROR(J18/J22,0) -> 1.8957983 | K20: =IFERROR(K18/K22,0) -> 2.2217333
A21: 摊薄每股收益 | B21: 0.27 | C21: 0.33 | D21: 0.53 | E21: 0.71 | F21: 1.07 | G21: =IFERROR(G18/G23,0) -> 1.0477297 | H21: =IFERROR(H18/H23,0) -> 1.3033439 | I21: =IFERROR(I18/I23,0) -> 1.5890285 | J21: =IFERROR(J18/J23,0) -> 1.8957983 | K21: =IFERROR(K18/K23,0) -> 2.2217333
A22: 加权平均流通股数 | B22: =IFERROR(B17/B20,0) -> 1585.0889 | C22: =IFERROR(C17/C20,0) -> 1548.9697 | D22: =IFERROR(D17/D20,0) -> 1435.0811 | E22: =IFERROR(E17/E20,0) -> 1450.9324 | F22: =IFERROR(F17/F20,0) -> 1384.2093 | G22: =F22+IFERROR((Cash!G26/Cash!G25)+(Cash!G27/Cash!G25),0) -> 1384.2093 | H22: =G22+IFERROR((Cash!H26/Cash!H25)+(Cash!H27/Cash!H25),0) -> 1384.2093 | I22: =H22+IFERROR((Cash!I26/Cash!I25)+(Cash!I27/Cash!I25),0) -> 1384.2093 | J22: =I22+IFERROR((Cash!J26/Cash!J25)+(Cash!J27/Cash!J25),0) -> 1384.2093 | K22: =J22+IFERROR((Cash!K26/Cash!K25)+(Cash!K27/Cash!K25),0) -> 1384.2093
A23: 摊薄加权平均流通股数 | B23: =IFERROR(B17/B21,0) -> 1585.0889 | C23: =IFERROR(C17/C21,0) -> 1548.9697 | D23: =IFERROR(D17/D21,0) -> 1435.0811 | E23: =IFERROR(E17/E21,0) -> 1450.9324 | F23: =IFERROR(F17/F21,0) -> 1384.2093 | G23: =F23+IFERROR((Cash!G26/Cash!G25)+(Cash!G27/Cash!G25),0) -> 1384.2093 | H23: =G23+IFERROR((Cash!H26/Cash!H25)+(Cash!H27/Cash!H25),0) -> 1384.2093 | I23: =H23+IFERROR((Cash!I26/Cash!I25)+(Cash!I27/Cash!I25),0) -> 1384.2093 | J23: =I23+IFERROR((Cash!J26/Cash!J25)+(Cash!J27/Cash!J25),0) -> 1384.2093 | K23: =J23+IFERROR((Cash!K26/Cash!K25)+(Cash!K27/Cash!K25),0) -> 1384.2093
A25: 利润率和增长驱动因素分析
A26: 收入增长率 | B26: =Revenue!B3 -> 0 | C26: =Revenue!C3 -> 0.27557125 | D26: =Revenue!D3 -> 0.23846742 | E26: =Revenue!E3 -> 0.20190487 | F26: =Revenue!F3 -> 0.15567919 | G26: =Revenue!G3 -> 0.2251006 | H26: =Revenue!H3 -> 0.19174889 | I26: =Revenue!I3 -> 0.17138741 | ... K26: =Revenue!K3 -> 0.13788352
A27: 毛利率 | B27: =IFERROR(B52/B3,0) -> 0.32647521 | C27: =IFERROR(C52/C3,0) -> 0.32945277 | D27: =IFERROR(D52/D3,0) -> 0.35585414 | E27: =IFERROR(E52/E3,0) -> 0.34820441 | F27: =IFERROR(F52/F3,0) -> 0.35706667 | G27: =IFERROR(AVERAGEIF(D27:F27,"<>0"),0) -> 0.3537084 | H27: =G27 -> 0.3537084 | I27: =H27 -> 0.3537084 | J27: =I27 -> 0.3537084 | K27: =J27 -> 0.3537084
A28: 研发费用占销售额的百分比 | B28: =IFERROR(B5/B3*-1,0) -> 0.092463081 | C28: =IFERROR(C5/C3*-1,0) -> 0.098609697 | D28: =IFERROR(D5/D3*-1,0) -> 0.093953316 | E28: =IFERROR(E5/E3*-1,0) -> 0.083795166 | F28: =IFERROR(F5/F3*-1,0) -> 0.072881836 | G28: =IFERROR(AVERAGEIF(D28:F28,"<>0"),0) -> 0.083543439 | H28: =G28 -> 0.083543439 | I28: =H28 -> 0.083543439 | J28: =I28 -> 0.083543439 | K28: =J28 -> 0.083543439
A29: 一般和行政费用占销售额的百分比 | B29: =IFERROR(B6/B3*-1,0) -> 0.038644347 | C29: =IFERROR(C6/C3*-1,0) -> 0.036826801 | D29: =IFERROR(D6/D3*-1,0) -> 0.045138682 | E29: =IFERROR(E6/E3*-1,0) -> 0.042195178 | F29: =IFERROR(F6/F3*-1,0) -> 0.041018611 | G29: =IFERROR(AVERAGEIF(D29:F29,"<>0"),0) -> 0.042784157 | H29: =G29 -> 0.042784157 | I29: =H29 -> 0.042784157 | J29: =I29 -> 0.042784157 | K29: =J29 -> 0.042784157
A30: 销售和营销费用占销售额的百分比 | B30: =IFERROR(B7/B3*-1,0) -> 0.095345391 | C30: =IFERROR(C7/C3*-1,0) -> 0.087590107 | D30: =IFERROR(D7/D3*-1,0) -> 0.089555246 | E30: =IFERROR(E7/E3*-1,0) -> 0.084625656 | F30: =IFERROR(F7/F3*-1,0) -> 0.078315188 | G30: =IFERROR(AVERAGEIF(D30:F30,"<>0"),0) -> 0.084165363 | H30: =G30 -> 0.084165363 | I30: =H30 -> 0.084165363 | J30: =I30 -> 0.084165363 | K30: =J30 -> 0.084165363
A31: 其他营业成本占销售额的百分比 | B31: =IFERROR(B8/B3*-1,0) -> -0.054893937 | C31: =IFERROR(C8/C3*-1,0) -> -0.043864898 | D31: =IFERROR(D8/D3*-1,0) -> -0.029783908 | E31: =IFERROR(E8/E3*-1,0) -> -0.03812728 | F31: =IFERROR(F8/F3*-1,0) -> -0.023672945 | G31: =IFERROR(AVERAGEIF(D31:F31,"<>0"),0) -> -0.030528044 | H31: =G31 -> -0.030528044 | I31: =H31 -> -0.030528044 | J31: =I31 -> -0.030528044 | K31: =J31 -> -0.030528044
A32: 折旧和摊销 | B32: =219222000/ReportUnit -> 219.222 | C32: =266999000/ReportUnit -> 266.999 | D32: =276812000/ReportUnit -> 276.812 | E32: 316 | F32: 353 | G32: =CFS!G4 -> 238.69435 | H32: =CFS!H4 -> 353.19132 | I32: =CFS!I4 -> 487.31163 | J32: =CFS!J4 -> 642.02159 | K32: =CFS!K4 -> 818.0635
A33: 折旧和摊销占销售额的百分比 | B33: =IFERROR(B32/B3,0) -> 0.047752857 | C33: =IFERROR(C32/C3,0) -> 0.045595306 | D33: =IFERROR(D32/D3,0) -> 0.038169004 | E33: =IFERROR(E32/E3,0) -> 0.036252913 | F33: =IFERROR(F32/F3,0) -> 0.035042351 | G33: =IFERROR(G32/G3,0) -> 0.019341445 | H33: =IFERROR(H32/H3,0) -> 0.024014417 | I33: =IFERROR(I32/I3,0) -> 0.028285786 | ... K33: =IFERROR(K32/K3,0) -> 0.036176534
A34: 息税折旧摊销前利润 (EBITDA) | B34: =B10+B32-B12 -> 1069.59 | C34: =C10+C32-C12 -> 1332.227 | D34: =D10+D32-D12 -> 1561.63 | E34: =E10+E32-E12 -> 2046.15 | F34: =F10+F32-F12 -> 2299.744 | G34: =G10+G32-G12 -> 2382.8769 | H34: =H10+H32-H12 -> 2908.5185 | I34: =I10+I32-I12 -> 3480.5897 | ... K34: =K10+K32-K12 -> 4746.942
A35: 息税折旧摊销前利润率 (EBITDA Margin) | B35: =IFERROR(B34/B3,0) -> 0.23298746 | C35: =IFERROR(C34/C3,0) -> 0.22750384 | D35: =IFERROR(D34/D3,0) -> 0.21532976 | E35: =IFERROR(E34/E3,0) -> 0.23474335 | F35: =IFERROR(F34/F3,0) -> 0.22829585 | G35: =IFERROR(G34/G3,0) -> 0.19308493 | H35: =IFERROR(H34/H3,0) -> 0.19775791 | I35: =IFERROR(I34/I3,0) -> 0.20202927 | ... K35: =IFERROR(K34/K3,0) -> 0.20992002
A36: 营业利润率 | B36: =IFERROR(B10/B3,0) -> 0.15491633 | C36: =IFERROR(C10/C3,0) -> 0.15029106 | D36: =IFERROR(D10/D3,0) -> 0.1569908 | E36: =IFERROR(E10/E3,0) -> 0.17571569 | F36: =IFERROR(F10/F3,0) -> 0.18852398 | G36: =IFERROR(G10/G3,0) -> 0.17374349 | H36: =IFERROR(H10/H3,0) -> 0.17374349 | I36: =IFERROR(I10/I3,0) -> 0.17374349 | ... K36: =IFERROR(K10/K3,0) -> 0.17374349
A37: 税前利润率 | B37: =IFERROR(B14/B3,0) -> 0.10297484 | C37: =IFERROR(C14/C3,0) -> 0.099462008 | D37: =IFERROR(D14/D3,0) -> 0.11868446 | E37: =IFERROR(E14/E3,0) -> 0.13853982 | F37: =IFERROR(F14/F3,0) -> 0.17321196 | G37: =IFERROR(G14/G3,0) -> 0.17610851 | H37: =IFERROR(H14/H3,0) -> 0.1756866 | I37: =IFERROR(I14/I3,0) -> 0.17661429 | ... K37: =IFERROR(K14/K3,0) -> 0.17949372
A38: 净利润率 | B38: =IFERROR(B17/B3,0) -> 0.093225046 | C38: =IFERROR(C17/C3,0) -> 0.087290577 | D38: =IFERROR(D17/D3,0) -> 0.10487651 | E38: =IFERROR(E17/E3,0) -> 0.11818472 | F38: =IFERROR(F17/F3,0) -> 0.14702937 | G38: =IFERROR(G17/G3,0) -> 0.15178048 | H38: =IFERROR(H17/H3,0) -> 0.15141685 | I38: =IFERROR(I17/I3,0) -> 0.15221639 | ... K38: =IFERROR(K17/K3,0) -> 0.15469805
A40: 其他损益表假设
A41: 净利息费用比率 | B41: =IFERROR(B11/BS!B65,0) -> 0.61823176 | C41: =IFERROR(C11/BS!C65,0) -> 0.56626567 | D41: =IFERROR(D11/BS!D65,0) -> 0.1300544 | E41: =IFERROR(E11/BS!E65,0) -> 0.16352223 | F41: =IFERROR(F11/BS!F65,0) -> 0.11278676 | G41: =IFERROR(G11/BS!G65,0) -> -0.031537736 | H41: =IFERROR(H11/BS!H65,0) -> -0.017843106 | I41: =IFERROR(I11/BS!I65,0) -> -0.018481723 | ... K41: =IFERROR(K11/BS!K65,0) -> -0.020116094
A42: 有效税率 | B42: =IFERROR(B15/B14*-1,0) -> 0.094681353 | C42: =IFERROR(C15/C14*-1,0) -> 0.12237266 | D42: =IFERROR(D15/D14*-1,0) -> 0.11634167 | E42: =IFERROR(E15/E14*-1,0) -> 0.14692594 | F42: =IFERROR(F15/F14*-1,0) -> 0.15115927 | G42: =IFERROR(G15/-IF(G14>0,G14,0),0) -> 0.13814229 | H42: =IFERROR(H15/-IF(H14>0,H14,0),0) -> 0.13814229 | I42: =IFERROR(I15/-IF(I14>0,I14,0),0) -> 0.13814229 | J42: =IFERROR(J15/-IF(J14>0,J14,0),0) -> 0.13814229 | K42: =IFERROR(K15/-IF(K14>0,K14,0),0) -> 0.13814229
A44: 杜邦分析
A45: 股本回报率 (ROE) | B45: =IFERROR(B17/BS!B40,0) -> 0.092396554 | C45: =IFERROR(C17/BS!C40,0) -> 0.10978749 | D45: =IFERROR(D17/BS!D40,0) -> 0.14721242 | E45: =IFERROR(E17/BS!E40,0) -> 0.18962572 | F45: =IFERROR(F17/BS!F40,0) -> 0.23751788 | G45: =IFERROR(G17/BS!G40,0) -> 0.2519254 | H45: =IFERROR(H17/BS!H40,0) -> 0.25131065 | I45: =IFERROR(I17/BS!I40,0) -> 0.24878822 | ... K45: =IFERROR(K17/BS!K40,0) -> 0.2374534
A46: 资产周转率 | B46: =IFERROR(B3/BS!B17,0) -> 0.36227207 | C46: =IFERROR(C3/BS!C17,0) -> 0.44954854 | D46: =IFERROR(D3/BS!D17,0) -> 0.5224935 | E46: =IFERROR(E3/BS!E17,0) -> 0.55424414 | F46: =IFERROR(F3/BS!F17,0) -> 0.57291562 | G46: =IFERROR(G3/BS!G17,0) -> 0.62009007 | H46: =IFERROR(H3/BS!H17,0) -> 0.64101543 | I46: =IFERROR(I3/BS!I17,0) -> 0.6544339 | ... K46: =IFERROR(K3/BS!K17,0) -> 0.65912078
...

Sheet BS
A1: ="03393.HK in "&IF(ReportUnit<1000, "", IF(ReportUnit<1000000, "Thousands", IF(ReportUnit<1000000000, "Millions", "Billions")))&" CNY" -> 03393.HK in Millions CNY | B1: FY2021A | C1: FY2022A | D1: FY2023A | E1: FY2024A | F1: FY2025A | G1: FY2026E | H1: FY2027E | I1: FY2028E | J1: FY2029E | K1: FY2030E
A2: 资产负债表
A3: 现金及现金等价物 | B3: =2578946000/ReportUnit -> 2578.946 | C3: =2027928000/ReportUnit -> 2027.928 | D3: =2644896000/ReportUnit -> 2644.896 | E3: =2790300000/ReportUnit -> 2790.3 | F3: =3015242000/ReportUnit -> 3015.242 | G3: =F3+CFS!G33 -> 2995.5299 | H3: =G3+CFS!H33 -> 3671.709 | I3: =H3+CFS!I33 -> 4746.1531 | J3: =I3+CFS!J33 -> 6280.902 | K3: =J3+CFS!K33 -> 8534.0736
A4: 短期投资 | B4: =418521000/ReportUnit -> 418.521 | C4: =832384000/ReportUnit -> 832.384 | D4: =880896000/ReportUnit -> 880.896 | E4: =564547000/ReportUnit -> 564.547 | F4: =416832000/ReportUnit -> 416.832 | G4: =Cash!G10 -> 416.832 | H4: =Cash!H10 -> 416.832 | I4: =Cash!I10 -> 416.832 | J4: =Cash!J10 -> 416.832 | K4: =Cash!K10 -> 416.832
A5: 应收款 (净值) | B5: =5032803000/ReportUnit -> 5032.803 | C5: =5302441000/ReportUnit -> 5302.441 | D5: =5352833000/ReportUnit -> 5352.833 | E5: =6681631000/ReportUnit -> 6681.631 | F5: =8023896000/ReportUnit -> 8023.896 | G5: =IFERROR(G46/365*IS!G3,0) -> 9007.875 | H5: =IFERROR(H46/365*IS!H3,0) -> 9929.2362 | I5: =IFERROR(I46/365*IS!I3,0) -> 10686.974 | J5: =IFERROR(J46/365*IS!J3,0) -> 11238.67 | K5: =IFERROR(K46/365*IS!K3,0) -> 11549.224
A6: 存货 | B6: =990758000/ReportUnit -> 990.758 | C6: =1080835000/ReportUnit -> 1080.835 | D6: =1205919000/ReportUnit -> 1205.919 | E6: =1264093000/ReportUnit -> 1264.093 | F6: =1437888000/ReportUnit -> 1437.888 | G6: =IFERROR(G47/365*IS!G4*-1,0) -> 1783.226 | H6: =IFERROR(H47/365*IS!H4*-1,0) -> 2125.1576 | I6: =IFERROR(I47/365*IS!I4*-1,0) -> 2489.3828 | J6: =IFERROR(J47/365*IS!J4*-1,0) -> 2871.5435 | K6: =IFERROR(K47/365*IS!K4*-1,0) -> 3267.4821
A7: 其他流动资产 | B7: =567313000/ReportUnit -> 567.313 | C7: =552693000/ReportUnit -> 552.693 | D7: =404953000/ReportUnit -> 404.953 | E7: =473495000/ReportUnit -> 473.495 | F7: =424959000/ReportUnit -> 424.959 | G7: =IS!G3*G57 -> 626.70172 | H7: =IS!H3*H57 -> 746.87108 | I7: =IS!I3*I57 -> 874.87538 | J7: =IS!J3*J57 -> 1009.183 | K7: =IS!K3*K57 -> 1148.3327
A8: 流动资产总额 | B8: =9588341000/ReportUnit -> 9588.341 | C8: =9796281000/ReportUnit -> 9796.281 | D8: =10489497000/ReportUnit -> 10489.497 | E8: =11774066000/ReportUnit -> 11774.066 | F8: =13318817000/ReportUnit -> 13318.817 | G8: =G3+G4+G5+G6+G7 -> 14830.165 | H8: =H3+H4+H5+H6+H7 -> 16889.806 | I8: =I3+I4+I5+I6+I7 -> 19214.218 | J8: =J3+J4+J5+J6+J7 -> 21817.131 | K8: =K3+K4+K5+K6+K7 -> 24915.944
A10: 物业、厂房及设备 (净值) | B10: =1472208000/ReportUnit -> 1472.208 | C10: =1615569000/ReportUnit -> 1615.569 | D10: =1958179000/ReportUnit -> 1958.179 | E10: =2167583000/ReportUnit -> 2167.583 | F10: =2333133000/ReportUnit -> 2333.133 | G10: ='D&A'!G5 -> 2899.9814 | H10: ='D&A'!H5 -> 3521.9461 | I10: ='D&A'!I5 -> 4193.0099 | J10: ='D&A'!J5 -> 4904.5355 | K10: ='D&A'!K5 -> 5645.5282
A11: 商誉 | B11: =338317000/ReportUnit -> 338.317 | C11: =330636000/ReportUnit -> 330.636 | D11: =330636000/ReportUnit -> 330.636 | E11: =330636000/ReportUnit -> 330.636 | F11: =330636000/ReportUnit -> 330.636 | G11: =F11 -> 330.636 | H11: =G11 -> 330.636 | I11: =H11 -> 330.636 | J11: =I11 -> 330.636 | K11: =J11 -> 330.636
A12: 无形资产 | B12: =568210000/ReportUnit -> 568.21 | C12: =546483000/ReportUnit -> 546.483 | D12: =523826000/ReportUnit -> 523.826 | E12: =511578000/ReportUnit -> 511.578 | F12: =519259000/ReportUnit -> 519.259 | G12: ='D&A'!G27 -> 674.46372 | H12: ='D&A'!H27 -> 844.27739 | I12: ='D&A'!I27 -> 1027.1051 | J12: ='D&A'!J27 -> 1220.6575 | K12: ='D&A'!K27 -> 1422.0204
A13: 长期投资 | B13: =0/ReportUnit -> 0 | C13: =8395000/ReportUnit -> 8.395 | D13: =9151000/ReportUnit -> 9.151 | E13: =9426000/ReportUnit -> 9.426 | F13: =10373000/ReportUnit -> 10.373 | G13: =Cash!G12 -> 10.373 | H13: =Cash!H12 -> 10.373 | I13: =Cash!I12 -> 10.373 | J13: =Cash!J12 -> 10.373 | K13: =Cash!K12 -> 10.373
A14: 递延税资产 | B14: =62143000/ReportUnit -> 62.143 | C14: =91464000/ReportUnit -> 91.464 | D14: =119564000/ReportUnit -> 119.564 | E14: =153786000/ReportUnit -> 153.786 | F14: =162867000/ReportUnit -> 162.867 | G14: =Tax!G17 -> 162.867 | H14: =Tax!H17 -> 162.867 | I14: =Tax!I17 -> 162.867 | J14: =Tax!J17 -> 162.867 | K14: =Tax!K17 -> 162.867
A15: 其他非流动资产 | B15: =642920000/ReportUnit -> 642.92 | C15: =637227000/ReportUnit -> 637.227 | D15: =449266000/ReportUnit -> 449.266 | E15: =779823000/ReportUnit -> 779.823 | F15: =907827000/ReportUnit -> 907.827 | G15: =IS!G3*G58 -> 993.59337 | H15: =IS!H3*H58 -> 1184.1138 | I15: =IS!I3*I58 -> 1387.056 | J15: =IS!J3*J58 -> 1599.9916 | K15: =IS!K3*K58 -> 1820.6041
A16: 非流动资产总额 | B16: =3083798000/ReportUnit -> 3083.798 | C16: =3229774000/ReportUnit -> 3229.774 | D16: =3390622000/ReportUnit -> 3390.622 | E16: =3952832000/ReportUnit -> 3952.832 | F16: =4264095000/ReportUnit -> 4264.095 | G16: =G10+G11+G12+G13+G14+G15 -> 5071.9145 | H16: =H10+H11+H12+H13+H14+H15 -> 6054.2133 | I16: =I10+I11+I12+I13+I14+I15 -> 7111.047 | J16: =J10+J11+J12+J13+J14+J15 -> 8229.0606 | K16: =K10+K11+K12+K13+K14+K15 -> 9392.0287
A17: 资产总额 | B17: =12672139000/ReportUnit -> 12672.139 | C17: =13026055000/ReportUnit -> 13026.055 | D17: =13880119000/ReportUnit -> 13880.119 | E17: =15726898000/ReportUnit -> 15726.898 | F17: =17582912000/ReportUnit -> 17582.912 | G17: =G8+G16 -> 19902.079 | H17: =H8+H16 -> 22944.019 | I17: =I8+I16 -> 26325.265 | J17: =J8+J16 -> 30046.191 | K17: =K8+K16 -> 34307.973
A19: 应付账款 | B19: =3629591000/ReportUnit -> 3629.591 | C19: =4050619000/ReportUnit -> 4050.619 | D19: =4391674000/ReportUnit -> 4391.674 | E19: =5619291000/ReportUnit -> 5619.291 | F19: =6548212000/ReportUnit -> 6548.212 | G19: =IFERROR(G48/365*IS!G4*-1,0) -> 7242.0539 | H19: =IFERROR(H48/365*IS!H4*-1,0) -> 8370.2901 | I19: =IFERROR(I48/365*IS!I4*-1,0) -> 9499.8002 | J19: =IFERROR(J48/365*IS!J4*-1,0) -> 10606.291 | K19: =IFERROR(K48/365*IS!K4*-1,0) -> 11868.523
A20: 短期债务 | B20: =2046566000/ReportUnit -> 2046.566 | C20: =1714799000/ReportUnit -> 1714.799 | D20: =1679302000/ReportUnit -> 1679.302 | E20: =1615723000/ReportUnit -> 1615.723 | F20: =1400820000/ReportUnit -> 1400.82 | G20: =Cash!G16 -> 1400.82 | H20: =Cash!H16 -> 1400.82 | I20: =Cash!I16 -> 1400.82 | J20: =Cash!J16 -> 1400.82 | K20: =Cash!K16 -> 1400.82
A21: 应交税金 | B21: =74530000/ReportUnit -> 74.53 | C21: =100053000/ReportUnit -> 100.053 | D21: =101575000/ReportUnit -> 101.575 | E21: =110795000/ReportUnit -> 110.795 | F21: =137103000/ReportUnit -> 137.103 | G21: =F21 -> 137.103 | H21: =G21 -> 137.103 | I21: =H21 -> 137.103 | J21: =I21 -> 137.103 | K21: =J21 -> 137.103
A22: 递延收入 | B22: =0/ReportUnit -> 0 | C22: =0/ReportUnit -> 0 | D22: =0/ReportUnit -> 0 | E22: =0/ReportUnit -> 0 | F22: =0/ReportUnit -> 0 | G22: =IS!G3*G55 -> 0 | H22: =IS!H3*H55 -> 0 | I22: =IS!I3*I55 -> 0 | J22: =IS!J3*J55 -> 0 | K22: =IS!K3*K55 -> 0
A23: 其他流动负债 | B23: =7891000/ReportUnit -> 7.891 | C23: =47231000/ReportUnit -> 47.231 | D23: =55160000/ReportUnit -> 55.16 | E23: =30301000/ReportUnit -> 30.301 | F23: =9257000/ReportUnit -> 9.257 | G23: =IS!G51*G59*-1 -> 48.850145 | H23: =IS!H51*H59*-1 -> 58.217106 | I23: =IS!I51*I59*-1 -> 68.194785 | J23: =IS!J51*J59*-1 -> 78.663793 | K23: =IS!K51*K59*-1 -> 89.510234
A24: 流动负债总额 | B24: =5758578000/ReportUnit -> 5758.578 | C24: =5912702000/ReportUnit -> 5912.702 | D24: =6227711000/ReportUnit -> 6227.711 | E24: =7376110000/ReportUnit -> 7376.11 | F24: =8095392000/ReportUnit -> 8095.392 | G24: =G19+G20+G21+G22+G23 -> 8828.827 | H24: =H19+H20+H21+H22+H23 -> 9966.4302 | I24: =I19+I20+I21+I22+I23 -> 11105.918 | J24: =J19+J20+J21+J22+J23 -> 12222.878 | K24: =K19+K20+K21+K22+K23 -> 13495.957
A26: 长期债务 | B26: =790335000/ReportUnit -> 790.335 | C26: =946843000/ReportUnit -> 946.843 | D26: =835144000/ReportUnit -> 835.144 | E26: =971473000/ReportUnit -> 971.473 | F26: =1086081000/ReportUnit -> 1086.081 | G26: =Cash!G18 -> 1086.081 | H26: =Cash!H18 -> 1086.081 | I26: =Cash!I18 -> 1086.081 | J26: =Cash!J18 -> 1086.081 | K26: =Cash!K18 -> 1086.081
A27: 递延收入非流动部分 | B27: =0/ReportUnit -> 0 | C27: =0/ReportUnit -> 0 | D27: =0/ReportUnit -> 0 | E27: =0/ReportUnit -> 0 | F27: =0/ReportUnit -> 0 | G27: =F27 -> 0 | H27: =G27 -> 0 | I27: =H27 -> 0 | J27: =I27 -> 0 | K27: =J27 -> 0
A28: 递延税负债 | B28: =34466000/ReportUnit -> 34.466 | C28: =33499000/ReportUnit -> 33.499 | D28: =36848000/ReportUnit -> 36.848 | E28: =38872000/ReportUnit -> 38.872 | F28: =45686000/ReportUnit -> 45.686 | G28: =Tax!G19 -> 45.686 | H28: =Tax!H19 -> 45.686 | I28: =Tax!I19 -> 45.686 | J28: =Tax!J19 -> 45.686 | K28: =Tax!K19 -> 45.686
A29: 租赁负债 | B29: =8898000/ReportUnit -> 8.898 | C29: =4535000/ReportUnit -> 4.535 | D29: =3795000/ReportUnit -> 3.795 | E29: =19515000/ReportUnit -> 19.515 | F29: =12816000/ReportUnit -> 12.816 | G29: =F29 -> 12.816 | H29: =G29 -> 12.816 | I29: =H29 -> 12.816 | J29: =I29 -> 12.816 | K29: =J29 -> 12.816
A30: 其他非流动负债 | B30: =0/ReportUnit -> 0 | C30: =0/ReportUnit -> 0 | D30: =0/ReportUnit -> 0 | E30: =0/ReportUnit -> 0 | F30: =27448000/ReportUnit -> 27.448 | G30: =IS!G51*G60*-1 -> 34.239046 | H30: =IS!H51*H60*-1 -> 40.804346 | I30: =IS!I51*I60*-1 -> 47.797697 | J30: =IS!J51*J60*-1 -> 55.13542 | K30: =IS!K51*K60*-1 -> 62.737686
A31: 非流动负债总额 | B31: =833699000/ReportUnit -> 833.699 | C31: =984877000/ReportUnit -> 984.877 | D31: =875787000/ReportUnit -> 875.787 | E31: =1029860000/ReportUnit -> 1029.86 | F31: =1172031000/ReportUnit -> 1172.031 | G31: =G26+G27+G28+G29+G30 -> 1178.822 | H31: =H26+H27+H28+H29+H30 -> 1185.3873 | I31: =I26+I27+I28+I29+I30 -> 1192.3807 | J31: =J26+J27+J28+J29+J30 -> 1199.7184 | K31: =K26+K27+K28+K29+K30 -> 1207.3207
A32: 负债总额 | B32: =6592277000/ReportUnit -> 6592.277 | C32: =6897579000/ReportUnit -> 6897.579 | D32: =7103498000/ReportUnit -> 7103.498 | E32: =8405970000/ReportUnit -> 8405.97 | F32: =9267423000/ReportUnit -> 9267.423 | G32: =G24+G31 -> 10007.649 | H32: =H24+H31 -> 11151.818 | I32: =I24+I31 -> 12298.299 | J32: =J24+J31 -> 13422.597 | K32: =K24+K31 -> 14703.277
A34: 实收资本 | B34: =9906000/ReportUnit -> 9.906 | C34: =9906000/ReportUnit -> 9.906 | D34: =9906000/ReportUnit -> 9.906 | E34: =9906000/ReportUnit -> 9.906 | F34: =9906000/ReportUnit -> 9.906 | G34: =Cash!G28 -> 9.906 | H34: =Cash!H28 -> 9.906 | I34: =Cash!I28 -> 9.906 | J34: =Cash!J28 -> 9.906 | K34: =Cash!K28 -> 9.906
A35: 资本公积 | B35: =0/ReportUnit -> 0 | C35: =0/ReportUnit -> 0 | D35: =0/ReportUnit -> 0 | E35: =0/ReportUnit -> 0 | F35: =0/ReportUnit -> 0 | G35: =Cash!G29 -> 0 | H35: =Cash!H29 -> 0 | I35: =Cash!I29 -> 0 | J35: =Cash!J29 -> 0 | K35: =Cash!K29 -> 0
A36: 优先股 | B36: =0/ReportUnit -> 0 | C36: =0/ReportUnit -> 0 | D36: =0/ReportUnit -> 0 | E36: =0/ReportUnit -> 0 | F36: =0/ReportUnit -> 0 | G36: =F36 -> 0 | H36: =G36 -> 0 | I36: =H36 -> 0 | J36: =I36 -> 0 | K36: =J36 -> 0
A37: 留存收益 | B37: =0/ReportUnit -> 0 | C37: =0/ReportUnit -> 0 | D37: =0/ReportUnit -> 0 | E37: =0/ReportUnit -> 0 | F37: =0/ReportUnit -> 0 | G37: =F37+IS!G17+CFS!G28 -> 1199.5195 | H37: =G37+IS!H17+CFS!H28 -> 2625.6207 | I37: =H37+IS!I17+CFS!I28 -> 4304.9587 | J37: =I37+IS!J17+CFS!J28 -> 6256.2238 | K37: =J37+IS!K17+CFS!K28 -> 8496.4045
A38: 累计其他综合收益 (亏损) | B38: =4622020000/ReportUnit -> 4622.02 | C38: =4645998000/ReportUnit -> 4645.998 | D38: =5156730000/ReportUnit -> 5156.73 | E38: =5422701000/ReportUnit -> 5422.701 | F38: =6225852000/ReportUnit -> 6225.852 | G38: =F38 -> 6225.852 | H38: =G38 -> 6225.852 | I38: =H38 -> 6225.852 | J38: =I38 -> 6225.852 | K38: =J38 -> 6225.852
A39: 其他股东权益总额 | B39: =0/ReportUnit -> 0 | C39: =0/ReportUnit -> 0 | D39: =0/ReportUnit -> 0 | E39: =0/ReportUnit -> 0 | F39: =0/ReportUnit -> 0 | G39: =F39 -> 0 | H39: =G39 -> 0 | I39: =H39 -> 0 | J39: =I39 -> 0 | K39: =J39 -> 0
A40: 股东权益总额 | B40: =4631926000/ReportUnit -> 4631.926 | C40: =4655904000/ReportUnit -> 4655.904 | D40: =5166636000/ReportUnit -> 5166.636 | E40: =5432607000/ReportUnit -> 5432.607 | F40: =6235758000/ReportUnit -> 6235.758 | G40: =G34+G35+G36+G37+G38+G39 -> 7435.2775 | H40: =H34+H35+H36+H37+H38+H39 -> 8861.3787 | I40: =I34+I35+I36+I37+I38+I39 -> 10540.717 | J40: =J34+J35+J36+J37+J38+J39 -> 12491.982 | K40: =K34+K35+K36+K37+K38+K39 -> 14732.162
A41: 少数股东权益 | B41: =1447936000/ReportUnit -> 1447.936 | C41: =1472572000/ReportUnit -> 1472.572 | D41: =1609985000/ReportUnit -> 1609.985 | E41: =1888321000/ReportUnit -> 1888.321 | F41: =2079731000/ReportUnit -> 2079.731 | G41: =IF(F40<0,F41,G42*G56) -> 2459.1525 | H41: =IF(F40<0,G41,H42*H56) -> 2930.8229 | I41: =IF(F40<0,H41,I42*I56) -> 3486.2492 | J41: =IF(F40<0,I41,J42*J56) -> 4131.6129 | K41: =IF(F40<0,J41,K42*K56) -> 4872.533
A42: 权益总额 | B42: =B40+B41 -> 6079.862 | C42: =C40+C41 -> 6128.476 | D42: =D40+D41 -> 6776.621 | E42: =E40+E41 -> 7320.928 | F42: =F40+F41 -> 8315.489 | G42: =G40+G41 -> 9894.43 | H42: =H40+H41 -> 11792.202 | I42: =I40+I41 -> 14026.966 | ... K42: =K40+K41 -> 19604.695
A43: 负债和权益总额 | B43: =B32+B42 -> 12672.139 | C43: =C32+C42 -> 13026.055 | D43: =D32+D42 -> 13880.119 | E43: =E32+E42 -> 15726.898 | F43: =F32+F42 -> 17582.912 | G43: =G32+G42 -> 19902.079 | H43: =H32+H42 -> 22944.019 | I43: =I32+I42 -> 26325.265 | ... K43: =K32+K42 -> 34307.973
A45: 资产周转率
...

Sheet CFS
A1: ="03393.HK in "&IF(ReportUnit<1000, "", IF(ReportUnit<1000000, "Thousands", IF(ReportUnit<1000000000, "Millions", "Billions")))&" CNY" -> 03393.HK in Millions CNY | B1: FY2021A | C1: FY2022A | D1: FY2023A | E1: FY2024A | F1: FY2025A | G1: FY2026E | H1: FY2027E | I1: FY2028E | J1: FY2029E | K1: FY2030E
A2: 现金流量表
A3: 净利润 | B3: =427974000/ReportUnit -> 427.974 | C3: =511160000/ReportUnit -> 511.16 | D3: =760593000/ReportUnit -> 760.593 | E3: =1030162000/ReportUnit -> 1030.162 | F3: =1481104000/ReportUnit -> 1481.104 | G3: =IS!G17 -> 1873.1353 | H3: =IS!H17 -> 2226.9588 | I3: =IS!I17 -> 2622.4061 | J3: =IS!J17 -> 3047.0397 | K3: =IS!K17 -> 3498.202
A4: 折旧和摊销 | B4: =IS!B32 -> 219.222 | C4: =IS!C32 -> 266.999 | D4: =IS!D32 -> 276.812 | E4: =IS!E32 -> 316 | F4: =IS!F32 -> 353 | G4: =-'D&A'!G25-'D&A'!G47 -> 238.69435 | H4: =-'D&A'!H25-'D&A'!H47 -> 353.19132 | I4: =-'D&A'!I25-'D&A'!I47 -> 487.31163 | J4: =-'D&A'!J25-'D&A'!J47 -> 642.02159 | K4: =-'D&A'!K25-'D&A'!K47 -> 818.0635
A5: 所得税费用 | B5: =44759000/ReportUnit -> 44.759 | C5: =71274000/ReportUnit -> 71.274 | D5: =100139000/ReportUnit -> 100.139 | E5: =0/ReportUnit -> 0 | F5: =0/ReportUnit -> 0 | G5: =-Tax!G6 -> 300.23425 | H5: =-Tax!H6 -> 356.94662 | I5: =-Tax!I6 -> 420.33063 | J5: =-Tax!J6 -> 488.39274 | K5: =-Tax!K6 -> 560.70699
A6: 应收账款变动 | B6: =-235266000/ReportUnit -> -235.266 | C6: =-450818000/ReportUnit -> -450.818 | D6: =-198186000/ReportUnit -> -198.186 | E6: =0/ReportUnit -> 0 | F6: =0/ReportUnit -> 0 | G6: =+(BS!F5-BS!G5) -> -983.979 | H6: =+(BS!G5-BS!H5) -> -921.36123 | I6: =+(BS!H5-BS!I5) -> -757.73813 | J6: =+(BS!I5-BS!J5) -> -551.69577 | K6: =+(BS!J5-BS!K5) -> -310.55354
A7: 存货变动 | B7: =-488616000/ReportUnit -> -488.616 | C7: =-109740000/ReportUnit -> -109.74 | D7: =-117801000/ReportUnit -> -117.801 | E7: =0/ReportUnit -> 0 | F7: =0/ReportUnit -> 0 | G7: =+(BS!F6-BS!G6) -> -345.33796 | H7: =+(BS!G6-BS!H6) -> -341.93159 | I7: =+(BS!H6-BS!I6) -> -364.22525 | J7: =+(BS!I6-BS!J6) -> -382.16073 | K7: =+(BS!J6-BS!K6) -> -395.93853
A8: 应付账款变动 | B8: =266913000/ReportUnit -> 266.913 | C8: =328915000/ReportUnit -> 328.915 | D8: =277420000/ReportUnit -> 277.42 | E8: =0/ReportUnit -> 0 | F8: =0/ReportUnit -> 0 | G8: =-(BS!F19-BS!G19) -> 693.84186 | H8: =-(BS!G19-BS!H19) -> 1128.2362 | I8: =-(BS!H19-BS!I19) -> 1129.5101 | J8: =-(BS!I19-BS!J19) -> 1106.4911 | K8: =-(BS!J19-BS!K19) -> 1262.232
A9: 其他营运资金变动 | B9: =-127886000/ReportUnit -> -127.886 | C9: =100147000/ReportUnit -> 100.147 | D9: =149214000/ReportUnit -> 149.214 | E9: =0/ReportUnit -> 0 | F9: =0/ReportUnit -> 0 | G9: =-(BS!F22-BS!G22)-(BS!F27-BS!G27) -> 0 | H9: =-(BS!G22-BS!H22)-(BS!G27-BS!H27) -> 0 | I9: =-(BS!H22-BS!I22)-(BS!H27-BS!I27) -> 0 | J9: =-(BS!I22-BS!J22)-(BS!I27-BS!J27) -> 0 | K9: =-(BS!J22-BS!K22)-(BS!J27-BS!K27) -> 0
A10: 其他非现金项目 | B10: =190647000/ReportUnit -> 190.647 | C10: =220350000/ReportUnit -> 220.35 | D10: =372134000/ReportUnit -> 372.134 | E10: =0/ReportUnit -> 0 | F10: =0/ReportUnit -> 0 | G10: =+(BS!F11-BS!G11)+(BS!F15-BS!G15)+(BS!F14-BS!G14)-(BS!F21-BS!G21)-(BS!F27-BS!G27)-(BS!F30-BS!G30)+(BS!F7-BS!G7)-(BS!F23-BS!G23)-'D&A'!G12-'D&A'!G34 -> -241.1249 | H10: =+(BS!G11-BS!H11)+(BS!G15-BS!H15)+(BS!G14-BS!H14)-(BS!G21-BS!H21)-(BS!G27-BS!H27)-(BS!G30-BS!H30)+(BS!G7-BS!H7)-(BS!G23-BS!H23)-'D&A'!H12-'D&A'!H34 -> -294.75752 | I10: =+(BS!H11-BS!I11)+(BS!H15-BS!I15)+(BS!H14-BS!I14)-(BS!H21-BS!I21)-(BS!H27-BS!I27)-(BS!H30-BS!I30)+(BS!H7-BS!I7)-(BS!H23-BS!I23)-'D&A'!I12-'D&A'!I34 -> -313.97547 | J10: =+(BS!I11-BS!J11)+(BS!I15-BS!J15)+(BS!I14-BS!J14)-(BS!I21-BS!J21)-(BS!I27-BS!J27)-(BS!I30-BS!J30)+(BS!I7-BS!J7)-(BS!I23-BS!J23)-'D&A'!J12-'D&A'!J34 -> -329.43651 | K10: =+(BS!J11-BS!K11)+(BS!J15-BS!K15)+(BS!J14-BS!K14)-(BS!J21-BS!K21)-(BS!J27-BS!K27)-(BS!J30-BS!K30)+(BS!J7-BS!K7)-(BS!J23-BS!K23)-'D&A'!K12-'D&A'!K34 -> -341.31347
A11: 缴纳税金 | B11: =-46124000/ReportUnit -> -46.124 | C11: =-75057000/ReportUnit -> -75.057 | D11: =-123730000/ReportUnit -> -123.73 | E11: =0/ReportUnit -> 0 | F11: =0/ReportUnit -> 0 | G11: =Tax!G21 -> -300.23425 | H11: =Tax!H21 -> -356.94662 | I11: =Tax!I21 -> -420.33063 | J11: =Tax!J21 -> -488.39274 | K11: =Tax!K21 -> -560.70699
A12: 经营活动提供的净现金 | B12: =251623000/ReportUnit -> 251.623 | C12: =863230000/ReportUnit -> 863.23 | D12: =1496595000/ReportUnit -> 1496.595 | E12: 927 | F12: 1835 | G12: =G3+G4+G5+G6+G7+G8+G9+G11+G10 -> 1235.2296 | H12: =H3+H4+H5+H6+H7+H8+H9+H11+H10 -> 2150.336 | I12: =I3+I4+I5+I6+I7+I8+I9+I11+I10 -> 2803.289 | J12: =J3+J4+J5+J6+J7+J8+J9+J11+J10 -> 3532.2594 | K12: =K3+K4+K5+K6+K7+K8+K9+K11+K10 -> 4530.692
A14: 投资购买 | B14: =0/ReportUnit -> 0 | C14: =-29898000/ReportUnit -> -29.898 | D14: =-33267000/ReportUnit -> -33.267 | E14: =0/ReportUnit -> 0 | F14: =0/ReportUnit -> 0 | G14: =+IF((BS!F4-BS!G4)>0,0,(BS!F4-BS!G4)) -> 0 | H14: =+IF((BS!G4-BS!H4)>0,0,(BS!G4-BS!H4)) -> 0 | I14: =+IF((BS!H4-BS!I4)>0,0,(BS!H4-BS!I4)) -> 0 | J14: =+IF((BS!I4-BS!J4)>0,0,(BS!I4-BS!J4)) -> 0 | K14: =+IF((BS!J4-BS!K4)>0,0,(BS!J4-BS!K4)) -> 0
A15: 投资销售/到期 | B15: =3060000/ReportUnit -> 3.06 | C15: =0/ReportUnit -> 0 | D15: =0/ReportUnit -> 0 | E15: =0/ReportUnit -> 0 | F15: =0/ReportUnit -> 0 | G15: =+IF((BS!F4-BS!G4)<0,0,(BS!F4-BS!G4)) -> 0 | H15: =+IF((BS!G4-BS!H4)<0,0,(BS!G4-BS!H4)) -> 0 | I15: =+IF((BS!H4-BS!I4)<0,0,(BS!H4-BS!I4)) -> 0 | J15: =+IF((BS!I4-BS!J4)<0,0,(BS!I4-BS!J4)) -> 0 | K15: =+IF((BS!J4-BS!K4)<0,0,(BS!J4-BS!K4)) -> 0
A16: 物业、厂房及设备的资本支出 | B16: =-216651000/ReportUnit -> -216.651 | C16: =-246336000/ReportUnit -> -246.336 | D16: =-446293000/ReportUnit -> -446.293 | E16: =0/ReportUnit -> 0 | F16: =0/ReportUnit -> 0 | G16: =-'D&A'!G15 -> -759.45005 | H16: =-'D&A'!H15 -> -905.07375 | I16: =-'D&A'!I15 -> -1060.192 | J16: =-'D&A'!J15 -> -1222.9487 | K16: =-'D&A'!K15 -> -1391.5732
A17: 物业、厂房及设备的销售 | B17: =6246000/ReportUnit -> 6.246 | C17: =20072000/ReportUnit -> 20.072 | D17: =6466000/ReportUnit -> 6.466 | E17: =0/ReportUnit -> 0 | F17: =0/ReportUnit -> 0 | G17: ='D&A'!G10 -> 0 | H17: ='D&A'!H10 -> 0 | I17: ='D&A'!I10 -> 0 | J17: ='D&A'!J10 -> 0 | K17: ='D&A'!K10 -> 0
A18: 无形资产的资本支出 | B18: =-162782000/ReportUnit -> -162.782 | C18: =-143404000/ReportUnit -> -143.404 | D18: =-118293000/ReportUnit -> -118.293 | E18: =0/ReportUnit -> 0 | F18: =0/ReportUnit -> 0 | G18: =-'D&A'!G37 -> -201.29741 | H18: =-'D&A'!H37 -> -239.89596 | I18: =-'D&A'!I37 -> -281.01111 | J18: =-'D&A'!J37 -> -324.15088 | K18: =-'D&A'!K37 -> -368.84595
A19: 无形资产的销售 | B19: =0/ReportUnit -> 0 | C19: =0/ReportUnit -> 0 | D19: =0/ReportUnit -> 0 | E19: =0/ReportUnit -> 0 | F19: =0/ReportUnit -> 0 | G19: ='D&A'!G32 -> 0 | H19: ='D&A'!H32 -> 0 | I19: ='D&A'!I32 -> 0 | J19: ='D&A'!J32 -> 0 | K19: ='D&A'!K32 -> 0
A20: 并购 (净值) | B20: =-44483000/ReportUnit -> -44.483 | C20: =-5160000/ReportUnit -> -5.16 | D20: =-37970000/ReportUnit -> -37.97 | E20: =0/ReportUnit -> 0 | F20: =0/ReportUnit -> 0 | G20: =+(BS!F13-BS!G13) -> 0 | H20: =+(BS!G13-BS!H13) -> 0 | I20: =+(BS!H13-BS!I13) -> 0 | J20: =+(BS!I13-BS!J13) -> 0 | K20: =+(BS!J13-BS!K13) -> 0
